/*
 * Decompiled with CFR 0.152.
 * 
 * Could not load the following classes:
 *  net.minecraft.entity.Entity
 *  net.minecraft.world.World
 *  net.minecraft.world.gen.feature.WorldGenerator
 */
package net.divinerpg.dimensions.boiling.gen;

import java.util.Random;
import net.divinerpg.entities.boil.npc.EntityEscapedConvict;
import net.divinerpg.utils.blocks.JourneyBlocks;
import net.minecraft.entity.Entity;
import net.minecraft.world.World;
import net.minecraft.world.gen.feature.WorldGenerator;

public class WorldGenBrisonNetwork
extends WorldGenerator {
    public boolean generate(World world, Random rand, int x, int y, int z) {
        int i = x;
        int cx = i + 7;
        int j = y;
        int cy = j - 1;
        int k = z;
        int cz = k + 7;
        if (world.getBlock(cx + 3, cy, cz) == JourneyBlocks.hotBlock && world.getBlock(cx - 3, cy, cz) == JourneyBlocks.hotBlock && world.getBlock(cx, cy, cz + 3) == JourneyBlocks.hotBlock && world.getBlock(cx, cy, cz - 3) == JourneyBlocks.hotBlock) {
            world.setBlock(i + 0, j + 0, k + 1, JourneyBlocks.sizzlingPost);
            world.setBlock(i + 0, j + 11, k + 6, JourneyBlocks.smallBrisonBrick);
            world.setBlock(i + 0, j + 11, k + 7, JourneyBlocks.smallBrisonBrick);
            world.setBlock(i + 0, j + 11, k + 8, JourneyBlocks.smallBrisonBrick);
            world.setBlock(i + 0, j + 12, k + 6, JourneyBlocks.boilingLog);
            world.setBlock(i + 0, j + 12, k + 7, JourneyBlocks.boilingBars);
            world.setBlock(i + 0, j + 12, k + 8, JourneyBlocks.boilingLog);
            world.setBlock(i + 0, j + 13, k + 6, JourneyBlocks.boilingLog);
            world.setBlock(i + 0, j + 13, k + 7, JourneyBlocks.boilingBars);
            world.setBlock(i + 0, j + 13, k + 8, JourneyBlocks.boilingLog);
            world.setBlock(i + 0, j + 14, k + 6, JourneyBlocks.boilingLog);
            world.setBlock(i + 0, j + 14, k + 7, JourneyBlocks.boilingBars);
            world.setBlock(i + 0, j + 14, k + 8, JourneyBlocks.boilingLog);
            world.setBlock(i + 0, j + 15, k + 6, JourneyBlocks.smallBrisonBrick);
            world.setBlock(i + 0, j + 15, k + 7, JourneyBlocks.smallBrisonBrick);
            world.setBlock(i + 0, j + 15, k + 8, JourneyBlocks.smallBrisonBrick);
            world.setBlock(i + 1, j + 11, k + 6, JourneyBlocks.smallBrisonBrick);
            world.setBlock(i + 1, j + 11, k + 8, JourneyBlocks.smallBrisonBrick);
            world.setBlock(i + 1, j + 12, k + 6, JourneyBlocks.boilingBars);
            world.setBlock(i + 1, j + 12, k + 8, JourneyBlocks.boilingBars);
            world.setBlock(i + 1, j + 13, k + 6, JourneyBlocks.boilingBars);
            world.setBlock(i + 1, j + 13, k + 8, JourneyBlocks.boilingBars);
            world.setBlock(i + 1, j + 14, k + 6, JourneyBlocks.boilingBars);
            world.setBlock(i + 1, j + 14, k + 7, JourneyBlocks.boilingLamp);
            world.setBlock(i + 1, j + 14, k + 8, JourneyBlocks.boilingBars);
            world.setBlock(i + 1, j + 15, k + 6, JourneyBlocks.smallBrisonBrick);
            world.setBlock(i + 1, j + 15, k + 7, JourneyBlocks.smallBrisonBrick);
            world.setBlock(i + 1, j + 15, k + 8, JourneyBlocks.smallBrisonBrick);
            world.setBlock(i + 1, j + 16, k + 7, JourneyBlocks.sizzlingPost);
            world.setBlock(i + 1, j + 17, k + 7, JourneyBlocks.sizzlingPost);
            world.setBlock(i + 2, j + 11, k + 6, JourneyBlocks.smallBrisonBrick);
            world.setBlock(i + 2, j + 11, k + 7, JourneyBlocks.smallBrisonBrick);
            world.setBlock(i + 2, j + 11, k + 8, JourneyBlocks.smallBrisonBrick);
            world.setBlock(i + 2, j + 12, k + 6, JourneyBlocks.boilingLog);
            world.setBlock(i + 2, j + 12, k + 7, JourneyBlocks.boilingBars);
            world.setBlock(i + 2, j + 12, k + 8, JourneyBlocks.boilingLog);
            world.setBlock(i + 2, j + 13, k + 6, JourneyBlocks.boilingLog);
            world.setBlock(i + 2, j + 13, k + 7, JourneyBlocks.boilingBars);
            world.setBlock(i + 2, j + 13, k + 8, JourneyBlocks.boilingLog);
            world.setBlock(i + 2, j + 14, k + 6, JourneyBlocks.boilingLog);
            world.setBlock(i + 2, j + 14, k + 7, JourneyBlocks.boilingBars);
            world.setBlock(i + 2, j + 14, k + 8, JourneyBlocks.boilingLog);
            world.setBlock(i + 2, j + 15, k + 6, JourneyBlocks.smallBrisonBrick);
            world.setBlock(i + 2, j + 15, k + 7, JourneyBlocks.smallBrisonBrick);
            world.setBlock(i + 2, j + 15, k + 8, JourneyBlocks.smallBrisonBrick);
            world.setBlock(i + 2, j + 17, k + 7, JourneyBlocks.sizzlingPost);
            world.setBlock(i + 3, j + 17, k + 7, JourneyBlocks.sizzlingPost);
            world.setBlock(i + 4, j + 17, k + 7, JourneyBlocks.sizzlingPost);
            world.setBlock(i + 5, j + 0, k + 5, JourneyBlocks.smallBrisonBrick);
            world.setBlock(i + 5, j + 0, k + 6, JourneyBlocks.smallBrisonBrick);
            world.setBlock(i + 5, j + 0, k + 7, JourneyBlocks.smallBrisonBrick);
            world.setBlock(i + 5, j + 0, k + 8, JourneyBlocks.smallBrisonBrick);
            world.setBlock(i + 5, j + 0, k + 9, JourneyBlocks.smallBrisonBrick);
            world.setBlock(i + 5, j + 1, k + 5, JourneyBlocks.boilingLog);
            world.setBlock(i + 5, j + 1, k + 6, JourneyBlocks.sizzlingPost);
            world.setBlock(i + 5, j + 1, k + 8, JourneyBlocks.sizzlingPost);
            world.setBlock(i + 5, j + 1, k + 9, JourneyBlocks.boilingLog);
            world.setBlock(i + 5, j + 2, k + 5, JourneyBlocks.boilingLog);
            world.setBlock(i + 5, j + 2, k + 6, JourneyBlocks.sizzlingPost);
            world.setBlock(i + 5, j + 2, k + 8, JourneyBlocks.sizzlingPost);
            world.setBlock(i + 5, j + 2, k + 9, JourneyBlocks.boilingLog);
            world.setBlock(i + 5, j + 3, k + 5, JourneyBlocks.boilingLog);
            world.setBlock(i + 5, j + 3, k + 6, JourneyBlocks.sizzlingPost);
            world.setBlock(i + 5, j + 3, k + 8, JourneyBlocks.sizzlingPost);
            world.setBlock(i + 5, j + 3, k + 9, JourneyBlocks.boilingLog);
            world.setBlock(i + 5, j + 4, k + 5, JourneyBlocks.boilingLog);
            world.setBlock(i + 5, j + 4, k + 6, JourneyBlocks.sizzlingPost);
            world.setBlock(i + 5, j + 4, k + 8, JourneyBlocks.sizzlingPost);
            world.setBlock(i + 5, j + 4, k + 9, JourneyBlocks.boilingLog);
            world.setBlock(i + 5, j + 17, k + 7, JourneyBlocks.sizzlingPost);
            world.setBlock(i + 6, j + 0, k + 5, JourneyBlocks.smallBrisonBrick);
            world.setBlock(i + 6, j + 0, k + 6, JourneyBlocks.smallBrisonBrick);
            world.setBlock(i + 6, j + 0, k + 7, JourneyBlocks.smallBrisonBrick);
            world.setBlock(i + 6, j + 0, k + 8, JourneyBlocks.smallBrisonBrick);
            world.setBlock(i + 6, j + 0, k + 9, JourneyBlocks.smallBrisonBrick);
            world.setBlock(i + 6, j + 1, k + 5, JourneyBlocks.sizzlingPost);
            world.setBlock(i + 6, j + 1, k + 9, JourneyBlocks.sizzlingPost);
            world.setBlock(i + 6, j + 2, k + 5, JourneyBlocks.sizzlingPost);
            world.setBlock(i + 6, j + 2, k + 9, JourneyBlocks.sizzlingPost);
            world.setBlock(i + 6, j + 3, k + 5, JourneyBlocks.sizzlingPost);
            world.setBlock(i + 6, j + 3, k + 6, JourneyBlocks.boilingLog);
            world.setBlock(i + 6, j + 3, k + 8, JourneyBlocks.boilingLog);
            world.setBlock(i + 6, j + 3, k + 9, JourneyBlocks.sizzlingPost);
            world.setBlock(i + 6, j + 4, k + 5, JourneyBlocks.sizzlingPost);
            world.setBlock(i + 6, j + 4, k + 6, JourneyBlocks.boilingLog);
            world.setBlock(i + 6, j + 4, k + 7, JourneyBlocks.smallBrisonBrick);
            world.setBlock(i + 6, j + 4, k + 8, JourneyBlocks.boilingLog);
            world.setBlock(i + 6, j + 4, k + 9, JourneyBlocks.sizzlingPost);
            world.setBlock(i + 6, j + 4, k + 12, JourneyBlocks.smallBrisonBrick);
            world.setBlock(i + 6, j + 4, k + 13, JourneyBlocks.smallBrisonBrick);
            world.setBlock(i + 6, j + 4, k + 14, JourneyBlocks.smallBrisonBrick);
            world.setBlock(i + 6, j + 5, k + 12, JourneyBlocks.boilingLog);
            world.setBlock(i + 6, j + 5, k + 13, JourneyBlocks.boilingBars);
            world.setBlock(i + 6, j + 5, k + 14, JourneyBlocks.boilingLog);
            world.setBlock(i + 6, j + 6, k + 12, JourneyBlocks.boilingLog);
            world.setBlock(i + 6, j + 6, k + 13, JourneyBlocks.boilingBars);
            world.setBlock(i + 6, j + 6, k + 14, JourneyBlocks.boilingLog);
            world.setBlock(i + 6, j + 7, k + 12, JourneyBlocks.boilingLog);
            world.setBlock(i + 6, j + 7, k + 13, JourneyBlocks.boilingBars);
            world.setBlock(i + 6, j + 7, k + 14, JourneyBlocks.boilingLog);
            world.setBlock(i + 6, j + 8, k + 12, JourneyBlocks.smallBrisonBrick);
            world.setBlock(i + 6, j + 8, k + 13, JourneyBlocks.smallBrisonBrick);
            world.setBlock(i + 6, j + 8, k + 14, JourneyBlocks.smallBrisonBrick);
            world.setBlock(i + 6, j + 10, k + 0, JourneyBlocks.smallBrisonBrick);
            world.setBlock(i + 6, j + 10, k + 1, JourneyBlocks.smallBrisonBrick);
            world.setBlock(i + 6, j + 10, k + 2, JourneyBlocks.smallBrisonBrick);
            world.setBlock(i + 6, j + 11, k + 0, JourneyBlocks.boilingLog);
            world.setBlock(i + 6, j + 11, k + 1, JourneyBlocks.boilingBars);
            world.setBlock(i + 6, j + 11, k + 2, JourneyBlocks.boilingLog);
            world.setBlock(i + 6, j + 12, k + 0, JourneyBlocks.boilingLog);
            world.setBlock(i + 6, j + 12, k + 1, JourneyBlocks.boilingBars);
            world.setBlock(i + 6, j + 12, k + 2, JourneyBlocks.boilingLog);
            world.setBlock(i + 6, j + 13, k + 0, JourneyBlocks.boilingLog);
            world.setBlock(i + 6, j + 13, k + 1, JourneyBlocks.boilingBars);
            world.setBlock(i + 6, j + 13, k + 2, JourneyBlocks.boilingLog);
            world.setBlock(i + 6, j + 14, k + 0, JourneyBlocks.smallBrisonBrick);
            world.setBlock(i + 6, j + 14, k + 1, JourneyBlocks.smallBrisonBrick);
            world.setBlock(i + 6, j + 14, k + 2, JourneyBlocks.smallBrisonBrick);
            world.setBlock(i + 6, j + 15, k + 7, JourneyBlocks.sizzlingPost);
            world.setBlock(i + 6, j + 16, k + 7, JourneyBlocks.sizzlingPost);
            world.setBlock(i + 6, j + 17, k + 7, JourneyBlocks.sizzlingPost);
            world.setBlock(i + 7, j + 0, k + 5, JourneyBlocks.smallBrisonBrick);
            world.setBlock(i + 7, j + 0, k + 6, JourneyBlocks.smallBrisonBrick);
            world.setBlock(i + 7, j + 0, k + 7, JourneyBlocks.brisonStone);
            world.setBlock(i + 7, j + 0, k + 8, JourneyBlocks.smallBrisonBrick);
            world.setBlock(i + 7, j + 0, k + 9, JourneyBlocks.smallBrisonBrick);
            world.setBlock(i + 7, j + 4, k + 6, JourneyBlocks.smallBrisonBrick);
            world.setBlock(i + 7, j + 4, k + 7, JourneyBlocks.boilingLamp);
            world.setBlock(i + 7, j + 4, k + 8, JourneyBlocks.smallBrisonBrick);
            world.setBlock(i + 7, j + 4, k + 12, JourneyBlocks.smallBrisonBrick);
            world.setBlock(i + 7, j + 4, k + 14, JourneyBlocks.smallBrisonBrick);
            world.setBlock(i + 7, j + 5, k + 7, JourneyBlocks.sizzlingPost);
            world.setBlock(i + 7, j + 5, k + 12, JourneyBlocks.boilingBars);
            world.setBlock(i + 7, j + 5, k + 14, JourneyBlocks.boilingBars);
            world.setBlock(i + 7, j + 6, k + 7, JourneyBlocks.sizzlingPost);
            world.setBlock(i + 7, j + 6, k + 12, JourneyBlocks.boilingBars);
            world.setBlock(i + 7, j + 6, k + 14, JourneyBlocks.boilingBars);
            world.setBlock(i + 7, j + 7, k + 7, JourneyBlocks.sizzlingPost);
            world.setBlock(i + 7, j + 7, k + 12, JourneyBlocks.boilingBars);
            world.setBlock(i + 7, j + 7, k + 13, JourneyBlocks.boilingLamp);
            world.setBlock(i + 7, j + 7, k + 14, JourneyBlocks.boilingBars);
            world.setBlock(i + 7, j + 8, k + 7, JourneyBlocks.sizzlingPost);
            world.setBlock(i + 7, j + 8, k + 12, JourneyBlocks.smallBrisonBrick);
            world.setBlock(i + 7, j + 8, k + 13, JourneyBlocks.smallBrisonBrick);
            world.setBlock(i + 7, j + 8, k + 14, JourneyBlocks.smallBrisonBrick);
            world.setBlock(i + 7, j + 9, k + 7, JourneyBlocks.boilingLog);
            world.setBlock(i + 7, j + 9, k + 8, JourneyBlocks.sizzlingPost);
            world.setBlock(i + 7, j + 9, k + 13, JourneyBlocks.sizzlingPost);
            world.setBlock(i + 7, j + 10, k + 0, JourneyBlocks.smallBrisonBrick);
            world.setBlock(i + 7, j + 10, k + 2, JourneyBlocks.smallBrisonBrick);
            world.setBlock(i + 7, j + 10, k + 7, JourneyBlocks.boilingLamp);
            world.setBlock(i + 7, j + 10, k + 8, JourneyBlocks.sizzlingPost);
            world.setBlock(i + 7, j + 10, k + 9, JourneyBlocks.sizzlingPost);
            world.setBlock(i + 7, j + 10, k + 10, JourneyBlocks.sizzlingPost);
            world.setBlock(i + 7, j + 10, k + 11, JourneyBlocks.sizzlingPost);
            world.setBlock(i + 7, j + 10, k + 12, JourneyBlocks.sizzlingPost);
            world.setBlock(i + 7, j + 10, k + 13, JourneyBlocks.sizzlingPost);
            world.setBlock(i + 7, j + 11, k + 0, JourneyBlocks.boilingBars);
            world.setBlock(i + 7, j + 11, k + 2, JourneyBlocks.boilingBars);
            world.setBlock(i + 7, j + 11, k + 7, JourneyBlocks.sizzlingPost);
            world.setBlock(i + 7, j + 12, k + 0, JourneyBlocks.boilingBars);
            world.setBlock(i + 7, j + 12, k + 2, JourneyBlocks.boilingBars);
            world.setBlock(i + 7, j + 12, k + 7, JourneyBlocks.sizzlingPost);
            world.setBlock(i + 7, j + 13, k + 0, JourneyBlocks.boilingBars);
            world.setBlock(i + 7, j + 13, k + 1, JourneyBlocks.boilingLamp);
            world.setBlock(i + 7, j + 13, k + 2, JourneyBlocks.boilingBars);
            world.setBlock(i + 7, j + 13, k + 7, JourneyBlocks.sizzlingPost);
            world.setBlock(i + 7, j + 14, k + 0, JourneyBlocks.smallBrisonBrick);
            world.setBlock(i + 7, j + 14, k + 1, JourneyBlocks.screamerSpawner);
            world.setBlock(i + 7, j + 14, k + 2, JourneyBlocks.smallBrisonBrick);
            world.setBlock(i + 7, j + 14, k + 7, JourneyBlocks.sizzlingPost);
            world.setBlock(i + 7, j + 15, k + 1, JourneyBlocks.sizzlingPost);
            world.setBlock(i + 7, j + 15, k + 6, JourneyBlocks.sizzlingPost);
            world.setBlock(i + 7, j + 15, k + 7, JourneyBlocks.boilingLog);
            world.setBlock(i + 7, j + 16, k + 1, JourneyBlocks.sizzlingPost);
            world.setBlock(i + 7, j + 16, k + 2, JourneyBlocks.sizzlingPost);
            world.setBlock(i + 7, j + 16, k + 3, JourneyBlocks.sizzlingPost);
            world.setBlock(i + 7, j + 16, k + 4, JourneyBlocks.sizzlingPost);
            world.setBlock(i + 7, j + 16, k + 5, JourneyBlocks.sizzlingPost);
            world.setBlock(i + 7, j + 16, k + 6, JourneyBlocks.sizzlingPost);
            world.setBlock(i + 7, j + 16, k + 7, JourneyBlocks.boilingLamp);
            world.setBlock(i + 8, j + 0, k + 5, JourneyBlocks.smallBrisonBrick);
            world.setBlock(i + 8, j + 0, k + 6, JourneyBlocks.smallBrisonBrick);
            world.setBlock(i + 8, j + 0, k + 7, JourneyBlocks.smallBrisonBrick);
            world.setBlock(i + 8, j + 0, k + 8, JourneyBlocks.smallBrisonBrick);
            world.setBlock(i + 8, j + 0, k + 9, JourneyBlocks.smallBrisonBrick);
            world.setBlock(i + 8, j + 1, k + 5, JourneyBlocks.sizzlingPost);
            world.setBlock(i + 8, j + 1, k + 9, JourneyBlocks.sizzlingPost);
            world.setBlock(i + 8, j + 2, k + 5, JourneyBlocks.sizzlingPost);
            world.setBlock(i + 8, j + 2, k + 9, JourneyBlocks.sizzlingPost);
            world.setBlock(i + 8, j + 3, k + 5, JourneyBlocks.sizzlingPost);
            world.setBlock(i + 8, j + 3, k + 6, JourneyBlocks.boilingLog);
            world.setBlock(i + 8, j + 3, k + 8, JourneyBlocks.boilingLog);
            world.setBlock(i + 8, j + 3, k + 9, JourneyBlocks.sizzlingPost);
            world.setBlock(i + 8, j + 4, k + 5, JourneyBlocks.sizzlingPost);
            world.setBlock(i + 8, j + 4, k + 6, JourneyBlocks.boilingLog);
            world.setBlock(i + 8, j + 4, k + 7, JourneyBlocks.smallBrisonBrick);
            world.setBlock(i + 8, j + 4, k + 8, JourneyBlocks.boilingLog);
            world.setBlock(i + 8, j + 4, k + 9, JourneyBlocks.sizzlingPost);
            world.setBlock(i + 8, j + 4, k + 12, JourneyBlocks.smallBrisonBrick);
            world.setBlock(i + 8, j + 4, k + 13, JourneyBlocks.smallBrisonBrick);
            world.setBlock(i + 8, j + 4, k + 14, JourneyBlocks.smallBrisonBrick);
            world.setBlock(i + 8, j + 5, k + 12, JourneyBlocks.boilingLog);
            world.setBlock(i + 8, j + 5, k + 13, JourneyBlocks.boilingBars);
            world.setBlock(i + 8, j + 5, k + 14, JourneyBlocks.boilingLog);
            world.setBlock(i + 8, j + 6, k + 12, JourneyBlocks.boilingLog);
            world.setBlock(i + 8, j + 6, k + 13, JourneyBlocks.boilingBars);
            world.setBlock(i + 8, j + 6, k + 14, JourneyBlocks.boilingLog);
            world.setBlock(i + 8, j + 7, k + 12, JourneyBlocks.boilingLog);
            world.setBlock(i + 8, j + 7, k + 13, JourneyBlocks.boilingBars);
            world.setBlock(i + 8, j + 7, k + 14, JourneyBlocks.boilingLog);
            world.setBlock(i + 8, j + 8, k + 12, JourneyBlocks.smallBrisonBrick);
            world.setBlock(i + 8, j + 8, k + 13, JourneyBlocks.smallBrisonBrick);
            world.setBlock(i + 8, j + 8, k + 14, JourneyBlocks.smallBrisonBrick);
            world.setBlock(i + 8, j + 10, k + 0, JourneyBlocks.smallBrisonBrick);
            world.setBlock(i + 8, j + 10, k + 1, JourneyBlocks.smallBrisonBrick);
            world.setBlock(i + 8, j + 10, k + 2, JourneyBlocks.smallBrisonBrick);
            world.setBlock(i + 8, j + 10, k + 7, JourneyBlocks.sizzlingPost);
            world.setBlock(i + 8, j + 11, k + 0, JourneyBlocks.boilingLog);
            world.setBlock(i + 8, j + 11, k + 1, JourneyBlocks.boilingBars);
            world.setBlock(i + 8, j + 11, k + 2, JourneyBlocks.boilingLog);
            world.setBlock(i + 8, j + 11, k + 7, JourneyBlocks.sizzlingPost);
            world.setBlock(i + 8, j + 12, k + 0, JourneyBlocks.boilingLog);
            world.setBlock(i + 8, j + 12, k + 1, JourneyBlocks.boilingBars);
            world.setBlock(i + 8, j + 12, k + 2, JourneyBlocks.boilingLog);
            world.setBlock(i + 8, j + 13, k + 0, JourneyBlocks.boilingLog);
            world.setBlock(i + 8, j + 13, k + 1, JourneyBlocks.boilingBars);
            world.setBlock(i + 8, j + 13, k + 2, JourneyBlocks.boilingLog);
            world.setBlock(i + 8, j + 14, k + 0, JourneyBlocks.smallBrisonBrick);
            world.setBlock(i + 8, j + 14, k + 1, JourneyBlocks.smallBrisonBrick);
            world.setBlock(i + 8, j + 14, k + 2, JourneyBlocks.smallBrisonBrick);
            world.setBlock(i + 9, j + 0, k + 5, JourneyBlocks.smallBrisonBrick);
            world.setBlock(i + 9, j + 0, k + 6, JourneyBlocks.smallBrisonBrick);
            world.setBlock(i + 9, j + 0, k + 7, JourneyBlocks.smallBrisonBrick);
            world.setBlock(i + 9, j + 0, k + 8, JourneyBlocks.smallBrisonBrick);
            world.setBlock(i + 9, j + 0, k + 9, JourneyBlocks.smallBrisonBrick);
            world.setBlock(i + 9, j + 1, k + 5, JourneyBlocks.boilingLog);
            world.setBlock(i + 9, j + 1, k + 6, JourneyBlocks.sizzlingPost);
            world.setBlock(i + 9, j + 1, k + 8, JourneyBlocks.sizzlingPost);
            world.setBlock(i + 9, j + 1, k + 9, JourneyBlocks.boilingLog);
            world.setBlock(i + 9, j + 2, k + 5, JourneyBlocks.boilingLog);
            world.setBlock(i + 9, j + 2, k + 6, JourneyBlocks.sizzlingPost);
            world.setBlock(i + 9, j + 2, k + 8, JourneyBlocks.sizzlingPost);
            world.setBlock(i + 9, j + 2, k + 9, JourneyBlocks.boilingLog);
            world.setBlock(i + 9, j + 3, k + 5, JourneyBlocks.boilingLog);
            world.setBlock(i + 9, j + 3, k + 6, JourneyBlocks.sizzlingPost);
            world.setBlock(i + 9, j + 3, k + 8, JourneyBlocks.sizzlingPost);
            world.setBlock(i + 9, j + 3, k + 9, JourneyBlocks.boilingLog);
            world.setBlock(i + 9, j + 4, k + 5, JourneyBlocks.boilingLog);
            world.setBlock(i + 9, j + 4, k + 6, JourneyBlocks.sizzlingPost);
            world.setBlock(i + 9, j + 4, k + 8, JourneyBlocks.sizzlingPost);
            world.setBlock(i + 9, j + 4, k + 9, JourneyBlocks.boilingLog);
            world.setBlock(i + 9, j + 11, k + 7, JourneyBlocks.sizzlingPost);
            world.setBlock(i + 10, j + 11, k + 7, JourneyBlocks.sizzlingPost);
            world.setBlock(i + 11, j + 11, k + 7, JourneyBlocks.sizzlingPost);
            world.setBlock(i + 12, j + 5, k + 6, JourneyBlocks.smallBrisonBrick);
            world.setBlock(i + 12, j + 5, k + 7, JourneyBlocks.smallBrisonBrick);
            world.setBlock(i + 12, j + 5, k + 8, JourneyBlocks.smallBrisonBrick);
            world.setBlock(i + 12, j + 6, k + 6, JourneyBlocks.boilingLog);
            world.setBlock(i + 12, j + 6, k + 7, JourneyBlocks.boilingBars);
            world.setBlock(i + 12, j + 6, k + 8, JourneyBlocks.boilingLog);
            world.setBlock(i + 12, j + 7, k + 6, JourneyBlocks.boilingLog);
            world.setBlock(i + 12, j + 7, k + 7, JourneyBlocks.boilingBars);
            world.setBlock(i + 12, j + 7, k + 8, JourneyBlocks.boilingLog);
            world.setBlock(i + 12, j + 8, k + 6, JourneyBlocks.boilingLog);
            world.setBlock(i + 12, j + 8, k + 7, JourneyBlocks.boilingBars);
            world.setBlock(i + 12, j + 8, k + 8, JourneyBlocks.boilingLog);
            world.setBlock(i + 12, j + 9, k + 6, JourneyBlocks.smallBrisonBrick);
            world.setBlock(i + 12, j + 9, k + 7, JourneyBlocks.smallBrisonBrick);
            world.setBlock(i + 12, j + 9, k + 8, JourneyBlocks.smallBrisonBrick);
            world.setBlock(i + 12, j + 11, k + 7, JourneyBlocks.sizzlingPost);
            world.setBlock(i + 13, j + 5, k + 6, JourneyBlocks.smallBrisonBrick);
            world.setBlock(i + 13, j + 5, k + 8, JourneyBlocks.smallBrisonBrick);
            world.setBlock(i + 13, j + 6, k + 6, JourneyBlocks.boilingBars);
            world.setBlock(i + 13, j + 6, k + 8, JourneyBlocks.boilingBars);
            world.setBlock(i + 13, j + 7, k + 6, JourneyBlocks.boilingBars);
            world.setBlock(i + 13, j + 7, k + 8, JourneyBlocks.boilingBars);
            world.setBlock(i + 13, j + 8, k + 6, JourneyBlocks.boilingBars);
            world.setBlock(i + 13, j + 8, k + 7, JourneyBlocks.boilingLamp);
            world.setBlock(i + 13, j + 8, k + 8, JourneyBlocks.boilingBars);
            world.setBlock(i + 13, j + 9, k + 6, JourneyBlocks.smallBrisonBrick);
            world.setBlock(i + 13, j + 9, k + 7, JourneyBlocks.smallBrisonBrick);
            world.setBlock(i + 13, j + 9, k + 8, JourneyBlocks.smallBrisonBrick);
            world.setBlock(i + 13, j + 10, k + 7, JourneyBlocks.sizzlingPost);
            world.setBlock(i + 13, j + 11, k + 7, JourneyBlocks.sizzlingPost);
            world.setBlock(i + 14, j + 5, k + 6, JourneyBlocks.smallBrisonBrick);
            world.setBlock(i + 14, j + 5, k + 7, JourneyBlocks.smallBrisonBrick);
            world.setBlock(i + 14, j + 5, k + 8, JourneyBlocks.smallBrisonBrick);
            world.setBlock(i + 14, j + 6, k + 6, JourneyBlocks.boilingLog);
            world.setBlock(i + 14, j + 6, k + 7, JourneyBlocks.boilingBars);
            world.setBlock(i + 14, j + 6, k + 8, JourneyBlocks.boilingLog);
            world.setBlock(i + 14, j + 7, k + 6, JourneyBlocks.boilingLog);
            world.setBlock(i + 14, j + 7, k + 7, JourneyBlocks.boilingBars);
            world.setBlock(i + 14, j + 7, k + 8, JourneyBlocks.boilingLog);
            world.setBlock(i + 14, j + 8, k + 6, JourneyBlocks.boilingLog);
            world.setBlock(i + 14, j + 8, k + 7, JourneyBlocks.boilingBars);
            world.setBlock(i + 14, j + 8, k + 8, JourneyBlocks.boilingLog);
            world.setBlock(i + 14, j + 9, k + 6, JourneyBlocks.smallBrisonBrick);
            world.setBlock(i + 14, j + 9, k + 7, JourneyBlocks.smallBrisonBrick);
            world.setBlock(i + 14, j + 9, k + 8, JourneyBlocks.smallBrisonBrick);
            if (!world.isRemote) {
                EntityEscapedConvict smith = new EntityEscapedConvict(world);
                smith.setLocationAndAngles(i + 7, j + 1, k + 7, 0.0f, 0.0f);
                world.spawnEntityInWorld((Entity)smith);
            }
            return true;
        }
        return false;
    }
}

