/*
 * Decompiled with CFR 0.152.
 * 
 * Could not load the following classes:
 *  net.minecraft.block.Block
 *  net.minecraft.init.Blocks
 *  net.minecraft.world.World
 *  net.minecraft.world.gen.feature.WorldGenerator
 */
package net.divinerpg.dimensions.euca.gen;

import java.util.Random;
import net.divinerpg.utils.blocks.JourneyBlocks;
import net.minecraft.block.Block;
import net.minecraft.init.Blocks;
import net.minecraft.world.World;
import net.minecraft.world.gen.feature.WorldGenerator;

public class EucaSmallSphereDungeon
extends WorldGenerator {
    public boolean locationIsValidSpawn(World w, int i, int j, int k) {
        for (int p = 0; p < 11; ++p) {
            for (int l = 0; l < 11; ++l) {
                if (w.getBlock(i + p, j, k + l) != Blocks.air) continue;
            }
        }
        return false;
    }

    /*
     * Opcode count of 15693 triggered aggressive code reduction.  Override with --aggressivesizethreshold.
     */
    public boolean generate(World w, Random r, int i, int j, int k) {
        if (!w.isRemote) {
            if (this.locationIsValidSpawn(w, i, --j, k)) {
                return true;
            }
            this.setBlock(w, i + 0, j + 6, k + 6, JourneyBlocks.euca_gold_stone);
            this.setBlock(w, i + 0, j + 6, k + 7, JourneyBlocks.euca_gold_stone);
            this.setBlock(w, i + 0, j + 6, k + 8, JourneyBlocks.euca_gold_stone);
            this.setBlock(w, i + 0, j + 6, k + 9, JourneyBlocks.euca_gold_stone);
            this.setBlock(w, i + 0, j + 6, k + 10, JourneyBlocks.euca_gold_stone);
            this.setBlock(w, i + 0, j + 6, k + 11, JourneyBlocks.goldite_oak_log_side);
            this.setBlock(w, i + 0, j + 7, k + 6, JourneyBlocks.euca_gold_stone);
            this.setBlock(w, i + 0, j + 7, k + 7, JourneyBlocks.euca_runic_lamp);
            this.setBlock(w, i + 0, j + 7, k + 8, JourneyBlocks.euca_runic_lamp);
            this.setBlock(w, i + 0, j + 7, k + 9, JourneyBlocks.euca_runic_lamp);
            this.setBlock(w, i + 0, j + 7, k + 10, JourneyBlocks.euca_gold_stone);
            this.setBlock(w, i + 0, j + 7, k + 11, JourneyBlocks.goldite_oak_log_side);
            this.setBlock(w, i + 0, j + 8, k + 6, JourneyBlocks.euca_gold_stone);
            this.setBlock(w, i + 0, j + 8, k + 7, JourneyBlocks.euca_runic_lamp);
            this.setBlock(w, i + 0, j + 8, k + 8, JourneyBlocks.euca_square_dungeon_bricks);
            this.setBlock(w, i + 0, j + 8, k + 9, JourneyBlocks.euca_runic_lamp);
            this.setBlock(w, i + 0, j + 8, k + 10, JourneyBlocks.euca_gold_stone);
            this.setBlock(w, i + 0, j + 8, k + 11, JourneyBlocks.goldite_oak_log_side);
            this.setBlock(w, i + 0, j + 8, k + 12, JourneyBlocks.goldite_oak_log_side);
            this.setBlock(w, i + 0, j + 9, k + 6, JourneyBlocks.euca_gold_stone);
            this.setBlock(w, i + 0, j + 9, k + 7, JourneyBlocks.euca_runic_lamp);
            this.setBlock(w, i + 0, j + 9, k + 8, JourneyBlocks.euca_runic_lamp);
            this.setBlock(w, i + 0, j + 9, k + 9, JourneyBlocks.euca_runic_lamp);
            this.setBlock(w, i + 0, j + 9, k + 10, JourneyBlocks.euca_gold_stone);
            this.setBlock(w, i + 0, j + 9, k + 12, JourneyBlocks.goldite_oak_log_side);
            this.setBlock(w, i + 0, j + 10, k + 6, JourneyBlocks.goldite_oak_log_side);
            this.setBlock(w, i + 0, j + 10, k + 7, JourneyBlocks.euca_gold_stone);
            this.setBlock(w, i + 0, j + 10, k + 8, JourneyBlocks.euca_gold_stone);
            this.setBlock(w, i + 0, j + 10, k + 9, JourneyBlocks.euca_gold_stone);
            this.setBlock(w, i + 0, j + 10, k + 10, JourneyBlocks.euca_gold_stone);
            this.setBlock(w, i + 0, j + 10, k + 12, JourneyBlocks.goldite_oak_log_side);
            this.setBlock(w, i + 0, j + 11, k + 8, JourneyBlocks.goldite_oak_log_side);
            this.setBlock(w, i + 1, j + 4, k + 6, JourneyBlocks.euca_gold_stone);
            this.setBlock(w, i + 1, j + 4, k + 7, JourneyBlocks.euca_gold_stone);
            this.setBlock(w, i + 1, j + 4, k + 8, JourneyBlocks.euca_gold_stone);
            this.setBlock(w, i + 1, j + 4, k + 9, JourneyBlocks.euca_gold_stone);
            this.setBlock(w, i + 1, j + 4, k + 10, JourneyBlocks.euca_gold_stone);
            this.setBlock(w, i + 1, j + 5, k + 5, JourneyBlocks.euca_gold_stone);
            this.setBlock(w, i + 1, j + 5, k + 6, JourneyBlocks.euca_gold_stone);
            this.setBlock(w, i + 1, j + 5, k + 7, JourneyBlocks.euca_gold_stone);
            this.setBlock(w, i + 1, j + 5, k + 8, JourneyBlocks.euca_gold_stone);
            this.setBlock(w, i + 1, j + 5, k + 9, JourneyBlocks.euca_gold_stone);
            this.setBlock(w, i + 1, j + 5, k + 10, JourneyBlocks.euca_gold_stone);
            this.setBlock(w, i + 1, j + 5, k + 11, JourneyBlocks.euca_gold_stone);
            this.setBlock(w, i + 1, j + 6, k + 4, JourneyBlocks.euca_gold_stone);
            this.setBlock(w, i + 1, j + 6, k + 5, JourneyBlocks.euca_gold_stone);
            this.setBlock(w, i + 1, j + 6, k + 6, JourneyBlocks.euca_gold_stone);
            this.setBlock(w, i + 1, j + 6, k + 7, JourneyBlocks.euca_gold_stone);
            this.setBlock(w, i + 1, j + 6, k + 8, JourneyBlocks.euca_gold_stone);
            this.setBlock(w, i + 1, j + 6, k + 9, JourneyBlocks.euca_gold_stone);
            this.setBlock(w, i + 1, j + 6, k + 10, JourneyBlocks.euca_gold_stone);
            this.setBlock(w, i + 1, j + 6, k + 11, JourneyBlocks.euca_gold_stone);
            this.setBlock(w, i + 1, j + 6, k + 12, JourneyBlocks.euca_gold_stone);
            this.setBlock(w, i + 1, j + 7, k + 4, JourneyBlocks.euca_gold_stone);
            this.setBlock(w, i + 1, j + 7, k + 5, JourneyBlocks.euca_gold_stone);
            this.setBlock(w, i + 1, j + 7, k + 6, JourneyBlocks.euca_gold_stone);
            this.setBlock(w, i + 1, j + 7, k + 7, JourneyBlocks.euca_square_dungeon_bricks);
            this.setBlock(w, i + 1, j + 7, k + 8, JourneyBlocks.euca_square_dungeon_bricks);
            this.setBlock(w, i + 1, j + 7, k + 9, JourneyBlocks.euca_square_dungeon_bricks);
            this.setBlock(w, i + 1, j + 7, k + 10, JourneyBlocks.euca_gold_stone);
            this.setBlock(w, i + 1, j + 7, k + 11, JourneyBlocks.euca_gold_stone);
            this.setBlock(w, i + 1, j + 7, k + 12, JourneyBlocks.euca_gold_stone);
            this.setBlock(w, i + 1, j + 7, k + 13, JourneyBlocks.goldite_oak_log_side);
            this.setBlock(w, i + 1, j + 8, k + 4, JourneyBlocks.euca_gold_stone);
            this.setBlock(w, i + 1, j + 8, k + 5, JourneyBlocks.euca_gold_stone);
            this.setBlock(w, i + 1, j + 8, k + 6, JourneyBlocks.euca_gold_stone);
            this.setBlock(w, i + 1, j + 8, k + 7, JourneyBlocks.euca_square_dungeon_bricks);
            this.setBlock(w, i + 1, j + 8, k + 8, JourneyBlocks.euca_square_dungeon_bricks);
            this.setBlock(w, i + 1, j + 8, k + 9, JourneyBlocks.euca_square_dungeon_bricks);
            this.setBlock(w, i + 1, j + 8, k + 10, JourneyBlocks.euca_gold_stone);
            this.setBlock(w, i + 1, j + 8, k + 11, JourneyBlocks.euca_gold_stone);
            this.setBlock(w, i + 1, j + 8, k + 12, JourneyBlocks.euca_gold_stone);
            this.setBlock(w, i + 1, j + 8, k + 13, JourneyBlocks.goldite_oak_log_side);
            this.setBlock(w, i + 1, j + 9, k + 4, JourneyBlocks.goldite_oak_log_side);
            this.setBlock(w, i + 1, j + 9, k + 5, JourneyBlocks.euca_gold_stone);
            this.setBlock(w, i + 1, j + 9, k + 6, JourneyBlocks.euca_gold_stone);
            this.setBlock(w, i + 1, j + 9, k + 7, JourneyBlocks.euca_square_dungeon_bricks);
            this.setBlock(w, i + 1, j + 9, k + 8, JourneyBlocks.euca_square_dungeon_bricks);
            this.setBlock(w, i + 1, j + 9, k + 9, JourneyBlocks.euca_square_dungeon_bricks);
            this.setBlock(w, i + 1, j + 9, k + 10, JourneyBlocks.euca_gold_stone);
            this.setBlock(w, i + 1, j + 9, k + 11, JourneyBlocks.goldite_oak_log_side);
            this.setBlock(w, i + 1, j + 9, k + 12, JourneyBlocks.goldite_oak_log_side);
            this.setBlock(w, i + 1, j + 10, k + 4, JourneyBlocks.goldite_oak_log_side);
            this.setBlock(w, i + 1, j + 10, k + 5, JourneyBlocks.goldite_oak_log_side);
            this.setBlock(w, i + 1, j + 10, k + 6, JourneyBlocks.euca_gold_stone);
            this.setBlock(w, i + 1, j + 10, k + 7, JourneyBlocks.euca_square_dungeon_bricks);
            this.setBlock(w, i + 1, j + 10, k + 8, JourneyBlocks.euca_square_dungeon_bricks);
            this.setBlock(w, i + 1, j + 10, k + 9, JourneyBlocks.euca_square_dungeon_bricks);
            this.setBlock(w, i + 1, j + 10, k + 10, JourneyBlocks.euca_gold_stone);
            this.setBlock(w, i + 1, j + 10, k + 11, JourneyBlocks.goldite_oak_log_side);
            this.setBlock(w, i + 1, j + 10, k + 12, JourneyBlocks.goldite_oak_log_side);
            this.setBlock(w, i + 1, j + 11, k + 5, JourneyBlocks.goldite_oak_log_side);
            this.setBlock(w, i + 1, j + 11, k + 6, JourneyBlocks.goldite_oak_log_side);
            this.setBlock(w, i + 1, j + 11, k + 7, JourneyBlocks.euca_gold_stone);
            this.setBlock(w, i + 1, j + 11, k + 8, JourneyBlocks.euca_gold_stone);
            this.setBlock(w, i + 1, j + 11, k + 9, JourneyBlocks.euca_gold_stone);
            this.setBlock(w, i + 1, j + 11, k + 10, JourneyBlocks.euca_gold_stone);
            this.setBlock(w, i + 1, j + 11, k + 11, JourneyBlocks.goldite_oak_log_side);
            this.setBlock(w, i + 1, j + 11, k + 12, JourneyBlocks.goldite_oak_log_side);
            this.setBlock(w, i + 1, j + 12, k + 6, JourneyBlocks.goldite_oak_log_side);
            this.setBlock(w, i + 1, j + 12, k + 7, JourneyBlocks.goldite_oak_log_side);
            this.setBlock(w, i + 1, j + 12, k + 8, JourneyBlocks.goldite_oak_log_side);
            this.setBlock(w, i + 1, j + 12, k + 9, JourneyBlocks.euca_gold_stone);
            this.setBlock(w, i + 1, j + 12, k + 10, JourneyBlocks.goldite_oak_log_side);
            this.setBlock(w, i + 1, j + 12, k + 11, JourneyBlocks.goldite_oak_log_side);
            this.setBlock(w, i + 2, j + 3, k + 5, JourneyBlocks.euca_gold_stone);
            this.setBlock(w, i + 2, j + 3, k + 6, JourneyBlocks.euca_gold_stone);
            this.setBlock(w, i + 2, j + 3, k + 7, JourneyBlocks.euca_gold_stone);
            this.setBlock(w, i + 2, j + 3, k + 8, JourneyBlocks.euca_gold_stone);
            this.setBlock(w, i + 2, j + 3, k + 9, JourneyBlocks.euca_gold_stone);
            this.setBlock(w, i + 2, j + 3, k + 10, JourneyBlocks.euca_gold_stone);
            this.setBlock(w, i + 2, j + 3, k + 11, JourneyBlocks.euca_gold_stone);
            this.setBlock(w, i + 2, j + 4, k + 4, JourneyBlocks.euca_gold_stone);
            this.setBlock(w, i + 2, j + 4, k + 5, JourneyBlocks.euca_gold_stone);
            this.setBlock(w, i + 2, j + 4, k + 6, JourneyBlocks.euca_gold_stone);
            this.setBlock(w, i + 2, j + 4, k + 7, JourneyBlocks.euca_gold_stone);
            this.setBlock(w, i + 2, j + 4, k + 8, JourneyBlocks.euca_gold_stone);
            this.setBlock(w, i + 2, j + 4, k + 9, JourneyBlocks.euca_gold_stone);
            this.setBlock(w, i + 2, j + 4, k + 10, JourneyBlocks.euca_gold_stone);
            this.setBlock(w, i + 2, j + 4, k + 11, JourneyBlocks.euca_gold_stone);
            this.setBlock(w, i + 2, j + 4, k + 12, JourneyBlocks.euca_gold_stone);
            this.setBlock(w, i + 2, j + 5, k + 3, JourneyBlocks.euca_gold_stone);
            this.setBlock(w, i + 2, j + 5, k + 4, JourneyBlocks.euca_gold_stone);
            this.setBlock(w, i + 2, j + 5, k + 5, JourneyBlocks.euca_gold_stone);
            this.setBlock(w, i + 2, j + 5, k + 6, JourneyBlocks.euca_gold_stone);
            this.setBlock(w, i + 2, j + 5, k + 7, JourneyBlocks.euca_gold_stone);
            this.setBlock(w, i + 2, j + 5, k + 8, JourneyBlocks.euca_gold_stone);
            this.setBlock(w, i + 2, j + 5, k + 9, JourneyBlocks.euca_gold_stone);
            this.setBlock(w, i + 2, j + 5, k + 10, JourneyBlocks.euca_gold_stone);
            this.setBlock(w, i + 2, j + 5, k + 11, JourneyBlocks.euca_gold_stone);
            this.setBlock(w, i + 2, j + 5, k + 12, JourneyBlocks.euca_gold_stone);
            this.setBlock(w, i + 2, j + 5, k + 13, JourneyBlocks.euca_gold_stone);
            this.setBlock(w, i + 2, j + 6, k + 3, JourneyBlocks.euca_gold_stone);
            this.setBlock(w, i + 2, j + 6, k + 4, JourneyBlocks.euca_gold_stone);
            this.setBlock(w, i + 2, j + 6, k + 5, JourneyBlocks.euca_gold_stone);
            this.setBlock(w, i + 2, j + 6, k + 6, JourneyBlocks.euca_gold_stone);
            this.setBlock(w, i + 2, j + 6, k + 7, JourneyBlocks.eucatile);
            this.setBlock(w, i + 2, j + 6, k + 8, JourneyBlocks.eucatile);
            this.setBlock(w, i + 2, j + 6, k + 9, JourneyBlocks.eucatile);
            this.setBlock(w, i + 2, j + 6, k + 10, JourneyBlocks.euca_gold_stone);
            this.setBlock(w, i + 2, j + 6, k + 11, JourneyBlocks.euca_gold_stone);
            this.setBlock(w, i + 2, j + 6, k + 12, JourneyBlocks.euca_gold_stone);
            this.setBlock(w, i + 2, j + 6, k + 13, JourneyBlocks.euca_gold_stone);
            this.setBlock(w, i + 2, j + 7, k + 3, JourneyBlocks.euca_gold_stone);
            this.setBlock(w, i + 2, j + 7, k + 4, JourneyBlocks.euca_square_dungeon_bricks);
            this.setBlock(w, i + 2, j + 7, k + 5, JourneyBlocks.euca_square_dungeon_bricks);
            this.setBlock(w, i + 2, j + 7, k + 6, JourneyBlocks.euca_square_dungeon_bricks);
            this.setBlock(w, i + 2, j + 7, k + 10, JourneyBlocks.euca_square_dungeon_bricks);
            this.setBlock(w, i + 2, j + 7, k + 11, JourneyBlocks.euca_square_dungeon_bricks);
            this.setBlock(w, i + 2, j + 7, k + 12, JourneyBlocks.euca_square_dungeon_bricks);
            this.setBlock(w, i + 2, j + 7, k + 13, JourneyBlocks.euca_gold_stone);
            this.setBlock(w, i + 2, j + 8, k + 3, JourneyBlocks.euca_gold_stone);
            this.setBlock(w, i + 2, j + 8, k + 4, JourneyBlocks.euca_square_dungeon_bricks);
            this.setBlock(w, i + 2, j + 8, k + 5, JourneyBlocks.euca_square_dungeon_bricks);
            this.setBlock(w, i + 2, j + 8, k + 6, JourneyBlocks.euca_square_dungeon_bricks);
            this.setBlock(w, i + 2, j + 8, k + 10, JourneyBlocks.euca_square_dungeon_bricks);
            this.setBlock(w, i + 2, j + 8, k + 11, JourneyBlocks.euca_square_dungeon_bricks);
            this.setBlock(w, i + 2, j + 8, k + 12, JourneyBlocks.euca_square_dungeon_bricks);
            this.setBlock(w, i + 2, j + 8, k + 13, JourneyBlocks.euca_gold_stone);
            this.setBlock(w, i + 2, j + 9, k + 3, JourneyBlocks.euca_gold_stone);
            this.setBlock(w, i + 2, j + 9, k + 4, JourneyBlocks.euca_square_dungeon_bricks);
            this.setBlock(w, i + 2, j + 9, k + 5, JourneyBlocks.euca_square_dungeon_bricks);
            this.setBlock(w, i + 2, j + 9, k + 6, JourneyBlocks.euca_square_dungeon_bricks);
            this.setBlock(w, i + 2, j + 9, k + 10, JourneyBlocks.euca_square_dungeon_bricks);
            this.setBlock(w, i + 2, j + 9, k + 11, JourneyBlocks.euca_square_dungeon_bricks);
            this.setBlock(w, i + 2, j + 9, k + 12, JourneyBlocks.euca_square_dungeon_bricks);
            this.setBlock(w, i + 2, j + 9, k + 13, JourneyBlocks.euca_gold_stone);
            this.setBlock(w, i + 2, j + 10, k + 3, JourneyBlocks.goldite_oak_log_side);
            this.setBlock(w, i + 2, j + 10, k + 4, JourneyBlocks.euca_square_dungeon_bricks);
            this.setBlock(w, i + 2, j + 10, k + 5, JourneyBlocks.euca_square_dungeon_bricks);
            this.setBlock(w, i + 2, j + 10, k + 6, JourneyBlocks.euca_square_dungeon_bricks);
            this.setBlock(w, i + 2, j + 10, k + 10, JourneyBlocks.euca_square_dungeon_bricks);
            this.setBlock(w, i + 2, j + 10, k + 11, JourneyBlocks.euca_square_dungeon_bricks);
            this.setBlock(w, i + 2, j + 10, k + 12, JourneyBlocks.euca_square_dungeon_bricks);
            this.setBlock(w, i + 2, j + 10, k + 13, JourneyBlocks.euca_gold_stone);
            this.setBlock(w, i + 2, j + 11, k + 3, JourneyBlocks.goldite_oak_log_side);
            this.setBlock(w, i + 2, j + 11, k + 4, JourneyBlocks.euca_gold_stone);
            this.setBlock(w, i + 2, j + 11, k + 5, JourneyBlocks.euca_gold_stone);
            this.setBlock(w, i + 2, j + 11, k + 6, JourneyBlocks.euca_gold_stone);
            this.setBlock(w, i + 2, j + 11, k + 7, JourneyBlocks.euca_runic_lamp);
            this.setBlock(w, i + 2, j + 11, k + 8, JourneyBlocks.euca_square_dungeon_bricks);
            this.setBlock(w, i + 2, j + 11, k + 9, JourneyBlocks.euca_runic_lamp);
            this.setBlock(w, i + 2, j + 11, k + 10, JourneyBlocks.euca_gold_stone);
            this.setBlock(w, i + 2, j + 11, k + 11, JourneyBlocks.euca_gold_stone);
            this.setBlock(w, i + 2, j + 11, k + 12, JourneyBlocks.euca_gold_stone);
            this.setBlock(w, i + 2, j + 11, k + 13, JourneyBlocks.euca_gold_stone);
            this.setBlock(w, i + 2, j + 12, k + 4, JourneyBlocks.euca_gold_stone);
            this.setBlock(w, i + 2, j + 12, k + 5, JourneyBlocks.euca_gold_stone);
            this.setBlock(w, i + 2, j + 12, k + 6, JourneyBlocks.euca_gold_stone);
            this.setBlock(w, i + 2, j + 12, k + 7, JourneyBlocks.euca_gold_stone);
            this.setBlock(w, i + 2, j + 12, k + 8, JourneyBlocks.euca_gold_stone);
            this.setBlock(w, i + 2, j + 12, k + 9, JourneyBlocks.euca_gold_stone);
            this.setBlock(w, i + 2, j + 12, k + 10, JourneyBlocks.euca_gold_stone);
            this.setBlock(w, i + 2, j + 12, k + 11, JourneyBlocks.euca_gold_stone);
            this.setBlock(w, i + 2, j + 12, k + 12, JourneyBlocks.goldite_oak_log_side);
            this.setBlock(w, i + 2, j + 13, k + 5, JourneyBlocks.euca_gold_stone);
            this.setBlock(w, i + 2, j + 13, k + 6, JourneyBlocks.goldite_oak_log_side);
            this.setBlock(w, i + 2, j + 13, k + 7, JourneyBlocks.goldite_oak_log_side);
            this.setBlock(w, i + 2, j + 13, k + 8, JourneyBlocks.euca_gold_stone);
            this.setBlock(w, i + 2, j + 13, k + 9, JourneyBlocks.euca_gold_stone);
            this.setBlock(w, i + 2, j + 13, k + 10, JourneyBlocks.goldite_oak_log_side);
            this.setBlock(w, i + 2, j + 13, k + 11, JourneyBlocks.goldite_oak_log_side);
            this.setBlock(w, i + 2, j + 13, k + 12, JourneyBlocks.goldite_oak_log_side);
            this.setBlock(w, i + 2, j + 14, k + 11, JourneyBlocks.goldite_oak_log_side);
            this.setBlock(w, i + 3, j + 2, k + 5, JourneyBlocks.euca_gold_stone);
            this.setBlock(w, i + 3, j + 2, k + 6, JourneyBlocks.euca_gold_stone);
            this.setBlock(w, i + 3, j + 2, k + 7, JourneyBlocks.euca_gold_stone);
            this.setBlock(w, i + 3, j + 2, k + 8, JourneyBlocks.euca_gold_stone);
            this.setBlock(w, i + 3, j + 2, k + 9, JourneyBlocks.euca_gold_stone);
            this.setBlock(w, i + 3, j + 2, k + 10, JourneyBlocks.euca_gold_stone);
            this.setBlock(w, i + 3, j + 2, k + 11, JourneyBlocks.euca_gold_stone);
            this.setBlock(w, i + 3, j + 3, k + 4, JourneyBlocks.euca_gold_stone);
            this.setBlock(w, i + 3, j + 3, k + 5, JourneyBlocks.euca_gold_stone);
            this.setBlock(w, i + 3, j + 3, k + 6, JourneyBlocks.euca_gold_stone);
            this.setBlock(w, i + 3, j + 3, k + 7, JourneyBlocks.euca_gold_stone);
            this.setBlock(w, i + 3, j + 3, k + 8, JourneyBlocks.euca_gold_stone);
            this.setBlock(w, i + 3, j + 3, k + 9, JourneyBlocks.euca_gold_stone);
            this.setBlock(w, i + 3, j + 3, k + 10, JourneyBlocks.euca_gold_stone);
            this.setBlock(w, i + 3, j + 3, k + 11, JourneyBlocks.euca_gold_stone);
            this.setBlock(w, i + 3, j + 3, k + 12, JourneyBlocks.euca_gold_stone);
            this.setBlock(w, i + 3, j + 4, k + 3, JourneyBlocks.euca_gold_stone);
            this.setBlock(w, i + 3, j + 4, k + 4, JourneyBlocks.euca_gold_stone);
            this.setBlock(w, i + 3, j + 4, k + 5, JourneyBlocks.euca_gold_stone);
            this.setBlock(w, i + 3, j + 4, k + 6, JourneyBlocks.euca_gold_stone);
            this.setBlock(w, i + 3, j + 4, k + 7, JourneyBlocks.euca_gold_stone);
            this.setBlock(w, i + 3, j + 4, k + 8, JourneyBlocks.euca_gold_stone);
            this.setBlock(w, i + 3, j + 4, k + 9, JourneyBlocks.euca_gold_stone);
            this.setBlock(w, i + 3, j + 4, k + 10, JourneyBlocks.euca_gold_stone);
            this.setBlock(w, i + 3, j + 4, k + 11, JourneyBlocks.euca_gold_stone);
            this.setBlock(w, i + 3, j + 4, k + 12, JourneyBlocks.euca_gold_stone);
            this.setBlock(w, i + 3, j + 4, k + 13, JourneyBlocks.euca_gold_stone);
            this.setBlock(w, i + 3, j + 5, k + 2, JourneyBlocks.euca_gold_stone);
            this.setBlock(w, i + 3, j + 5, k + 3, JourneyBlocks.euca_gold_stone);
            this.setBlock(w, i + 3, j + 5, k + 4, JourneyBlocks.euca_gold_stone);
            this.setBlock(w, i + 3, j + 5, k + 5, JourneyBlocks.euca_gold_stone);
            this.setBlock(w, i + 3, j + 5, k + 6, JourneyBlocks.euca_gold_stone);
            this.setBlock(w, i + 3, j + 5, k + 7, JourneyBlocks.euca_gold_stone);
            this.setBlock(w, i + 3, j + 5, k + 8, JourneyBlocks.euca_gold_stone);
            this.setBlock(w, i + 3, j + 5, k + 9, JourneyBlocks.euca_gold_stone);
            this.setBlock(w, i + 3, j + 5, k + 10, JourneyBlocks.euca_gold_stone);
            this.setBlock(w, i + 3, j + 5, k + 11, JourneyBlocks.euca_gold_stone);
            this.setBlock(w, i + 3, j + 5, k + 12, JourneyBlocks.euca_gold_stone);
            this.setBlock(w, i + 3, j + 5, k + 13, JourneyBlocks.euca_gold_stone);
            this.setBlock(w, i + 3, j + 5, k + 14, JourneyBlocks.euca_gold_stone);
            this.setBlock(w, i + 3, j + 6, k + 2, JourneyBlocks.euca_gold_stone);
            this.setBlock(w, i + 3, j + 6, k + 3, JourneyBlocks.eucatile);
            this.setBlock(w, i + 3, j + 6, k + 4, JourneyBlocks.eucatile);
            this.setBlock(w, i + 3, j + 6, k + 5, JourneyBlocks.eucatile);
            this.setBlock(w, i + 3, j + 6, k + 6, JourneyBlocks.eucatile);
            this.setBlock(w, i + 3, j + 6, k + 7, JourneyBlocks.eucatile);
            this.setBlock(w, i + 3, j + 6, k + 8, JourneyBlocks.eucatile);
            this.setBlock(w, i + 3, j + 6, k + 9, JourneyBlocks.eucatile);
            this.setBlock(w, i + 3, j + 6, k + 10, JourneyBlocks.eucatile);
            this.setBlock(w, i + 3, j + 6, k + 11, JourneyBlocks.eucatile);
            this.setBlock(w, i + 3, j + 6, k + 12, JourneyBlocks.eucatile);
            this.setBlock(w, i + 3, j + 6, k + 13, JourneyBlocks.eucatile);
            this.setBlock(w, i + 3, j + 6, k + 14, JourneyBlocks.euca_gold_stone);
            this.setBlock(w, i + 3, j + 7, k + 2, JourneyBlocks.euca_gold_stone);
            this.setBlock(w, i + 3, j + 7, k + 3, JourneyBlocks.euca_square_dungeon_bricks);
            this.setBlock(w, i + 3, j + 7, k + 4, JourneyBlocks.euca_square_dungeon_bricks);
            this.setBlock(w, i + 3, j + 7, k + 12, JourneyBlocks.euca_square_dungeon_bricks);
            this.setBlock(w, i + 3, j + 7, k + 13, JourneyBlocks.euca_square_dungeon_bricks);
            this.setBlock(w, i + 3, j + 7, k + 14, JourneyBlocks.euca_gold_stone);
            this.setBlock(w, i + 3, j + 8, k + 2, JourneyBlocks.euca_gold_stone);
            this.setBlock(w, i + 3, j + 8, k + 3, JourneyBlocks.goldbotSpawner);
            this.setBlock(w, i + 3, j + 8, k + 13, JourneyBlocks.goldbotSpawner);
            this.setBlock(w, i + 3, j + 8, k + 14, JourneyBlocks.euca_gold_stone);
            this.setBlock(w, i + 3, j + 9, k + 2, JourneyBlocks.goldite_oak_log_side);
            this.setBlock(w, i + 3, j + 9, k + 3, JourneyBlocks.euca_square_dungeon_bricks);
            this.setBlock(w, i + 3, j + 9, k + 13, JourneyBlocks.euca_square_dungeon_bricks);
            this.setBlock(w, i + 3, j + 9, k + 14, JourneyBlocks.euca_gold_stone);
            this.setBlock(w, i + 3, j + 10, k + 2, JourneyBlocks.euca_gold_stone);
            this.setBlock(w, i + 3, j + 10, k + 3, JourneyBlocks.euca_square_dungeon_bricks);
            this.setBlock(w, i + 3, j + 10, k + 13, JourneyBlocks.euca_square_dungeon_bricks);
            this.setBlock(w, i + 3, j + 10, k + 14, JourneyBlocks.euca_gold_stone);
            this.setBlock(w, i + 3, j + 11, k + 2, JourneyBlocks.euca_gold_stone);
            this.setBlock(w, i + 3, j + 11, k + 3, JourneyBlocks.euca_square_dungeon_bricks);
            this.setBlock(w, i + 3, j + 11, k + 4, JourneyBlocks.euca_runic_lamp);
            this.setBlock(w, i + 3, j + 11, k + 5, JourneyBlocks.euca_square_dungeon_bricks);
            this.setBlock(w, i + 3, j + 11, k + 6, JourneyBlocks.euca_square_dungeon_bricks);
            this.setBlock(w, i + 3, j + 11, k + 7, JourneyBlocks.euca_square_dungeon_bricks);
            this.setBlock(w, i + 3, j + 11, k + 8, JourneyBlocks.euca_square_dungeon_bricks);
            this.setBlock(w, i + 3, j + 11, k + 9, JourneyBlocks.euca_square_dungeon_bricks);
            this.setBlock(w, i + 3, j + 11, k + 10, JourneyBlocks.euca_square_dungeon_bricks);
            this.setBlock(w, i + 3, j + 11, k + 11, JourneyBlocks.euca_square_dungeon_bricks);
            this.setBlock(w, i + 3, j + 11, k + 12, JourneyBlocks.euca_runic_lamp);
            this.setBlock(w, i + 3, j + 11, k + 13, JourneyBlocks.euca_square_dungeon_bricks);
            this.setBlock(w, i + 3, j + 11, k + 14, JourneyBlocks.euca_gold_stone);
            this.setBlock(w, i + 3, j + 12, k + 3, JourneyBlocks.goldite_oak_log_side);
            this.setBlock(w, i + 3, j + 12, k + 4, JourneyBlocks.euca_gold_stone);
            this.setBlock(w, i + 3, j + 12, k + 5, JourneyBlocks.euca_gold_stone);
            this.setBlock(w, i + 3, j + 12, k + 6, JourneyBlocks.euca_gold_stone);
            this.setBlock(w, i + 3, j + 12, k + 7, JourneyBlocks.euca_gold_stone);
            this.setBlock(w, i + 3, j + 12, k + 8, JourneyBlocks.euca_gold_stone);
            this.setBlock(w, i + 3, j + 12, k + 9, JourneyBlocks.euca_gold_stone);
            this.setBlock(w, i + 3, j + 12, k + 10, JourneyBlocks.euca_gold_stone);
            this.setBlock(w, i + 3, j + 12, k + 11, JourneyBlocks.euca_gold_stone);
            this.setBlock(w, i + 3, j + 12, k + 12, JourneyBlocks.euca_gold_stone);
            this.setBlock(w, i + 3, j + 12, k + 13, JourneyBlocks.euca_gold_stone);
            this.setBlock(w, i + 3, j + 13, k + 4, JourneyBlocks.goldite_oak_log_side);
            this.setBlock(w, i + 3, j + 13, k + 5, JourneyBlocks.euca_gold_stone);
            this.setBlock(w, i + 3, j + 13, k + 6, JourneyBlocks.euca_gold_stone);
            this.setBlock(w, i + 3, j + 13, k + 7, JourneyBlocks.euca_gold_stone);
            this.setBlock(w, i + 3, j + 13, k + 8, JourneyBlocks.euca_gold_stone);
            this.setBlock(w, i + 3, j + 13, k + 9, JourneyBlocks.euca_gold_stone);
            this.setBlock(w, i + 3, j + 13, k + 10, JourneyBlocks.euca_gold_stone);
            this.setBlock(w, i + 3, j + 13, k + 11, JourneyBlocks.euca_gold_stone);
            this.setBlock(w, i + 3, j + 13, k + 12, JourneyBlocks.euca_gold_stone);
            this.setBlock(w, i + 3, j + 14, k + 5, JourneyBlocks.euca_gold_stone);
            this.setBlock(w, i + 3, j + 14, k + 6, JourneyBlocks.euca_gold_stone);
            this.setBlock(w, i + 3, j + 14, k + 7, JourneyBlocks.goldite_oak_log_side);
            this.setBlock(w, i + 3, j + 14, k + 8, JourneyBlocks.euca_gold_stone);
            this.setBlock(w, i + 3, j + 14, k + 9, JourneyBlocks.euca_gold_stone);
            this.setBlock(w, i + 3, j + 14, k + 10, JourneyBlocks.goldite_oak_log_side);
            this.setBlock(w, i + 3, j + 14, k + 11, JourneyBlocks.goldite_oak_log_side);
            this.setBlock(w, i + 3, j + 15, k + 9, JourneyBlocks.goldite_oak_log_side);
            this.setBlock(w, i + 3, j + 15, k + 10, JourneyBlocks.goldite_oak_log_side);
            this.setBlock(w, i + 3, j + 26, k + 7, JourneyBlocks.eucagoldleaves);
            this.setBlock(w, i + 3, j + 26, k + 8, JourneyBlocks.eucagoldleaves);
            this.setBlock(w, i + 3, j + 26, k + 9, JourneyBlocks.eucagoldleaves);
            this.setBlock(w, i + 3, j + 26, k + 10, JourneyBlocks.goldite_oak_log_side);
            this.setBlock(w, i + 3, j + 27, k + 6, JourneyBlocks.eucagoldleaves);
            this.setBlock(w, i + 3, j + 27, k + 7, JourneyBlocks.eucagoldleaves);
            this.setBlock(w, i + 3, j + 27, k + 8, JourneyBlocks.eucagoldleaves);
            this.setBlock(w, i + 3, j + 27, k + 9, JourneyBlocks.eucagoldleaves);
            this.setBlock(w, i + 3, j + 27, k + 10, JourneyBlocks.goldite_oak_log_side);
            this.setBlock(w, i + 3, j + 28, k + 6, JourneyBlocks.eucagoldleaves);
            this.setBlock(w, i + 3, j + 28, k + 7, JourneyBlocks.eucagoldleaves);
            this.setBlock(w, i + 3, j + 28, k + 8, JourneyBlocks.eucagoldleaves);
            this.setBlock(w, i + 3, j + 28, k + 9, JourneyBlocks.eucagoldleaves);
            this.setBlock(w, i + 3, j + 28, k + 10, JourneyBlocks.eucagoldleaves);
            this.setBlock(w, i + 3, j + 29, k + 6, JourneyBlocks.eucagoldleaves);
            this.setBlock(w, i + 3, j + 29, k + 7, JourneyBlocks.eucagoldleaves);
            this.setBlock(w, i + 3, j + 29, k + 8, JourneyBlocks.eucagoldleaves);
            this.setBlock(w, i + 3, j + 29, k + 9, JourneyBlocks.eucagoldleaves);
            this.setBlock(w, i + 3, j + 29, k + 10, JourneyBlocks.eucagoldleaves);
            this.setBlock(w, i + 3, j + 30, k + 7, JourneyBlocks.eucagoldleaves);
            this.setBlock(w, i + 3, j + 30, k + 8, JourneyBlocks.eucagoldleaves);
            this.setBlock(w, i + 3, j + 30, k + 9, JourneyBlocks.eucagoldleaves);
            this.setBlock(w, i + 4, j + 1, k + 6, JourneyBlocks.euca_gold_stone);
            this.setBlock(w, i + 4, j + 1, k + 7, JourneyBlocks.euca_gold_stone);
            this.setBlock(w, i + 4, j + 1, k + 8, JourneyBlocks.euca_gold_stone);
            this.setBlock(w, i + 4, j + 1, k + 9, JourneyBlocks.euca_gold_stone);
            this.setBlock(w, i + 4, j + 1, k + 10, JourneyBlocks.euca_gold_stone);
            this.setBlock(w, i + 4, j + 2, k + 4, JourneyBlocks.euca_gold_stone);
            this.setBlock(w, i + 4, j + 2, k + 5, JourneyBlocks.euca_gold_stone);
            this.setBlock(w, i + 4, j + 2, k + 6, JourneyBlocks.euca_gold_stone);
            this.setBlock(w, i + 4, j + 2, k + 7, JourneyBlocks.euca_gold_stone);
            this.setBlock(w, i + 4, j + 2, k + 8, JourneyBlocks.euca_gold_stone);
            this.setBlock(w, i + 4, j + 2, k + 9, JourneyBlocks.euca_gold_stone);
            this.setBlock(w, i + 4, j + 2, k + 10, JourneyBlocks.euca_gold_stone);
            this.setBlock(w, i + 4, j + 2, k + 11, JourneyBlocks.euca_gold_stone);
            this.setBlock(w, i + 4, j + 2, k + 12, JourneyBlocks.euca_gold_stone);
            this.setBlock(w, i + 4, j + 3, k + 3, JourneyBlocks.euca_gold_stone);
            this.setBlock(w, i + 4, j + 3, k + 4, JourneyBlocks.euca_gold_stone);
            this.setBlock(w, i + 4, j + 3, k + 5, JourneyBlocks.euca_gold_stone);
            this.setBlock(w, i + 4, j + 3, k + 6, JourneyBlocks.euca_gold_stone);
            this.setBlock(w, i + 4, j + 3, k + 7, JourneyBlocks.euca_gold_stone);
            this.setBlock(w, i + 4, j + 3, k + 8, JourneyBlocks.euca_gold_stone);
            this.setBlock(w, i + 4, j + 3, k + 9, JourneyBlocks.euca_gold_stone);
            this.setBlock(w, i + 4, j + 3, k + 10, JourneyBlocks.euca_gold_stone);
            this.setBlock(w, i + 4, j + 3, k + 11, JourneyBlocks.euca_gold_stone);
            this.setBlock(w, i + 4, j + 3, k + 12, JourneyBlocks.euca_gold_stone);
            this.setBlock(w, i + 4, j + 3, k + 13, JourneyBlocks.euca_gold_stone);
            this.setBlock(w, i + 4, j + 4, k + 2, JourneyBlocks.euca_gold_stone);
            this.setBlock(w, i + 4, j + 4, k + 3, JourneyBlocks.euca_gold_stone);
            this.setBlock(w, i + 4, j + 4, k + 4, JourneyBlocks.euca_gold_stone);
            this.setBlock(w, i + 4, j + 4, k + 5, JourneyBlocks.euca_gold_stone);
            this.setBlock(w, i + 4, j + 4, k + 6, JourneyBlocks.euca_gold_stone);
            this.setBlock(w, i + 4, j + 4, k + 7, JourneyBlocks.euca_gold_stone);
            this.setBlock(w, i + 4, j + 4, k + 8, JourneyBlocks.euca_gold_stone);
            this.setBlock(w, i + 4, j + 4, k + 9, JourneyBlocks.euca_gold_stone);
            this.setBlock(w, i + 4, j + 4, k + 10, JourneyBlocks.euca_gold_stone);
            this.setBlock(w, i + 4, j + 4, k + 11, JourneyBlocks.euca_gold_stone);
            this.setBlock(w, i + 4, j + 4, k + 12, JourneyBlocks.euca_gold_stone);
            this.setBlock(w, i + 4, j + 4, k + 13, JourneyBlocks.euca_gold_stone);
            this.setBlock(w, i + 4, j + 4, k + 14, JourneyBlocks.euca_gold_stone);
            this.setBlock(w, i + 4, j + 5, k + 2, JourneyBlocks.euca_gold_stone);
            this.setBlock(w, i + 4, j + 5, k + 3, JourneyBlocks.euca_gold_stone);
            this.setBlock(w, i + 4, j + 5, k + 4, JourneyBlocks.euca_gold_stone);
            this.setBlock(w, i + 4, j + 5, k + 5, JourneyBlocks.euca_gold_stone);
            this.setBlock(w, i + 4, j + 5, k + 6, JourneyBlocks.euca_gold_stone);
            this.setBlock(w, i + 4, j + 5, k + 7, JourneyBlocks.euca_gold_stone);
            this.setBlock(w, i + 4, j + 5, k + 8, JourneyBlocks.euca_gold_stone);
            this.setBlock(w, i + 4, j + 5, k + 9, JourneyBlocks.euca_gold_stone);
            this.setBlock(w, i + 4, j + 5, k + 10, JourneyBlocks.euca_gold_stone);
            this.setBlock(w, i + 4, j + 5, k + 11, JourneyBlocks.euca_gold_stone);
            this.setBlock(w, i + 4, j + 5, k + 12, JourneyBlocks.euca_gold_stone);
            this.setBlock(w, i + 4, j + 5, k + 13, JourneyBlocks.euca_gold_stone);
            this.setBlock(w, i + 4, j + 5, k + 14, JourneyBlocks.euca_gold_stone);
            this.setBlock(w, i + 4, j + 6, k + 1, JourneyBlocks.euca_gold_stone);
            this.setBlock(w, i + 4, j + 6, k + 2, JourneyBlocks.euca_gold_stone);
            this.setBlock(w, i + 4, j + 6, k + 3, JourneyBlocks.eucatile);
            this.setBlock(w, i + 4, j + 6, k + 4, JourneyBlocks.eucatile);
            this.setBlock(w, i + 4, j + 6, k + 5, JourneyBlocks.eucatile);
            this.setBlock(w, i + 4, j + 6, k + 6, JourneyBlocks.eucatile);
            this.setBlock(w, i + 4, j + 6, k + 7, JourneyBlocks.eucatile);
            this.setBlock(w, i + 4, j + 6, k + 8, JourneyBlocks.eucatile);
            this.setBlock(w, i + 4, j + 6, k + 9, JourneyBlocks.eucatile);
            this.setBlock(w, i + 4, j + 6, k + 10, JourneyBlocks.eucatile);
            this.setBlock(w, i + 4, j + 6, k + 11, JourneyBlocks.eucatile);
            this.setBlock(w, i + 4, j + 6, k + 12, JourneyBlocks.eucatile);
            this.setBlock(w, i + 4, j + 6, k + 13, JourneyBlocks.eucatile);
            this.setBlock(w, i + 4, j + 6, k + 14, JourneyBlocks.euca_gold_stone);
            this.setBlock(w, i + 4, j + 6, k + 15, JourneyBlocks.euca_gold_stone);
            this.setBlock(w, i + 4, j + 7, k + 1, JourneyBlocks.euca_gold_stone);
            this.setBlock(w, i + 4, j + 7, k + 2, JourneyBlocks.euca_square_dungeon_bricks);
            this.setBlock(w, i + 4, j + 7, k + 3, JourneyBlocks.euca_square_dungeon_bricks);
            this.setBlock(w, i + 4, j + 7, k + 4, JourneyBlocks.euca_square_dungeon_bricks);
            this.setBlock(w, i + 4, j + 7, k + 12, JourneyBlocks.euca_square_dungeon_bricks);
            this.setBlock(w, i + 4, j + 7, k + 13, JourneyBlocks.euca_square_dungeon_bricks);
            this.setBlock(w, i + 4, j + 7, k + 14, JourneyBlocks.euca_square_dungeon_bricks);
            this.setBlock(w, i + 4, j + 7, k + 15, JourneyBlocks.euca_gold_stone);
            this.setBlock(w, i + 4, j + 8, k + 1, JourneyBlocks.euca_gold_stone);
            this.setBlock(w, i + 4, j + 8, k + 2, JourneyBlocks.euca_square_dungeon_bricks);
            this.setBlock(w, i + 4, j + 8, k + 14, JourneyBlocks.euca_square_dungeon_bricks);
            this.setBlock(w, i + 4, j + 8, k + 15, JourneyBlocks.euca_gold_stone);
            this.setBlock(w, i + 4, j + 9, k + 1, JourneyBlocks.euca_gold_stone);
            this.setBlock(w, i + 4, j + 9, k + 2, JourneyBlocks.euca_square_dungeon_bricks);
            this.setBlock(w, i + 4, j + 9, k + 14, JourneyBlocks.euca_square_dungeon_bricks);
            this.setBlock(w, i + 4, j + 9, k + 15, JourneyBlocks.euca_gold_stone);
            this.setBlock(w, i + 4, j + 10, k + 1, JourneyBlocks.euca_gold_stone);
            this.setBlock(w, i + 4, j + 10, k + 2, JourneyBlocks.euca_square_dungeon_bricks);
            this.setBlock(w, i + 4, j + 10, k + 14, JourneyBlocks.euca_square_dungeon_bricks);
            this.setBlock(w, i + 4, j + 10, k + 15, JourneyBlocks.goldite_oak_log_side);
            this.setBlock(w, i + 4, j + 11, k + 2, JourneyBlocks.euca_gold_stone);
            this.setBlock(w, i + 4, j + 11, k + 3, JourneyBlocks.euca_runic_lamp);
            this.setBlock(w, i + 4, j + 11, k + 4, JourneyBlocks.euca_square_dungeon_bricks);
            this.setBlock(w, i + 4, j + 11, k + 5, JourneyBlocks.euca_square_dungeon_bricks);
            this.setBlock(w, i + 4, j + 11, k + 6, JourneyBlocks.euca_square_dungeon_bricks);
            this.setBlock(w, i + 4, j + 11, k + 7, JourneyBlocks.euca_square_dungeon_bricks);
            this.setBlock(w, i + 4, j + 11, k + 8, JourneyBlocks.euca_square_dungeon_bricks);
            this.setBlock(w, i + 4, j + 11, k + 9, JourneyBlocks.euca_square_dungeon_bricks);
            this.setBlock(w, i + 4, j + 11, k + 10, JourneyBlocks.euca_square_dungeon_bricks);
            this.setBlock(w, i + 4, j + 11, k + 11, JourneyBlocks.euca_square_dungeon_bricks);
            this.setBlock(w, i + 4, j + 11, k + 12, JourneyBlocks.euca_square_dungeon_bricks);
            this.setBlock(w, i + 4, j + 11, k + 13, JourneyBlocks.euca_runic_lamp);
            this.setBlock(w, i + 4, j + 11, k + 14, JourneyBlocks.euca_gold_stone);
            this.setBlock(w, i + 4, j + 11, k + 15, JourneyBlocks.goldite_oak_log_side);
            this.setBlock(w, i + 4, j + 12, k + 2, JourneyBlocks.euca_gold_stone);
            this.setBlock(w, i + 4, j + 12, k + 3, JourneyBlocks.euca_gold_stone);
            this.setBlock(w, i + 4, j + 12, k + 4, JourneyBlocks.euca_gold_stone);
            this.setBlock(w, i + 4, j + 12, k + 5, JourneyBlocks.euca_gold_stone);
            this.setBlock(w, i + 4, j + 12, k + 6, JourneyBlocks.euca_gold_stone);
            this.setBlock(w, i + 4, j + 12, k + 7, JourneyBlocks.euca_gold_stone);
            this.setBlock(w, i + 4, j + 12, k + 8, JourneyBlocks.euca_gold_stone);
            this.setBlock(w, i + 4, j + 12, k + 9, JourneyBlocks.euca_gold_stone);
            this.setBlock(w, i + 4, j + 12, k + 10, JourneyBlocks.euca_gold_stone);
            this.setBlock(w, i + 4, j + 12, k + 11, JourneyBlocks.euca_gold_stone);
            this.setBlock(w, i + 4, j + 12, k + 12, JourneyBlocks.euca_gold_stone);
            this.setBlock(w, i + 4, j + 12, k + 13, JourneyBlocks.euca_gold_stone);
            this.setBlock(w, i + 4, j + 12, k + 14, JourneyBlocks.euca_gold_stone);
            this.setBlock(w, i + 4, j + 13, k + 3, JourneyBlocks.goldite_oak_log_side);
            this.setBlock(w, i + 4, j + 13, k + 4, JourneyBlocks.euca_gold_stone);
            this.setBlock(w, i + 4, j + 13, k + 5, JourneyBlocks.euca_gold_stone);
            this.setBlock(w, i + 4, j + 13, k + 6, JourneyBlocks.euca_gold_stone);
            this.setBlock(w, i + 4, j + 13, k + 7, JourneyBlocks.euca_gold_stone);
            this.setBlock(w, i + 4, j + 13, k + 8, JourneyBlocks.euca_gold_stone);
            this.setBlock(w, i + 4, j + 13, k + 9, JourneyBlocks.euca_gold_stone);
            this.setBlock(w, i + 4, j + 13, k + 10, JourneyBlocks.euca_gold_stone);
            this.setBlock(w, i + 4, j + 13, k + 11, JourneyBlocks.euca_gold_stone);
            this.setBlock(w, i + 4, j + 13, k + 12, JourneyBlocks.euca_gold_stone);
            this.setBlock(w, i + 4, j + 13, k + 13, JourneyBlocks.euca_gold_stone);
            this.setBlock(w, i + 4, j + 14, k + 4, JourneyBlocks.goldite_oak_log_side);
            this.setBlock(w, i + 4, j + 14, k + 5, JourneyBlocks.euca_gold_stone);
            this.setBlock(w, i + 4, j + 14, k + 6, JourneyBlocks.euca_gold_stone);
            this.setBlock(w, i + 4, j + 14, k + 7, JourneyBlocks.euca_gold_stone);
            this.setBlock(w, i + 4, j + 14, k + 8, JourneyBlocks.euca_gold_stone);
            this.setBlock(w, i + 4, j + 14, k + 9, JourneyBlocks.euca_gold_stone);
            this.setBlock(w, i + 4, j + 14, k + 10, JourneyBlocks.euca_gold_stone);
            this.setBlock(w, i + 4, j + 14, k + 11, JourneyBlocks.euca_gold_stone);
            this.setBlock(w, i + 4, j + 14, k + 12, JourneyBlocks.euca_gold_stone);
            this.setBlock(w, i + 4, j + 15, k + 5, JourneyBlocks.goldite_oak_log_side);
            this.setBlock(w, i + 4, j + 15, k + 6, JourneyBlocks.euca_gold_stone);
            this.setBlock(w, i + 4, j + 15, k + 7, JourneyBlocks.goldite_oak_log_side);
            this.setBlock(w, i + 4, j + 15, k + 8, JourneyBlocks.goldite_oak_log_side);
            this.setBlock(w, i + 4, j + 15, k + 9, JourneyBlocks.goldite_oak_log_side);
            this.setBlock(w, i + 4, j + 15, k + 10, JourneyBlocks.euca_gold_stone);
            this.setBlock(w, i + 4, j + 15, k + 11, JourneyBlocks.goldite_oak_log_side);
            this.setBlock(w, i + 4, j + 16, k + 8, JourneyBlocks.goldite_oak_log_side);
            this.setBlock(w, i + 4, j + 16, k + 10, JourneyBlocks.goldite_oak_log_side);
            this.setBlock(w, i + 4, j + 24, k + 10, JourneyBlocks.goldite_oak_log_side);
            this.setBlock(w, i + 4, j + 25, k + 5, JourneyBlocks.goldite_oak_log_side);
            this.setBlock(w, i + 4, j + 25, k + 6, JourneyBlocks.goldite_oak_log_side);
            this.setBlock(w, i + 4, j + 25, k + 7, JourneyBlocks.eucagoldleaves);
            this.setBlock(w, i + 4, j + 25, k + 8, JourneyBlocks.eucagoldleaves);
            this.setBlock(w, i + 4, j + 25, k + 9, JourneyBlocks.eucagoldleaves);
            this.setBlock(w, i + 4, j + 25, k + 10, JourneyBlocks.goldite_oak_log_side);
            this.setBlock(w, i + 4, j + 25, k + 11, JourneyBlocks.goldite_oak_log_side);
            this.setBlock(w, i + 4, j + 26, k + 5, JourneyBlocks.goldite_oak_log_side);
            this.setBlock(w, i + 4, j + 26, k + 6, JourneyBlocks.eucagoldleaves);
            this.setBlock(w, i + 4, j + 26, k + 7, JourneyBlocks.eucagoldleaves);
            this.setBlock(w, i + 4, j + 26, k + 8, JourneyBlocks.eucagoldleaves);
            this.setBlock(w, i + 4, j + 26, k + 9, JourneyBlocks.eucagoldleaves);
            this.setBlock(w, i + 4, j + 26, k + 10, JourneyBlocks.eucagoldleaves);
            this.setBlock(w, i + 4, j + 26, k + 11, JourneyBlocks.goldite_oak_log_side);
            this.setBlock(w, i + 4, j + 27, k + 5, JourneyBlocks.goldite_oak_log_side);
            this.setBlock(w, i + 4, j + 27, k + 6, JourneyBlocks.eucagoldleaves);
            this.setBlock(w, i + 4, j + 27, k + 7, JourneyBlocks.eucagoldleaves);
            this.setBlock(w, i + 4, j + 27, k + 8, JourneyBlocks.eucagoldleaves);
            this.setBlock(w, i + 4, j + 27, k + 9, JourneyBlocks.eucagoldleaves);
            this.setBlock(w, i + 4, j + 27, k + 10, JourneyBlocks.eucagoldleaves);
            this.setBlock(w, i + 4, j + 27, k + 11, JourneyBlocks.eucagoldleaves);
            this.setBlock(w, i + 4, j + 28, k + 5, JourneyBlocks.eucagoldleaves);
            this.setBlock(w, i + 4, j + 28, k + 6, JourneyBlocks.eucagoldleaves);
            this.setBlock(w, i + 4, j + 28, k + 7, JourneyBlocks.eucagoldleaves);
            this.setBlock(w, i + 4, j + 28, k + 8, JourneyBlocks.eucagoldleaves);
            this.setBlock(w, i + 4, j + 28, k + 9, JourneyBlocks.eucagoldleaves);
            this.setBlock(w, i + 4, j + 28, k + 10, JourneyBlocks.eucagoldleaves);
            this.setBlock(w, i + 4, j + 28, k + 11, JourneyBlocks.eucagoldleaves);
            this.setBlock(w, i + 4, j + 29, k + 5, JourneyBlocks.eucagoldleaves);
            this.setBlock(w, i + 4, j + 29, k + 6, JourneyBlocks.eucagoldleaves);
            this.setBlock(w, i + 4, j + 29, k + 7, JourneyBlocks.eucagoldleaves);
            this.setBlock(w, i + 4, j + 29, k + 8, JourneyBlocks.eucagoldleaves);
            this.setBlock(w, i + 4, j + 29, k + 9, JourneyBlocks.eucagoldleaves);
            this.setBlock(w, i + 4, j + 29, k + 10, JourneyBlocks.eucagoldleaves);
            this.setBlock(w, i + 4, j + 29, k + 11, JourneyBlocks.eucagoldleaves);
            this.setBlock(w, i + 4, j + 30, k + 5, JourneyBlocks.eucagoldleaves);
            this.setBlock(w, i + 4, j + 30, k + 6, JourneyBlocks.eucagoldleaves);
            this.setBlock(w, i + 4, j + 30, k + 7, JourneyBlocks.eucagoldleaves);
            this.setBlock(w, i + 4, j + 30, k + 8, JourneyBlocks.eucagoldleaves);
            this.setBlock(w, i + 4, j + 30, k + 9, JourneyBlocks.eucagoldleaves);
            this.setBlock(w, i + 4, j + 30, k + 10, JourneyBlocks.eucagoldleaves);
            this.setBlock(w, i + 4, j + 30, k + 11, JourneyBlocks.eucagoldleaves);
            this.setBlock(w, i + 4, j + 31, k + 6, JourneyBlocks.eucagoldleaves);
            this.setBlock(w, i + 4, j + 31, k + 7, JourneyBlocks.eucagoldleaves);
            this.setBlock(w, i + 4, j + 31, k + 8, JourneyBlocks.eucagoldleaves);
            this.setBlock(w, i + 4, j + 31, k + 9, JourneyBlocks.eucagoldleaves);
            this.setBlock(w, i + 4, j + 31, k + 10, JourneyBlocks.eucagoldleaves);
            this.setBlock(w, i + 5, j + 1, k + 5, JourneyBlocks.euca_gold_stone);
            this.setBlock(w, i + 5, j + 1, k + 6, JourneyBlocks.euca_gold_stone);
            this.setBlock(w, i + 5, j + 1, k + 7, JourneyBlocks.euca_gold_stone);
            this.setBlock(w, i + 5, j + 1, k + 8, JourneyBlocks.euca_gold_stone);
            this.setBlock(w, i + 5, j + 1, k + 9, JourneyBlocks.euca_gold_stone);
            this.setBlock(w, i + 5, j + 1, k + 10, JourneyBlocks.euca_gold_stone);
            this.setBlock(w, i + 5, j + 1, k + 11, JourneyBlocks.euca_gold_stone);
            this.setBlock(w, i + 5, j + 2, k + 3, JourneyBlocks.euca_gold_stone);
            this.setBlock(w, i + 5, j + 2, k + 4, JourneyBlocks.euca_gold_stone);
            this.setBlock(w, i + 5, j + 2, k + 5, JourneyBlocks.euca_gold_stone);
            this.setBlock(w, i + 5, j + 2, k + 6, JourneyBlocks.euca_gold_stone);
            this.setBlock(w, i + 5, j + 2, k + 7, JourneyBlocks.euca_gold_stone);
            this.setBlock(w, i + 5, j + 2, k + 8, JourneyBlocks.euca_gold_stone);
            this.setBlock(w, i + 5, j + 2, k + 9, JourneyBlocks.euca_gold_stone);
            this.setBlock(w, i + 5, j + 2, k + 10, JourneyBlocks.euca_gold_stone);
            this.setBlock(w, i + 5, j + 2, k + 11, JourneyBlocks.euca_gold_stone);
            this.setBlock(w, i + 5, j + 2, k + 12, JourneyBlocks.euca_gold_stone);
            this.setBlock(w, i + 5, j + 2, k + 13, JourneyBlocks.euca_gold_stone);
            this.setBlock(w, i + 5, j + 3, k + 2, JourneyBlocks.euca_gold_stone);
            this.setBlock(w, i + 5, j + 3, k + 3, JourneyBlocks.euca_gold_stone);
            this.setBlock(w, i + 5, j + 3, k + 4, JourneyBlocks.euca_gold_stone);
            this.setBlock(w, i + 5, j + 3, k + 5, JourneyBlocks.euca_gold_stone);
            this.setBlock(w, i + 5, j + 3, k + 6, JourneyBlocks.euca_gold_stone);
            this.setBlock(w, i + 5, j + 3, k + 7, JourneyBlocks.euca_gold_stone);
            this.setBlock(w, i + 5, j + 3, k + 8, JourneyBlocks.euca_gold_stone);
            this.setBlock(w, i + 5, j + 3, k + 9, JourneyBlocks.euca_gold_stone);
            this.setBlock(w, i + 5, j + 3, k + 10, JourneyBlocks.euca_gold_stone);
            this.setBlock(w, i + 5, j + 3, k + 11, JourneyBlocks.euca_gold_stone);
            this.setBlock(w, i + 5, j + 3, k + 12, JourneyBlocks.euca_gold_stone);
            this.setBlock(w, i + 5, j + 3, k + 13, JourneyBlocks.euca_gold_stone);
            this.setBlock(w, i + 5, j + 3, k + 14, JourneyBlocks.euca_gold_stone);
            this.setBlock(w, i + 5, j + 4, k + 2, JourneyBlocks.euca_gold_stone);
            this.setBlock(w, i + 5, j + 4, k + 3, JourneyBlocks.euca_gold_stone);
            this.setBlock(w, i + 5, j + 4, k + 4, JourneyBlocks.euca_gold_stone);
            this.setBlock(w, i + 5, j + 4, k + 5, JourneyBlocks.euca_gold_stone);
            this.setBlock(w, i + 5, j + 4, k + 6, JourneyBlocks.euca_gold_stone);
            this.setBlock(w, i + 5, j + 4, k + 7, JourneyBlocks.euca_gold_stone);
            this.setBlock(w, i + 5, j + 4, k + 8, JourneyBlocks.euca_gold_stone);
            this.setBlock(w, i + 5, j + 4, k + 9, JourneyBlocks.euca_gold_stone);
            this.setBlock(w, i + 5, j + 4, k + 10, JourneyBlocks.euca_gold_stone);
            this.setBlock(w, i + 5, j + 4, k + 11, JourneyBlocks.euca_gold_stone);
            this.setBlock(w, i + 5, j + 4, k + 12, JourneyBlocks.euca_gold_stone);
            this.setBlock(w, i + 5, j + 4, k + 13, JourneyBlocks.euca_gold_stone);
            this.setBlock(w, i + 5, j + 4, k + 14, JourneyBlocks.euca_gold_stone);
            this.setBlock(w, i + 5, j + 5, k + 1, JourneyBlocks.euca_gold_stone);
            this.setBlock(w, i + 5, j + 5, k + 2, JourneyBlocks.euca_gold_stone);
            this.setBlock(w, i + 5, j + 5, k + 3, JourneyBlocks.euca_gold_stone);
            this.setBlock(w, i + 5, j + 5, k + 4, JourneyBlocks.euca_gold_stone);
            this.setBlock(w, i + 5, j + 5, k + 5, JourneyBlocks.euca_gold_stone);
            this.setBlock(w, i + 5, j + 5, k + 6, JourneyBlocks.euca_gold_stone);
            this.setBlock(w, i + 5, j + 5, k + 7, JourneyBlocks.euca_gold_stone);
            this.setBlock(w, i + 5, j + 5, k + 8, JourneyBlocks.euca_gold_stone);
            this.setBlock(w, i + 5, j + 5, k + 9, JourneyBlocks.euca_gold_stone);
            this.setBlock(w, i + 5, j + 5, k + 10, JourneyBlocks.euca_gold_stone);
            this.setBlock(w, i + 5, j + 5, k + 11, JourneyBlocks.euca_gold_stone);
            this.setBlock(w, i + 5, j + 5, k + 12, JourneyBlocks.euca_gold_stone);
            this.setBlock(w, i + 5, j + 5, k + 13, JourneyBlocks.euca_gold_stone);
            this.setBlock(w, i + 5, j + 5, k + 14, JourneyBlocks.euca_gold_stone);
            this.setBlock(w, i + 5, j + 5, k + 15, JourneyBlocks.euca_gold_stone);
            this.setBlock(w, i + 5, j + 6, k + 1, JourneyBlocks.euca_gold_stone);
            this.setBlock(w, i + 5, j + 6, k + 2, JourneyBlocks.euca_gold_stone);
            this.setBlock(w, i + 5, j + 6, k + 3, JourneyBlocks.eucatile);
            this.setBlock(w, i + 5, j + 6, k + 4, JourneyBlocks.eucatile);
            this.setBlock(w, i + 5, j + 6, k + 5, JourneyBlocks.eucatile);
            this.setBlock(w, i + 5, j + 6, k + 6, JourneyBlocks.eucatile);
            this.setBlock(w, i + 5, j + 6, k + 7, JourneyBlocks.eucatile);
            this.setBlock(w, i + 5, j + 6, k + 8, JourneyBlocks.eucatile);
            this.setBlock(w, i + 5, j + 6, k + 9, JourneyBlocks.eucatile);
            this.setBlock(w, i + 5, j + 6, k + 10, JourneyBlocks.eucatile);
            this.setBlock(w, i + 5, j + 6, k + 11, JourneyBlocks.eucatile);
            this.setBlock(w, i + 5, j + 6, k + 12, JourneyBlocks.eucatile);
            this.setBlock(w, i + 5, j + 6, k + 13, JourneyBlocks.eucatile);
            this.setBlock(w, i + 5, j + 6, k + 14, JourneyBlocks.euca_gold_stone);
            this.setBlock(w, i + 5, j + 6, k + 15, JourneyBlocks.euca_gold_stone);
            this.setBlock(w, i + 5, j + 7, k + 1, JourneyBlocks.euca_gold_stone);
            this.setBlock(w, i + 5, j + 7, k + 2, JourneyBlocks.euca_square_dungeon_bricks);
            this.setBlock(w, i + 5, j + 7, k + 14, JourneyBlocks.euca_square_dungeon_bricks);
            this.setBlock(w, i + 5, j + 7, k + 15, JourneyBlocks.euca_gold_stone);
            this.setBlock(w, i + 5, j + 8, k + 1, JourneyBlocks.euca_gold_stone);
            this.setBlock(w, i + 5, j + 8, k + 2, JourneyBlocks.euca_square_dungeon_bricks);
            this.setBlock(w, i + 5, j + 8, k + 14, JourneyBlocks.euca_square_dungeon_bricks);
            this.setBlock(w, i + 5, j + 8, k + 15, JourneyBlocks.euca_gold_stone);
            this.setBlock(w, i + 5, j + 9, k + 1, JourneyBlocks.goldite_oak_log_side);
            this.setBlock(w, i + 5, j + 9, k + 2, JourneyBlocks.euca_square_dungeon_bricks);
            this.setBlock(w, i + 5, j + 9, k + 14, JourneyBlocks.euca_square_dungeon_bricks);
            this.setBlock(w, i + 5, j + 9, k + 15, JourneyBlocks.euca_gold_stone);
            this.setBlock(w, i + 5, j + 9, k + 16, JourneyBlocks.goldite_oak_log_side);
            this.setBlock(w, i + 5, j + 10, k + 1, JourneyBlocks.goldite_oak_log_side);
            this.setBlock(w, i + 5, j + 10, k + 2, JourneyBlocks.euca_square_dungeon_bricks);
            this.setBlock(w, i + 5, j + 10, k + 14, JourneyBlocks.euca_square_dungeon_bricks);
            this.setBlock(w, i + 5, j + 10, k + 15, JourneyBlocks.euca_gold_stone);
            this.setBlock(w, i + 5, j + 10, k + 16, JourneyBlocks.goldite_oak_log_side);
            this.setBlock(w, i + 5, j + 11, k + 1, JourneyBlocks.goldite_oak_log_side);
            this.setBlock(w, i + 5, j + 11, k + 2, JourneyBlocks.euca_gold_stone);
            this.setBlock(w, i + 5, j + 11, k + 3, JourneyBlocks.euca_square_dungeon_bricks);
            this.setBlock(w, i + 5, j + 11, k + 4, JourneyBlocks.euca_square_dungeon_bricks);
            this.setBlock(w, i + 5, j + 11, k + 5, JourneyBlocks.euca_square_dungeon_bricks);
            this.setBlock(w, i + 5, j + 11, k + 6, JourneyBlocks.euca_square_dungeon_bricks);
            this.setBlock(w, i + 5, j + 11, k + 7, JourneyBlocks.euca_square_dungeon_bricks);
            this.setBlock(w, i + 5, j + 11, k + 8, JourneyBlocks.euca_square_dungeon_bricks);
            this.setBlock(w, i + 5, j + 11, k + 9, JourneyBlocks.euca_square_dungeon_bricks);
            this.setBlock(w, i + 5, j + 11, k + 10, JourneyBlocks.euca_square_dungeon_bricks);
            this.setBlock(w, i + 5, j + 11, k + 11, JourneyBlocks.euca_square_dungeon_bricks);
            this.setBlock(w, i + 5, j + 11, k + 12, JourneyBlocks.euca_square_dungeon_bricks);
            this.setBlock(w, i + 5, j + 11, k + 13, JourneyBlocks.euca_square_dungeon_bricks);
            this.setBlock(w, i + 5, j + 11, k + 14, JourneyBlocks.euca_gold_stone);
            this.setBlock(w, i + 5, j + 11, k + 15, JourneyBlocks.euca_gold_stone);
            this.setBlock(w, i + 5, j + 11, k + 16, JourneyBlocks.goldite_oak_log_side);
            this.setBlock(w, i + 5, j + 12, k + 2, JourneyBlocks.euca_gold_stone);
            this.setBlock(w, i + 5, j + 12, k + 3, JourneyBlocks.euca_gold_stone);
            this.setBlock(w, i + 5, j + 12, k + 4, JourneyBlocks.euca_gold_stone);
            this.setBlock(w, i + 5, j + 12, k + 5, JourneyBlocks.euca_gold_stone);
            this.setBlock(w, i + 5, j + 12, k + 6, JourneyBlocks.euca_gold_stone);
            this.setBlock(w, i + 5, j + 12, k + 7, JourneyBlocks.euca_gold_stone);
            this.setBlock(w, i + 5, j + 12, k + 8, JourneyBlocks.euca_gold_stone);
            this.setBlock(w, i + 5, j + 12, k + 9, JourneyBlocks.euca_gold_stone);
            this.setBlock(w, i + 5, j + 12, k + 10, JourneyBlocks.euca_gold_stone);
            this.setBlock(w, i + 5, j + 12, k + 11, JourneyBlocks.euca_gold_stone);
            this.setBlock(w, i + 5, j + 12, k + 12, JourneyBlocks.euca_gold_stone);
            this.setBlock(w, i + 5, j + 12, k + 13, JourneyBlocks.euca_gold_stone);
            this.setBlock(w, i + 5, j + 12, k + 14, JourneyBlocks.euca_gold_stone);
            this.setBlock(w, i + 5, j + 12, k + 15, JourneyBlocks.goldite_oak_log_side);
            this.setBlock(w, i + 5, j + 13, k + 2, JourneyBlocks.goldite_oak_log_side);
            this.setBlock(w, i + 5, j + 13, k + 3, JourneyBlocks.euca_gold_stone);
            this.setBlock(w, i + 5, j + 13, k + 4, JourneyBlocks.euca_gold_stone);
            this.setBlock(w, i + 5, j + 13, k + 5, JourneyBlocks.euca_gold_stone);
            this.setBlock(w, i + 5, j + 13, k + 6, JourneyBlocks.euca_gold_stone);
            this.setBlock(w, i + 5, j + 13, k + 7, JourneyBlocks.euca_gold_stone);
            this.setBlock(w, i + 5, j + 13, k + 8, JourneyBlocks.euca_gold_stone);
            this.setBlock(w, i + 5, j + 13, k + 9, JourneyBlocks.euca_gold_stone);
            this.setBlock(w, i + 5, j + 13, k + 10, JourneyBlocks.euca_gold_stone);
            this.setBlock(w, i + 5, j + 13, k + 11, JourneyBlocks.euca_gold_stone);
            this.setBlock(w, i + 5, j + 13, k + 12, JourneyBlocks.euca_gold_stone);
            this.setBlock(w, i + 5, j + 13, k + 13, JourneyBlocks.euca_gold_stone);
            this.setBlock(w, i + 5, j + 13, k + 14, JourneyBlocks.euca_gold_stone);
            this.setBlock(w, i + 5, j + 14, k + 3, JourneyBlocks.euca_gold_stone);
            this.setBlock(w, i + 5, j + 14, k + 4, JourneyBlocks.euca_gold_stone);
            this.setBlock(w, i + 5, j + 14, k + 5, JourneyBlocks.euca_gold_stone);
            this.setBlock(w, i + 5, j + 14, k + 6, JourneyBlocks.euca_gold_stone);
            this.setBlock(w, i + 5, j + 14, k + 7, JourneyBlocks.euca_gold_stone);
            this.setBlock(w, i + 5, j + 14, k + 8, JourneyBlocks.euca_gold_stone);
            this.setBlock(w, i + 5, j + 14, k + 9, JourneyBlocks.euca_gold_stone);
            this.setBlock(w, i + 5, j + 14, k + 10, JourneyBlocks.euca_gold_stone);
            this.setBlock(w, i + 5, j + 14, k + 11, JourneyBlocks.euca_gold_stone);
            this.setBlock(w, i + 5, j + 14, k + 12, JourneyBlocks.euca_gold_stone);
            this.setBlock(w, i + 5, j + 14, k + 13, JourneyBlocks.euca_gold_stone);
            this.setBlock(w, i + 5, j + 15, k + 4, JourneyBlocks.goldite_oak_log_side);
            this.setBlock(w, i + 5, j + 15, k + 5, JourneyBlocks.euca_gold_stone);
            this.setBlock(w, i + 5, j + 15, k + 6, JourneyBlocks.euca_gold_stone);
            this.setBlock(w, i + 5, j + 15, k + 7, JourneyBlocks.euca_gold_stone);
            this.setBlock(w, i + 5, j + 15, k + 8, JourneyBlocks.euca_gold_stone);
            this.setBlock(w, i + 5, j + 15, k + 9, JourneyBlocks.euca_gold_stone);
            this.setBlock(w, i + 5, j + 15, k + 10, JourneyBlocks.euca_gold_stone);
            this.setBlock(w, i + 5, j + 15, k + 11, JourneyBlocks.euca_gold_stone);
            this.setBlock(w, i + 5, j + 16, k + 5, JourneyBlocks.goldite_oak_log_side);
            this.setBlock(w, i + 5, j + 16, k + 6, JourneyBlocks.goldite_oak_log_side);
            this.setBlock(w, i + 5, j + 16, k + 7, JourneyBlocks.euca_square_dungeon_bricks);
            this.setBlock(w, i + 5, j + 16, k + 8, JourneyBlocks.goldite_oak_log_side);
            this.setBlock(w, i + 5, j + 16, k + 9, JourneyBlocks.goldite_oak_log_side);
            this.setBlock(w, i + 5, j + 16, k + 10, JourneyBlocks.goldite_oak_log_side);
            this.setBlock(w, i + 5, j + 17, k + 6, JourneyBlocks.goldite_oak_log_side);
            this.setBlock(w, i + 5, j + 17, k + 8, JourneyBlocks.goldite_oak_log_side);
            this.setBlock(w, i + 5, j + 17, k + 9, JourneyBlocks.goldite_oak_log_side);
            this.setBlock(w, i + 5, j + 17, k + 10, JourneyBlocks.goldite_oak_log_side);
            this.setBlock(w, i + 5, j + 18, k + 9, JourneyBlocks.goldite_oak_log_side);
            this.setBlock(w, i + 5, j + 19, k + 8, JourneyBlocks.goldite_oak_log_side);
            this.setBlock(w, i + 5, j + 19, k + 9, JourneyBlocks.goldite_oak_log_side);
            this.setBlock(w, i + 5, j + 20, k + 8, JourneyBlocks.goldite_oak_log_side);
            this.setBlock(w, i + 5, j + 23, k + 10, JourneyBlocks.goldite_oak_log_side);
            this.setBlock(w, i + 5, j + 24, k + 5, JourneyBlocks.goldite_oak_log_side);
            this.setBlock(w, i + 5, j + 24, k + 6, JourneyBlocks.goldite_oak_log_side);
            this.setBlock(w, i + 5, j + 24, k + 7, JourneyBlocks.eucagoldleaves);
            this.setBlock(w, i + 5, j + 24, k + 8, JourneyBlocks.eucagoldleaves);
            this.setBlock(w, i + 5, j + 24, k + 9, JourneyBlocks.eucagoldleaves);
            this.setBlock(w, i + 5, j + 24, k + 10, JourneyBlocks.goldite_oak_log_side);
            this.setBlock(w, i + 5, j + 24, k + 11, JourneyBlocks.goldite_oak_log_side);
            this.setBlock(w, i + 5, j + 25, k + 4, JourneyBlocks.goldite_oak_log_side);
            this.setBlock(w, i + 5, j + 25, k + 5, JourneyBlocks.goldite_oak_log_side);
            this.setBlock(w, i + 5, j + 25, k + 6, JourneyBlocks.goldite_oak_log_side);
            this.setBlock(w, i + 5, j + 25, k + 7, JourneyBlocks.goldite_oak_log_side);
            this.setBlock(w, i + 5, j + 25, k + 8, JourneyBlocks.goldite_oak_log_side);
            this.setBlock(w, i + 5, j + 25, k + 9, JourneyBlocks.goldite_oak_log_side);
            this.setBlock(w, i + 5, j + 25, k + 10, JourneyBlocks.eucagoldleaves);
            this.setBlock(w, i + 5, j + 25, k + 11, JourneyBlocks.eucagoldleaves);
            this.setBlock(w, i + 5, j + 26, k + 4, JourneyBlocks.eucagoldleaves);
            this.setBlock(w, i + 5, j + 26, k + 5, JourneyBlocks.eucagoldleaves);
            this.setBlock(w, i + 5, j + 26, k + 6, JourneyBlocks.eucagoldleaves);
            this.setBlock(w, i + 5, j + 26, k + 7, JourneyBlocks.eucagoldleaves);
            this.setBlock(w, i + 5, j + 26, k + 8, JourneyBlocks.eucagoldleaves);
            this.setBlock(w, i + 5, j + 26, k + 9, JourneyBlocks.eucagoldleaves);
            this.setBlock(w, i + 5, j + 26, k + 10, JourneyBlocks.eucagoldleaves);
            this.setBlock(w, i + 5, j + 26, k + 11, JourneyBlocks.eucagoldleaves);
            this.setBlock(w, i + 5, j + 26, k + 12, JourneyBlocks.eucagoldleaves);
            this.setBlock(w, i + 5, j + 27, k + 4, JourneyBlocks.eucagoldleaves);
            this.setBlock(w, i + 5, j + 27, k + 5, JourneyBlocks.eucagoldleaves);
            this.setBlock(w, i + 5, j + 27, k + 6, JourneyBlocks.eucagoldleaves);
            this.setBlock(w, i + 5, j + 27, k + 7, JourneyBlocks.eucagoldleaves);
            this.setBlock(w, i + 5, j + 27, k + 8, JourneyBlocks.eucagoldleaves);
            this.setBlock(w, i + 5, j + 27, k + 9, JourneyBlocks.eucagoldleaves);
            this.setBlock(w, i + 5, j + 27, k + 10, JourneyBlocks.eucagoldleaves);
            this.setBlock(w, i + 5, j + 27, k + 11, JourneyBlocks.eucagoldleaves);
            this.setBlock(w, i + 5, j + 27, k + 12, JourneyBlocks.eucagoldleaves);
            this.setBlock(w, i + 5, j + 28, k + 4, JourneyBlocks.eucagoldleaves);
            this.setBlock(w, i + 5, j + 28, k + 5, JourneyBlocks.eucagoldleaves);
            this.setBlock(w, i + 5, j + 28, k + 6, JourneyBlocks.eucagoldleaves);
            this.setBlock(w, i + 5, j + 28, k + 7, JourneyBlocks.eucagoldleaves);
            this.setBlock(w, i + 5, j + 28, k + 8, JourneyBlocks.eucagoldleaves);
            this.setBlock(w, i + 5, j + 28, k + 9, JourneyBlocks.eucagoldleaves);
            this.setBlock(w, i + 5, j + 28, k + 10, JourneyBlocks.eucagoldleaves);
            this.setBlock(w, i + 5, j + 28, k + 11, JourneyBlocks.eucagoldleaves);
            this.setBlock(w, i + 5, j + 28, k + 12, JourneyBlocks.eucagoldleaves);
            this.setBlock(w, i + 5, j + 29, k + 4, JourneyBlocks.eucagoldleaves);
            this.setBlock(w, i + 5, j + 29, k + 5, JourneyBlocks.eucagoldleaves);
            this.setBlock(w, i + 5, j + 29, k + 6, JourneyBlocks.eucagoldleaves);
            this.setBlock(w, i + 5, j + 29, k + 7, JourneyBlocks.eucagoldleaves);
            this.setBlock(w, i + 5, j + 29, k + 8, JourneyBlocks.eucagoldleaves);
            this.setBlock(w, i + 5, j + 29, k + 9, JourneyBlocks.eucagoldleaves);
            this.setBlock(w, i + 5, j + 29, k + 10, JourneyBlocks.eucagoldleaves);
            this.setBlock(w, i + 5, j + 29, k + 11, JourneyBlocks.eucagoldleaves);
            this.setBlock(w, i + 5, j + 29, k + 12, JourneyBlocks.eucagoldleaves);
            this.setBlock(w, i + 5, j + 30, k + 4, JourneyBlocks.eucagoldleaves);
            this.setBlock(w, i + 5, j + 30, k + 5, JourneyBlocks.eucagoldleaves);
            this.setBlock(w, i + 5, j + 30, k + 6, JourneyBlocks.eucagoldleaves);
            this.setBlock(w, i + 5, j + 30, k + 7, JourneyBlocks.eucagoldleaves);
            this.setBlock(w, i + 5, j + 30, k + 8, JourneyBlocks.eucagoldleaves);
            this.setBlock(w, i + 5, j + 30, k + 9, JourneyBlocks.eucagoldleaves);
            this.setBlock(w, i + 5, j + 30, k + 10, JourneyBlocks.eucagoldleaves);
            this.setBlock(w, i + 5, j + 30, k + 11, JourneyBlocks.eucagoldleaves);
            this.setBlock(w, i + 5, j + 30, k + 12, JourneyBlocks.eucagoldleaves);
            this.setBlock(w, i + 5, j + 31, k + 5, JourneyBlocks.eucagoldleaves);
            this.setBlock(w, i + 5, j + 31, k + 6, JourneyBlocks.eucagoldleaves);
            this.setBlock(w, i + 5, j + 31, k + 7, JourneyBlocks.eucagoldleaves);
            this.setBlock(w, i + 5, j + 31, k + 8, JourneyBlocks.eucagoldleaves);
            this.setBlock(w, i + 5, j + 31, k + 9, JourneyBlocks.eucagoldleaves);
            this.setBlock(w, i + 5, j + 31, k + 10, JourneyBlocks.eucagoldleaves);
            this.setBlock(w, i + 5, j + 31, k + 11, JourneyBlocks.eucagoldleaves);
            this.setBlock(w, i + 5, j + 32, k + 6, JourneyBlocks.eucagoldleaves);
            this.setBlock(w, i + 5, j + 32, k + 7, JourneyBlocks.eucagoldleaves);
            this.setBlock(w, i + 5, j + 32, k + 8, JourneyBlocks.eucagoldleaves);
            this.setBlock(w, i + 5, j + 32, k + 9, JourneyBlocks.eucagoldleaves);
            this.setBlock(w, i + 5, j + 32, k + 10, JourneyBlocks.eucagoldleaves);
            this.setBlock(w, i + 6, j + 0, k + 6, JourneyBlocks.euca_gold_stone);
            this.setBlock(w, i + 6, j + 0, k + 7, JourneyBlocks.euca_gold_stone);
            this.setBlock(w, i + 6, j + 0, k + 8, JourneyBlocks.euca_gold_stone);
            this.setBlock(w, i + 6, j + 0, k + 9, JourneyBlocks.euca_gold_stone);
            this.setBlock(w, i + 6, j + 0, k + 10, JourneyBlocks.euca_gold_stone);
            this.setBlock(w, i + 6, j + 1, k + 4, JourneyBlocks.euca_gold_stone);
            this.setBlock(w, i + 6, j + 1, k + 5, JourneyBlocks.euca_gold_stone);
            this.setBlock(w, i + 6, j + 1, k + 6, JourneyBlocks.euca_gold_stone);
            this.setBlock(w, i + 6, j + 1, k + 7, JourneyBlocks.euca_gold_stone);
            this.setBlock(w, i + 6, j + 1, k + 8, JourneyBlocks.euca_gold_stone);
            this.setBlock(w, i + 6, j + 1, k + 9, JourneyBlocks.euca_gold_stone);
            this.setBlock(w, i + 6, j + 1, k + 10, JourneyBlocks.euca_gold_stone);
            this.setBlock(w, i + 6, j + 1, k + 11, JourneyBlocks.euca_gold_stone);
            this.setBlock(w, i + 6, j + 1, k + 12, JourneyBlocks.euca_gold_stone);
            this.setBlock(w, i + 6, j + 2, k + 3, JourneyBlocks.euca_gold_stone);
            this.setBlock(w, i + 6, j + 2, k + 4, JourneyBlocks.euca_gold_stone);
            this.setBlock(w, i + 6, j + 2, k + 5, JourneyBlocks.euca_gold_stone);
            this.setBlock(w, i + 6, j + 2, k + 6, JourneyBlocks.euca_gold_stone);
            this.setBlock(w, i + 6, j + 2, k + 7, JourneyBlocks.euca_gold_stone);
            this.setBlock(w, i + 6, j + 2, k + 8, JourneyBlocks.euca_gold_stone);
            this.setBlock(w, i + 6, j + 2, k + 9, JourneyBlocks.euca_gold_stone);
            this.setBlock(w, i + 6, j + 2, k + 10, JourneyBlocks.euca_gold_stone);
            this.setBlock(w, i + 6, j + 2, k + 11, JourneyBlocks.euca_gold_stone);
            this.setBlock(w, i + 6, j + 2, k + 12, JourneyBlocks.euca_gold_stone);
            this.setBlock(w, i + 6, j + 2, k + 13, JourneyBlocks.euca_gold_stone);
            this.setBlock(w, i + 6, j + 3, k + 2, JourneyBlocks.euca_gold_stone);
            this.setBlock(w, i + 6, j + 3, k + 3, JourneyBlocks.euca_gold_stone);
            this.setBlock(w, i + 6, j + 3, k + 4, JourneyBlocks.euca_gold_stone);
            this.setBlock(w, i + 6, j + 3, k + 5, JourneyBlocks.euca_gold_stone);
            this.setBlock(w, i + 6, j + 3, k + 6, JourneyBlocks.euca_gold_stone);
            this.setBlock(w, i + 6, j + 3, k + 7, JourneyBlocks.euca_gold_stone);
            this.setBlock(w, i + 6, j + 3, k + 8, JourneyBlocks.euca_gold_stone);
            this.setBlock(w, i + 6, j + 3, k + 9, JourneyBlocks.euca_gold_stone);
            this.setBlock(w, i + 6, j + 3, k + 10, JourneyBlocks.euca_gold_stone);
            this.setBlock(w, i + 6, j + 3, k + 11, JourneyBlocks.euca_gold_stone);
            this.setBlock(w, i + 6, j + 3, k + 12, JourneyBlocks.euca_gold_stone);
            this.setBlock(w, i + 6, j + 3, k + 13, JourneyBlocks.euca_gold_stone);
            this.setBlock(w, i + 6, j + 3, k + 14, JourneyBlocks.euca_gold_stone);
            this.setBlock(w, i + 6, j + 4, k + 1, JourneyBlocks.euca_gold_stone);
            this.setBlock(w, i + 6, j + 4, k + 2, JourneyBlocks.euca_gold_stone);
            this.setBlock(w, i + 6, j + 4, k + 3, JourneyBlocks.euca_gold_stone);
            this.setBlock(w, i + 6, j + 4, k + 4, JourneyBlocks.euca_gold_stone);
            this.setBlock(w, i + 6, j + 4, k + 5, JourneyBlocks.euca_gold_stone);
            this.setBlock(w, i + 6, j + 4, k + 6, JourneyBlocks.euca_gold_stone);
            this.setBlock(w, i + 6, j + 4, k + 7, JourneyBlocks.euca_gold_stone);
            this.setBlock(w, i + 6, j + 4, k + 8, JourneyBlocks.euca_gold_stone);
            this.setBlock(w, i + 6, j + 4, k + 9, JourneyBlocks.euca_gold_stone);
            this.setBlock(w, i + 6, j + 4, k + 10, JourneyBlocks.euca_gold_stone);
            this.setBlock(w, i + 6, j + 4, k + 11, JourneyBlocks.euca_gold_stone);
            this.setBlock(w, i + 6, j + 4, k + 12, JourneyBlocks.euca_gold_stone);
            this.setBlock(w, i + 6, j + 4, k + 13, JourneyBlocks.euca_gold_stone);
            this.setBlock(w, i + 6, j + 4, k + 14, JourneyBlocks.euca_gold_stone);
            this.setBlock(w, i + 6, j + 4, k + 15, JourneyBlocks.euca_gold_stone);
            this.setBlock(w, i + 6, j + 5, k + 1, JourneyBlocks.euca_gold_stone);
            this.setBlock(w, i + 6, j + 5, k + 2, JourneyBlocks.euca_gold_stone);
            this.setBlock(w, i + 6, j + 5, k + 3, JourneyBlocks.euca_gold_stone);
            this.setBlock(w, i + 6, j + 5, k + 4, JourneyBlocks.euca_gold_stone);
            this.setBlock(w, i + 6, j + 5, k + 5, JourneyBlocks.euca_gold_stone);
            this.setBlock(w, i + 6, j + 5, k + 6, JourneyBlocks.euca_gold_stone);
            this.setBlock(w, i + 6, j + 5, k + 7, JourneyBlocks.euca_gold_stone);
            this.setBlock(w, i + 6, j + 5, k + 8, JourneyBlocks.euca_gold_stone);
            this.setBlock(w, i + 6, j + 5, k + 9, JourneyBlocks.euca_gold_stone);
            this.setBlock(w, i + 6, j + 5, k + 10, JourneyBlocks.euca_gold_stone);
            this.setBlock(w, i + 6, j + 5, k + 11, JourneyBlocks.euca_gold_stone);
            this.setBlock(w, i + 6, j + 5, k + 12, JourneyBlocks.euca_gold_stone);
            this.setBlock(w, i + 6, j + 5, k + 13, JourneyBlocks.euca_gold_stone);
            this.setBlock(w, i + 6, j + 5, k + 14, JourneyBlocks.euca_gold_stone);
            this.setBlock(w, i + 6, j + 5, k + 15, JourneyBlocks.euca_gold_stone);
            this.setBlock(w, i + 6, j + 6, k + 0, JourneyBlocks.euca_gold_stone);
            this.setBlock(w, i + 6, j + 6, k + 1, JourneyBlocks.euca_gold_stone);
            this.setBlock(w, i + 6, j + 6, k + 2, JourneyBlocks.euca_gold_stone);
            this.setBlock(w, i + 6, j + 6, k + 3, JourneyBlocks.eucatile);
            this.setBlock(w, i + 6, j + 6, k + 4, JourneyBlocks.eucatile);
            this.setBlock(w, i + 6, j + 6, k + 5, JourneyBlocks.eucatile);
            this.setBlock(w, i + 6, j + 6, k + 6, JourneyBlocks.eucatile);
            this.setBlock(w, i + 6, j + 6, k + 7, JourneyBlocks.eucatile);
            this.setBlock(w, i + 6, j + 6, k + 8, JourneyBlocks.eucatile);
            this.setBlock(w, i + 6, j + 6, k + 9, JourneyBlocks.eucatile);
            this.setBlock(w, i + 6, j + 6, k + 10, JourneyBlocks.eucatile);
            this.setBlock(w, i + 6, j + 6, k + 11, JourneyBlocks.eucatile);
            this.setBlock(w, i + 6, j + 6, k + 12, JourneyBlocks.eucatile);
            this.setBlock(w, i + 6, j + 6, k + 13, JourneyBlocks.eucatile);
            this.setBlock(w, i + 6, j + 6, k + 14, JourneyBlocks.euca_gold_stone);
            this.setBlock(w, i + 6, j + 6, k + 15, JourneyBlocks.euca_gold_stone);
            this.setBlock(w, i + 6, j + 6, k + 16, JourneyBlocks.euca_gold_stone);
            this.setBlock(w, i + 6, j + 7, k + 0, JourneyBlocks.euca_gold_stone);
            this.setBlock(w, i + 6, j + 7, k + 1, JourneyBlocks.euca_gold_stone);
            this.setBlock(w, i + 6, j + 7, k + 2, JourneyBlocks.euca_square_dungeon_bricks);
            this.setBlock(w, i + 6, j + 7, k + 14, JourneyBlocks.euca_square_dungeon_bricks);
            this.setBlock(w, i + 6, j + 7, k + 15, JourneyBlocks.euca_gold_stone);
            this.setBlock(w, i + 6, j + 7, k + 16, JourneyBlocks.euca_gold_stone);
            this.setBlock(w, i + 6, j + 8, k + 0, JourneyBlocks.euca_gold_stone);
            this.setBlock(w, i + 6, j + 8, k + 1, JourneyBlocks.euca_gold_stone);
            this.setBlock(w, i + 6, j + 8, k + 2, JourneyBlocks.euca_square_dungeon_bricks);
            this.setBlock(w, i + 6, j + 8, k + 14, JourneyBlocks.euca_square_dungeon_bricks);
            this.setBlock(w, i + 6, j + 8, k + 15, JourneyBlocks.euca_gold_stone);
            this.setBlock(w, i + 6, j + 8, k + 16, JourneyBlocks.euca_gold_stone);
            this.setBlock(w, i + 6, j + 9, k + 0, JourneyBlocks.euca_gold_stone);
            this.setBlock(w, i + 6, j + 9, k + 1, JourneyBlocks.euca_gold_stone);
            this.setBlock(w, i + 6, j + 9, k + 2, JourneyBlocks.euca_square_dungeon_bricks);
            this.setBlock(w, i + 6, j + 9, k + 14, JourneyBlocks.euca_square_dungeon_bricks);
            this.setBlock(w, i + 6, j + 9, k + 15, JourneyBlocks.euca_gold_stone);
            this.setBlock(w, i + 6, j + 9, k + 16, JourneyBlocks.euca_gold_stone);
            this.setBlock(w, i + 6, j + 10, k + 0, JourneyBlocks.goldite_oak_log_side);
            this.setBlock(w, i + 6, j + 10, k + 1, JourneyBlocks.euca_gold_stone);
            this.setBlock(w, i + 6, j + 10, k + 2, JourneyBlocks.euca_square_dungeon_bricks);
            this.setBlock(w, i + 6, j + 10, k + 14, JourneyBlocks.euca_square_dungeon_bricks);
            this.setBlock(w, i + 6, j + 10, k + 15, JourneyBlocks.euca_gold_stone);
            this.setBlock(w, i + 6, j + 10, k + 16, JourneyBlocks.euca_gold_stone);
            this.setBlock(w, i + 6, j + 11, k + 1, JourneyBlocks.goldite_oak_log_side);
            this.setBlock(w, i + 6, j + 11, k + 2, JourneyBlocks.euca_gold_stone);
            this.setBlock(w, i + 6, j + 11, k + 3, JourneyBlocks.euca_square_dungeon_bricks);
            this.setBlock(w, i + 6, j + 11, k + 4, JourneyBlocks.euca_square_dungeon_bricks);
            this.setBlock(w, i + 6, j + 11, k + 5, JourneyBlocks.euca_square_dungeon_bricks);
            this.setBlock(w, i + 6, j + 11, k + 11, JourneyBlocks.euca_square_dungeon_bricks);
            this.setBlock(w, i + 6, j + 11, k + 12, JourneyBlocks.euca_square_dungeon_bricks);
            this.setBlock(w, i + 6, j + 11, k + 13, JourneyBlocks.euca_square_dungeon_bricks);
            this.setBlock(w, i + 6, j + 11, k + 14, JourneyBlocks.euca_gold_stone);
            this.setBlock(w, i + 6, j + 11, k + 15, JourneyBlocks.euca_gold_stone);
            this.setBlock(w, i + 6, j + 11, k + 16, JourneyBlocks.goldite_oak_log_side);
            this.setBlock(w, i + 6, j + 12, k + 1, JourneyBlocks.goldite_oak_log_side);
            this.setBlock(w, i + 6, j + 12, k + 2, JourneyBlocks.euca_gold_stone);
            this.setBlock(w, i + 6, j + 12, k + 3, JourneyBlocks.euca_gold_stone);
            this.setBlock(w, i + 6, j + 12, k + 4, JourneyBlocks.euca_gold_stone);
            this.setBlock(w, i + 6, j + 12, k + 5, JourneyBlocks.euca_gold_stone);
            this.setBlock(w, i + 6, j + 12, k + 6, JourneyBlocks.euca_runic_lamp);
            this.setBlock(w, i + 6, j + 12, k + 7, JourneyBlocks.euca_square_dungeon_bricks);
            this.setBlock(w, i + 6, j + 12, k + 8, JourneyBlocks.euca_square_dungeon_bricks);
            this.setBlock(w, i + 6, j + 12, k + 9, JourneyBlocks.euca_square_dungeon_bricks);
            this.setBlock(w, i + 6, j + 12, k + 10, JourneyBlocks.euca_runic_lamp);
            this.setBlock(w, i + 6, j + 12, k + 11, JourneyBlocks.euca_gold_stone);
            this.setBlock(w, i + 6, j + 12, k + 12, JourneyBlocks.euca_gold_stone);
            this.setBlock(w, i + 6, j + 12, k + 13, JourneyBlocks.euca_gold_stone);
            this.setBlock(w, i + 6, j + 12, k + 14, JourneyBlocks.euca_gold_stone);
            this.setBlock(w, i + 6, j + 12, k + 15, JourneyBlocks.euca_gold_stone);
            this.setBlock(w, i + 6, j + 12, k + 16, JourneyBlocks.goldite_oak_log_side);
            this.setBlock(w, i + 6, j + 13, k + 2, JourneyBlocks.goldite_oak_log_side);
            this.setBlock(w, i + 6, j + 13, k + 3, JourneyBlocks.euca_gold_stone);
            this.setBlock(w, i + 6, j + 13, k + 4, JourneyBlocks.euca_gold_stone);
            this.setBlock(w, i + 6, j + 13, k + 5, JourneyBlocks.euca_gold_stone);
            this.setBlock(w, i + 6, j + 13, k + 6, JourneyBlocks.euca_square_dungeon_bricks);
            this.setBlock(w, i + 6, j + 13, k + 7, JourneyBlocks.euca_square_dungeon_bricks);
            this.setBlock(w, i + 6, j + 13, k + 8, JourneyBlocks.euca_square_dungeon_bricks);
            this.setBlock(w, i + 6, j + 13, k + 9, JourneyBlocks.euca_square_dungeon_bricks);
            this.setBlock(w, i + 6, j + 13, k + 10, JourneyBlocks.euca_square_dungeon_bricks);
            this.setBlock(w, i + 6, j + 13, k + 11, JourneyBlocks.euca_gold_stone);
            this.setBlock(w, i + 6, j + 13, k + 12, JourneyBlocks.euca_gold_stone);
            this.setBlock(w, i + 6, j + 13, k + 13, JourneyBlocks.euca_gold_stone);
            this.setBlock(w, i + 6, j + 13, k + 14, JourneyBlocks.goldite_oak_log_side);
            this.setBlock(w, i + 6, j + 13, k + 15, JourneyBlocks.goldite_oak_log_side);
            this.setBlock(w, i + 6, j + 14, k + 3, JourneyBlocks.goldite_oak_log_side);
            this.setBlock(w, i + 6, j + 14, k + 4, JourneyBlocks.euca_gold_stone);
            this.setBlock(w, i + 6, j + 14, k + 5, JourneyBlocks.euca_gold_stone);
            this.setBlock(w, i + 6, j + 14, k + 6, JourneyBlocks.euca_square_dungeon_bricks);
            this.setBlock(w, i + 6, j + 14, k + 7, JourneyBlocks.euca_square_dungeon_bricks);
            this.setBlock(w, i + 6, j + 14, k + 8, JourneyBlocks.euca_square_dungeon_bricks);
            this.setBlock(w, i + 6, j + 14, k + 9, JourneyBlocks.euca_square_dungeon_bricks);
            this.setBlock(w, i + 6, j + 14, k + 10, JourneyBlocks.euca_square_dungeon_bricks);
            this.setBlock(w, i + 6, j + 14, k + 11, JourneyBlocks.euca_gold_stone);
            this.setBlock(w, i + 6, j + 14, k + 12, JourneyBlocks.euca_gold_stone);
            this.setBlock(w, i + 6, j + 14, k + 13, JourneyBlocks.euca_gold_stone);
            this.setBlock(w, i + 6, j + 15, k + 4, JourneyBlocks.euca_gold_stone);
            this.setBlock(w, i + 6, j + 15, k + 5, JourneyBlocks.euca_gold_stone);
            this.setBlock(w, i + 6, j + 15, k + 6, JourneyBlocks.euca_square_dungeon_bricks);
            this.setBlock(w, i + 6, j + 15, k + 7, JourneyBlocks.euca_square_dungeon_bricks);
            this.setBlock(w, i + 6, j + 15, k + 8, JourneyBlocks.euca_square_dungeon_bricks);
            this.setBlock(w, i + 6, j + 15, k + 9, JourneyBlocks.euca_square_dungeon_bricks);
            this.setBlock(w, i + 6, j + 15, k + 10, JourneyBlocks.euca_square_dungeon_bricks);
            this.setBlock(w, i + 6, j + 15, k + 11, JourneyBlocks.euca_gold_stone);
            this.setBlock(w, i + 6, j + 15, k + 12, JourneyBlocks.euca_gold_stone);
            this.setBlock(w, i + 6, j + 16, k + 5, JourneyBlocks.goldite_oak_log_side);
            this.setBlock(w, i + 6, j + 16, k + 6, JourneyBlocks.euca_square_dungeon_bricks);
            this.setBlock(w, i + 6, j + 16, k + 7, JourneyBlocks.euca_square_dungeon_bricks);
            this.setBlock(w, i + 6, j + 16, k + 8, JourneyBlocks.euca_square_dungeon_bricks);
            this.setBlock(w, i + 6, j + 16, k + 9, JourneyBlocks.euca_square_dungeon_bricks);
            this.setBlock(w, i + 6, j + 16, k + 10, JourneyBlocks.euca_square_dungeon_bricks);
            this.setBlock(w, i + 6, j + 16, k + 11, JourneyBlocks.euca_square_dungeon_bricks);
            this.setBlock(w, i + 6, j + 17, k + 5, JourneyBlocks.goldite_oak_log_side);
            this.setBlock(w, i + 6, j + 17, k + 6, JourneyBlocks.goldite_oak_log_side);
            this.setBlock(w, i + 6, j + 17, k + 10, JourneyBlocks.goldite_oak_log_side);
            this.setBlock(w, i + 6, j + 18, k + 5, JourneyBlocks.goldite_oak_log_side);
            this.setBlock(w, i + 6, j + 18, k + 6, JourneyBlocks.goldite_oak_log_side);
            this.setBlock(w, i + 6, j + 18, k + 10, JourneyBlocks.goldite_oak_log_side);
            this.setBlock(w, i + 6, j + 19, k + 6, JourneyBlocks.goldite_oak_log_side);
            this.setBlock(w, i + 6, j + 19, k + 9, JourneyBlocks.goldite_oak_log_side);
            this.setBlock(w, i + 6, j + 19, k + 10, JourneyBlocks.goldite_oak_log_side);
            this.setBlock(w, i + 6, j + 20, k + 6, JourneyBlocks.goldite_oak_log_side);
            this.setBlock(w, i + 6, j + 20, k + 7, JourneyBlocks.goldite_oak_log_side);
            this.setBlock(w, i + 6, j + 20, k + 8, JourneyBlocks.goldite_oak_log_side);
            this.setBlock(w, i + 6, j + 20, k + 9, JourneyBlocks.goldite_oak_log_side);
            this.setBlock(w, i + 6, j + 21, k + 7, JourneyBlocks.goldite_oak_log_side);
            this.setBlock(w, i + 6, j + 21, k + 8, JourneyBlocks.goldite_oak_log_side);
            this.setBlock(w, i + 6, j + 22, k + 9, JourneyBlocks.goldite_oak_log_side);
            this.setBlock(w, i + 6, j + 23, k + 7, JourneyBlocks.goldite_oak_log_side);
            this.setBlock(w, i + 6, j + 23, k + 8, JourneyBlocks.eucagoldleaves);
            this.setBlock(w, i + 6, j + 23, k + 9, JourneyBlocks.goldite_oak_log_side);
            this.setBlock(w, i + 6, j + 23, k + 10, JourneyBlocks.goldite_oak_log_side);
            this.setBlock(w, i + 6, j + 24, k + 5, JourneyBlocks.goldite_oak_log_side);
            this.setBlock(w, i + 6, j + 24, k + 6, JourneyBlocks.goldite_oak_log_side);
            this.setBlock(w, i + 6, j + 24, k + 7, JourneyBlocks.eucagoldleaves);
            this.setBlock(w, i + 6, j + 24, k + 8, JourneyBlocks.goldite_oak_log_side);
            this.setBlock(w, i + 6, j + 24, k + 9, JourneyBlocks.goldite_oak_log_side);
            this.setBlock(w, i + 6, j + 24, k + 10, JourneyBlocks.goldite_oak_log_side);
            this.setBlock(w, i + 6, j + 24, k + 11, JourneyBlocks.eucagoldleaves);
            this.setBlock(w, i + 6, j + 25, k + 4, JourneyBlocks.eucagoldleaves);
            this.setBlock(w, i + 6, j + 25, k + 5, JourneyBlocks.eucagoldleaves);
            this.setBlock(w, i + 6, j + 25, k + 6, JourneyBlocks.eucagoldleaves);
            this.setBlock(w, i + 6, j + 25, k + 7, JourneyBlocks.goldite_oak_log_side);
            this.setBlock(w, i + 6, j + 25, k + 8, JourneyBlocks.goldite_oak_log_side);
            this.setBlock(w, i + 6, j + 25, k + 9, JourneyBlocks.goldite_oak_log_side);
            this.setBlock(w, i + 6, j + 25, k + 10, JourneyBlocks.eucagoldleaves);
            this.setBlock(w, i + 6, j + 25, k + 11, JourneyBlocks.eucagoldleaves);
            this.setBlock(w, i + 6, j + 25, k + 12, JourneyBlocks.eucagoldleaves);
            this.setBlock(w, i + 6, j + 26, k + 4, JourneyBlocks.eucagoldleaves);
            this.setBlock(w, i + 6, j + 26, k + 5, JourneyBlocks.eucagoldleaves);
            this.setBlock(w, i + 6, j + 26, k + 6, JourneyBlocks.eucagoldleaves);
            this.setBlock(w, i + 6, j + 26, k + 7, JourneyBlocks.eucagoldleaves);
            this.setBlock(w, i + 6, j + 26, k + 8, JourneyBlocks.goldite_oak_log_side);
            this.setBlock(w, i + 6, j + 26, k + 9, JourneyBlocks.goldite_oak_log_side);
            this.setBlock(w, i + 6, j + 26, k + 10, JourneyBlocks.eucagoldleaves);
            this.setBlock(w, i + 6, j + 26, k + 11, JourneyBlocks.eucagoldleaves);
            this.setBlock(w, i + 6, j + 26, k + 12, JourneyBlocks.eucagoldleaves);
            this.setBlock(w, i + 6, j + 27, k + 3, JourneyBlocks.eucagoldleaves);
            this.setBlock(w, i + 6, j + 27, k + 4, JourneyBlocks.eucagoldleaves);
            this.setBlock(w, i + 6, j + 27, k + 5, JourneyBlocks.eucagoldleaves);
            this.setBlock(w, i + 6, j + 27, k + 6, JourneyBlocks.eucagoldleaves);
            this.setBlock(w, i + 6, j + 27, k + 7, JourneyBlocks.eucagoldleaves);
            this.setBlock(w, i + 6, j + 27, k + 8, JourneyBlocks.eucagoldleaves);
            this.setBlock(w, i + 6, j + 27, k + 9, JourneyBlocks.eucagoldleaves);
            this.setBlock(w, i + 6, j + 27, k + 10, JourneyBlocks.eucagoldleaves);
            this.setBlock(w, i + 6, j + 27, k + 11, JourneyBlocks.eucagoldleaves);
            this.setBlock(w, i + 6, j + 27, k + 12, JourneyBlocks.eucagoldleaves);
            this.setBlock(w, i + 6, j + 27, k + 13, JourneyBlocks.eucagoldleaves);
            this.setBlock(w, i + 6, j + 28, k + 3, JourneyBlocks.eucagoldleaves);
            this.setBlock(w, i + 6, j + 28, k + 4, JourneyBlocks.eucagoldleaves);
            this.setBlock(w, i + 6, j + 28, k + 5, JourneyBlocks.eucagoldleaves);
            this.setBlock(w, i + 6, j + 28, k + 6, JourneyBlocks.eucagoldleaves);
            this.setBlock(w, i + 6, j + 28, k + 7, JourneyBlocks.eucagoldleaves);
            this.setBlock(w, i + 6, j + 28, k + 8, JourneyBlocks.eucagoldleaves);
            this.setBlock(w, i + 6, j + 28, k + 9, JourneyBlocks.eucagoldleaves);
            this.setBlock(w, i + 6, j + 28, k + 10, JourneyBlocks.eucagoldleaves);
            this.setBlock(w, i + 6, j + 28, k + 11, JourneyBlocks.eucagoldleaves);
            this.setBlock(w, i + 6, j + 28, k + 12, JourneyBlocks.eucagoldleaves);
            this.setBlock(w, i + 6, j + 28, k + 13, JourneyBlocks.eucagoldleaves);
            this.setBlock(w, i + 6, j + 29, k + 3, JourneyBlocks.eucagoldleaves);
            this.setBlock(w, i + 6, j + 29, k + 4, JourneyBlocks.eucagoldleaves);
            this.setBlock(w, i + 6, j + 29, k + 5, JourneyBlocks.eucagoldleaves);
            this.setBlock(w, i + 6, j + 29, k + 6, JourneyBlocks.eucagoldleaves);
            this.setBlock(w, i + 6, j + 29, k + 7, JourneyBlocks.eucagoldleaves);
            this.setBlock(w, i + 6, j + 29, k + 8, JourneyBlocks.eucagoldleaves);
            this.setBlock(w, i + 6, j + 29, k + 9, JourneyBlocks.eucagoldleaves);
            this.setBlock(w, i + 6, j + 29, k + 10, JourneyBlocks.eucagoldleaves);
            this.setBlock(w, i + 6, j + 29, k + 11, JourneyBlocks.eucagoldleaves);
            this.setBlock(w, i + 6, j + 29, k + 12, JourneyBlocks.eucagoldleaves);
            this.setBlock(w, i + 6, j + 29, k + 13, JourneyBlocks.eucagoldleaves);
            this.setBlock(w, i + 6, j + 30, k + 4, JourneyBlocks.eucagoldleaves);
            this.setBlock(w, i + 6, j + 30, k + 5, JourneyBlocks.eucagoldleaves);
            this.setBlock(w, i + 6, j + 30, k + 6, JourneyBlocks.eucagoldleaves);
            this.setBlock(w, i + 6, j + 30, k + 7, JourneyBlocks.eucagoldleaves);
            this.setBlock(w, i + 6, j + 30, k + 8, JourneyBlocks.eucagoldleaves);
            this.setBlock(w, i + 6, j + 30, k + 9, JourneyBlocks.eucagoldleaves);
            this.setBlock(w, i + 6, j + 30, k + 10, JourneyBlocks.eucagoldleaves);
            this.setBlock(w, i + 6, j + 30, k + 11, JourneyBlocks.eucagoldleaves);
            this.setBlock(w, i + 6, j + 30, k + 12, JourneyBlocks.eucagoldleaves);
            this.setBlock(w, i + 6, j + 31, k + 4, JourneyBlocks.eucagoldleaves);
            this.setBlock(w, i + 6, j + 31, k + 5, JourneyBlocks.eucagoldleaves);
            this.setBlock(w, i + 6, j + 31, k + 6, JourneyBlocks.eucagoldleaves);
            this.setBlock(w, i + 6, j + 31, k + 7, JourneyBlocks.eucagoldleaves);
            this.setBlock(w, i + 6, j + 31, k + 8, JourneyBlocks.eucagoldleaves);
            this.setBlock(w, i + 6, j + 31, k + 9, JourneyBlocks.eucagoldleaves);
            this.setBlock(w, i + 6, j + 31, k + 10, JourneyBlocks.eucagoldleaves);
            this.setBlock(w, i + 6, j + 31, k + 11, JourneyBlocks.eucagoldleaves);
            this.setBlock(w, i + 6, j + 31, k + 12, JourneyBlocks.eucagoldleaves);
            this.setBlock(w, i + 6, j + 32, k + 5, JourneyBlocks.eucagoldleaves);
            this.setBlock(w, i + 6, j + 32, k + 6, JourneyBlocks.eucagoldleaves);
            this.setBlock(w, i + 6, j + 32, k + 7, JourneyBlocks.eucagoldleaves);
            this.setBlock(w, i + 6, j + 32, k + 8, JourneyBlocks.eucagoldleaves);
            this.setBlock(w, i + 6, j + 32, k + 9, JourneyBlocks.eucagoldleaves);
            this.setBlock(w, i + 6, j + 32, k + 10, JourneyBlocks.eucagoldleaves);
            this.setBlock(w, i + 6, j + 32, k + 11, JourneyBlocks.eucagoldleaves);
            this.setBlock(w, i + 6, j + 33, k + 7, JourneyBlocks.eucagoldleaves);
            this.setBlock(w, i + 6, j + 33, k + 8, JourneyBlocks.eucagoldleaves);
            this.setBlock(w, i + 6, j + 33, k + 9, JourneyBlocks.eucagoldleaves);
            this.setBlock(w, i + 7, j + 0, k + 6, JourneyBlocks.euca_gold_stone);
            this.setBlock(w, i + 7, j + 0, k + 7, JourneyBlocks.euca_gold_stone);
            this.setBlock(w, i + 7, j + 0, k + 8, JourneyBlocks.euca_gold_stone);
            this.setBlock(w, i + 7, j + 0, k + 9, JourneyBlocks.euca_gold_stone);
            this.setBlock(w, i + 7, j + 0, k + 10, JourneyBlocks.euca_gold_stone);
            this.setBlock(w, i + 7, j + 1, k + 4, JourneyBlocks.euca_gold_stone);
            this.setBlock(w, i + 7, j + 1, k + 5, JourneyBlocks.euca_gold_stone);
            this.setBlock(w, i + 7, j + 1, k + 6, JourneyBlocks.euca_gold_stone);
            this.setBlock(w, i + 7, j + 1, k + 7, JourneyBlocks.euca_gold_stone);
            this.setBlock(w, i + 7, j + 1, k + 8, JourneyBlocks.euca_gold_stone);
            this.setBlock(w, i + 7, j + 1, k + 9, JourneyBlocks.euca_gold_stone);
            this.setBlock(w, i + 7, j + 1, k + 10, JourneyBlocks.euca_gold_stone);
            this.setBlock(w, i + 7, j + 1, k + 11, JourneyBlocks.euca_gold_stone);
            this.setBlock(w, i + 7, j + 1, k + 12, JourneyBlocks.euca_gold_stone);
            this.setBlock(w, i + 7, j + 2, k + 3, JourneyBlocks.euca_gold_stone);
            this.setBlock(w, i + 7, j + 2, k + 4, JourneyBlocks.euca_gold_stone);
            this.setBlock(w, i + 7, j + 2, k + 5, JourneyBlocks.euca_gold_stone);
            this.setBlock(w, i + 7, j + 2, k + 6, JourneyBlocks.euca_gold_stone);
            this.setBlock(w, i + 7, j + 2, k + 7, JourneyBlocks.euca_gold_stone);
            this.setBlock(w, i + 7, j + 2, k + 8, JourneyBlocks.euca_gold_stone);
            this.setBlock(w, i + 7, j + 2, k + 9, JourneyBlocks.euca_gold_stone);
            this.setBlock(w, i + 7, j + 2, k + 10, JourneyBlocks.euca_gold_stone);
            this.setBlock(w, i + 7, j + 2, k + 11, JourneyBlocks.euca_gold_stone);
            this.setBlock(w, i + 7, j + 2, k + 12, JourneyBlocks.euca_gold_stone);
            this.setBlock(w, i + 7, j + 2, k + 13, JourneyBlocks.euca_gold_stone);
            this.setBlock(w, i + 7, j + 3, k + 2, JourneyBlocks.euca_gold_stone);
            this.setBlock(w, i + 7, j + 3, k + 3, JourneyBlocks.euca_gold_stone);
            this.setBlock(w, i + 7, j + 3, k + 4, JourneyBlocks.euca_gold_stone);
            this.setBlock(w, i + 7, j + 3, k + 5, JourneyBlocks.euca_gold_stone);
            this.setBlock(w, i + 7, j + 3, k + 6, JourneyBlocks.euca_gold_stone);
            this.setBlock(w, i + 7, j + 3, k + 7, JourneyBlocks.euca_gold_stone);
            this.setBlock(w, i + 7, j + 3, k + 8, JourneyBlocks.euca_gold_stone);
            this.setBlock(w, i + 7, j + 3, k + 9, JourneyBlocks.euca_gold_stone);
            this.setBlock(w, i + 7, j + 3, k + 10, JourneyBlocks.euca_gold_stone);
            this.setBlock(w, i + 7, j + 3, k + 11, JourneyBlocks.euca_gold_stone);
            this.setBlock(w, i + 7, j + 3, k + 12, JourneyBlocks.euca_gold_stone);
            this.setBlock(w, i + 7, j + 3, k + 13, JourneyBlocks.euca_gold_stone);
            this.setBlock(w, i + 7, j + 3, k + 14, JourneyBlocks.euca_gold_stone);
            this.setBlock(w, i + 7, j + 4, k + 1, JourneyBlocks.euca_gold_stone);
            this.setBlock(w, i + 7, j + 4, k + 2, JourneyBlocks.euca_gold_stone);
            this.setBlock(w, i + 7, j + 4, k + 3, JourneyBlocks.euca_gold_stone);
            this.setBlock(w, i + 7, j + 4, k + 4, JourneyBlocks.euca_gold_stone);
            this.setBlock(w, i + 7, j + 4, k + 5, JourneyBlocks.euca_gold_stone);
            this.setBlock(w, i + 7, j + 4, k + 6, JourneyBlocks.euca_gold_stone);
            this.setBlock(w, i + 7, j + 4, k + 7, JourneyBlocks.euca_gold_stone);
            this.setBlock(w, i + 7, j + 4, k + 8, JourneyBlocks.euca_gold_stone);
            this.setBlock(w, i + 7, j + 4, k + 9, JourneyBlocks.euca_gold_stone);
            this.setBlock(w, i + 7, j + 4, k + 10, JourneyBlocks.euca_gold_stone);
            this.setBlock(w, i + 7, j + 4, k + 11, JourneyBlocks.euca_gold_stone);
            this.setBlock(w, i + 7, j + 4, k + 12, JourneyBlocks.euca_gold_stone);
            this.setBlock(w, i + 7, j + 4, k + 13, JourneyBlocks.euca_gold_stone);
            this.setBlock(w, i + 7, j + 4, k + 14, JourneyBlocks.euca_gold_stone);
            this.setBlock(w, i + 7, j + 4, k + 15, JourneyBlocks.euca_gold_stone);
            this.setBlock(w, i + 7, j + 5, k + 1, JourneyBlocks.euca_gold_stone);
            this.setBlock(w, i + 7, j + 5, k + 2, JourneyBlocks.euca_gold_stone);
            this.setBlock(w, i + 7, j + 5, k + 3, JourneyBlocks.euca_gold_stone);
            this.setBlock(w, i + 7, j + 5, k + 4, JourneyBlocks.euca_gold_stone);
            this.setBlock(w, i + 7, j + 5, k + 5, JourneyBlocks.euca_gold_stone);
            this.setBlock(w, i + 7, j + 5, k + 6, JourneyBlocks.euca_gold_stone);
            this.setBlock(w, i + 7, j + 5, k + 7, JourneyBlocks.euca_gold_stone);
            this.setBlock(w, i + 7, j + 5, k + 8, JourneyBlocks.euca_gold_stone);
            this.setBlock(w, i + 7, j + 5, k + 9, JourneyBlocks.euca_gold_stone);
            this.setBlock(w, i + 7, j + 5, k + 10, JourneyBlocks.euca_gold_stone);
            this.setBlock(w, i + 7, j + 5, k + 11, JourneyBlocks.euca_gold_stone);
            this.setBlock(w, i + 7, j + 5, k + 12, JourneyBlocks.euca_gold_stone);
            this.setBlock(w, i + 7, j + 5, k + 13, JourneyBlocks.euca_gold_stone);
            this.setBlock(w, i + 7, j + 5, k + 14, JourneyBlocks.euca_gold_stone);
            this.setBlock(w, i + 7, j + 5, k + 15, JourneyBlocks.euca_gold_stone);
            this.setBlock(w, i + 7, j + 6, k + 0, JourneyBlocks.euca_gold_stone);
            this.setBlock(w, i + 7, j + 6, k + 1, JourneyBlocks.euca_gold_stone);
            this.setBlock(w, i + 7, j + 6, k + 2, JourneyBlocks.eucatile);
            this.setBlock(w, i + 7, j + 6, k + 3, JourneyBlocks.eucatile);
            this.setBlock(w, i + 7, j + 6, k + 4, JourneyBlocks.eucatile);
            this.setBlock(w, i + 7, j + 6, k + 5, JourneyBlocks.eucatile);
            this.setBlock(w, i + 7, j + 6, k + 6, JourneyBlocks.eucatile);
            this.setBlock(w, i + 7, j + 6, k + 7, JourneyBlocks.eucatile);
            this.setBlock(w, i + 7, j + 6, k + 8, JourneyBlocks.eucatile);
            this.setBlock(w, i + 7, j + 6, k + 9, JourneyBlocks.eucatile);
            this.setBlock(w, i + 7, j + 6, k + 10, JourneyBlocks.eucatile);
            this.setBlock(w, i + 7, j + 6, k + 11, JourneyBlocks.eucatile);
            this.setBlock(w, i + 7, j + 6, k + 12, JourneyBlocks.eucatile);
            this.setBlock(w, i + 7, j + 6, k + 13, JourneyBlocks.eucatile);
            this.setBlock(w, i + 7, j + 6, k + 14, JourneyBlocks.eucatile);
            this.setBlock(w, i + 7, j + 6, k + 15, JourneyBlocks.euca_gold_stone);
            this.setBlock(w, i + 7, j + 6, k + 16, JourneyBlocks.euca_gold_stone);
            this.setBlock(w, i + 7, j + 7, k + 0, JourneyBlocks.euca_runic_lamp);
            this.setBlock(w, i + 7, j + 7, k + 1, JourneyBlocks.euca_square_dungeon_bricks);
            this.setBlock(w, i + 7, j + 7, k + 7, JourneyBlocks.euca_square_dungeon_bricks);
            this.setBlock(w, i + 7, j + 7, k + 8, JourneyBlocks.euca_square_dungeon_bricks);
            this.setBlock(w, i + 7, j + 7, k + 15, JourneyBlocks.euca_square_dungeon_bricks);
            this.setBlock(w, i + 7, j + 7, k + 16, JourneyBlocks.euca_runic_lamp);
            this.setBlock(w, i + 7, j + 8, k + 0, JourneyBlocks.euca_runic_lamp);
            this.setBlock(w, i + 7, j + 8, k + 1, JourneyBlocks.euca_square_dungeon_bricks);
            this.setBlock(w, i + 7, j + 8, k + 8, JourneyBlocks.euca_square_dungeon_bricks);
            this.setBlock(w, i + 7, j + 8, k + 9, JourneyBlocks.euca_square_dungeon_bricks);
            this.setBlock(w, i + 7, j + 8, k + 15, JourneyBlocks.euca_square_dungeon_bricks);
            this.setBlock(w, i + 7, j + 8, k + 16, JourneyBlocks.euca_runic_lamp);
            this.setBlock(w, i + 7, j + 9, k + 0, JourneyBlocks.euca_runic_lamp);
            this.setBlock(w, i + 7, j + 9, k + 1, JourneyBlocks.euca_square_dungeon_bricks);
            this.setBlock(w, i + 7, j + 9, k + 15, JourneyBlocks.euca_square_dungeon_bricks);
            this.setBlock(w, i + 7, j + 9, k + 16, JourneyBlocks.euca_runic_lamp);
            this.setBlock(w, i + 7, j + 10, k + 0, JourneyBlocks.euca_gold_stone);
            this.setBlock(w, i + 7, j + 10, k + 1, JourneyBlocks.euca_square_dungeon_bricks);
            this.setBlock(w, i + 7, j + 10, k + 15, JourneyBlocks.euca_square_dungeon_bricks);
            this.setBlock(w, i + 7, j + 10, k + 16, JourneyBlocks.euca_gold_stone);
            this.setBlock(w, i + 7, j + 11, k + 1, JourneyBlocks.euca_gold_stone);
            this.setBlock(w, i + 7, j + 11, k + 2, JourneyBlocks.euca_runic_lamp);
            this.setBlock(w, i + 7, j + 11, k + 3, JourneyBlocks.euca_square_dungeon_bricks);
            this.setBlock(w, i + 7, j + 11, k + 4, JourneyBlocks.euca_square_dungeon_bricks);
            this.setBlock(w, i + 7, j + 11, k + 5, JourneyBlocks.euca_square_dungeon_bricks);
            this.setBlock(w, i + 7, j + 11, k + 7, JourneyBlocks.euca_square_dungeon_bricks);
            this.setBlock(w, i + 7, j + 11, k + 8, JourneyBlocks.euca_square_dungeon_bricks);
            this.setBlock(w, i + 7, j + 11, k + 11, JourneyBlocks.euca_square_dungeon_bricks);
            this.setBlock(w, i + 7, j + 11, k + 12, JourneyBlocks.euca_square_dungeon_bricks);
            this.setBlock(w, i + 7, j + 11, k + 13, JourneyBlocks.euca_square_dungeon_bricks);
            this.setBlock(w, i + 7, j + 11, k + 14, JourneyBlocks.euca_runic_lamp);
            this.setBlock(w, i + 7, j + 11, k + 15, JourneyBlocks.euca_gold_stone);
            this.setBlock(w, i + 7, j + 11, k + 16, JourneyBlocks.goldite_oak_log_side);
