/*
 * Decompiled with CFR 0.152.
 * 
 * Could not load the following classes:
 *  net.minecraft.entity.Entity
 *  net.minecraft.init.Blocks
 *  net.minecraft.world.World
 *  net.minecraft.world.gen.feature.WorldGenerator
 */
package net.divinerpg.dimensions.boiling.gen;

import java.util.Random;
import net.divinerpg.entities.boil.npc.EntityBoilTrader;
import net.divinerpg.utils.blocks.JourneyBlocks;
import net.divinerpg.utils.blocks.VanillaBlocks;
import net.minecraft.entity.Entity;
import net.minecraft.init.Blocks;
import net.minecraft.world.World;
import net.minecraft.world.gen.feature.WorldGenerator;

public class WorldGenBoilingCastle
extends WorldGenerator {
    public boolean generate(World world, Random rand, int x, int y, int z) {
        world.setBlock(x + 5, y + 0, z + 7, JourneyBlocks.ash, 0, 3);
        world.setBlock(x + 2, y + 1, z + 6, JourneyBlocks.ash, 0, 3);
        world.setBlock(x + 5, y + 1, z + 6, JourneyBlocks.hotBlock, 0, 3);
        world.setBlock(x + 5, y + 1, z + 7, JourneyBlocks.ash, 0, 3);
        world.setBlock(x + 5, y + 1, z + 8, JourneyBlocks.hotBlock, 0, 3);
        world.setBlock(x + 7, y + 1, z + 10, JourneyBlocks.ash, 0, 3);
        world.setBlock(x + 5, y + 2, z + 5, JourneyBlocks.hotBlock, 0, 3);
        world.setBlock(x + 2, y + 2, z + 6, JourneyBlocks.hotBlock, 0, 3);
        world.setBlock(x + 5, y + 2, z + 6, JourneyBlocks.ash, 0, 3);
        world.setBlock(x + 6, y + 2, z + 6, JourneyBlocks.ash, 0, 3);
        world.setBlock(x + 4, y + 2, z + 7, JourneyBlocks.hotBlock, 0, 3);
        world.setBlock(x + 5, y + 2, z + 7, JourneyBlocks.hotBlock, 0, 3);
        world.setBlock(x + 6, y + 2, z + 7, JourneyBlocks.hotBlock, 0, 3);
        world.setBlock(x + 4, y + 2, z + 8, JourneyBlocks.ash, 0, 3);
        world.setBlock(x + 5, y + 2, z + 8, JourneyBlocks.hotBlock, 0, 3);
        world.setBlock(x + 6, y + 2, z + 8, JourneyBlocks.hotBlock, 0, 3);
        world.setBlock(x + 5, y + 2, z + 9, JourneyBlocks.hotBlock, 0, 3);
        world.setBlock(x + 2, y + 2, z + 10, JourneyBlocks.ash, 0, 3);
        world.setBlock(x + 7, y + 2, z + 10, JourneyBlocks.hotBlock, 0, 3);
        world.setBlock(x + 7, y + 2, z + 11, JourneyBlocks.hotBlock, 0, 3);
        world.setBlock(x + 4, y + 2, z + 12, JourneyBlocks.ash, 0, 3);
        world.setBlock(x + 6, y + 3, z + 3, JourneyBlocks.ash, 0, 3);
        world.setBlock(x + 3, y + 3, z + 5, JourneyBlocks.hotBlock, 0, 3);
        world.setBlock(x + 4, y + 3, z + 5, JourneyBlocks.ash, 0, 3);
        world.setBlock(x + 5, y + 3, z + 5, JourneyBlocks.hotBlock, 0, 3);
        world.setBlock(x + 6, y + 3, z + 5, JourneyBlocks.ash, 0, 3);
        world.setBlock(x + 2, y + 3, z + 6, JourneyBlocks.hotBlock, 0, 3);
        world.setBlock(x + 3, y + 3, z + 6, JourneyBlocks.hotBlock, 0, 3);
        world.setBlock(x + 4, y + 3, z + 6, JourneyBlocks.ash, 0, 3);
        world.setBlock(x + 5, y + 3, z + 6, JourneyBlocks.ash, 0, 3);
        world.setBlock(x + 6, y + 3, z + 6, JourneyBlocks.ash, 0, 3);
        world.setBlock(x + 7, y + 3, z + 6, JourneyBlocks.hotBlock, 0, 3);
        world.setBlock(x + 3, y + 3, z + 7, JourneyBlocks.hotBlock, 0, 3);
        world.setBlock(x + 4, y + 3, z + 7, JourneyBlocks.ash, 0, 3);
        world.setBlock(x + 5, y + 3, z + 7, JourneyBlocks.hotBlock, 0, 3);
        world.setBlock(x + 6, y + 3, z + 7, JourneyBlocks.ash, 0, 3);
        world.setBlock(x + 7, y + 3, z + 7, JourneyBlocks.hotBlock, 0, 3);
        world.setBlock(x + 9, y + 3, z + 7, JourneyBlocks.hotBlock, 0, 3);
        world.setBlock(x + 3, y + 3, z + 8, JourneyBlocks.hotBlock, 0, 3);
        world.setBlock(x + 4, y + 3, z + 8, JourneyBlocks.hotBlock, 0, 3);
        world.setBlock(x + 5, y + 3, z + 8, JourneyBlocks.hotBlock, 0, 3);
        world.setBlock(x + 6, y + 3, z + 8, JourneyBlocks.hotBlock, 0, 3);
        world.setBlock(x + 7, y + 3, z + 8, JourneyBlocks.ash, 0, 3);
        world.setBlock(x + 8, y + 3, z + 8, JourneyBlocks.ash, 0, 3);
        world.setBlock(x + 3, y + 3, z + 9, JourneyBlocks.ash, 0, 3);
        world.setBlock(x + 4, y + 3, z + 9, JourneyBlocks.hotBlock, 0, 3);
        world.setBlock(x + 5, y + 3, z + 9, JourneyBlocks.ash, 0, 3);
        world.setBlock(x + 6, y + 3, z + 9, JourneyBlocks.ash, 0, 3);
        world.setBlock(x + 7, y + 3, z + 9, JourneyBlocks.ash, 0, 3);
        world.setBlock(x + 8, y + 3, z + 9, JourneyBlocks.hotBlock, 0, 3);
        world.setBlock(x + 2, y + 3, z + 10, JourneyBlocks.ash, 0, 3);
        world.setBlock(x + 4, y + 3, z + 10, JourneyBlocks.hotBlock, 0, 3);
        world.setBlock(x + 5, y + 3, z + 10, JourneyBlocks.ash, 0, 3);
        world.setBlock(x + 6, y + 3, z + 10, JourneyBlocks.hotBlock, 0, 3);
        world.setBlock(x + 7, y + 3, z + 10, JourneyBlocks.ash, 0, 3);
        world.setBlock(x + 2, y + 3, z + 11, JourneyBlocks.hotBlock, 0, 3);
        world.setBlock(x + 4, y + 3, z + 12, JourneyBlocks.hotBlock, 0, 3);
        world.setBlock(x + 7, y + 3, z + 12, JourneyBlocks.hotBlock, 0, 3);
        world.setBlock(x + 3, y + 3, z + 13, JourneyBlocks.ash, 0, 3);
        world.setBlock(x + 7, y + 3, z + 13, JourneyBlocks.hotBlock, 0, 3);
        world.setBlock(x + 7, y + 3, z + 14, JourneyBlocks.hotBlock, 0, 3);
        world.setBlock(x + 6, y + 4, z + 3, JourneyBlocks.hotBlock, 0, 3);
        world.setBlock(x + 8, y + 4, z + 3, JourneyBlocks.hotBlock, 0, 3);
        world.setBlock(x + 3, y + 4, z + 4, JourneyBlocks.hotBlock, 0, 3);
        world.setBlock(x + 4, y + 4, z + 4, JourneyBlocks.hotBlock, 0, 3);
        world.setBlock(x + 5, y + 4, z + 4, JourneyBlocks.ash, 0, 3);
        world.setBlock(x + 6, y + 4, z + 4, JourneyBlocks.ash, 0, 3);
        world.setBlock(x + 7, y + 4, z + 4, JourneyBlocks.hotBlock, 0, 3);
        world.setBlock(x + 3, y + 4, z + 5, JourneyBlocks.ash, 0, 3);
        world.setBlock(x + 4, y + 4, z + 5, JourneyBlocks.ash, 0, 3);
        world.setBlock(x + 5, y + 4, z + 5, JourneyBlocks.ash, 0, 3);
        world.setBlock(x + 6, y + 4, z + 5, JourneyBlocks.hotBlock, 0, 3);
        world.setBlock(x + 7, y + 4, z + 5, JourneyBlocks.ash, 0, 3);
        world.setBlock(x + 8, y + 4, z + 5, JourneyBlocks.hotBlock, 0, 3);
        world.setBlock(x + 2, y + 4, z + 6, JourneyBlocks.ash, 0, 3);
        world.setBlock(x + 3, y + 4, z + 6, JourneyBlocks.ash, 0, 3);
        world.setBlock(x + 4, y + 4, z + 6, JourneyBlocks.hotBlock, 0, 3);
        world.setBlock(x + 5, y + 4, z + 6, JourneyBlocks.hotBlock, 0, 3);
        world.setBlock(x + 6, y + 4, z + 6, JourneyBlocks.hotBlock, 0, 3);
        world.setBlock(x + 7, y + 4, z + 6, JourneyBlocks.ash, 0, 3);
        world.setBlock(x + 8, y + 4, z + 6, JourneyBlocks.hotBlock, 0, 3);
        world.setBlock(x + 3, y + 4, z + 7, JourneyBlocks.ash, 0, 3);
        world.setBlock(x + 4, y + 4, z + 7, JourneyBlocks.hotBlock, 0, 3);
        world.setBlock(x + 5, y + 4, z + 7, JourneyBlocks.hotBlock, 0, 3);
        world.setBlock(x + 6, y + 4, z + 7, JourneyBlocks.hotBlock, 0, 3);
        world.setBlock(x + 7, y + 4, z + 7, JourneyBlocks.hotBlock, 0, 3);
        world.setBlock(x + 8, y + 4, z + 7, JourneyBlocks.ash, 0, 3);
        world.setBlock(x + 9, y + 4, z + 7, JourneyBlocks.ash, 0, 3);
        world.setBlock(x + 2, y + 4, z + 8, JourneyBlocks.hotBlock, 0, 3);
        world.setBlock(x + 3, y + 4, z + 8, JourneyBlocks.hotBlock, 0, 3);
        world.setBlock(x + 4, y + 4, z + 8, JourneyBlocks.hotBlock, 0, 3);
        world.setBlock(x + 5, y + 4, z + 8, JourneyBlocks.hotBlock, 0, 3);
        world.setBlock(x + 6, y + 4, z + 8, JourneyBlocks.hotBlock, 0, 3);
        world.setBlock(x + 7, y + 4, z + 8, JourneyBlocks.hotBlock, 0, 3);
        world.setBlock(x + 8, y + 4, z + 8, JourneyBlocks.hotBlock, 0, 3);
        world.setBlock(x + 9, y + 4, z + 8, JourneyBlocks.hotBlock, 0, 3);
        world.setBlock(x + 2, y + 4, z + 9, JourneyBlocks.hotBlock, 0, 3);
        world.setBlock(x + 3, y + 4, z + 9, JourneyBlocks.hotBlock, 0, 3);
        world.setBlock(x + 4, y + 4, z + 9, JourneyBlocks.hotBlock, 0, 3);
        world.setBlock(x + 5, y + 4, z + 9, JourneyBlocks.ash, 0, 3);
        world.setBlock(x + 6, y + 4, z + 9, JourneyBlocks.ash, 0, 3);
        world.setBlock(x + 7, y + 4, z + 9, JourneyBlocks.hotBlock, 0, 3);
        world.setBlock(x + 8, y + 4, z + 9, JourneyBlocks.ash, 0, 3);
        world.setBlock(x + 9, y + 4, z + 9, JourneyBlocks.ash, 0, 3);
        world.setBlock(x + 3, y + 4, z + 10, JourneyBlocks.ash, 0, 3);
        world.setBlock(x + 4, y + 4, z + 10, JourneyBlocks.hotBlock, 0, 3);
        world.setBlock(x + 5, y + 4, z + 10, JourneyBlocks.ash, 0, 3);
        world.setBlock(x + 6, y + 4, z + 10, JourneyBlocks.ash, 0, 3);
        world.setBlock(x + 7, y + 4, z + 10, JourneyBlocks.ash, 0, 3);
        world.setBlock(x + 8, y + 4, z + 10, JourneyBlocks.ash, 0, 3);
        world.setBlock(x + 2, y + 4, z + 11, JourneyBlocks.hotBlock, 0, 3);
        world.setBlock(x + 3, y + 4, z + 11, JourneyBlocks.hotBlock, 0, 3);
        world.setBlock(x + 4, y + 4, z + 11, JourneyBlocks.ash, 0, 3);
        world.setBlock(x + 5, y + 4, z + 11, JourneyBlocks.ash, 0, 3);
        world.setBlock(x + 6, y + 4, z + 11, JourneyBlocks.hotBlock, 0, 3);
        world.setBlock(x + 7, y + 4, z + 11, JourneyBlocks.hotBlock, 0, 3);
        world.setBlock(x + 2, y + 4, z + 12, JourneyBlocks.ash, 0, 3);
        world.setBlock(x + 4, y + 4, z + 12, JourneyBlocks.hotBlock, 0, 3);
        world.setBlock(x + 5, y + 4, z + 12, JourneyBlocks.ash, 0, 3);
        world.setBlock(x + 3, y + 4, z + 13, JourneyBlocks.hotBlock, 0, 3);
        world.setBlock(x + 4, y + 4, z + 13, JourneyBlocks.hotBlock, 0, 3);
        world.setBlock(x + 7, y + 4, z + 14, JourneyBlocks.hotBlock, 0, 3);
        world.setBlock(x + 8, y + 4, z + 14, JourneyBlocks.hotBlock, 0, 3);
        world.setBlock(x + 4, y + 4, z + 15, JourneyBlocks.hotBlock, 0, 3);
        world.setBlock(x + 5, y + 4, z + 15, JourneyBlocks.ash, 0, 3);
        world.setBlock(x + 6, y + 4, z + 15, JourneyBlocks.hotBlock, 0, 3);
        world.setBlock(x + 5, y + 5, z + 2, JourneyBlocks.hotBlock, 0, 3);
        world.setBlock(x + 6, y + 5, z + 2, JourneyBlocks.hotBlock, 0, 3);
        world.setBlock(x + 3, y + 5, z + 3, JourneyBlocks.hotBlock, 0, 3);
        world.setBlock(x + 4, y + 5, z + 3, JourneyBlocks.ash, 0, 3);
        world.setBlock(x + 5, y + 5, z + 3, JourneyBlocks.ash, 0, 3);
        world.setBlock(x + 6, y + 5, z + 3, JourneyBlocks.ash, 0, 3);
        world.setBlock(x + 7, y + 5, z + 3, JourneyBlocks.ash, 0, 3);
        world.setBlock(x + 8, y + 5, z + 3, JourneyBlocks.hotBlock, 0, 3);
        world.setBlock(x + 2, y + 5, z + 4, JourneyBlocks.ash, 0, 3);
        world.setBlock(x + 3, y + 5, z + 4, JourneyBlocks.ash, 0, 3);
        world.setBlock(x + 4, y + 5, z + 4, JourneyBlocks.ash, 0, 3);
        world.setBlock(x + 5, y + 5, z + 4, JourneyBlocks.ash, 0, 3);
        world.setBlock(x + 6, y + 5, z + 4, JourneyBlocks.ash, 0, 3);
        world.setBlock(x + 7, y + 5, z + 4, JourneyBlocks.ash, 0, 3);
        world.setBlock(x + 8, y + 5, z + 4, JourneyBlocks.ash, 0, 3);
        world.setBlock(x + 9, y + 5, z + 4, JourneyBlocks.hotBlock, 0, 3);
        world.setBlock(x + 10, y + 5, z + 4, JourneyBlocks.hotBlock, 0, 3);
        world.setBlock(x + 2, y + 5, z + 5, JourneyBlocks.hotBlock, 0, 3);
        world.setBlock(x + 3, y + 5, z + 5, JourneyBlocks.ash, 0, 3);
        world.setBlock(x + 4, y + 5, z + 5, JourneyBlocks.ash, 0, 3);
        world.setBlock(x + 5, y + 5, z + 5, JourneyBlocks.ash, 0, 3);
        world.setBlock(x + 6, y + 5, z + 5, JourneyBlocks.ash, 0, 3);
        world.setBlock(x + 7, y + 5, z + 5, JourneyBlocks.ash, 0, 3);
        world.setBlock(x + 8, y + 5, z + 5, JourneyBlocks.ash, 0, 3);
        world.setBlock(x + 9, y + 5, z + 5, JourneyBlocks.ash, 0, 3);
        world.setBlock(x + 1, y + 5, z + 6, JourneyBlocks.ash, 0, 3);
        world.setBlock(x + 2, y + 5, z + 6, JourneyBlocks.ash, 0, 3);
        world.setBlock(x + 3, y + 5, z + 6, JourneyBlocks.ash, 0, 3);
        world.setBlock(x + 4, y + 5, z + 6, JourneyBlocks.ash, 0, 3);
        world.setBlock(x + 5, y + 5, z + 6, JourneyBlocks.ash, 0, 3);
        world.setBlock(x + 6, y + 5, z + 6, JourneyBlocks.ash, 0, 3);
        world.setBlock(x + 7, y + 5, z + 6, JourneyBlocks.ash, 0, 3);
        world.setBlock(x + 8, y + 5, z + 6, JourneyBlocks.ash, 0, 3);
        world.setBlock(x + 9, y + 5, z + 6, JourneyBlocks.ash, 0, 3);
        world.setBlock(x + 1, y + 5, z + 7, JourneyBlocks.ash, 0, 3);
        world.setBlock(x + 2, y + 5, z + 7, JourneyBlocks.ash, 0, 3);
        world.setBlock(x + 3, y + 5, z + 7, JourneyBlocks.ash, 0, 3);
        world.setBlock(x + 4, y + 5, z + 7, JourneyBlocks.ash, 0, 3);
        world.setBlock(x + 5, y + 5, z + 7, JourneyBlocks.ash, 0, 3);
        world.setBlock(x + 6, y + 5, z + 7, JourneyBlocks.ash, 0, 3);
        world.setBlock(x + 7, y + 5, z + 7, JourneyBlocks.ash, 0, 3);
        world.setBlock(x + 8, y + 5, z + 7, JourneyBlocks.ash, 0, 3);
        world.setBlock(x + 9, y + 5, z + 7, JourneyBlocks.ash, 0, 3);
        world.setBlock(x + 10, y + 5, z + 7, JourneyBlocks.hotBlock, 0, 3);
        world.setBlock(x + 1, y + 5, z + 8, JourneyBlocks.ash, 0, 3);
        world.setBlock(x + 2, y + 5, z + 8, JourneyBlocks.ash, 0, 3);
        world.setBlock(x + 3, y + 5, z + 8, JourneyBlocks.ash, 0, 3);
        world.setBlock(x + 4, y + 5, z + 8, JourneyBlocks.ash, 0, 3);
        world.setBlock(x + 5, y + 5, z + 8, JourneyBlocks.ash, 0, 3);
        world.setBlock(x + 6, y + 5, z + 8, JourneyBlocks.ash, 0, 3);
        world.setBlock(x + 7, y + 5, z + 8, JourneyBlocks.ash, 0, 3);
        world.setBlock(x + 8, y + 5, z + 8, JourneyBlocks.ash, 0, 3);
        world.setBlock(x + 9, y + 5, z + 8, JourneyBlocks.ash, 0, 3);
        world.setBlock(x + 10, y + 5, z + 8, JourneyBlocks.ash, 0, 3);
        world.setBlock(x + 1, y + 5, z + 9, JourneyBlocks.ash, 0, 3);
        world.setBlock(x + 2, y + 5, z + 9, JourneyBlocks.ash, 0, 3);
        world.setBlock(x + 3, y + 5, z + 9, JourneyBlocks.ash, 0, 3);
        world.setBlock(x + 4, y + 5, z + 9, JourneyBlocks.ash, 0, 3);
        world.setBlock(x + 5, y + 5, z + 9, JourneyBlocks.ash, 0, 3);
        world.setBlock(x + 6, y + 5, z + 9, JourneyBlocks.ash, 0, 3);
        world.setBlock(x + 7, y + 5, z + 9, JourneyBlocks.ash, 0, 3);
        world.setBlock(x + 8, y + 5, z + 9, JourneyBlocks.ash, 0, 3);
        world.setBlock(x + 9, y + 5, z + 9, JourneyBlocks.ash, 0, 3);
        world.setBlock(x + 10, y + 5, z + 9, JourneyBlocks.ash, 0, 3);
        world.setBlock(x + 2, y + 5, z + 10, JourneyBlocks.ash, 0, 3);
        world.setBlock(x + 3, y + 5, z + 10, JourneyBlocks.ash, 0, 3);
        world.setBlock(x + 4, y + 5, z + 10, JourneyBlocks.ash, 0, 3);
        world.setBlock(x + 5, y + 5, z + 10, JourneyBlocks.ash, 0, 3);
        world.setBlock(x + 6, y + 5, z + 10, JourneyBlocks.ash, 0, 3);
        world.setBlock(x + 7, y + 5, z + 10, JourneyBlocks.ash, 0, 3);
        world.setBlock(x + 8, y + 5, z + 10, JourneyBlocks.ash, 0, 3);
        world.setBlock(x + 9, y + 5, z + 10, JourneyBlocks.ash, 0, 3);
        world.setBlock(x + 2, y + 5, z + 11, JourneyBlocks.hotBlock, 0, 3);
        world.setBlock(x + 4, y + 5, z + 11, JourneyBlocks.ash, 0, 3);
        world.setBlock(x + 5, y + 5, z + 11, JourneyBlocks.ash, 0, 3);
        world.setBlock(x + 6, y + 5, z + 11, JourneyBlocks.ash, 0, 3);
        world.setBlock(x + 7, y + 5, z + 11, JourneyBlocks.ash, 0, 3);
        world.setBlock(x + 8, y + 5, z + 11, JourneyBlocks.ash, 0, 3);
        world.setBlock(x + 3, y + 5, z + 12, JourneyBlocks.ash, 0, 3);
        world.setBlock(x + 7, y + 5, z + 12, JourneyBlocks.ash, 0, 3);
        world.setBlock(x + 5, y + 5, z + 13, JourneyBlocks.ash, 0, 3);
        world.setBlock(x + 3, y + 5, z + 14, JourneyBlocks.hotBlock, 0, 3);
        world.setBlock(x + 3, y + 5, z + 15, JourneyBlocks.hotBlock, 0, 3);
        world.setBlock(x + 5, y + 5, z + 15, JourneyBlocks.hotBlock, 0, 3);
        world.setBlock(x + 8, y + 5, z + 15, JourneyBlocks.hotBlock, 0, 3);
        world.setBlock(x + 5, y + 5, z + 16, JourneyBlocks.hotBlock, 0, 3);
        world.setBlock(x + 5, y + 6, z + 0, JourneyBlocks.hotBlock, 0, 3);
        world.setBlock(x + 6, y + 6, z + 0, JourneyBlocks.hotBlock, 0, 3);
        world.setBlock(x + 7, y + 6, z + 0, JourneyBlocks.hotBlock, 0, 3);
        world.setBlock(x + 2, y + 6, z + 1, JourneyBlocks.hotBlock, 0, 3);
        world.setBlock(x + 3, y + 6, z + 1, JourneyBlocks.hotBlock, 0, 3);
        world.setBlock(x + 4, y + 6, z + 1, JourneyBlocks.hotBlock, 0, 3);
        world.setBlock(x + 5, y + 6, z + 1, JourneyBlocks.hotBlock, 0, 3);
        world.setBlock(x + 8, y + 6, z + 1, JourneyBlocks.hotBlock, 0, 3);
        world.setBlock(x + 1, y + 6, z + 2, JourneyBlocks.hotBlock, 0, 3);
        world.setBlock(x + 2, y + 6, z + 2, JourneyBlocks.hotBlock, 0, 3);
        world.setBlock(x + 4, y + 6, z + 2, JourneyBlocks.hotBlock, 0, 3);
        world.setBlock(x + 5, y + 6, z + 2, JourneyBlocks.hotBlock, 0, 3);
        world.setBlock(x + 6, y + 6, z + 2, JourneyBlocks.hotBlock, 0, 3);
        world.setBlock(x + 7, y + 6, z + 2, JourneyBlocks.hotBlock, 0, 3);
        world.setBlock(x + 8, y + 6, z + 2, JourneyBlocks.hotBlock, 0, 3);
        world.setBlock(x + 9, y + 6, z + 2, JourneyBlocks.hotBlock, 0, 3);
        world.setBlock(x + 2, y + 6, z + 3, JourneyBlocks.hotBlock, 0, 3);
        world.setBlock(x + 3, y + 6, z + 3, JourneyBlocks.hotBlock, 0, 3);
        world.setBlock(x + 4, y + 6, z + 3, JourneyBlocks.hotBlock, 0, 3);
        world.setBlock(x + 5, y + 6, z + 3, JourneyBlocks.hotBlock, 0, 3);
        world.setBlock(x + 6, y + 6, z + 3, JourneyBlocks.hotBlock, 0, 3);
        world.setBlock(x + 7, y + 6, z + 3, JourneyBlocks.hotBlock, 0, 3);
        world.setBlock(x + 8, y + 6, z + 3, JourneyBlocks.hotBlock, 0, 3);
        world.setBlock(x + 9, y + 6, z + 3, JourneyBlocks.hotBlock, 0, 3);
        world.setBlock(x + 1, y + 6, z + 4, JourneyBlocks.hotBlock, 0, 3);
        world.setBlock(x + 2, y + 6, z + 4, JourneyBlocks.hotBlock, 0, 3);
        world.setBlock(x + 3, y + 6, z + 4, JourneyBlocks.hotBlock, 0, 3);
        world.setBlock(x + 4, y + 6, z + 4, JourneyBlocks.hotBlock, 0, 3);
        world.setBlock(x + 5, y + 6, z + 4, JourneyBlocks.hotBlock, 0, 3);
        world.setBlock(x + 6, y + 6, z + 4, JourneyBlocks.hotBlock, 0, 3);
        world.setBlock(x + 7, y + 6, z + 4, JourneyBlocks.hotBlock, 0, 3);
        world.setBlock(x + 8, y + 6, z + 4, JourneyBlocks.hotBlock, 0, 3);
        world.setBlock(x + 9, y + 6, z + 4, JourneyBlocks.hotBlock, 0, 3);
        world.setBlock(x + 0, y + 6, z + 5, JourneyBlocks.hotBlock, 0, 3);
        world.setBlock(x + 1, y + 6, z + 5, JourneyBlocks.hotBlock, 0, 3);
        world.setBlock(x + 2, y + 6, z + 5, JourneyBlocks.hotBlock, 0, 3);
        world.setBlock(x + 3, y + 6, z + 5, JourneyBlocks.hotBlock, 0, 3);
        world.setBlock(x + 4, y + 6, z + 5, JourneyBlocks.hotBlock, 0, 3);
        world.setBlock(x + 5, y + 6, z + 5, JourneyBlocks.hotBlock, 0, 3);
        world.setBlock(x + 6, y + 6, z + 5, JourneyBlocks.hotBlock, 0, 3);
        world.setBlock(x + 7, y + 6, z + 5, JourneyBlocks.hotBlock, 0, 3);
        world.setBlock(x + 8, y + 6, z + 5, JourneyBlocks.hotBlock, 0, 3);
        world.setBlock(x + 9, y + 6, z + 5, JourneyBlocks.hotBlock, 0, 3);
        world.setBlock(x + 10, y + 6, z + 5, JourneyBlocks.hotBlock, 0, 3);
        world.setBlock(x + 0, y + 6, z + 6, JourneyBlocks.hotBlock, 0, 3);
        world.setBlock(x + 1, y + 6, z + 6, JourneyBlocks.hotBlock, 0, 3);
        world.setBlock(x + 2, y + 6, z + 6, JourneyBlocks.hotBlock, 0, 3);
        world.setBlock(x + 3, y + 6, z + 6, JourneyBlocks.hotBlock, 0, 3);
        world.setBlock(x + 4, y + 6, z + 6, JourneyBlocks.hotBlock, 0, 3);
        world.setBlock(x + 5, y + 6, z + 6, JourneyBlocks.hotBlock, 0, 3);
        world.setBlock(x + 6, y + 6, z + 6, JourneyBlocks.hotBlock, 0, 3);
        world.setBlock(x + 7, y + 6, z + 6, JourneyBlocks.hotBlock, 0, 3);
        world.setBlock(x + 9, y + 6, z + 6, JourneyBlocks.hotBlock, 0, 3);
        world.setBlock(x + 10, y + 6, z + 6, JourneyBlocks.hotBlock, 0, 3);
        world.setBlock(x + 11, y + 6, z + 6, JourneyBlocks.hotBlock, 0, 3);
        world.setBlock(x + 1, y + 6, z + 7, JourneyBlocks.hotBlock, 0, 3);
        world.setBlock(x + 2, y + 6, z + 7, JourneyBlocks.hotBlock, 0, 3);
        world.setBlock(x + 3, y + 6, z + 7, JourneyBlocks.hotBlock, 0, 3);
        world.setBlock(x + 4, y + 6, z + 7, JourneyBlocks.hotBlock, 0, 3);
        world.setBlock(x + 5, y + 6, z + 7, JourneyBlocks.hotBlock, 0, 3);
        world.setBlock(x + 6, y + 6, z + 7, JourneyBlocks.hotBlock, 0, 3);
        world.setBlock(x + 7, y + 6, z + 7, JourneyBlocks.hotBlock, 0, 3);
        world.setBlock(x + 8, y + 6, z + 7, JourneyBlocks.hotBlock, 0, 3);
        world.setBlock(x + 9, y + 6, z + 7, JourneyBlocks.hotBlock, 0, 3);
        world.setBlock(x + 10, y + 6, z + 7, JourneyBlocks.hotBlock, 0, 3);
        world.setBlock(x + 0, y + 6, z + 8, JourneyBlocks.hotBlock, 0, 3);
        world.setBlock(x + 1, y + 6, z + 8, JourneyBlocks.hotBlock, 0, 3);
        world.setBlock(x + 2, y + 6, z + 8, JourneyBlocks.hotBlock, 0, 3);
        world.setBlock(x + 3, y + 6, z + 8, JourneyBlocks.hotBlock, 0, 3);
        world.setBlock(x + 4, y + 6, z + 8, JourneyBlocks.hotBlock, 0, 3);
        world.setBlock(x + 5, y + 6, z + 8, JourneyBlocks.hotBlock, 0, 3);
        world.setBlock(x + 6, y + 6, z + 8, JourneyBlocks.hotBlock, 0, 3);
        world.setBlock(x + 7, y + 6, z + 8, JourneyBlocks.hotBlock, 0, 3);
        world.setBlock(x + 8, y + 6, z + 8, JourneyBlocks.hotBlock, 0, 3);
        world.setBlock(x + 9, y + 6, z + 8, JourneyBlocks.hotBlock, 0, 3);
        world.setBlock(x + 10, y + 6, z + 8, JourneyBlocks.hotBlock, 0, 3);
        world.setBlock(x + 11, y + 6, z + 8, JourneyBlocks.hotBlock, 0, 3);
        world.setBlock(x + 0, y + 6, z + 9, JourneyBlocks.hotBlock, 0, 3);
        world.setBlock(x + 1, y + 6, z + 9, JourneyBlocks.hotBlock, 0, 3);
        world.setBlock(x + 2, y + 6, z + 9, JourneyBlocks.hotBlock, 0, 3);
        world.setBlock(x + 3, y + 6, z + 9, JourneyBlocks.hotBlock, 0, 3);
        world.setBlock(x + 4, y + 6, z + 9, JourneyBlocks.hotBlock, 0, 3);
        world.setBlock(x + 5, y + 6, z + 9, JourneyBlocks.hotBlock, 0, 3);
        world.setBlock(x + 6, y + 6, z + 9, JourneyBlocks.hotBlock, 0, 3);
        world.setBlock(x + 7, y + 6, z + 9, JourneyBlocks.hotBlock, 0, 3);
        world.setBlock(x + 8, y + 6, z + 9, JourneyBlocks.hotBlock, 0, 3);
        world.setBlock(x + 9, y + 6, z + 9, JourneyBlocks.hotBlock, 0, 3);
        world.setBlock(x + 10, y + 6, z + 9, JourneyBlocks.hotBlock, 0, 3);
        world.setBlock(x + 11, y + 6, z + 9, JourneyBlocks.hotBlock, 0, 3);
        world.setBlock(x + 0, y + 6, z + 10, JourneyBlocks.hotBlock, 0, 3);
        world.setBlock(x + 1, y + 6, z + 10, JourneyBlocks.hotBlock, 0, 3);
        world.setBlock(x + 2, y + 6, z + 10, JourneyBlocks.hotBlock, 0, 3);
        world.setBlock(x + 3, y + 6, z + 10, JourneyBlocks.hotBlock, 0, 3);
        world.setBlock(x + 4, y + 6, z + 10, JourneyBlocks.hotBlock, 0, 3);
        world.setBlock(x + 5, y + 6, z + 10, JourneyBlocks.hotBlock, 0, 3);
        world.setBlock(x + 6, y + 6, z + 10, JourneyBlocks.hotBlock, 0, 3);
        world.setBlock(x + 7, y + 6, z + 10, JourneyBlocks.hotBlock, 0, 3);
        world.setBlock(x + 8, y + 6, z + 10, JourneyBlocks.hotBlock, 0, 3);
        world.setBlock(x + 9, y + 6, z + 10, JourneyBlocks.hotBlock, 0, 3);
        world.setBlock(x + 10, y + 6, z + 10, JourneyBlocks.hotBlock, 0, 3);
        world.setBlock(x + 1, y + 6, z + 11, JourneyBlocks.hotBlock, 0, 3);
        world.setBlock(x + 3, y + 6, z + 11, JourneyBlocks.hotBlock, 0, 3);
        world.setBlock(x + 4, y + 6, z + 11, JourneyBlocks.hotBlock, 0, 3);
        world.setBlock(x + 5, y + 6, z + 11, JourneyBlocks.hotBlock, 0, 3);
        world.setBlock(x + 6, y + 6, z + 11, JourneyBlocks.hotBlock, 0, 3);
        world.setBlock(x + 7, y + 6, z + 11, JourneyBlocks.hotBlock, 0, 3);
        world.setBlock(x + 8, y + 6, z + 11, JourneyBlocks.hotBlock, 0, 3);
        world.setBlock(x + 10, y + 6, z + 11, JourneyBlocks.hotBlock, 0, 3);
        world.setBlock(x + 1, y + 6, z + 12, JourneyBlocks.hotBlock, 0, 3);
        world.setBlock(x + 2, y + 6, z + 12, JourneyBlocks.hotBlock, 0, 3);
        world.setBlock(x + 3, y + 6, z + 12, JourneyBlocks.hotBlock, 0, 3);
        world.setBlock(x + 4, y + 6, z + 12, JourneyBlocks.hotBlock, 0, 3);
        world.setBlock(x + 5, y + 6, z + 12, JourneyBlocks.hotBlock, 0, 3);
        world.setBlock(x + 6, y + 6, z + 12, JourneyBlocks.hotBlock, 0, 3);
        world.setBlock(x + 7, y + 6, z + 12, JourneyBlocks.hotBlock, 0, 3);
        world.setBlock(x + 8, y + 6, z + 12, JourneyBlocks.hotBlock, 0, 3);
        world.setBlock(x + 9, y + 6, z + 12, JourneyBlocks.hotBlock, 0, 3);
        world.setBlock(x + 2, y + 6, z + 13, JourneyBlocks.hotBlock, 0, 3);
        world.setBlock(x + 3, y + 6, z + 13, JourneyBlocks.hotBlock, 0, 3);
        world.setBlock(x + 5, y + 6, z + 13, JourneyBlocks.hotBlock, 0, 3);
        world.setBlock(x + 6, y + 6, z + 13, JourneyBlocks.hotBlock, 0, 3);
        world.setBlock(x + 7, y + 6, z + 13, JourneyBlocks.hotBlock, 0, 3);
        world.setBlock(x + 8, y + 6, z + 13, JourneyBlocks.hotBlock, 0, 3);
        world.setBlock(x + 1, y + 6, z + 14, JourneyBlocks.hotBlock, 0, 3);
        world.setBlock(x + 2, y + 6, z + 14, JourneyBlocks.hotBlock, 0, 3);
        world.setBlock(x + 3, y + 6, z + 14, JourneyBlocks.hotBlock, 0, 3);
        world.setBlock(x + 4, y + 6, z + 14, JourneyBlocks.hotBlock, 0, 3);
        world.setBlock(x + 5, y + 6, z + 14, JourneyBlocks.hotBlock, 0, 3);
        world.setBlock(x + 7, y + 6, z + 14, JourneyBlocks.hotBlock, 0, 3);
        world.setBlock(x + 8, y + 6, z + 14, JourneyBlocks.hotBlock, 0, 3);
        world.setBlock(x + 9, y + 6, z + 14, JourneyBlocks.hotBlock, 0, 3);
        world.setBlock(x + 2, y + 6, z + 15, JourneyBlocks.hotBlock, 0, 3);
        world.setBlock(x + 3, y + 6, z + 15, JourneyBlocks.hotBlock, 0, 3);
        world.setBlock(x + 4, y + 6, z + 15, JourneyBlocks.hotBlock, 0, 3);
        world.setBlock(x + 5, y + 6, z + 15, JourneyBlocks.hotBlock, 0, 3);
        world.setBlock(x + 6, y + 6, z + 15, JourneyBlocks.hotBlock, 0, 3);
        world.setBlock(x + 7, y + 6, z + 15, JourneyBlocks.hotBlock, 0, 3);
        world.setBlock(x + 8, y + 6, z + 15, JourneyBlocks.hotBlock, 0, 3);
        world.setBlock(x + 3, y + 6, z + 16, JourneyBlocks.hotBlock, 0, 3);
        world.setBlock(x + 4, y + 6, z + 16, JourneyBlocks.hotBlock, 0, 3);
        world.setBlock(x + 5, y + 6, z + 16, JourneyBlocks.hotBlock, 0, 3);
        world.setBlock(x + 6, y + 6, z + 16, JourneyBlocks.hotBlock, 0, 3);
        world.setBlock(x + 7, y + 6, z + 16, JourneyBlocks.hotBlock, 0, 3);
        world.setBlock(x + 3, y + 7, z + 1, JourneyBlocks.dungeonBrickCarved, 0, 3);
        world.setBlock(x + 4, y + 7, z + 1, JourneyBlocks.hotBlock, 0, 3);
        world.setBlock(x + 5, y + 7, z + 1, JourneyBlocks.hotBlock, 0, 3);
        world.setBlock(x + 7, y + 7, z + 1, JourneyBlocks.dungeonBrickCarved, 0, 3);
        world.setBlock(x + 2, y + 7, z + 2, JourneyBlocks.dungeonBrickCarved, 0, 3);
        world.setBlock(x + 3, y + 7, z + 2, JourneyBlocks.dungeonBrick, 0, 3);
        world.setBlock(x + 4, y + 7, z + 2, JourneyBlocks.dungeonBrick, 0, 3);
        world.setBlock(x + 5, y + 7, z + 2, JourneyBlocks.dungeonBrick, 0, 3);
        world.setBlock(x + 6, y + 7, z + 2, JourneyBlocks.dungeonBrick, 0, 3);
        world.setBlock(x + 7, y + 7, z + 2, JourneyBlocks.dungeonBrick, 0, 3);
        world.setBlock(x + 8, y + 7, z + 2, JourneyBlocks.dungeonBrickCarved, 0, 3);
        world.setBlock(x + 3, y + 7, z + 3, JourneyBlocks.dungeonBrick, 0, 3);
        world.setBlock(x + 4, y + 7, z + 3, JourneyBlocks.brisonStone, 0, 3);
        world.setBlock(x + 5, y + 7, z + 3, JourneyBlocks.brisonStone, 0, 3);
        world.setBlock(x + 6, y + 7, z + 3, JourneyBlocks.brisonStone, 0, 3);
        world.setBlock(x + 7, y + 7, z + 3, JourneyBlocks.dungeonBrick, 0, 3);
        world.setBlock(x + 2, y + 7, z + 4, JourneyBlocks.hotBlock, 0, 3);
        world.setBlock(x + 3, y + 7, z + 4, JourneyBlocks.dungeonBrick, 0, 3);
        world.setBlock(x + 4, y + 7, z + 4, JourneyBlocks.brisonStone, 0, 3);
        world.setBlock(x + 5, y + 7, z + 4, JourneyBlocks.brisonStone, 0, 3);
        world.setBlock(x + 6, y + 7, z + 4, JourneyBlocks.brisonStone, 0, 3);
        world.setBlock(x + 7, y + 7, z + 4, JourneyBlocks.dungeonBrick, 0, 3);
        world.setBlock(x + 2, y + 7, z + 5, JourneyBlocks.hotBlock, 0, 3);
        world.setBlock(x + 3, y + 7, z + 5, JourneyBlocks.dungeonBrick, 0, 3);
        world.setBlock(x + 4, y + 7, z + 5, JourneyBlocks.brisonStone, 0, 3);
        world.setBlock(x + 5, y + 7, z + 5, JourneyBlocks.brisonStone, 0, 3);
        world.setBlock(x + 6, y + 7, z + 5, JourneyBlocks.brisonStone, 0, 3);
        world.setBlock(x + 7, y + 7, z + 5, JourneyBlocks.dungeonBrick, 0, 3);
        world.setBlock(x + 9, y + 7, z + 5, JourneyBlocks.hotBlock, 0, 3);
        world.setBlock(x + 2, y + 7, z + 6, JourneyBlocks.dungeonBrick, 0, 3);
        world.setBlock(x + 3, y + 7, z + 6, JourneyBlocks.dungeonBrick, 0, 3);
        world.setBlock(x + 4, y + 7, z + 6, JourneyBlocks.dungeonBrick, 0, 3);
        world.setBlock(x + 5, y + 7, z + 6, JourneyBlocks.brisonStone, 0, 3);
        world.setBlock(x + 6, y + 7, z + 6, JourneyBlocks.dungeonBrick, 0, 3);
        world.setBlock(x + 7, y + 7, z + 6, JourneyBlocks.dungeonBrick, 0, 3);
        world.setBlock(x + 8, y + 7, z + 6, JourneyBlocks.dungeonBrick, 0, 3);
        world.setBlock(x + 9, y + 7, z + 6, JourneyBlocks.hotBlock, 0, 3);
        world.setBlock(x + 2, y + 7, z + 7, JourneyBlocks.dungeonBrick, 0, 3);
        world.setBlock(x + 3, y + 7, z + 7, JourneyBlocks.dungeonBrick, 0, 3);
        world.setBlock(x + 4, y + 7, z + 7, JourneyBlocks.brisonStone, 0, 3);
        world.setBlock(x + 5, y + 7, z + 7, JourneyBlocks.brisonStone, 0, 3);
        world.setBlock(x + 6, y + 7, z + 7, JourneyBlocks.brisonStone, 0, 3);
        world.setBlock(x + 7, y + 7, z + 7, JourneyBlocks.dungeonBrick, 0, 3);
        world.setBlock(x + 8, y + 7, z + 7, JourneyBlocks.dungeonBrick, 0, 3);
        world.setBlock(x + 9, y + 7, z + 7, JourneyBlocks.hotBlock, 0, 3);
        world.setBlock(x + 2, y + 7, z + 8, JourneyBlocks.hotBlock, 0, 3);
        world.setBlock(x + 3, y + 7, z + 8, JourneyBlocks.brisonStone, 0, 3);
        world.setBlock(x + 4, y + 7, z + 8, JourneyBlocks.brisonStone, 0, 3);
        world.setBlock(x + 5, y + 7, z + 8, JourneyBlocks.dungeonBrick, 0, 3);
        world.setBlock(x + 6, y + 7, z + 8, JourneyBlocks.brisonStone, 0, 3);
        world.setBlock(x + 7, y + 7, z + 8, JourneyBlocks.brisonStone, 0, 3);
        world.setBlock(x + 8, y + 7, z + 8, JourneyBlocks.hotBlock, 0, 3);
        world.setBlock(x + 9, y + 7, z + 8, JourneyBlocks.hotBlock, 0, 3);
        world.setBlock(x + 2, y + 7, z + 9, JourneyBlocks.dungeonBrick, 0, 3);
        world.setBlock(x + 3, y + 7, z + 9, JourneyBlocks.dungeonBrick, 0, 3);
        world.setBlock(x + 4, y + 7, z + 9, JourneyBlocks.brisonStone, 0, 3);
        world.setBlock(x + 5, y + 7, z + 9, JourneyBlocks.brisonStone, 0, 3);
        world.setBlock(x + 6, y + 7, z + 9, JourneyBlocks.brisonStone, 0, 3);
        world.setBlock(x + 7, y + 7, z + 9, JourneyBlocks.dungeonBrick, 0, 3);
        world.setBlock(x + 8, y + 7, z + 9, JourneyBlocks.dungeonBrick, 0, 3);
        world.setBlock(x + 9, y + 7, z + 9, JourneyBlocks.hotBlock, 0, 3);
        world.setBlock(x + 2, y + 7, z + 10, JourneyBlocks.dungeonBrick, 0, 3);
        world.setBlock(x + 3, y + 7, z + 10, JourneyBlocks.dungeonBrick, 0, 3);
        world.setBlock(x + 4, y + 7, z + 10, JourneyBlocks.dungeonBrick, 0, 3);
        world.setBlock(x + 5, y + 7, z + 10, JourneyBlocks.brisonStone, 0, 3);
        world.setBlock(x + 6, y + 7, z + 10, JourneyBlocks.dungeonBrick, 0, 3);
        world.setBlock(x + 7, y + 7, z + 10, JourneyBlocks.dungeonBrick, 0, 3);
        world.setBlock(x + 8, y + 7, z + 10, JourneyBlocks.dungeonBrick, 0, 3);
        world.setBlock(x + 9, y + 7, z + 10, JourneyBlocks.hotBlock, 0, 3);
        world.setBlock(x + 3, y + 7, z + 11, JourneyBlocks.dungeonBrick, 0, 3);
        world.setBlock(x + 4, y + 7, z + 11, JourneyBlocks.brisonStone, 0, 3);
        world.setBlock(x + 5, y + 7, z + 11, JourneyBlocks.brisonStone, 0, 3);
        world.setBlock(x + 6, y + 7, z + 11, JourneyBlocks.brisonStone, 0, 3);
        world.setBlock(x + 7, y + 7, z + 11, JourneyBlocks.dungeonBrick, 0, 3);
        world.setBlock(x + 8, y + 7, z + 11, JourneyBlocks.hotBlock, 0, 3);
        world.setBlock(x + 3, y + 7, z + 12, JourneyBlocks.dungeonBrick, 0, 3);
        world.setBlock(x + 4, y + 7, z + 12, JourneyBlocks.brisonStone, 0, 3);
        world.setBlock(x + 5, y + 7, z + 12, JourneyBlocks.brisonStone, 0, 3);
        world.setBlock(x + 6, y + 7, z + 12, JourneyBlocks.brisonStone, 0, 3);
        world.setBlock(x + 7, y + 7, z + 12, JourneyBlocks.dungeonBrick, 0, 3);
        world.setBlock(x + 8, y + 7, z + 12, JourneyBlocks.hotBlock, 0, 3);
        world.setBlock(x + 3, y + 7, z + 13, JourneyBlocks.dungeonBrick, 0, 3);
        world.setBlock(x + 5, y + 7, z + 13, JourneyBlocks.brisonStone, 0, 3);
        world.setBlock(x + 6, y + 7, z + 13, JourneyBlocks.brisonStone, 0, 3);
        world.setBlock(x + 7, y + 7, z + 13, JourneyBlocks.dungeonBrick, 0, 3);
        world.setBlock(x + 2, y + 7, z + 14, JourneyBlocks.dungeonBrickCarved, 0, 3);
        world.setBlock(x + 3, y + 7, z + 14, JourneyBlocks.dungeonBrick, 0, 3);
        world.setBlock(x + 4, y + 7, z + 14, JourneyBlocks.dungeonBrick, 0, 3);
        world.setBlock(x + 5, y + 7, z + 14, JourneyBlocks.dungeonBrick, 0, 3);
        world.setBlock(x + 6, y + 7, z + 14, JourneyBlocks.dungeonBrick, 0, 3);
        world.setBlock(x + 7, y + 7, z + 14, JourneyBlocks.dungeonBrick, 0, 3);
        world.setBlock(x + 8, y + 7, z + 14, JourneyBlocks.dungeonBrickCarved, 0, 3);
        world.setBlock(x + 3, y + 7, z + 15, JourneyBlocks.dungeonBrickCarved, 0, 3);
        world.setBlock(x + 5, y + 7, z + 15, JourneyBlocks.hotBlock, 0, 3);
        world.setBlock(x + 6, y + 7, z + 15, JourneyBlocks.hotBlock, 0, 3);
        world.setBlock(x + 7, y + 7, z + 15, JourneyBlocks.dungeonBrickCarved, 0, 3);
        world.setBlock(x + 3, y + 8, z + 1, JourneyBlocks.dungeonBrickCarved, 0, 3);
        world.setBlock(x + 7, y + 8, z + 1, JourneyBlocks.dungeonBrickCarved, 0, 3);
        world.setBlock(x + 2, y + 8, z + 2, JourneyBlocks.dungeonBrickCarved, 0, 3);
        world.setBlock(x + 3, y + 8, z + 2, JourneyBlocks.dungeonBrick, 0, 3);
        world.setBlock(x + 4, y + 8, z + 2, JourneyBlocks.dungeonBrick, 0, 3);
        world.setBlock(x + 5, y + 8, z + 2, JourneyBlocks.dungeonBrickCarvedStairs, 2, 3);
        world.setBlock(x + 6, y + 8, z + 2, JourneyBlocks.dungeonBrick, 0, 3);
        world.setBlock(x + 7, y + 8, z + 2, JourneyBlocks.dungeonBrick, 0, 3);
        world.setBlock(x + 8, y + 8, z + 2, JourneyBlocks.dungeonBrickCarved, 0, 3);
        world.setBlock(x + 3, y + 8, z + 3, JourneyBlocks.dungeonBrickCarvedStairs, 0, 3);
        world.setBlock(x + 7, y + 8, z + 3, JourneyBlocks.dungeonBrickCarvedStairs, 1, 3);
        world.setBlock(x + 3, y + 8, z + 4, JourneyBlocks.dungeonBrick, 0, 3);
        world.setBlock(x + 7, y + 8, z + 4, JourneyBlocks.dungeonBrick, 0, 3);
        world.setBlock(x + 3, y + 8, z + 5, JourneyBlocks.dungeonBrick, 0, 3);
        world.setBlock(x + 4, y + 8, z + 5, JourneyBlocks.dungeonBrickStairs, 4, 3);
        world.setBlock(x + 6, y + 8, z + 5, JourneyBlocks.dungeonBrickStairs, 5, 3);
        world.setBlock(x + 7, y + 8, z + 5, JourneyBlocks.dungeonBrick, 0, 3);
        world.setBlock(x + 2, y + 8, z + 6, JourneyBlocks.dungeonBrickCarved, 0, 3);
        world.setBlock(x + 3, y + 8, z + 6, JourneyBlocks.dungeonBrick, 0, 3);
        world.setBlock(x + 4, y + 8, z + 6, JourneyBlocks.dungeonBrick, 0, 3);
        world.setBlock(x + 6, y + 8, z + 6, JourneyBlocks.dungeonBrick, 0, 3);
        world.setBlock(x + 7, y + 8, z + 6, JourneyBlocks.dungeonBrick, 0, 3);
        world.setBlock(x + 8, y + 8, z + 6, JourneyBlocks.dungeonBrickCarved, 0, 3);
        world.setBlock(x + 3, y + 8, z + 7, JourneyBlocks.dungeonBrickCarvedStairs, 3, 3);
        world.setBlock(x + 7, y + 8, z + 7, JourneyBlocks.dungeonBrickCarvedStairs, 3, 3);
        world.setBlock(x + 3, y + 8, z + 9, JourneyBlocks.dungeonBrickCarvedStairs, 2, 3);
        world.setBlock(x + 7, y + 8, z + 9, JourneyBlocks.dungeonBrickCarvedStairs, 2, 3);
        world.setBlock(x + 2, y + 8, z + 10, JourneyBlocks.dungeonBrickCarved, 0, 3);
        world.setBlock(x + 3, y + 8, z + 10, JourneyBlocks.dungeonBrick, 0, 3);
        world.setBlock(x + 4, y + 8, z + 10, JourneyBlocks.dungeonBrick, 0, 3);
        world.setBlock(x + 6, y + 8, z + 10, JourneyBlocks.dungeonBrick, 0, 3);
        world.setBlock(x + 7, y + 8, z + 10, JourneyBlocks.dungeonBrick, 0, 3);
        world.setBlock(x + 8, y + 8, z + 10, JourneyBlocks.dungeonBrickCarved, 0, 3);
        world.setBlock(x + 3, y + 8, z + 11, JourneyBlocks.dungeonBrick, 0, 3);
        world.setBlock(x + 4, y + 8, z + 11, JourneyBlocks.dungeonBrickStairs, 5, 3);
        world.setBlock(x + 6, y + 8, z + 11, JourneyBlocks.dungeonBrickStairs, 4, 3);
        world.setBlock(x + 7, y + 8, z + 11, JourneyBlocks.dungeonBrick, 0, 3);
        world.setBlock(x + 3, y + 8, z + 12, JourneyBlocks.dungeonBrick, 0, 3);
        world.setBlock(x + 7, y + 8, z + 12, JourneyBlocks.dungeonBrick, 0, 3);
        world.setBlock(x + 3, y + 8, z + 13, JourneyBlocks.dungeonBrickCarvedStairs, 1, 3);
        world.setBlock(x + 7, y + 8, z + 13, JourneyBlocks.dungeonBrickCarvedStairs, 0, 3);
        world.setBlock(x + 2, y + 8, z + 14, JourneyBlocks.dungeonBrickCarved, 0, 3);
        world.setBlock(x + 3, y + 8, z + 14, JourneyBlocks.dungeonBrick, 0, 3);
        world.setBlock(x + 4, y + 8, z + 14, JourneyBlocks.dungeonBrick, 0, 3);
        world.setBlock(x + 5, y + 8, z + 14, JourneyBlocks.dungeonBrickCarvedStairs, 2, 3);
        world.setBlock(x + 6, y + 8, z + 14, JourneyBlocks.dungeonBrick, 0, 3);
        world.setBlock(x + 7, y + 8, z + 14, JourneyBlocks.dungeonBrick, 0, 3);
        world.setBlock(x + 8, y + 8, z + 14, JourneyBlocks.dungeonBrickCarved, 0, 3);
        world.setBlock(x + 3, y + 8, z + 15, JourneyBlocks.dungeonBrickCarved, 0, 3);
        world.setBlock(x + 7, y + 8, z + 15, JourneyBlocks.dungeonBrickCarved, 0, 3);
        world.setBlock(x + 3, y + 9, z + 1, JourneyBlocks.dungeonBrickCarvedStairs, 2, 3);
        world.setBlock(x + 7, y + 9, z + 1, JourneyBlocks.dungeonBrickCarvedStairs, 2, 3);
        world.setBlock(x + 2, y + 9, z + 2, JourneyBlocks.dungeonBrickCarvedStairs, 0, 3);
        world.setBlock(x + 3, y + 9, z + 2, JourneyBlocks.dungeonBrick, 0, 3);
        world.setBlock(x + 4, y + 9, z + 2, JourneyBlocks.dungeonBrickStairs, 0, 3);
        world.setBlock(x + 6, y + 9, z + 2, JourneyBlocks.dungeonBrickStairs, 1, 3);
        world.setBlock(x + 7, y + 9, z + 2, JourneyBlocks.dungeonBrick, 0, 3);
        world.setBlock(x + 8, y + 9, z + 2, JourneyBlocks.dungeonBrickCarvedStairs, 1, 3);
        world.setBlock(x + 3, y + 9, z + 4, JourneyBlocks.dungeonBrickCarvedStairs, 6, 3);
        world.setBlock(x + 7, y + 9, z + 4, JourneyBlocks.dungeonBrickCarvedStairs, 7, 3);
        world.setBlock(x + 3, y + 9, z + 5, JourneyBlocks.dungeonBrick, 0, 3);
        world.setBlock(x + 7, y + 9, z + 5, JourneyBlocks.dungeonBrick, 0, 3);
        world.setBlock(x + 2, y + 9, z + 6, JourneyBlocks.dungeonBrickCarvedStairs, 0, 3);
        world.setBlock(x + 3, y + 9, z + 6, JourneyBlocks.dungeonBrick, 0, 3);
        world.setBlock(x + 4, y + 9, z + 6, JourneyBlocks.dungeonBrickStairs, 0, 3);
        world.setBlock(x + 6, y + 9, z + 6, JourneyBlocks.dungeonBrickStairs, 1, 3);
        world.setBlock(x + 7, y + 9, z + 6, JourneyBlocks.dungeonBrick, 0, 3);
        world.setBlock(x + 8, y + 9, z + 6, JourneyBlocks.dungeonBrickCarvedStairs, 0, 3);
        world.setBlock(x + 2, y + 9, z + 10, JourneyBlocks.dungeonBrickCarvedStairs, 0, 3);
        world.setBlock(x + 3, y + 9, z + 10, JourneyBlocks.dungeonBrick, 0, 3);
        world.setBlock(x + 4, y + 9, z + 10, JourneyBlocks.dungeonBrickStairs, 1, 3);
        world.setBlock(x + 6, y + 9, z + 10, JourneyBlocks.dungeonBrickStairs, 0, 3);
        world.setBlock(x + 7, y + 9, z + 10, JourneyBlocks.dungeonBrick, 0, 3);
        world.setBlock(x + 8, y + 9, z + 10, JourneyBlocks.dungeonBrickCarvedStairs, 1, 3);
        world.setBlock(x + 3, y + 9, z + 11, JourneyBlocks.dungeonBrick, 0, 3);
        world.setBlock(x + 7, y + 9, z + 11, JourneyBlocks.dungeonBrick, 0, 3);
        world.setBlock(x + 3, y + 9, z + 12, JourneyBlocks.dungeonBrickCarvedStairs, 7, 3);
        world.setBlock(x + 7, y + 9, z + 12, JourneyBlocks.dungeonBrickCarvedStairs, 6, 3);
        world.setBlock(x + 2, y + 9, z + 14, JourneyBlocks.dungeonBrickCarvedStairs, 0, 3);
        world.setBlock(x + 3, y + 9, z + 14, JourneyBlocks.dungeonBrick, 0, 3);
        world.setBlock(x + 4, y + 9, z + 14, JourneyBlocks.dungeonBrickStairs, 1, 3);
        world.setBlock(x + 6, y + 9, z + 14, JourneyBlocks.dungeonBrickStairs, 0, 3);
        world.setBlock(x + 7, y + 9, z + 14, JourneyBlocks.dungeonBrick, 0, 3);
        world.setBlock(x + 8, y + 9, z + 14, JourneyBlocks.dungeonBrickCarvedStairs, 1, 3);
        world.setBlock(x + 3, y + 9, z + 15, JourneyBlocks.dungeonBrickCarvedStairs, 3, 3);
        world.setBlock(x + 7, y + 9, z + 15, JourneyBlocks.dungeonBrickCarvedStairs, 3, 3);
        world.setBlock(x + 3, y + 10, z + 2, JourneyBlocks.dungeonBrick, 0, 3);
        world.setBlock(x + 4, y + 10, z + 2, JourneyBlocks.dungeonBrick, 0, 3);
        world.setBlock(x + 5, y + 10, z + 2, JourneyBlocks.dungeonBrickCarvedStairs, 6, 3);
        world.setBlock(x + 6, y + 10, z + 2, JourneyBlocks.dungeonBrick, 0, 3);
        world.setBlock(x + 7, y + 10, z + 2, JourneyBlocks.dungeonBrick, 0, 3);
        world.setBlock(x + 3, y + 10, z + 3, JourneyBlocks.dungeonBrickCarvedStairs, 4, 3);
        world.setBlock(x + 7, y + 10, z + 3, JourneyBlocks.dungeonBrickCarvedStairs, 5, 3);
        world.setBlock(x + 3, y + 10, z + 4, JourneyBlocks.dungeonBrick, 0, 3);
        world.setBlock(x + 7, y + 10, z + 4, JourneyBlocks.dungeonBrickCarved, 0, 3);
        world.setBlock(x + 3, y + 10, z + 5, JourneyBlocks.dungeonBrickCarvedStairs, 2, 3);
        world.setBlock(x + 7, y + 10, z + 5, JourneyBlocks.dungeonBrickCarvedStairs, 3, 3);
        world.setBlock(x + 3, y + 10, z + 6, JourneyBlocks.dungeonBrick, 0, 3);
        world.setBlock(x + 4, y + 10, z + 6, JourneyBlocks.dungeonBrickStairs, 4, 3);
        world.setBlock(x + 5, y + 10, z + 6, JourneyBlocks.dungeonBrick, 0, 3);
        world.setBlock(x + 6, y + 10, z + 6, JourneyBlocks.dungeonBrickStairs, 5, 3);
        world.setBlock(x + 7, y + 10, z + 6, JourneyBlocks.dungeonBrick, 0, 3);
        world.setBlock(x + 3, y + 10, z + 7, JourneyBlocks.dungeonBrickCarvedStairs, 7, 3);
        world.setBlock(x + 7, y + 10, z + 7, JourneyBlocks.dungeonBrickCarvedStairs, 7, 3);
        if (rand.nextInt(100) < 50) {
            world.setBlock(x + 5, y + 9, z + 8, VanillaBlocks.case5, 7, 3);
        } else {
            world.setBlock(x + 5, y + 9, z + 8, VanillaBlocks.case7, 7, 3);
        }
        world.setBlock(x + 5, y + 8, z + 8, Blocks.nether_brick_fence, 7, 3);
        world.setBlock(x + 3, y + 10, z + 9, JourneyBlocks.dungeonBrickCarvedStairs, 6, 3);
        world.setBlock(x + 7, y + 10, z + 9, JourneyBlocks.dungeonBrickCarvedStairs, 6, 3);
        world.setBlock(x + 3, y + 10, z + 10, JourneyBlocks.dungeonBrick, 0, 3);
        world.setBlock(x + 4, y + 10, z + 10, JourneyBlocks.dungeonBrickStairs, 5, 3);
        world.setBlock(x + 5, y + 10, z + 10, JourneyBlocks.dungeonBrick, 0, 3);
        world.setBlock(x + 6, y + 10, z + 10, JourneyBlocks.dungeonBrickStairs, 4, 3);
        world.setBlock(x + 7, y + 10, z + 10, JourneyBlocks.dungeonBrick, 0, 3);
        world.setBlock(x + 3, y + 10, z + 11, JourneyBlocks.dungeonBrickCarvedStairs, 3, 3);
        world.setBlock(x + 7, y + 10, z + 11, JourneyBlocks.dungeonBrickCarvedStairs, 2, 3);
        world.setBlock(x + 3, y + 10, z + 12, JourneyBlocks.dungeonBrickCarved, 0, 3);
        world.setBlock(x + 7, y + 10, z + 12, JourneyBlocks.dungeonBrick, 0, 3);
        world.setBlock(x + 3, y + 10, z + 13, JourneyBlocks.dungeonBrickCarvedStairs, 5, 3);
        world.setBlock(x + 7, y + 10, z + 13, JourneyBlocks.dungeonBrickCarvedStairs, 4, 3);
        world.setBlock(x + 3, y + 10, z + 14, JourneyBlocks.dungeonBrick, 0, 3);
        world.setBlock(x + 4, y + 10, z + 14, JourneyBlocks.dungeonBrick, 0, 3);
        world.setBlock(x + 5, y + 10, z + 14, JourneyBlocks.dungeonBrickCarvedStairs, 6, 3);
        world.setBlock(x + 6, y + 10, z + 14, JourneyBlocks.dungeonBrick, 0, 3);
        world.setBlock(x + 7, y + 10, z + 14, JourneyBlocks.dungeonBrick, 0, 3);
        world.setBlock(x + 3, y + 11, z + 2, JourneyBlocks.dungeonBrick, 0, 3);
        world.setBlock(x + 4, y + 11, z + 2, JourneyBlocks.dungeonBrickCarved, 0, 3);
        world.setBlock(x + 5, y + 11, z + 2, JourneyBlocks.dungeonBrickCarved, 0, 3);
        world.setBlock(x + 6, y + 11, z + 2, JourneyBlocks.dungeonBrickCarved, 0, 3);
        world.setBlock(x + 7, y + 11, z + 2, JourneyBlocks.dungeonBrick, 0, 3);
        world.setBlock(x + 3, y + 11, z + 3, JourneyBlocks.dungeonBrickCarved, 0, 3);
        world.setBlock(x + 4, y + 11, z + 3, JourneyBlocks.brisonStone, 0, 3);
        world.setBlock(x + 5, y + 11, z + 3, JourneyBlocks.brisonStone, 0, 3);
        world.setBlock(x + 6, y + 11, z + 3, JourneyBlocks.brisonStone, 0, 3);
        world.setBlock(x + 7, y + 11, z + 3, JourneyBlocks.dungeonBrickCarved, 0, 3);
        world.setBlock(x + 3, y + 11, z + 4, JourneyBlocks.dungeonBrickCarved, 0, 3);
        world.setBlock(x + 4, y + 11, z + 4, JourneyBlocks.brisonStone, 0, 3);
        world.setBlock(x + 6, y + 11, z + 4, JourneyBlocks.brisonStone, 0, 3);
        world.setBlock(x + 7, y + 11, z + 4, JourneyBlocks.dungeonBrickCarved, 0, 3);
        world.setBlock(x + 3, y + 11, z + 5, JourneyBlocks.dungeonBrickCarved, 0, 3);
        world.setBlock(x + 4, y + 11, z + 5, JourneyBlocks.brisonStone, 0, 3);
        world.setBlock(x + 5, y + 11, z + 5, JourneyBlocks.brisonStone, 0, 3);
        world.setBlock(x + 6, y + 11, z + 5, JourneyBlocks.brisonStone, 0, 3);
        world.setBlock(x + 7, y + 11, z + 5, JourneyBlocks.dungeonBrickCarved, 0, 3);
        world.setBlock(x + 3, y + 11, z + 6, JourneyBlocks.dungeonBrick, 0, 3);
        world.setBlock(x + 4, y + 11, z + 6, JourneyBlocks.dungeonBrickCarved, 0, 3);
        world.setBlock(x + 5, y + 11, z + 6, JourneyBlocks.boilingLamp, 0, 3);
        world.setBlock(x + 6, y + 11, z + 6, JourneyBlocks.dungeonBrickCarved, 0, 3);
        world.setBlock(x + 7, y + 11, z + 6, JourneyBlocks.dungeonBrick, 0, 3);
        world.setBlock(x + 3, y + 11, z + 7, JourneyBlocks.dungeonBrick, 0, 3);
        world.setBlock(x + 4, y + 11, z + 7, JourneyBlocks.boilingLamp, 0, 3);
        world.setBlock(x + 5, y + 11, z + 7, JourneyBlocks.boilingLamp, 0, 3);
        world.setBlock(x + 6, y + 11, z + 7, JourneyBlocks.boilingLamp, 0, 3);
        world.setBlock(x + 7, y + 11, z + 7, JourneyBlocks.dungeonBrick, 0, 3);
        world.setBlock(x + 3, y + 11, z + 8, JourneyBlocks.dungeonBrick, 0, 3);
        world.setBlock(x + 5, y + 11, z + 8, JourneyBlocks.dungeonBrick, 0, 3);
        world.setBlock(x + 7, y + 11, z + 8, JourneyBlocks.dungeonBrick, 0, 3);
        world.setBlock(x + 3, y + 11, z + 9, JourneyBlocks.dungeonBrick, 0, 3);
        world.setBlock(x + 4, y + 11, z + 9, JourneyBlocks.boilingLamp, 0, 3);
        world.setBlock(x + 5, y + 11, z + 9, JourneyBlocks.boilingLamp, 0, 3);
        world.setBlock(x + 6, y + 11, z + 9, JourneyBlocks.boilingLamp, 0, 3);
        world.setBlock(x + 7, y + 11, z + 9, JourneyBlocks.dungeonBrick, 0, 3);
        world.setBlock(x + 3, y + 11, z + 10, JourneyBlocks.dungeonBrick, 0, 3);
        world.setBlock(x + 4, y + 11, z + 10, JourneyBlocks.dungeonBrickCarved, 0, 3);
        world.setBlock(x + 5, y + 11, z + 10, JourneyBlocks.boilingLamp, 0, 3);
        world.setBlock(x + 6, y + 11, z + 10, JourneyBlocks.dungeonBrickCarved, 0, 3);
        world.setBlock(x + 7, y + 11, z + 10, JourneyBlocks.dungeonBrick, 0, 3);
        world.setBlock(x + 3, y + 11, z + 11, JourneyBlocks.dungeonBrickCarved, 0, 3);
        world.setBlock(x + 4, y + 11, z + 11, JourneyBlocks.brisonStone, 0, 3);
        world.setBlock(x + 5, y + 11, z + 11, JourneyBlocks.brisonStone, 0, 3);
        world.setBlock(x + 6, y + 11, z + 11, JourneyBlocks.brisonStone, 0, 3);
        world.setBlock(x + 7, y + 11, z + 11, JourneyBlocks.dungeonBrickCarved, 0, 3);
        world.setBlock(x + 3, y + 11, z + 12, JourneyBlocks.dungeonBrickCarved, 0, 3);
        world.setBlock(x + 4, y + 11, z + 12, JourneyBlocks.brisonStone, 0, 3);
        world.setBlock(x + 6, y + 11, z + 12, JourneyBlocks.brisonStone, 0, 3);
        world.setBlock(x + 7, y + 11, z + 12, JourneyBlocks.dungeonBrickCarved, 0, 3);
        world.setBlock(x + 3, y + 11, z + 13, JourneyBlocks.dungeonBrickCarved, 0, 3);
        world.setBlock(x + 4, y + 11, z + 13, JourneyBlocks.brisonStone, 0, 3);
        world.setBlock(x + 5, y + 11, z + 13, JourneyBlocks.brisonStone, 0, 3);
        world.setBlock(x + 6, y + 11, z + 13, JourneyBlocks.brisonStone, 0, 3);
        world.setBlock(x + 7, y + 11, z + 13, JourneyBlocks.dungeonBrickCarved, 0, 3);
        world.setBlock(x + 3, y + 11, z + 14, JourneyBlocks.dungeonBrick, 0, 3);
        world.setBlock(x + 4, y + 11, z + 14, JourneyBlocks.dungeonBrickCarved, 0, 3);
        world.setBlock(x + 5, y + 11, z + 14, JourneyBlocks.dungeonBrickCarved, 0, 3);
        world.setBlock(x + 6, y + 11, z + 14, JourneyBlocks.dungeonBrickCarved, 0, 3);
        world.setBlock(x + 7, y + 11, z + 14, JourneyBlocks.dungeonBrick, 0, 3);
        world.setBlock(x + 3, y + 12, z + 1, JourneyBlocks.dungeonBrickCarvedStairs, 6, 3);
        world.setBlock(x + 7, y + 12, z + 1, JourneyBlocks.dungeonBrickCarvedStairs, 6, 3);
        world.setBlock(x + 2, y + 12, z + 2, JourneyBlocks.dungeonBrickCarvedStairs, 4, 3);
        world.setBlock(x + 3, y + 12, z + 2, JourneyBlocks.dungeonBrick, 0, 3);
        world.setBlock(x + 4, y + 12, z + 2, JourneyBlocks.dungeonBrickCarved, 0, 3);
        world.setBlock(x + 5, y + 12, z + 2, JourneyBlocks.dungeonBrickCarved, 0, 3);
        world.setBlock(x + 6, y + 12, z + 2, JourneyBlocks.dungeonBrickCarved, 0, 3);
        world.setBlock(x + 7, y + 12, z + 2, JourneyBlocks.dungeonBrick, 0, 3);
        world.setBlock(x + 8, y + 12, z + 2, JourneyBlocks.dungeonBrickCarvedStairs, 5, 3);
        world.setBlock(x + 3, y + 12, z + 3, JourneyBlocks.dungeonBrickCarved, 0, 3);
        world.setBlock(x + 7, y + 12, z + 3, JourneyBlocks.dungeonBrickCarved, 0, 3);
        world.setBlock(x + 3, y + 12, z + 4, JourneyBlocks.dungeonBrickCarved, 0, 3);
        world.setBlock(x + 7, y + 12, z + 4, JourneyBlocks.dungeonBrickCarved, 0, 3);
        world.setBlock(x + 3, y + 12, z + 5, JourneyBlocks.dungeonBrickCarved, 0, 3);
        world.setBlock(x + 7, y + 12, z + 5, JourneyBlocks.dungeonBrickCarved, 0, 3);
        world.setBlock(x + 2, y + 12, z + 6, JourneyBlocks.dungeonBrickCarvedStairs, 4, 3);
        world.setBlock(x + 3, y + 12, z + 6, JourneyBlocks.dungeonBrick, 0, 3);
        world.setBlock(x + 7, y + 12, z + 6, JourneyBlocks.dungeonBrick, 0, 3);
        world.setBlock(x + 8, y + 12, z + 6, JourneyBlocks.dungeonBrickStairs, 5, 3);
        world.setBlock(x + 3, y + 12, z + 7, JourneyBlocks.dungeonBrickCarvedStairs, 7, 3);
        world.setBlock(x + 7, y + 12, z + 7, JourneyBlocks.dungeonBrickStairs, 7, 3);
        world.setBlock(x + 3, y + 12, z + 9, JourneyBlocks.dungeonBrickStairs, 6, 3);
        world.setBlock(x + 7, y + 12, z + 9, JourneyBlocks.dungeonBrickCarvedStairs, 6, 3);
        world.setBlock(x + 2, y + 12, z + 10, JourneyBlocks.dungeonBrickStairs, 4, 3);
        world.setBlock(x + 3, y + 12, z + 10, JourneyBlocks.dungeonBrick, 0, 3);
        world.setBlock(x + 7, y + 12, z + 10, JourneyBlocks.dungeonBrick, 0, 3);
        world.setBlock(x + 8, y + 12, z + 10, JourneyBlocks.dungeonBrickCarvedStairs, 5, 3);
        world.setBlock(x + 3, y + 12, z + 11, JourneyBlocks.dungeonBrickCarved, 0, 3);
        world.setBlock(x + 7, y + 12, z + 11, JourneyBlocks.dungeonBrickCarved, 0, 3);
        world.setBlock(x + 3, y + 12, z + 12, JourneyBlocks.dungeonBrickCarved, 0, 3);
        world.setBlock(x + 7, y + 12, z + 12, JourneyBlocks.dungeonBrickCarved, 0, 3);
        world.setBlock(x + 3, y + 12, z + 13, JourneyBlocks.dungeonBrickCarved, 0, 3);
        world.setBlock(x + 7, y + 12, z + 13, JourneyBlocks.dungeonBrickCarved, 0, 3);
        world.setBlock(x + 2, y + 12, z + 14, JourneyBlocks.dungeonBrickCarvedStairs, 4, 3);
        world.setBlock(x + 3, y + 12, z + 14, JourneyBlocks.dungeonBrick, 0, 3);
        world.setBlock(x + 4, y + 12, z + 14, JourneyBlocks.dungeonBrickCarved, 0, 3);
        world.setBlock(x + 5, y + 12, z + 14, JourneyBlocks.dungeonBrickCarved, 0, 3);
        world.setBlock(x + 6, y + 12, z + 14, JourneyBlocks.dungeonBrickCarved, 0, 3);
        world.setBlock(x + 7, y + 12, z + 14, JourneyBlocks.dungeonBrick, 0, 3);
        world.setBlock(x + 8, y + 12, z + 14, JourneyBlocks.dungeonBrickCarvedStairs, 5, 3);
        world.setBlock(x + 3, y + 12, z + 15, JourneyBlocks.dungeonBrickCarvedStairs, 7, 3);
        world.setBlock(x + 7, y + 12, z + 15, JourneyBlocks.dungeonBrickCarvedStairs, 7, 3);
        world.setBlock(x + 3, y + 13, z + 1, JourneyBlocks.dungeonBrickCarvedStairs, 2, 3);
        world.setBlock(x + 7, y + 13, z + 1, JourneyBlocks.dungeonBrickCarvedStairs, 2, 3);
        world.setBlock(x + 2, y + 13, z + 2, JourneyBlocks.dungeonBrickCarvedStairs, 0, 3);
        world.setBlock(x + 3, y + 13, z + 2, JourneyBlocks.dungeonBrick, 0, 3);
        world.setBlock(x + 4, y + 13, z + 2, JourneyBlocks.dungeonBrickStairs, 1, 3);
        world.setBlock(x + 5, y + 13, z + 2, JourneyBlocks.dungeonBrickStairs, 2, 3);
        world.setBlock(x + 6, y + 13, z + 2, JourneyBlocks.dungeonBrickStairs, 0, 3);
        world.setBlock(x + 7, y + 13, z + 2, JourneyBlocks.dungeonBrick, 0, 3);
        world.setBlock(x + 8, y + 13, z + 2, JourneyBlocks.dungeonBrickCarvedStairs, 1, 3);
        world.setBlock(x + 3, y + 13, z + 3, JourneyBlocks.dungeonBrickStairs, 3, 3);
        world.setBlock(x + 7, y + 13, z + 3, JourneyBlocks.dungeonBrickStairs, 3, 3);
        world.setBlock(x + 3, y + 13, z + 4, JourneyBlocks.dungeonBrickStairs, 0, 3);
        world.setBlock(x + 7, y + 13, z + 4, JourneyBlocks.dungeonBrickStairs, 1, 3);
        world.setBlock(x + 3, y + 13, z + 5, JourneyBlocks.dungeonBrickStairs, 2, 3);
        world.setBlock(x + 7, y + 13, z + 5, JourneyBlocks.dungeonBrickStairs, 2, 3);
        world.setBlock(x + 2, y + 13, z + 6, JourneyBlocks.dungeonBrickCarvedStairs, 0, 3);
        world.setBlock(x + 3, y + 13, z + 6, JourneyBlocks.dungeonBrick, 0, 3);
        world.setBlock(x + 7, y + 13, z + 6, JourneyBlocks.dungeonBrickCarved, 0, 3);
        world.setBlock(x + 8, y + 13, z + 6, JourneyBlocks.dungeonBrickStairs, 1, 3);
        world.setBlock(x + 3, y + 13, z + 7, JourneyBlocks.dungeonBrickCarvedStairs, 3, 3);
        world.setBlock(x + 7, y + 13, z + 7, JourneyBlocks.dungeonBrickStairs, 3, 3);
        world.setBlock(x + 3, y + 13, z + 9, JourneyBlocks.dungeonBrickStairs, 2, 3);
        world.setBlock(x + 7, y + 13, z + 9, JourneyBlocks.dungeonBrickCarvedStairs, 2, 3);
        world.setBlock(x + 2, y + 13, z + 10, JourneyBlocks.dungeonBrickStairs, 0, 3);
        world.setBlock(x + 3, y + 13, z + 10, JourneyBlocks.dungeonBrickCarved, 0, 3);
        world.setBlock(x + 7, y + 13, z + 10, JourneyBlocks.dungeonBrick, 0, 3);
        world.setBlock(x + 8, y + 13, z + 10, JourneyBlocks.dungeonBrickCarvedStairs, 1, 3);
        world.setBlock(x + 3, y + 13, z + 11, JourneyBlocks.dungeonBrickStairs, 3, 3);
        world.setBlock(x + 7, y + 13, z + 11, JourneyBlocks.dungeonBrickStairs, 3, 3);
        world.setBlock(x + 3, y + 13, z + 12, JourneyBlocks.dungeonBrickStairs, 0, 3);
        world.setBlock(x + 7, y + 13, z + 12, JourneyBlocks.dungeonBrickStairs, 1, 3);
        world.setBlock(x + 3, y + 13, z + 13, JourneyBlocks.dungeonBrickStairs, 2, 3);
        world.setBlock(x + 7, y + 13, z + 13, JourneyBlocks.dungeonBrickStairs, 2, 3);
        world.setBlock(x + 2, y + 13, z + 14, JourneyBlocks.dungeonBrickCarvedStairs, 0, 3);
        world.setBlock(x + 3, y + 13, z + 14, JourneyBlocks.dungeonBrick, 0, 3);
        world.setBlock(x + 4, y + 13, z + 14, JourneyBlocks.dungeonBrickStairs, 1, 3);
        world.setBlock(x + 5, y + 13, z + 14, JourneyBlocks.dungeonBrickStairs, 3, 3);
        world.setBlock(x + 6, y + 13, z + 14, JourneyBlocks.dungeonBrickStairs, 0, 3);
        world.setBlock(x + 7, y + 13, z + 14, JourneyBlocks.dungeonBrick, 0, 3);
        world.setBlock(x + 8, y + 13, z + 14, JourneyBlocks.dungeonBrickCarvedStairs, 1, 3);
        world.setBlock(x + 3, y + 13, z + 15, JourneyBlocks.dungeonBrickCarvedStairs, 3, 3);
        world.setBlock(x + 7, y + 13, z + 15, JourneyBlocks.dungeonBrickCarvedStairs, 3, 3);
        world.setBlock(x + 3, y + 14, z + 2, JourneyBlocks.boilingLamp, 0, 3);
        world.setBlock(x + 4, y + 14, z + 2, JourneyBlocks.dungeonBrickCarved, 0, 3);
        world.setBlock(x + 5, y + 14, z + 2, JourneyBlocks.dungeonBrickStairs, 6, 3);
        world.setBlock(x + 6, y + 14, z + 2, JourneyBlocks.dungeonBrickCarved, 0, 3);
        world.setBlock(x + 7, y + 14, z + 2, JourneyBlocks.boilingLamp, 0, 3);
        world.setBlock(x + 3, y + 14, z + 3, JourneyBlocks.dungeonBrickCarved, 0, 3);
        world.setBlock(x + 7, y + 14, z + 3, JourneyBlocks.dungeonBrickCarved, 0, 3);
        world.setBlock(x + 3, y + 14, z + 4, JourneyBlocks.dungeonBrickStairs, 4, 3);
        world.setBlock(x + 7, y + 14, z + 4, JourneyBlocks.dungeonBrickStairs, 5, 3);
        world.setBlock(x + 3, y + 14, z + 5, JourneyBlocks.dungeonBrickCarved, 0, 3);
        world.setBlock(x + 7, y + 14, z + 5, JourneyBlocks.dungeonBrickCarved, 0, 3);
        world.setBlock(x + 3, y + 14, z + 11, JourneyBlocks.dungeonBrickCarved, 0, 3);
        world.setBlock(x + 7, y + 14, z + 11, JourneyBlocks.dungeonBrickCarved, 0, 3);
        world.setBlock(x + 3, y + 14, z + 12, JourneyBlocks.dungeonBrickStairs, 4, 3);
        world.setBlock(x + 7, y + 14, z + 12, JourneyBlocks.dungeonBrickStairs, 5, 3);
        world.setBlock(x + 3, y + 14, z + 13, JourneyBlocks.dungeonBrickCarved, 0, 3);
        world.setBlock(x + 7, y + 14, z + 13, JourneyBlocks.dungeonBrickCarved, 0, 3);
        world.setBlock(x + 3, y + 14, z + 14, JourneyBlocks.boilingLamp, 0, 3);
        world.setBlock(x + 4, y + 14, z + 14, JourneyBlocks.dungeonBrickCarved, 0, 3);
        world.setBlock(x + 5, y + 14, z + 14, JourneyBlocks.dungeonBrickStairs, 7, 3);
        world.setBlock(x + 6, y + 14, z + 14, JourneyBlocks.dungeonBrickCarved, 0, 3);
        world.setBlock(x + 7, y + 14, z + 14, JourneyBlocks.boilingLamp, 0, 3);
        world.setBlock(x + 4, y + 15, z + 2, JourneyBlocks.dungeonBrick, 0, 3);
        world.setBlock(x + 5, y + 15, z + 2, JourneyBlocks.dungeonBrickStairs, 2, 3);
        world.setBlock(x + 6, y + 15, z + 2, JourneyBlocks.dungeonBrick, 0, 3);
        world.setBlock(x + 3, y + 15, z + 3, JourneyBlocks.dungeonBrick, 0, 3);
        world.setBlock(x + 7, y + 15, z + 3, JourneyBlocks.dungeonBrick, 0, 3);
        world.setBlock(x + 3, y + 15, z + 4, JourneyBlocks.dungeonBrickStairs, 0, 3);
        world.setBlock(x + 7, y + 15, z + 4, JourneyBlocks.dungeonBrickStairs, 1, 3);
        world.setBlock(x + 3, y + 15, z + 5, JourneyBlocks.boilingLamp, 0, 3);
        world.setBlock(x + 7, y + 15, z + 5, JourneyBlocks.boilingLamp, 0, 3);
        world.setBlock(x + 3, y + 15, z + 11, JourneyBlocks.boilingLamp, 0, 3);
        world.setBlock(x + 7, y + 15, z + 11, JourneyBlocks.boilingLamp, 0, 3);
        world.setBlock(x + 3, y + 15, z + 12, JourneyBlocks.dungeonBrickStairs, 0, 3);
        world.setBlock(x + 7, y + 15, z + 12, JourneyBlocks.dungeonBrickStairs, 0, 3);
        world.setBlock(x + 3, y + 15, z + 13, JourneyBlocks.dungeonBrick, 0, 3);
        world.setBlock(x + 7, y + 15, z + 13, JourneyBlocks.dungeonBrick, 0, 3);
        world.setBlock(x + 4, y + 15, z + 14, JourneyBlocks.dungeonBrick, 0, 3);
        world.setBlock(x + 5, y + 15, z + 14, JourneyBlocks.dungeonBrickStairs, 2, 3);
        world.setBlock(x + 6, y + 15, z + 14, JourneyBlocks.dungeonBrick, 0, 3);
        world.setBlock(x + 4, y + 16, z + 2, JourneyBlocks.dungeonBrickStairs, 3, 3);
        world.setBlock(x + 6, y + 16, z + 2, JourneyBlocks.dungeonBrickStairs, 3, 3);
        world.setBlock(x + 3, y + 16, z + 3, JourneyBlocks.dungeonBrickStairs, 1, 3);
        world.setBlock(x + 7, y + 16, z + 3, JourneyBlocks.dungeonBrickStairs, 0, 3);
        world.setBlock(x + 3, y + 16, z + 5, JourneyBlocks.dungeonBrickStairs, 1, 3);
        world.setBlock(x + 7, y + 16, z + 5, JourneyBlocks.dungeonBrickStairs, 0, 3);
        world.setBlock(x + 3, y + 16, z + 11, JourneyBlocks.dungeonBrickStairs, 1, 3);
        world.setBlock(x + 7, y + 16, z + 11, JourneyBlocks.dungeonBrickStairs, 0, 3);
        world.setBlock(x + 3, y + 16, z + 13, JourneyBlocks.dungeonBrickStairs, 1, 3);
        world.setBlock(x + 7, y + 16, z + 13, JourneyBlocks.dungeonBrickStairs, 0, 3);
        world.setBlock(x + 4, y + 16, z + 14, JourneyBlocks.dungeonBrickStairs, 2, 3);
        world.setBlock(x + 6, y + 16, z + 14, JourneyBlocks.dungeonBrickStairs, 2, 3);
        if (!world.isRemote) {
            EntityBoilTrader smith = new EntityBoilTrader(world);
            smith.setLocationAndAngles(x + 6, y + 8, z + 12, 0.0f, 0.0f);
            world.spawnEntityInWorld((Entity)smith);
        }
        return true;
    }
}

