/*
 * Decompiled with CFR 0.152.
 * 
 * Could not load the following classes:
 *  net.minecraft.world.World
 *  net.minecraft.world.gen.feature.WorldGenerator
 */
package net.divinerpg.dimensions.boiling.gen;

import java.util.Random;
import net.divinerpg.utils.blocks.JourneyBlocks;
import net.minecraft.world.World;
import net.minecraft.world.gen.feature.WorldGenerator;

public class WorldGenIsland
extends WorldGenerator {
    public boolean generate(World world, Random rand, int x, int y, int z) {
        int i = x;
        int j = y;
        int k = z;
        world.setBlock(i + 1, j + 4, k + 4, JourneyBlocks.hotBlock);
        world.setBlock(i + 1, j + 4, k + 5, JourneyBlocks.hotBlock);
        world.setBlock(i + 2, j + 3, k + 5, JourneyBlocks.ash);
        world.setBlock(i + 2, j + 3, k + 6, JourneyBlocks.ash);
        world.setBlock(i + 2, j + 4, k + 3, JourneyBlocks.hotBlock);
        world.setBlock(i + 2, j + 4, k + 4, JourneyBlocks.hotBlock);
        world.setBlock(i + 2, j + 4, k + 5, JourneyBlocks.hotBlock);
        world.setBlock(i + 2, j + 4, k + 6, JourneyBlocks.hotBlock);
        world.setBlock(i + 2, j + 4, k + 7, JourneyBlocks.hotBlock);
        world.setBlock(i + 3, j + 2, k + 5, JourneyBlocks.ash);
        world.setBlock(i + 3, j + 2, k + 6, JourneyBlocks.hotBlock);
        world.setBlock(i + 3, j + 3, k + 3, JourneyBlocks.ash);
        world.setBlock(i + 3, j + 3, k + 4, JourneyBlocks.ash);
        world.setBlock(i + 3, j + 3, k + 5, JourneyBlocks.ash);
        world.setBlock(i + 3, j + 3, k + 6, JourneyBlocks.ash);
        world.setBlock(i + 3, j + 3, k + 7, JourneyBlocks.ash);
        world.setBlock(i + 3, j + 4, k + 2, JourneyBlocks.hotBlock);
        world.setBlock(i + 3, j + 4, k + 3, JourneyBlocks.hotBlock);
        world.setBlock(i + 3, j + 4, k + 4, JourneyBlocks.hotBlock);
        world.setBlock(i + 3, j + 4, k + 5, JourneyBlocks.hotBlock);
        world.setBlock(i + 3, j + 4, k + 6, JourneyBlocks.hotBlock);
        world.setBlock(i + 3, j + 4, k + 7, JourneyBlocks.hotBlock);
        world.setBlock(i + 3, j + 4, k + 8, JourneyBlocks.hotBlock);
        world.setBlock(i + 4, j + 2, k + 4, JourneyBlocks.ash);
        world.setBlock(i + 4, j + 2, k + 5, JourneyBlocks.hotBlock);
        world.setBlock(i + 4, j + 2, k + 6, JourneyBlocks.hotBlock);
        world.setBlock(i + 4, j + 2, k + 7, JourneyBlocks.ash);
        world.setBlock(i + 4, j + 3, k + 3, JourneyBlocks.ash);
        world.setBlock(i + 4, j + 3, k + 4, JourneyBlocks.ash);
        world.setBlock(i + 4, j + 3, k + 5, JourneyBlocks.ash);
        world.setBlock(i + 4, j + 3, k + 6, JourneyBlocks.ash);
        world.setBlock(i + 4, j + 3, k + 7, JourneyBlocks.ash);
        world.setBlock(i + 4, j + 4, k + 2, JourneyBlocks.hotBlock);
        world.setBlock(i + 4, j + 4, k + 3, JourneyBlocks.hotBlock);
        world.setBlock(i + 4, j + 4, k + 4, JourneyBlocks.hotBlock);
        world.setBlock(i + 4, j + 4, k + 5, JourneyBlocks.hotBlock);
        world.setBlock(i + 4, j + 4, k + 6, JourneyBlocks.hotBlock);
        world.setBlock(i + 4, j + 4, k + 7, JourneyBlocks.hotBlock);
        world.setBlock(i + 4, j + 4, k + 8, JourneyBlocks.hotBlock);
        world.setBlock(i + 4, j + 4, k + 9, JourneyBlocks.hotBlock);
        world.setBlock(i + 5, j + 1, k + 5, JourneyBlocks.hotBlock);
        world.setBlock(i + 5, j + 1, k + 6, JourneyBlocks.hotBlock);
        world.setBlock(i + 5, j + 2, k + 3, JourneyBlocks.hotBlock);
        world.setBlock(i + 5, j + 2, k + 4, JourneyBlocks.hotBlock);
        world.setBlock(i + 5, j + 2, k + 5, JourneyBlocks.hotBlock);
        world.setBlock(i + 5, j + 2, k + 6, JourneyBlocks.hotBlock);
        world.setBlock(i + 5, j + 2, k + 7, JourneyBlocks.hotBlock);
        world.setBlock(i + 5, j + 2, k + 8, JourneyBlocks.ash);
        world.setBlock(i + 5, j + 3, k + 2, JourneyBlocks.ash);
        world.setBlock(i + 5, j + 3, k + 3, JourneyBlocks.ash);
        world.setBlock(i + 5, j + 3, k + 4, JourneyBlocks.ash);
        world.setBlock(i + 5, j + 3, k + 5, JourneyBlocks.ash);
        world.setBlock(i + 5, j + 3, k + 6, JourneyBlocks.ash);
        world.setBlock(i + 5, j + 3, k + 7, JourneyBlocks.ash);
        world.setBlock(i + 5, j + 3, k + 8, JourneyBlocks.ash);
        world.setBlock(i + 5, j + 4, k + 1, JourneyBlocks.hotBlock);
        world.setBlock(i + 5, j + 4, k + 2, JourneyBlocks.hotBlock);
        world.setBlock(i + 5, j + 4, k + 3, JourneyBlocks.hotBlock);
        world.setBlock(i + 5, j + 4, k + 4, JourneyBlocks.hotBlock);
        world.setBlock(i + 5, j + 4, k + 5, JourneyBlocks.hotBlock);
        world.setBlock(i + 5, j + 4, k + 6, JourneyBlocks.hotBlock);
        world.setBlock(i + 5, j + 4, k + 7, JourneyBlocks.hotBlock);
        world.setBlock(i + 5, j + 4, k + 8, JourneyBlocks.hotBlock);
        world.setBlock(i + 5, j + 4, k + 9, JourneyBlocks.hotBlock);
        world.setBlock(i + 6, j + 0, k + 5, JourneyBlocks.hotBlock);
        world.setBlock(i + 6, j + 1, k + 4, JourneyBlocks.hotBlock);
        world.setBlock(i + 6, j + 1, k + 5, JourneyBlocks.hotBlock);
        world.setBlock(i + 6, j + 1, k + 6, JourneyBlocks.hotBlock);
        world.setBlock(i + 6, j + 1, k + 7, JourneyBlocks.hotBlock);
        world.setBlock(i + 6, j + 2, k + 2, JourneyBlocks.ash);
        world.setBlock(i + 6, j + 2, k + 3, JourneyBlocks.hotBlock);
        world.setBlock(i + 6, j + 2, k + 4, JourneyBlocks.hotBlock);
        world.setBlock(i + 6, j + 2, k + 5, JourneyBlocks.hotBlock);
        world.setBlock(i + 6, j + 2, k + 6, JourneyBlocks.hotBlock);
        world.setBlock(i + 6, j + 2, k + 7, JourneyBlocks.hotBlock);
        world.setBlock(i + 6, j + 2, k + 8, JourneyBlocks.hotBlock);
        world.setBlock(i + 6, j + 3, k + 1, JourneyBlocks.ash);
        world.setBlock(i + 6, j + 3, k + 2, JourneyBlocks.ash);
        world.setBlock(i + 6, j + 3, k + 3, JourneyBlocks.ash);
        world.setBlock(i + 6, j + 3, k + 4, JourneyBlocks.ash);
        world.setBlock(i + 6, j + 3, k + 5, JourneyBlocks.ash);
        world.setBlock(i + 6, j + 3, k + 6, JourneyBlocks.ash);
        world.setBlock(i + 6, j + 3, k + 7, JourneyBlocks.ash);
        world.setBlock(i + 6, j + 3, k + 8, JourneyBlocks.ash);
        world.setBlock(i + 6, j + 3, k + 9, JourneyBlocks.ash);
        world.setBlock(i + 6, j + 4, k + 0, JourneyBlocks.hotBlock);
        world.setBlock(i + 6, j + 4, k + 1, JourneyBlocks.hotBlock);
        world.setBlock(i + 6, j + 4, k + 2, JourneyBlocks.hotBlock);
        world.setBlock(i + 6, j + 4, k + 3, JourneyBlocks.hotBlock);
        world.setBlock(i + 6, j + 4, k + 4, JourneyBlocks.hotBlock);
        world.setBlock(i + 6, j + 4, k + 5, JourneyBlocks.hotBlock);
        world.setBlock(i + 6, j + 4, k + 6, JourneyBlocks.hotBlock);
        world.setBlock(i + 6, j + 4, k + 7, JourneyBlocks.hotBlock);
        world.setBlock(i + 6, j + 4, k + 8, JourneyBlocks.hotBlock);
        world.setBlock(i + 6, j + 4, k + 9, JourneyBlocks.hotBlock);
        world.setBlock(i + 6, j + 4, k + 10, JourneyBlocks.hotBlock);
        world.setBlock(i + 7, j + 1, k + 5, JourneyBlocks.hotBlock);
        world.setBlock(i + 7, j + 1, k + 6, JourneyBlocks.hotBlock);
        world.setBlock(i + 7, j + 2, k + 2, JourneyBlocks.hotBlock);
        world.setBlock(i + 7, j + 2, k + 3, JourneyBlocks.hotBlock);
        world.setBlock(i + 7, j + 2, k + 4, JourneyBlocks.hotBlock);
        world.setBlock(i + 7, j + 2, k + 5, JourneyBlocks.hotBlock);
        world.setBlock(i + 7, j + 2, k + 6, JourneyBlocks.hotBlock);
        world.setBlock(i + 7, j + 2, k + 7, JourneyBlocks.hotBlock);
        world.setBlock(i + 7, j + 3, k + 1, JourneyBlocks.ash);
        world.setBlock(i + 7, j + 3, k + 2, JourneyBlocks.ash);
        world.setBlock(i + 7, j + 3, k + 3, JourneyBlocks.ash);
        world.setBlock(i + 7, j + 3, k + 4, JourneyBlocks.ash);
        world.setBlock(i + 7, j + 3, k + 5, JourneyBlocks.ash);
        world.setBlock(i + 7, j + 3, k + 6, JourneyBlocks.ash);
        world.setBlock(i + 7, j + 3, k + 7, JourneyBlocks.ash);
        world.setBlock(i + 7, j + 3, k + 8, JourneyBlocks.ash);
        world.setBlock(i + 7, j + 4, k + 0, JourneyBlocks.hotBlock);
        world.setBlock(i + 7, j + 4, k + 1, JourneyBlocks.hotBlock);
        world.setBlock(i + 7, j + 4, k + 2, JourneyBlocks.hotBlock);
        world.setBlock(i + 7, j + 4, k + 3, JourneyBlocks.hotBlock);
        world.setBlock(i + 7, j + 4, k + 4, JourneyBlocks.hotBlock);
        world.setBlock(i + 7, j + 4, k + 5, JourneyBlocks.hotBlock);
        world.setBlock(i + 7, j + 4, k + 6, JourneyBlocks.hotBlock);
        world.setBlock(i + 7, j + 4, k + 7, JourneyBlocks.hotBlock);
        world.setBlock(i + 7, j + 4, k + 8, JourneyBlocks.hotBlock);
        world.setBlock(i + 7, j + 4, k + 9, JourneyBlocks.hotBlock);
        world.setBlock(i + 7, j + 4, k + 10, JourneyBlocks.hotBlock);
        world.setBlock(i + 8, j + 1, k + 5, JourneyBlocks.hotBlock);
        world.setBlock(i + 8, j + 2, k + 3, JourneyBlocks.ash);
        world.setBlock(i + 8, j + 2, k + 4, JourneyBlocks.hotBlock);
        world.setBlock(i + 8, j + 2, k + 5, JourneyBlocks.hotBlock);
        world.setBlock(i + 8, j + 2, k + 6, JourneyBlocks.hotBlock);
        world.setBlock(i + 8, j + 2, k + 7, JourneyBlocks.ash);
        world.setBlock(i + 8, j + 3, k + 2, JourneyBlocks.ash);
        world.setBlock(i + 8, j + 3, k + 3, JourneyBlocks.ash);
        world.setBlock(i + 8, j + 3, k + 4, JourneyBlocks.ash);
        world.setBlock(i + 8, j + 3, k + 5, JourneyBlocks.ash);
        world.setBlock(i + 8, j + 3, k + 6, JourneyBlocks.ash);
        world.setBlock(i + 8, j + 3, k + 7, JourneyBlocks.ash);
        world.setBlock(i + 8, j + 4, k + 1, JourneyBlocks.hotBlock);
        world.setBlock(i + 8, j + 4, k + 2, JourneyBlocks.hotBlock);
        world.setBlock(i + 8, j + 4, k + 3, JourneyBlocks.hotBlock);
        world.setBlock(i + 8, j + 4, k + 4, JourneyBlocks.hotBlock);
        world.setBlock(i + 8, j + 4, k + 5, JourneyBlocks.hotBlock);
        world.setBlock(i + 8, j + 4, k + 6, JourneyBlocks.hotBlock);
        world.setBlock(i + 8, j + 4, k + 7, JourneyBlocks.hotBlock);
        world.setBlock(i + 8, j + 4, k + 8, JourneyBlocks.hotBlock);
        world.setBlock(i + 8, j + 4, k + 9, JourneyBlocks.hotBlock);
        world.setBlock(i + 9, j + 2, k + 4, JourneyBlocks.ash);
        world.setBlock(i + 9, j + 2, k + 5, JourneyBlocks.hotBlock);
        world.setBlock(i + 9, j + 3, k + 3, JourneyBlocks.ash);
        world.setBlock(i + 9, j + 3, k + 4, JourneyBlocks.ash);
        world.setBlock(i + 9, j + 3, k + 5, JourneyBlocks.ash);
        world.setBlock(i + 9, j + 3, k + 6, JourneyBlocks.ash);
        world.setBlock(i + 9, j + 3, k + 7, JourneyBlocks.ash);
        world.setBlock(i + 9, j + 4, k + 2, JourneyBlocks.hotBlock);
        world.setBlock(i + 9, j + 4, k + 3, JourneyBlocks.hotBlock);
        world.setBlock(i + 9, j + 4, k + 4, JourneyBlocks.hotBlock);
        world.setBlock(i + 9, j + 4, k + 5, JourneyBlocks.hotBlock);
        world.setBlock(i + 9, j + 4, k + 6, JourneyBlocks.hotBlock);
        world.setBlock(i + 9, j + 4, k + 7, JourneyBlocks.hotBlock);
        world.setBlock(i + 9, j + 4, k + 8, JourneyBlocks.hotBlock);
        world.setBlock(i + 10, j + 3, k + 4, JourneyBlocks.ash);
        world.setBlock(i + 10, j + 3, k + 5, JourneyBlocks.ash);
        world.setBlock(i + 10, j + 4, k + 3, JourneyBlocks.hotBlock);
        world.setBlock(i + 10, j + 4, k + 4, JourneyBlocks.hotBlock);
        world.setBlock(i + 10, j + 4, k + 5, JourneyBlocks.hotBlock);
        world.setBlock(i + 10, j + 4, k + 6, JourneyBlocks.hotBlock);
        world.setBlock(i + 10, j + 4, k + 7, JourneyBlocks.hotBlock);
        world.setBlock(i + 11, j + 4, k + 5, JourneyBlocks.hotBlock);
        return true;
    }
}

