/*
 * Decompiled with CFR 0.152.
 * 
 * Could not load the following classes:
 *  net.minecraft.block.Block
 */
package net.divinerpg.dimensions.arcana.components;

import java.util.Random;
import net.divinerpg.dimensions.arcana.ChunkPrimer;
import net.divinerpg.dimensions.arcana.components.DungeonComponentBase;
import net.divinerpg.utils.blocks.ArcanaBlocks;
import net.minecraft.block.Block;

public class DungeonComponent13
extends DungeonComponentBase {
    @Override
    public boolean generate(ChunkPrimer chunkPrimer, Random rand, int i, int j, int k) {
        Block heatTraps = ArcanaBlocks.heatTrap;
        Block dungeonBricks = ArcanaBlocks.degradedBrick;
        Block ancientbricks = ArcanaBlocks.ancientBrick;
        Block ancientstone = ArcanaBlocks.ancientStone;
        Block arcaniteMetal = ArcanaBlocks.arcaniumMetal;
        Block ancientTile = ArcanaBlocks.ancientTile;
        Block arcanaPower = ArcanaBlocks.arcaniumPower;
        chunkPrimer.setBlock(i + 0, j + 0, k + 0, dungeonBricks);
        chunkPrimer.setBlock(i + 0, j + 0, k + 1, dungeonBricks);
        chunkPrimer.setBlock(i + 0, j + 0, k + 2, dungeonBricks);
        chunkPrimer.setBlock(i + 0, j + 0, k + 3, dungeonBricks);
        chunkPrimer.setBlock(i + 0, j + 0, k + 4, dungeonBricks);
        chunkPrimer.setBlock(i + 0, j + 0, k + 5, dungeonBricks);
        chunkPrimer.setBlock(i + 0, j + 0, k + 6, dungeonBricks);
        chunkPrimer.setBlock(i + 0, j + 0, k + 7, dungeonBricks);
        chunkPrimer.setBlock(i + 0, j + 0, k + 8, dungeonBricks);
        chunkPrimer.setBlock(i + 0, j + 0, k + 9, dungeonBricks);
        chunkPrimer.setBlock(i + 0, j + 0, k + 10, dungeonBricks);
        chunkPrimer.setBlock(i + 0, j + 0, k + 11, dungeonBricks);
        chunkPrimer.setBlock(i + 0, j + 0, k + 12, dungeonBricks);
        chunkPrimer.setBlock(i + 0, j + 0, k + 13, dungeonBricks);
        chunkPrimer.setBlock(i + 0, j + 0, k + 14, dungeonBricks);
        chunkPrimer.setBlock(i + 0, j + 0, k + 15, dungeonBricks);
        chunkPrimer.setBlock(i + 0, j + 1, k + 0, ancientstone);
        chunkPrimer.setBlock(i + 0, j + 1, k + 1, ancientstone);
        chunkPrimer.setBlock(i + 0, j + 1, k + 2, ancientstone);
        chunkPrimer.setBlock(i + 0, j + 1, k + 3, dungeonBricks);
        chunkPrimer.setBlock(i + 0, j + 1, k + 4, dungeonBricks);
        chunkPrimer.setBlock(i + 0, j + 1, k + 5, dungeonBricks);
        chunkPrimer.setBlock(i + 0, j + 1, k + 6, ancientstone);
        chunkPrimer.setBlock(i + 0, j + 1, k + 7, ancientstone);
        chunkPrimer.setBlock(i + 0, j + 1, k + 8, ancientstone);
        chunkPrimer.setBlock(i + 0, j + 1, k + 9, ancientstone);
        chunkPrimer.setBlock(i + 0, j + 1, k + 10, ancientstone);
        chunkPrimer.setBlock(i + 0, j + 1, k + 11, ancientstone);
        chunkPrimer.setBlock(i + 0, j + 1, k + 12, ancientstone);
        chunkPrimer.setBlock(i + 0, j + 1, k + 13, dungeonBricks);
        chunkPrimer.setBlock(i + 0, j + 1, k + 14, dungeonBricks);
        chunkPrimer.setBlock(i + 0, j + 1, k + 15, dungeonBricks);
        chunkPrimer.setBlock(i + 0, j + 2, k + 0, ancientstone);
        chunkPrimer.setBlock(i + 0, j + 2, k + 1, dungeonBricks);
        chunkPrimer.setBlock(i + 0, j + 2, k + 2, dungeonBricks);
        chunkPrimer.setBlock(i + 0, j + 2, k + 3, dungeonBricks);
        chunkPrimer.setBlock(i + 0, j + 2, k + 4, ancientstone);
        chunkPrimer.setBlock(i + 0, j + 2, k + 5, dungeonBricks);
        chunkPrimer.setBlock(i + 0, j + 2, k + 6, dungeonBricks);
        chunkPrimer.setBlock(i + 0, j + 2, k + 7, dungeonBricks);
        chunkPrimer.setBlock(i + 0, j + 2, k + 8, ancientstone);
        chunkPrimer.setBlock(i + 0, j + 2, k + 9, dungeonBricks);
        chunkPrimer.setBlock(i + 0, j + 2, k + 10, dungeonBricks);
        chunkPrimer.setBlock(i + 0, j + 2, k + 11, dungeonBricks);
        chunkPrimer.setBlock(i + 0, j + 2, k + 12, dungeonBricks);
        chunkPrimer.setBlock(i + 0, j + 2, k + 13, dungeonBricks);
        chunkPrimer.setBlock(i + 0, j + 2, k + 14, ancientstone);
        chunkPrimer.setBlock(i + 0, j + 2, k + 15, ancientstone);
        chunkPrimer.setBlock(i + 0, j + 3, k + 0, dungeonBricks);
        chunkPrimer.setBlock(i + 0, j + 3, k + 1, dungeonBricks);
        chunkPrimer.setBlock(i + 0, j + 3, k + 2, ancientstone);
        chunkPrimer.setBlock(i + 0, j + 3, k + 3, ancientstone);
        chunkPrimer.setBlock(i + 0, j + 3, k + 4, ancientstone);
        chunkPrimer.setBlock(i + 0, j + 3, k + 5, ancientstone);
        chunkPrimer.setBlock(i + 0, j + 3, k + 6, ancientstone);
        chunkPrimer.setBlock(i + 0, j + 3, k + 7, dungeonBricks);
        chunkPrimer.setBlock(i + 0, j + 3, k + 8, dungeonBricks);
        chunkPrimer.setBlock(i + 0, j + 3, k + 9, dungeonBricks);
        chunkPrimer.setBlock(i + 0, j + 3, k + 10, ancientstone);
        chunkPrimer.setBlock(i + 0, j + 3, k + 11, dungeonBricks);
        chunkPrimer.setBlock(i + 0, j + 3, k + 12, dungeonBricks);
        chunkPrimer.setBlock(i + 0, j + 3, k + 13, dungeonBricks);
        chunkPrimer.setBlock(i + 0, j + 3, k + 14, ancientstone);
        chunkPrimer.setBlock(i + 0, j + 3, k + 15, ancientstone);
        chunkPrimer.setBlock(i + 0, j + 4, k + 0, dungeonBricks);
        chunkPrimer.setBlock(i + 0, j + 4, k + 1, dungeonBricks);
        chunkPrimer.setBlock(i + 0, j + 4, k + 2, dungeonBricks);
        chunkPrimer.setBlock(i + 0, j + 4, k + 3, dungeonBricks);
        chunkPrimer.setBlock(i + 0, j + 4, k + 4, dungeonBricks);
        chunkPrimer.setBlock(i + 0, j + 4, k + 5, dungeonBricks);
        chunkPrimer.setBlock(i + 0, j + 4, k + 6, dungeonBricks);
        chunkPrimer.setBlock(i + 0, j + 4, k + 7, dungeonBricks);
        chunkPrimer.setBlock(i + 0, j + 4, k + 8, dungeonBricks);
        chunkPrimer.setBlock(i + 0, j + 4, k + 9, dungeonBricks);
        chunkPrimer.setBlock(i + 0, j + 4, k + 10, dungeonBricks);
        chunkPrimer.setBlock(i + 0, j + 4, k + 11, dungeonBricks);
        chunkPrimer.setBlock(i + 0, j + 4, k + 12, dungeonBricks);
        chunkPrimer.setBlock(i + 0, j + 4, k + 13, dungeonBricks);
        chunkPrimer.setBlock(i + 0, j + 4, k + 14, dungeonBricks);
        chunkPrimer.setBlock(i + 0, j + 4, k + 15, dungeonBricks);
        chunkPrimer.setBlock(i + 0, j + 5, k + 0, dungeonBricks);
        chunkPrimer.setBlock(i + 0, j + 5, k + 1, dungeonBricks);
        chunkPrimer.setBlock(i + 0, j + 5, k + 2, dungeonBricks);
        chunkPrimer.setBlock(i + 0, j + 5, k + 3, ancientbricks);
        chunkPrimer.setBlock(i + 0, j + 5, k + 4, ancientbricks);
        chunkPrimer.setBlock(i + 0, j + 5, k + 5, ancientbricks);
        chunkPrimer.setBlock(i + 0, j + 5, k + 6, dungeonBricks);
        chunkPrimer.setBlock(i + 0, j + 5, k + 7, dungeonBricks);
        chunkPrimer.setBlock(i + 0, j + 5, k + 8, dungeonBricks);
        chunkPrimer.setBlock(i + 0, j + 5, k + 9, ancientbricks);
        chunkPrimer.setBlock(i + 0, j + 5, k + 10, ancientbricks);
        chunkPrimer.setBlock(i + 0, j + 5, k + 11, ancientbricks);
        chunkPrimer.setBlock(i + 0, j + 5, k + 12, dungeonBricks);
        chunkPrimer.setBlock(i + 0, j + 5, k + 13, dungeonBricks);
        chunkPrimer.setBlock(i + 0, j + 5, k + 14, dungeonBricks);
        chunkPrimer.setBlock(i + 0, j + 5, k + 15, ancientbricks);
        chunkPrimer.setBlock(i + 0, j + 6, k + 0, dungeonBricks);
        chunkPrimer.setBlock(i + 0, j + 6, k + 1, ancientTile);
        chunkPrimer.setBlock(i + 0, j + 6, k + 2, dungeonBricks);
        chunkPrimer.setBlock(i + 0, j + 6, k + 3, ancientbricks);
        chunkPrimer.setBlock(i + 0, j + 6, k + 4, ancientTile);
        chunkPrimer.setBlock(i + 0, j + 6, k + 5, ancientbricks);
        chunkPrimer.setBlock(i + 0, j + 6, k + 6, dungeonBricks);
        chunkPrimer.setBlock(i + 0, j + 6, k + 7, ArcanaBlocks.arcanaLamp);
        chunkPrimer.setBlock(i + 0, j + 6, k + 8, dungeonBricks);
        chunkPrimer.setBlock(i + 0, j + 6, k + 9, ancientbricks);
        chunkPrimer.setBlock(i + 0, j + 6, k + 10, ancientTile);
        chunkPrimer.setBlock(i + 0, j + 6, k + 11, ancientbricks);
        chunkPrimer.setBlock(i + 0, j + 6, k + 12, dungeonBricks);
        chunkPrimer.setBlock(i + 0, j + 6, k + 13, ArcanaBlocks.arcanaLamp);
        chunkPrimer.setBlock(i + 0, j + 6, k + 14, dungeonBricks);
        chunkPrimer.setBlock(i + 0, j + 6, k + 15, ancientbricks);
        chunkPrimer.setBlock(i + 0, j + 7, k + 0, dungeonBricks);
        chunkPrimer.setBlock(i + 0, j + 7, k + 1, dungeonBricks);
        chunkPrimer.setBlock(i + 0, j + 7, k + 2, dungeonBricks);
        chunkPrimer.setBlock(i + 0, j + 7, k + 3, ancientbricks);
        chunkPrimer.setBlock(i + 0, j + 7, k + 4, ancientbricks);
        chunkPrimer.setBlock(i + 0, j + 7, k + 5, ancientbricks);
        chunkPrimer.setBlock(i + 0, j + 7, k + 6, dungeonBricks);
        chunkPrimer.setBlock(i + 0, j + 7, k + 7, dungeonBricks);
        chunkPrimer.setBlock(i + 0, j + 7, k + 8, dungeonBricks);
        chunkPrimer.setBlock(i + 0, j + 7, k + 9, ancientbricks);
        chunkPrimer.setBlock(i + 0, j + 7, k + 10, ancientbricks);
        chunkPrimer.setBlock(i + 0, j + 7, k + 11, ancientbricks);
        chunkPrimer.setBlock(i + 0, j + 7, k + 12, dungeonBricks);
        chunkPrimer.setBlock(i + 0, j + 7, k + 13, dungeonBricks);
        chunkPrimer.setBlock(i + 0, j + 7, k + 14, dungeonBricks);
        chunkPrimer.setBlock(i + 0, j + 7, k + 15, ancientbricks);
        chunkPrimer.setBlock(i + 1, j + 0, k + 0, ancientbricks);
        chunkPrimer.setBlock(i + 1, j + 0, k + 1, ancientbricks);
        chunkPrimer.setBlock(i + 1, j + 0, k + 2, ancientbricks);
        chunkPrimer.setBlock(i + 1, j + 0, k + 3, ancientbricks);
        chunkPrimer.setBlock(i + 1, j + 0, k + 4, ancientbricks);
        chunkPrimer.setBlock(i + 1, j + 0, k + 5, ancientbricks);
        chunkPrimer.setBlock(i + 1, j + 0, k + 6, ancientbricks);
        chunkPrimer.setBlock(i + 1, j + 0, k + 7, ancientbricks);
        chunkPrimer.setBlock(i + 1, j + 0, k + 8, ancientbricks);
        chunkPrimer.setBlock(i + 1, j + 0, k + 9, ancientbricks);
        chunkPrimer.setBlock(i + 1, j + 0, k + 10, ancientbricks);
        chunkPrimer.setBlock(i + 1, j + 0, k + 11, ancientbricks);
        chunkPrimer.setBlock(i + 1, j + 0, k + 12, ancientbricks);
        chunkPrimer.setBlock(i + 1, j + 0, k + 13, ancientbricks);
        chunkPrimer.setBlock(i + 1, j + 0, k + 14, ancientbricks);
        chunkPrimer.setBlock(i + 1, j + 0, k + 15, dungeonBricks);
        chunkPrimer.setBlock(i + 1, j + 1, k + 0, dungeonBricks);
        chunkPrimer.setBlock(i + 1, j + 1, k + 1, dungeonBricks);
        chunkPrimer.setBlock(i + 1, j + 1, k + 2, dungeonBricks);
        chunkPrimer.setBlock(i + 1, j + 1, k + 3, dungeonBricks);
        chunkPrimer.setBlock(i + 1, j + 1, k + 4, dungeonBricks);
        chunkPrimer.setBlock(i + 1, j + 1, k + 5, dungeonBricks);
        chunkPrimer.setBlock(i + 1, j + 1, k + 6, ancientbricks);
        chunkPrimer.setBlock(i + 1, j + 1, k + 7, heatTraps);
        chunkPrimer.setBlock(i + 1, j + 1, k + 8, heatTraps);
        chunkPrimer.setBlock(i + 1, j + 1, k + 9, ancientbricks);
        chunkPrimer.setBlock(i + 1, j + 1, k + 10, ancientbricks);
        chunkPrimer.setBlock(i + 1, j + 1, k + 11, ancientbricks);
        chunkPrimer.setBlock(i + 1, j + 1, k + 12, ancientbricks);
        chunkPrimer.setBlock(i + 1, j + 1, k + 13, ancientbricks);
        chunkPrimer.setBlock(i + 1, j + 1, k + 14, ancientbricks);
        chunkPrimer.setBlock(i + 1, j + 1, k + 15, dungeonBricks);
        chunkPrimer.setBlock(i + 1, j + 2, k + 0, heatTraps);
        chunkPrimer.setBlock(i + 1, j + 2, k + 1, heatTraps);
        chunkPrimer.setBlock(i + 1, j + 2, k + 2, heatTraps);
        chunkPrimer.setBlock(i + 1, j + 2, k + 3, heatTraps);
        chunkPrimer.setBlock(i + 1, j + 2, k + 4, heatTraps);
        chunkPrimer.setBlock(i + 1, j + 2, k + 5, heatTraps);
        chunkPrimer.setBlock(i + 1, j + 2, k + 6, ancientbricks);
        chunkPrimer.setBlock(i + 1, j + 2, k + 9, ancientbricks);
        chunkPrimer.setBlock(i + 1, j + 2, k + 10, ancientbricks);
        chunkPrimer.setBlock(i + 1, j + 2, k + 11, ancientbricks);
        chunkPrimer.setBlock(i + 1, j + 2, k + 12, ArcanaBlocks.arcanaLamp);
        chunkPrimer.setBlock(i + 1, j + 2, k + 13, ArcanaBlocks.arcanaLamp);
        chunkPrimer.setBlock(i + 1, j + 2, k + 14, ancientbricks);
        chunkPrimer.setBlock(i + 1, j + 2, k + 15, ancientstone);
        chunkPrimer.setBlock(i + 1, j + 3, k + 0, ancientbricks);
        chunkPrimer.setBlock(i + 1, j + 3, k + 10, ancientbricks);
        chunkPrimer.setBlock(i + 1, j + 3, k + 11, dungeonBricks);
        chunkPrimer.setBlock(i + 1, j + 3, k + 12, dungeonBricks);
        chunkPrimer.setBlock(i + 1, j + 3, k + 13, dungeonBricks);
        chunkPrimer.setBlock(i + 1, j + 3, k + 14, dungeonBricks);
        chunkPrimer.setBlock(i + 1, j + 3, k + 15, ancientstone);
        chunkPrimer.setBlock(i + 1, j + 4, k + 0, ancientbricks);
        chunkPrimer.setBlock(i + 1, j + 4, k + 11, dungeonBricks);
        chunkPrimer.setBlock(i + 1, j + 4, k + 15, dungeonBricks);
        chunkPrimer.setBlock(i + 1, j + 5, k + 0, ancientbricks);
        chunkPrimer.setBlock(i + 1, j + 5, k + 11, ancientbricks);
        chunkPrimer.setBlock(i + 1, j + 5, k + 15, ancientbricks);
        chunkPrimer.setBlock(i + 1, j + 6, k + 0, ancientbricks);
        chunkPrimer.setBlock(i + 1, j + 6, k + 11, dungeonBricks);
        chunkPrimer.setBlock(i + 1, j + 6, k + 15, ancientTile);
        chunkPrimer.setBlock(i + 1, j + 7, k + 0, ancientbricks);
        chunkPrimer.setBlock(i + 1, j + 7, k + 12, ancientbricks);
        chunkPrimer.setBlock(i + 1, j + 7, k + 13, ancientbricks);
        chunkPrimer.setBlock(i + 1, j + 7, k + 14, ancientbricks);
        chunkPrimer.setBlock(i + 1, j + 7, k + 15, ancientbricks);
        chunkPrimer.setBlock(i + 2, j + 0, k + 0, ancientbricks);
        chunkPrimer.setBlock(i + 2, j + 0, k + 1, ancientbricks);
        chunkPrimer.setBlock(i + 2, j + 0, k + 2, ancientbricks);
        chunkPrimer.setBlock(i + 2, j + 0, k + 3, ancientbricks);
        chunkPrimer.setBlock(i + 2, j + 0, k + 4, ancientbricks);
        chunkPrimer.setBlock(i + 2, j + 0, k + 5, ancientbricks);
        chunkPrimer.setBlock(i + 2, j + 0, k + 6, ancientbricks);
        chunkPrimer.setBlock(i + 2, j + 0, k + 7, ancientbricks);
        chunkPrimer.setBlock(i + 2, j + 0, k + 8, ancientbricks);
        chunkPrimer.setBlock(i + 2, j + 0, k + 9, ancientbricks);
        chunkPrimer.setBlock(i + 2, j + 0, k + 10, ancientbricks);
        chunkPrimer.setBlock(i + 2, j + 0, k + 11, ancientbricks);
        chunkPrimer.setBlock(i + 2, j + 0, k + 12, ancientbricks);
        chunkPrimer.setBlock(i + 2, j + 0, k + 13, ancientbricks);
        chunkPrimer.setBlock(i + 2, j + 0, k + 14, ancientbricks);
        chunkPrimer.setBlock(i + 2, j + 0, k + 15, dungeonBricks);
        chunkPrimer.setBlock(i + 2, j + 1, k + 0, ancientbricks);
        chunkPrimer.setBlock(i + 2, j + 1, k + 1, ancientbricks);
        chunkPrimer.setBlock(i + 2, j + 1, k + 2, ancientbricks);
        chunkPrimer.setBlock(i + 2, j + 1, k + 3, ancientbricks);
        chunkPrimer.setBlock(i + 2, j + 1, k + 4, ancientbricks);
        chunkPrimer.setBlock(i + 2, j + 1, k + 5, ancientbricks);
        chunkPrimer.setBlock(i + 2, j + 1, k + 6, ancientbricks);
        chunkPrimer.setBlock(i + 2, j + 1, k + 7, heatTraps);
        chunkPrimer.setBlock(i + 2, j + 1, k + 8, heatTraps);
        chunkPrimer.setBlock(i + 2, j + 1, k + 9, ancientbricks);
        chunkPrimer.setBlock(i + 2, j + 1, k + 11, ancientbricks);
        chunkPrimer.setBlock(i + 2, j + 1, k + 14, ancientbricks);
        chunkPrimer.setBlock(i + 2, j + 1, k + 15, dungeonBricks);
        chunkPrimer.setBlock(i + 2, j + 2, k + 0, ancientbricks);
        chunkPrimer.setBlock(i + 2, j + 2, k + 1, ancientbricks);
        chunkPrimer.setBlock(i + 2, j + 2, k + 2, ancientbricks);
        chunkPrimer.setBlock(i + 2, j + 2, k + 3, ancientbricks);
        chunkPrimer.setBlock(i + 2, j + 2, k + 4, ancientbricks);
        chunkPrimer.setBlock(i + 2, j + 2, k + 5, heatTraps);
        chunkPrimer.setBlock(i + 2, j + 2, k + 6, ancientbricks);
        chunkPrimer.setBlock(i + 2, j + 2, k + 9, ancientbricks);
        chunkPrimer.setBlock(i + 2, j + 2, k + 11, ancientbricks);
        chunkPrimer.setBlock(i + 2, j + 2, k + 14, ancientbricks);
        chunkPrimer.setBlock(i + 2, j + 2, k + 15, dungeonBricks);
        chunkPrimer.setBlock(i + 2, j + 3, k + 0, ancientbricks);
        chunkPrimer.setBlock(i + 2, j + 3, k + 10, ancientbricks);
        chunkPrimer.setBlock(i + 2, j + 3, k + 11, dungeonBricks);
        chunkPrimer.setBlock(i + 2, j + 3, k + 12, ancientbricks);
        chunkPrimer.setBlock(i + 2, j + 3, k + 13, ancientbricks);
        chunkPrimer.setBlock(i + 2, j + 3, k + 14, dungeonBricks);
        chunkPrimer.setBlock(i + 2, j + 3, k + 15, ancientstone);
        chunkPrimer.setBlock(i + 2, j + 4, k + 0, ancientbricks);
        chunkPrimer.setBlock(i + 2, j + 4, k + 11, dungeonBricks);
        chunkPrimer.setBlock(i + 2, j + 4, k + 13, ArcanaBlocks.arcaniumOre);
        chunkPrimer.setBlock(i + 2, j + 4, k + 15, dungeonBricks);
        chunkPrimer.setBlock(i + 2, j + 5, k + 0, ancientbricks);
        chunkPrimer.setBlock(i + 2, j + 5, k + 11, ancientbricks);
        chunkPrimer.setBlock(i + 2, j + 5, k + 15, ancientbricks);
        chunkPrimer.setBlock(i + 2, j + 6, k + 0, ancientbricks);
        chunkPrimer.setBlock(i + 2, j + 6, k + 11, dungeonBricks);
        chunkPrimer.setBlock(i + 2, j + 6, k + 15, ancientbricks);
        chunkPrimer.setBlock(i + 2, j + 7, k + 0, ancientbricks);
        chunkPrimer.setBlock(i + 2, j + 7, k + 12, ancientbricks);
        chunkPrimer.setBlock(i + 2, j + 7, k + 13, ancientbricks);
        chunkPrimer.setBlock(i + 2, j + 7, k + 14, ancientbricks);
        chunkPrimer.setBlock(i + 2, j + 7, k + 15, ancientbricks);
        chunkPrimer.setBlock(i + 3, j + 0, k + 0, ancientbricks);
        chunkPrimer.setBlock(i + 3, j + 0, k + 1, ancientbricks);
        chunkPrimer.setBlock(i + 3, j + 0, k + 2, ancientbricks);
        chunkPrimer.setBlock(i + 3, j + 0, k + 3, ancientbricks);
        chunkPrimer.setBlock(i + 3, j + 0, k + 4, ancientbricks);
        chunkPrimer.setBlock(i + 3, j + 0, k + 5, ancientbricks);
        chunkPrimer.setBlock(i + 3, j + 0, k + 6, ancientbricks);
        chunkPrimer.setBlock(i + 3, j + 0, k + 7, ancientbricks);
        chunkPrimer.setBlock(i + 3, j + 0, k + 8, ancientbricks);
        chunkPrimer.setBlock(i + 3, j + 0, k + 9, ancientbricks);
        chunkPrimer.setBlock(i + 3, j + 0, k + 10, ancientbricks);
        chunkPrimer.setBlock(i + 3, j + 0, k + 11, ancientbricks);
        chunkPrimer.setBlock(i + 3, j + 0, k + 12, ancientbricks);
        chunkPrimer.setBlock(i + 3, j + 0, k + 13, ancientbricks);
        chunkPrimer.setBlock(i + 3, j + 0, k + 14, ancientbricks);
        chunkPrimer.setBlock(i + 3, j + 0, k + 15, dungeonBricks);
        chunkPrimer.setBlock(i + 3, j + 1, k + 0, heatTraps);
        chunkPrimer.setBlock(i + 3, j + 1, k + 1, heatTraps);
        chunkPrimer.setBlock(i + 3, j + 1, k + 2, heatTraps);
        chunkPrimer.setBlock(i + 3, j + 1, k + 3, heatTraps);
        chunkPrimer.setBlock(i + 3, j + 1, k + 4, ancientbricks);
        chunkPrimer.setBlock(i + 3, j + 1, k + 5, ancientbricks);
        chunkPrimer.setBlock(i + 3, j + 1, k + 6, ancientbricks);
        chunkPrimer.setBlock(i + 3, j + 1, k + 7, heatTraps);
        chunkPrimer.setBlock(i + 3, j + 1, k + 8, heatTraps);
        chunkPrimer.setBlock(i + 3, j + 1, k + 9, ancientbricks);
        chunkPrimer.setBlock(i + 3, j + 1, k + 11, ancientbricks);
        chunkPrimer.setBlock(i + 3, j + 1, k + 14, ancientbricks);
        chunkPrimer.setBlock(i + 3, j + 1, k + 15, ancientstone);
        chunkPrimer.setBlock(i + 3, j + 2, k + 0, dungeonBricks);
        chunkPrimer.setBlock(i + 3, j + 2, k + 4, ancientbricks);
        chunkPrimer.setBlock(i + 3, j + 2, k + 5, heatTraps);
        chunkPrimer.setBlock(i + 3, j + 2, k + 6, ancientbricks);
        chunkPrimer.setBlock(i + 3, j + 2, k + 9, ancientbricks);
        chunkPrimer.setBlock(i + 3, j + 2, k + 11, ancientbricks);
        chunkPrimer.setBlock(i + 3, j + 2, k + 14, ancientbricks);
        chunkPrimer.setBlock(i + 3, j + 2, k + 15, dungeonBricks);
        chunkPrimer.setBlock(i + 3, j + 3, k + 0, ancientbricks);
        chunkPrimer.setBlock(i + 3, j + 3, k + 10, ancientbricks);
        chunkPrimer.setBlock(i + 3, j + 3, k + 11, dungeonBricks);
        chunkPrimer.setBlock(i + 3, j + 3, k + 12, ancientbricks);
        chunkPrimer.setBlock(i + 3, j + 3, k + 13, ancientbricks);
        chunkPrimer.setBlock(i + 3, j + 3, k + 14, dungeonBricks);
        chunkPrimer.setBlock(i + 3, j + 3, k + 15, ancientstone);
        chunkPrimer.setBlock(i + 3, j + 4, k + 0, ancientbricks);
        chunkPrimer.setBlock(i + 3, j + 4, k + 11, dungeonBricks);
        chunkPrimer.setBlock(i + 3, j + 4, k + 15, dungeonBricks);
        chunkPrimer.setBlock(i + 3, j + 5, k + 0, ancientbricks);
        chunkPrimer.setBlock(i + 3, j + 5, k + 11, ancientbricks);
        chunkPrimer.setBlock(i + 3, j + 5, k + 15, dungeonBricks);
        chunkPrimer.setBlock(i + 3, j + 6, k + 0, ancientbricks);
        chunkPrimer.setBlock(i + 3, j + 6, k + 11, dungeonBricks);
        chunkPrimer.setBlock(i + 3, j + 6, k + 15, dungeonBricks);
        chunkPrimer.setBlock(i + 3, j + 7, k + 0, ancientbricks);
        chunkPrimer.setBlock(i + 3, j + 7, k + 12, ancientbricks);
        chunkPrimer.setBlock(i + 3, j + 7, k + 13, ancientbricks);
        chunkPrimer.setBlock(i + 3, j + 7, k + 14, ancientbricks);
        chunkPrimer.setBlock(i + 3, j + 7, k + 15, dungeonBricks);
        chunkPrimer.setBlock(i + 4, j + 0, k + 0, ancientbricks);
        chunkPrimer.setBlock(i + 4, j + 0, k + 1, ancientbricks);
        chunkPrimer.setBlock(i + 4, j + 0, k + 2, ancientbricks);
        chunkPrimer.setBlock(i + 4, j + 0, k + 3, ancientbricks);
        chunkPrimer.setBlock(i + 4, j + 0, k + 4, ancientbricks);
        chunkPrimer.setBlock(i + 4, j + 0, k + 5, ancientbricks);
        chunkPrimer.setBlock(i + 4, j + 0, k + 6, ancientbricks);
        chunkPrimer.setBlock(i + 4, j + 0, k + 7, ancientbricks);
        chunkPrimer.setBlock(i + 4, j + 0, k + 8, ancientbricks);
        chunkPrimer.setBlock(i + 4, j + 0, k + 9, ancientbricks);
        chunkPrimer.setBlock(i + 4, j + 0, k + 10, ancientbricks);
        chunkPrimer.setBlock(i + 4, j + 0, k + 11, ancientbricks);
        chunkPrimer.setBlock(i + 4, j + 0, k + 12, ancientbricks);
        chunkPrimer.setBlock(i + 4, j + 0, k + 13, ancientbricks);
        chunkPrimer.setBlock(i + 4, j + 0, k + 14, ancientbricks);
        chunkPrimer.setBlock(i + 4, j + 0, k + 15, dungeonBricks);
        chunkPrimer.setBlock(i + 4, j + 1, k + 0, ancientbricks);
        chunkPrimer.setBlock(i + 4, j + 1, k + 1, ancientbricks);
        chunkPrimer.setBlock(i + 4, j + 1, k + 2, ancientbricks);
        chunkPrimer.setBlock(i + 4, j + 1, k + 3, heatTraps);
        chunkPrimer.setBlock(i + 4, j + 1, k + 4, ancientbricks);
        chunkPrimer.setBlock(i + 4, j + 1, k + 5, ancientbricks);
        chunkPrimer.setBlock(i + 4, j + 1, k + 6, ancientbricks);
        chunkPrimer.setBlock(i + 4, j + 1, k + 7, heatTraps);
        chunkPrimer.setBlock(i + 4, j + 1, k + 8, heatTraps);
        chunkPrimer.setBlock(i + 4, j + 1, k + 9, ancientbricks);
        chunkPrimer.setBlock(i + 4, j + 1, k + 11, ancientbricks);
        chunkPrimer.setBlock(i + 4, j + 1, k + 14, ancientbricks);
        chunkPrimer.setBlock(i + 4, j + 1, k + 15, ancientstone);
        chunkPrimer.setBlock(i + 4, j + 2, k + 0, dungeonBricks);
        chunkPrimer.setBlock(i + 4, j + 2, k + 4, ancientbricks);
        chunkPrimer.setBlock(i + 4, j + 2, k + 5, heatTraps);
        chunkPrimer.setBlock(i + 4, j + 2, k + 6, ancientbricks);
        chunkPrimer.setBlock(i + 4, j + 2, k + 9, ancientbricks);
        chunkPrimer.setBlock(i + 4, j + 2, k + 11, ancientbricks);
        chunkPrimer.setBlock(i + 4, j + 2, k + 14, ancientbricks);
        chunkPrimer.setBlock(i + 4, j + 2, k + 15, dungeonBricks);
        chunkPrimer.setBlock(i + 4, j + 3, k + 0, ancientbricks);
        chunkPrimer.setBlock(i + 4, j + 3, k + 10, ancientbricks);
        chunkPrimer.setBlock(i + 4, j + 3, k + 11, dungeonBricks);
        chunkPrimer.setBlock(i + 4, j + 3, k + 12, ancientbricks);
        chunkPrimer.setBlock(i + 4, j + 3, k + 13, ancientbricks);
        chunkPrimer.setBlock(i + 4, j + 3, k + 14, dungeonBricks);
        chunkPrimer.setBlock(i + 4, j + 3, k + 15, dungeonBricks);
        chunkPrimer.setBlock(i + 4, j + 4, k + 0, ancientbricks);
        chunkPrimer.setBlock(i + 4, j + 4, k + 11, dungeonBricks);
        chunkPrimer.setBlock(i + 4, j + 4, k + 15, dungeonBricks);
        chunkPrimer.setBlock(i + 4, j + 5, k + 0, ancientbricks);
        chunkPrimer.setBlock(i + 4, j + 5, k + 11, ancientbricks);
        chunkPrimer.setBlock(i + 4, j + 5, k + 15, dungeonBricks);
        chunkPrimer.setBlock(i + 4, j + 6, k + 0, ancientbricks);
        chunkPrimer.setBlock(i + 4, j + 6, k + 11, dungeonBricks);
        chunkPrimer.setBlock(i + 4, j + 6, k + 15, ancientTile);
        chunkPrimer.setBlock(i + 4, j + 7, k + 0, ancientbricks);
        chunkPrimer.setBlock(i + 4, j + 7, k + 12, ancientbricks);
        chunkPrimer.setBlock(i + 4, j + 7, k + 13, ancientbricks);
        chunkPrimer.setBlock(i + 4, j + 7, k + 14, ancientbricks);
        chunkPrimer.setBlock(i + 4, j + 7, k + 15, dungeonBricks);
        chunkPrimer.setBlock(i + 5, j + 0, k + 0, ancientbricks);
        chunkPrimer.setBlock(i + 5, j + 0, k + 1, ancientbricks);
        chunkPrimer.setBlock(i + 5, j + 0, k + 2, ancientbricks);
        chunkPrimer.setBlock(i + 5, j + 0, k + 3, ancientbricks);
        chunkPrimer.setBlock(i + 5, j + 0, k + 4, ancientbricks);
        chunkPrimer.setBlock(i + 5, j + 0, k + 5, ancientbricks);
        chunkPrimer.setBlock(i + 5, j + 0, k + 6, ancientbricks);
        chunkPrimer.setBlock(i + 5, j + 0, k + 7, ancientbricks);
        chunkPrimer.setBlock(i + 5, j + 0, k + 8, ancientbricks);
        chunkPrimer.setBlock(i + 5, j + 0, k + 9, ancientbricks);
        chunkPrimer.setBlock(i + 5, j + 0, k + 10, ancientbricks);
        chunkPrimer.setBlock(i + 5, j + 0, k + 11, ancientbricks);
        chunkPrimer.setBlock(i + 5, j + 0, k + 12, ancientbricks);
        chunkPrimer.setBlock(i + 5, j + 0, k + 13, ancientbricks);
        chunkPrimer.setBlock(i + 5, j + 0, k + 14, ancientbricks);
        chunkPrimer.setBlock(i + 5, j + 0, k + 15, dungeonBricks);
        chunkPrimer.setBlock(i + 5, j + 1, k + 0, dungeonBricks);
        chunkPrimer.setBlock(i + 5, j + 1, k + 2, ancientbricks);
        chunkPrimer.setBlock(i + 5, j + 1, k + 3, heatTraps);
        chunkPrimer.setBlock(i + 5, j + 1, k + 4, ancientbricks);
        chunkPrimer.setBlock(i + 5, j + 1, k + 5, ancientbricks);
        chunkPrimer.setBlock(i + 5, j + 1, k + 6, ancientbricks);
        chunkPrimer.setBlock(i + 5, j + 1, k + 7, heatTraps);
        chunkPrimer.setBlock(i + 5, j + 1, k + 8, heatTraps);
        chunkPrimer.setBlock(i + 5, j + 1, k + 9, ancientbricks);
        chunkPrimer.setBlock(i + 5, j + 1, k + 11, ArcanaBlocks.ancientBrickDoor, 3);
        chunkPrimer.setBlock(i + 5, j + 1, k + 14, ancientbricks);
        chunkPrimer.setBlock(i + 5, j + 1, k + 15, ancientstone);
        chunkPrimer.setBlock(i + 5, j + 2, k + 0, dungeonBricks);
        chunkPrimer.setBlock(i + 5, j + 2, k + 4, ancientbricks);
        chunkPrimer.setBlock(i + 5, j + 2, k + 5, heatTraps);
        chunkPrimer.setBlock(i + 5, j + 2, k + 6, ancientbricks);
        chunkPrimer.setBlock(i + 5, j + 2, k + 9, ancientbricks);
        chunkPrimer.setBlock(i + 5, j + 2, k + 11, ArcanaBlocks.ancientBrickDoor, 8);
        chunkPrimer.setBlock(i + 5, j + 2, k + 14, ancientbricks);
        chunkPrimer.setBlock(i + 5, j + 2, k + 15, ancientstone);
        chunkPrimer.setBlock(i + 5, j + 3, k + 0, dungeonBricks);
        chunkPrimer.setBlock(i + 5, j + 3, k + 10, ancientbricks);
        chunkPrimer.setBlock(i + 5, j + 3, k + 11, dungeonBricks);
        chunkPrimer.setBlock(i + 5, j + 3, k + 12, ancientbricks);
        chunkPrimer.setBlock(i + 5, j + 3, k + 13, ancientbricks);
        chunkPrimer.setBlock(i + 5, j + 3, k + 14, dungeonBricks);
        chunkPrimer.setBlock(i + 5, j + 3, k + 15, dungeonBricks);
        chunkPrimer.setBlock(i + 5, j + 4, k + 0, dungeonBricks);
        chunkPrimer.setBlock(i + 5, j + 4, k + 11, dungeonBricks);
        chunkPrimer.setBlock(i + 5, j + 4, k + 12, ArcanaBlocks.ancientBrickDoor, 2);
        chunkPrimer.setBlock(i + 5, j + 4, k + 13, ancientbricks);
        chunkPrimer.setBlock(i + 5, j + 4, k + 14, ancientbricks);
        chunkPrimer.setBlock(i + 5, j + 4, k + 15, dungeonBricks);
        chunkPrimer.setBlock(i + 5, j + 5, k + 0, ancientbricks);
        chunkPrimer.setBlock(i + 5, j + 5, k + 11, ancientbricks);
        chunkPrimer.setBlock(i + 5, j + 5, k + 12, ArcanaBlocks.ancientBrickDoor, 8);
        chunkPrimer.setBlock(i + 5, j + 5, k + 13, ancientbricks);
        chunkPrimer.setBlock(i + 5, j + 5, k + 14, ancientbricks);
        chunkPrimer.setBlock(i + 5, j + 5, k + 15, dungeonBricks);
        chunkPrimer.setBlock(i + 5, j + 6, k + 0, ancientbricks);
        chunkPrimer.setBlock(i + 5, j + 6, k + 11, dungeonBricks);
        chunkPrimer.setBlock(i + 5, j + 6, k + 12, ancientbricks);
        chunkPrimer.setBlock(i + 5, j + 6, k + 13, ancientbricks);
        chunkPrimer.setBlock(i + 5, j + 6, k + 14, ancientbricks);
        chunkPrimer.setBlock(i + 5, j + 6, k + 15, dungeonBricks);
        chunkPrimer.setBlock(i + 5, j + 7, k + 0, ancientbricks);
        chunkPrimer.setBlock(i + 5, j + 7, k + 12, ancientbricks);
        chunkPrimer.setBlock(i + 5, j + 7, k + 13, ancientbricks);
        chunkPrimer.setBlock(i + 5, j + 7, k + 14, ancientbricks);
        chunkPrimer.setBlock(i + 5, j + 7, k + 15, dungeonBricks);
        chunkPrimer.setBlock(i + 6, j + 0, k + 0, ancientbricks);
        chunkPrimer.setBlock(i + 6, j + 0, k + 1, ancientbricks);
        chunkPrimer.setBlock(i + 6, j + 0, k + 2, ancientbricks);
        chunkPrimer.setBlock(i + 6, j + 0, k + 3, ancientbricks);
        chunkPrimer.setBlock(i + 6, j + 0, k + 4, ancientbricks);
        chunkPrimer.setBlock(i + 6, j + 0, k + 5, ancientbricks);
        chunkPrimer.setBlock(i + 6, j + 0, k + 6, ancientbricks);
        chunkPrimer.setBlock(i + 6, j + 0, k + 7, ancientbricks);
        chunkPrimer.setBlock(i + 6, j + 0, k + 8, ancientbricks);
        chunkPrimer.setBlock(i + 6, j + 0, k + 9, ancientbricks);
        chunkPrimer.setBlock(i + 6, j + 0, k + 10, ancientbricks);
        chunkPrimer.setBlock(i + 6, j + 0, k + 11, ancientbricks);
        chunkPrimer.setBlock(i + 6, j + 0, k + 12, ancientbricks);
        chunkPrimer.setBlock(i + 6, j + 0, k + 13, ancientbricks);
        chunkPrimer.setBlock(i + 6, j + 0, k + 14, ancientbricks);
        chunkPrimer.setBlock(i + 6, j + 0, k + 15, dungeonBricks);
        chunkPrimer.setBlock(i + 6, j + 1, k + 0, arcaniteMetal);
        chunkPrimer.setBlock(i + 6, j + 1, k + 2, ancientbricks);
        chunkPrimer.setBlock(i + 6, j + 1, k + 3, heatTraps);
        chunkPrimer.setBlock(i + 6, j + 1, k + 4, ancientbricks);
        chunkPrimer.setBlock(i + 6, j + 1, k + 5, ancientbricks);
        chunkPrimer.setBlock(i + 6, j + 1, k + 6, ancientbricks);
        chunkPrimer.setBlock(i + 6, j + 1, k + 7, heatTraps);
        chunkPrimer.setBlock(i + 6, j + 1, k + 8, heatTraps);
        chunkPrimer.setBlock(i + 6, j + 1, k + 9, ancientbricks);
        chunkPrimer.setBlock(i + 6, j + 1, k + 10, ArcanaBlocks.ancientBrickDoor);
        chunkPrimer.setBlock(i + 6, j + 1, k + 11, ancientbricks);
        chunkPrimer.setBlock(i + 6, j + 1, k + 14, ancientbricks);
        chunkPrimer.setBlock(i + 6, j + 1, k + 15, ancientstone);
        chunkPrimer.setBlock(i + 6, j + 2, k + 0, arcaniteMetal);
        chunkPrimer.setBlock(i + 6, j + 2, k + 4, ancientbricks);
        chunkPrimer.setBlock(i + 6, j + 2, k + 5, heatTraps);
        chunkPrimer.setBlock(i + 6, j + 2, k + 6, ancientbricks);
        chunkPrimer.setBlock(i + 6, j + 2, k + 9, ancientbricks);
        chunkPrimer.setBlock(i + 6, j + 2, k + 10, ArcanaBlocks.ancientBrickDoor, 8);
        chunkPrimer.setBlock(i + 6, j + 2, k + 11, ancientbricks);
        chunkPrimer.setBlock(i + 6, j + 2, k + 14, ancientbricks);
        chunkPrimer.setBlock(i + 6, j + 2, k + 15, dungeonBricks);
        chunkPrimer.setBlock(i + 6, j + 3, k + 0, arcaniteMetal);
        chunkPrimer.setBlock(i + 6, j + 3, k + 10, ancientbricks);
        chunkPrimer.setBlock(i + 6, j + 3, k + 11, dungeonBricks);
        chunkPrimer.setBlock(i + 6, j + 3, k + 12, ancientbricks);
        chunkPrimer.setBlock(i + 6, j + 3, k + 13, ancientbricks);
        chunkPrimer.setBlock(i + 6, j + 3, k + 14, ancientbricks);
        chunkPrimer.setBlock(i + 6, j + 3, k + 15, dungeonBricks);
        chunkPrimer.setBlock(i + 6, j + 4, k + 0, dungeonBricks);
        chunkPrimer.setBlock(i + 6, j + 4, k + 11, dungeonBricks);
        chunkPrimer.setBlock(i + 6, j + 4, k + 15, dungeonBricks);
        chunkPrimer.setBlock(i + 6, j + 5, k + 0, ancientbricks);
        chunkPrimer.setBlock(i + 6, j + 5, k + 11, ancientbricks);
        chunkPrimer.setBlock(i + 6, j + 5, k + 15, ancientbricks);
        chunkPrimer.setBlock(i + 6, j + 6, k + 0, ancientbricks);
        chunkPrimer.setBlock(i + 6, j + 6, k + 11, dungeonBricks);
        chunkPrimer.setBlock(i + 6, j + 6, k + 15, ancientbricks);
        chunkPrimer.setBlock(i + 6, j + 7, k + 0, ancientbricks);
        chunkPrimer.setBlock(i + 6, j + 7, k + 12, ancientbricks);
        chunkPrimer.setBlock(i + 6, j + 7, k + 13, ancientbricks);
        chunkPrimer.setBlock(i + 6, j + 7, k + 14, ancientbricks);
        chunkPrimer.setBlock(i + 6, j + 7, k + 15, ancientbricks);
        chunkPrimer.setBlock(i + 7, j + 0, k + 0, ancientbricks);
        chunkPrimer.setBlock(i + 7, j + 0, k + 1, ancientbricks);
        chunkPrimer.setBlock(i + 7, j + 0, k + 2, ancientbricks);
        chunkPrimer.setBlock(i + 7, j + 0, k + 3, ancientbricks);
        chunkPrimer.setBlock(i + 7, j + 0, k + 4, ancientbricks);
        chunkPrimer.setBlock(i + 7, j + 0, k + 5, ancientbricks);
        chunkPrimer.setBlock(i + 7, j + 0, k + 6, ancientbricks);
        chunkPrimer.setBlock(i + 7, j + 0, k + 7, ancientbricks);
        chunkPrimer.setBlock(i + 7, j + 0, k + 8, ancientbricks);
        chunkPrimer.setBlock(i + 7, j + 0, k + 9, ancientbricks);
        chunkPrimer.setBlock(i + 7, j + 0, k + 10, ancientbricks);
        chunkPrimer.setBlock(i + 7, j + 0, k + 11, ancientbricks);
        chunkPrimer.setBlock(i + 7, j + 0, k + 12, ancientbricks);
        chunkPrimer.setBlock(i + 7, j + 0, k + 13, ancientbricks);
        chunkPrimer.setBlock(i + 7, j + 0, k + 14, ancientbricks);
        chunkPrimer.setBlock(i + 7, j + 0, k + 15, dungeonBricks);
        chunkPrimer.setBlock(i + 7, j + 1, k + 2, ancientbricks);
        chunkPrimer.setBlock(i + 7, j + 1, k + 3, heatTraps);
        chunkPrimer.setBlock(i + 7, j + 1, k + 4, ancientbricks);
        chunkPrimer.setBlock(i + 7, j + 1, k + 5, ancientbricks);
        chunkPrimer.setBlock(i + 7, j + 1, k + 6, ancientbricks);
        chunkPrimer.setBlock(i + 7, j + 1, k + 7, heatTraps);
        chunkPrimer.setBlock(i + 7, j + 1, k + 8, heatTraps);
        chunkPrimer.setBlock(i + 7, j + 1, k + 9, ancientbricks);
        chunkPrimer.setBlock(i + 7, j + 1, k + 11, ancientbricks);
        chunkPrimer.setBlock(i + 7, j + 1, k + 14, ancientbricks);
        chunkPrimer.setBlock(i + 7, j + 1, k + 15, ancientstone);
        chunkPrimer.setBlock(i + 7, j + 2, k + 4, ancientbricks);
        chunkPrimer.setBlock(i + 7, j + 2, k + 5, heatTraps);
        chunkPrimer.setBlock(i + 7, j + 2, k + 6, ancientbricks);
        chunkPrimer.setBlock(i + 7, j + 2, k + 9, ancientbricks);
        chunkPrimer.setBlock(i + 7, j + 2, k + 11, ancientbricks);
        chunkPrimer.setBlock(i + 7, j + 2, k + 14, ancientbricks);
        chunkPrimer.setBlock(i + 7, j + 2, k + 15, dungeonBricks);
        chunkPrimer.setBlock(i + 7, j + 3, k + 0, arcanaPower);
        chunkPrimer.setBlock(i + 7, j + 3, k + 10, ancientbricks);
        chunkPrimer.setBlock(i + 7, j + 3, k + 11, dungeonBricks);
        chunkPrimer.setBlock(i + 7, j + 3, k + 12, ancientbricks);
        chunkPrimer.setBlock(i + 7, j + 3, k + 13, ancientbricks);
        chunkPrimer.setBlock(i + 7, j + 3, k + 14, dungeonBricks);
        chunkPrimer.setBlock(i + 7, j + 3, k + 15, ancientstone);
        chunkPrimer.setBlock(i + 7, j + 4, k + 0, dungeonBricks);
        chunkPrimer.setBlock(i + 7, j + 4, k + 11, dungeonBricks);
        chunkPrimer.setBlock(i + 7, j + 4, k + 12, dungeonBricks);
        chunkPrimer.setBlock(i + 7, j + 4, k + 13, ArcanaBlocks.soulSludgeDoor, 2);
        chunkPrimer.setBlock(i + 7, j + 4, k + 14, dungeonBricks);
        chunkPrimer.setBlock(i + 7, j + 4, k + 15, dungeonBricks);
        chunkPrimer.setBlock(i + 7, j + 5, k + 0, ancientbricks);
        chunkPrimer.setBlock(i + 7, j + 5, k + 11, dungeonBricks);
        chunkPrimer.setBlock(i + 7, j + 5, k + 12, dungeonBricks);
        chunkPrimer.setBlock(i + 7, j + 5, k + 13, ArcanaBlocks.soulSludgeDoor, 8);
        chunkPrimer.setBlock(i + 7, j + 5, k + 14, dungeonBricks);
        chunkPrimer.setBlock(i + 7, j + 5, k + 15, ancientbricks);
        chunkPrimer.setBlock(i + 7, j + 6, k + 0, ancientbricks);
        chunkPrimer.setBlock(i + 7, j + 6, k + 11, dungeonBricks);
        chunkPrimer.setBlock(i + 7, j + 6, k + 12, dungeonBricks);
        chunkPrimer.setBlock(i + 7, j + 6, k + 13, dungeonBricks);
        chunkPrimer.setBlock(i + 7, j + 6, k + 14, dungeonBricks);
        chunkPrimer.setBlock(i + 7, j + 6, k + 15, ArcanaBlocks.arcanaLamp);
        chunkPrimer.setBlock(i + 7, j + 7, k + 0, ancientbricks);
        chunkPrimer.setBlock(i + 7, j + 7, k + 15, ancientbricks);
        chunkPrimer.setBlock(i + 8, j + 0, k + 0, ancientbricks);
        chunkPrimer.setBlock(i + 8, j + 0, k + 1, ancientbricks);
        chunkPrimer.setBlock(i + 8, j + 0, k + 2, ancientbricks);
        chunkPrimer.setBlock(i + 8, j + 0, k + 3, ancientbricks);
        chunkPrimer.setBlock(i + 8, j + 0, k + 4, ancientbricks);
        chunkPrimer.setBlock(i + 8, j + 0, k + 5, ancientbricks);
        chunkPrimer.setBlock(i + 8, j + 0, k + 6, ancientbricks);
        chunkPrimer.setBlock(i + 8, j + 0, k + 7, ancientbricks);
        chunkPrimer.setBlock(i + 8, j + 0, k + 8, ancientbricks);
        chunkPrimer.setBlock(i + 8, j + 0, k + 9, ancientbricks);
        chunkPrimer.setBlock(i + 8, j + 0, k + 10, ancientbricks);
        chunkPrimer.setBlock(i + 8, j + 0, k + 11, ancientbricks);
        chunkPrimer.setBlock(i + 8, j + 0, k + 12, ancientbricks);
        chunkPrimer.setBlock(i + 8, j + 0, k + 13, ancientbricks);
        chunkPrimer.setBlock(i + 8, j + 0, k + 14, ancientbricks);
        chunkPrimer.setBlock(i + 8, j + 0, k + 15, dungeonBricks);
        chunkPrimer.setBlock(i + 8, j + 1, k + 2, ancientbricks);
        chunkPrimer.setBlock(i + 8, j + 1, k + 3, heatTraps);
        chunkPrimer.setBlock(i + 8, j + 1, k + 4, ancientbricks);
        chunkPrimer.setBlock(i + 8, j + 1, k + 5, ancientbricks);
        chunkPrimer.setBlock(i + 8, j + 1, k + 6, ancientbricks);
        chunkPrimer.setBlock(i + 8, j + 1, k + 7, heatTraps);
        chunkPrimer.setBlock(i + 8, j + 1, k + 8, heatTraps);
        chunkPrimer.setBlock(i + 8, j + 1, k + 9, ancientbricks);
        chunkPrimer.setBlock(i + 8, j + 1, k + 10, ArcanaBlocks.arcaniumOre);
        chunkPrimer.setBlock(i + 8, j + 1, k + 11, ancientbricks);
        chunkPrimer.setBlock(i + 8, j + 1, k + 14, ancientbricks);
        chunkPrimer.setBlock(i + 8, j + 1, k + 15, dungeonBricks);
        chunkPrimer.setBlock(i + 8, j + 2, k + 4, ancientbricks);
        chunkPrimer.setBlock(i + 8, j + 2, k + 5, heatTraps);
        chunkPrimer.setBlock(i + 8, j + 2, k + 6, ancientbricks);
        chunkPrimer.setBlock(i + 8, j + 2, k + 9, ancientbricks);
        chunkPrimer.setBlock(i + 8, j + 2, k + 10, ArcanaBlocks.arcanaLamp);
        chunkPrimer.setBlock(i + 8, j + 2, k + 11, ancientbricks);
        chunkPrimer.setBlock(i + 8, j + 2, k + 14, ancientbricks);
        chunkPrimer.setBlock(i + 8, j + 2, k + 15, dungeonBricks);
        chunkPrimer.setBlock(i + 8, j + 3, k + 0, arcanaPower);
        chunkPrimer.setBlock(i + 8, j + 3, k + 10, ancientbricks);
        chunkPrimer.setBlock(i + 8, j + 3, k + 11, dungeonBricks);
        chunkPrimer.setBlock(i + 8, j + 3, k + 12, ancientbricks);
        chunkPrimer.setBlock(i + 8, j + 3, k + 13, ancientbricks);
        chunkPrimer.setBlock(i + 8, j + 3, k + 14, dungeonBricks);
        chunkPrimer.setBlock(i + 8, j + 3, k + 15, ancientstone);
        chunkPrimer.setBlock(i + 8, j + 4, k + 0, dungeonBricks);
        chunkPrimer.setBlock(i + 8, j + 4, k + 15, dungeonBricks);
        chunkPrimer.setBlock(i + 8, j + 5, k + 0, ancientbricks);
        chunkPrimer.setBlock(i + 8, j + 5, k + 15, ancientbricks);
        chunkPrimer.setBlock(i + 8, j + 6, k + 0, ancientbricks);
        chunkPrimer.setBlock(i + 8, j + 6, k + 15, ancientbricks);
        chunkPrimer.setBlock(i + 8, j + 7, k + 0, ancientbricks);
        chunkPrimer.setBlock(i + 8, j + 7, k + 15, ancientbricks);
        chunkPrimer.setBlock(i + 9, j + 0, k + 0, ancientbricks);
        chunkPrimer.setBlock(i + 9, j + 0, k + 1, ancientbricks);
        chunkPrimer.setBlock(i + 9, j + 0, k + 2, ancientbricks);
        chunkPrimer.setBlock(i + 9, j + 0, k + 3, ancientbricks);
        chunkPrimer.setBlock(i + 9, j + 0, k + 4, ancientbricks);
        chunkPrimer.setBlock(i + 9, j + 0, k + 5, ancientbricks);
        chunkPrimer.setBlock(i + 9, j + 0, k + 6, ancientbricks);
        chunkPrimer.setBlock(i + 9, j + 0, k + 7, ancientbricks);
        chunkPrimer.setBlock(i + 9, j + 0, k + 8, ancientbricks);
        chunkPrimer.setBlock(i + 9, j + 0, k + 9, ancientbricks);
        chunkPrimer.setBlock(i + 9, j + 0, k + 10, ancientbricks);
        chunkPrimer.setBlock(i + 9, j + 0, k + 11, ancientbricks);
        chunkPrimer.setBlock(i + 9, j + 0, k + 12, ancientbricks);
        chunkPrimer.setBlock(i + 9, j + 0, k + 13, ancientbricks);
        chunkPrimer.setBlock(i + 9, j + 0, k + 14, ancientbricks);
        chunkPrimer.setBlock(i + 9, j + 0, k + 15, dungeonBricks);
        chunkPrimer.setBlock(i + 9, j + 1, k + 0, arcaniteMetal);
        chunkPrimer.setBlock(i + 9, j + 1, k + 2, ancientbricks);
        chunkPrimer.setBlock(i + 9, j + 1, k + 3, heatTraps);
        chunkPrimer.setBlock(i + 9, j + 1, k + 4, ancientbricks);
        chunkPrimer.setBlock(i + 9, j + 1, k + 5, ancientbricks);
        chunkPrimer.setBlock(i + 9, j + 1, k + 6, ancientbricks);
        chunkPrimer.setBlock(i + 9, j + 1, k + 7, heatTraps);
        chunkPrimer.setBlock(i + 9, j + 1, k + 8, heatTraps);
        chunkPrimer.setBlock(i + 9, j + 1, k + 9, ancientbricks);
        chunkPrimer.setBlock(i + 9, j + 1, k + 10, ancientbricks);
        chunkPrimer.setBlock(i + 9, j + 1, k + 11, ancientbricks);
        chunkPrimer.setBlock(i + 9, j + 1, k + 14, ancientbricks);
        chunkPrimer.setBlock(i + 9, j + 1, k + 15, dungeonBricks);
        chunkPrimer.setBlock(i + 9, j + 2, k + 0, arcaniteMetal);
        chunkPrimer.setBlock(i + 9, j + 2, k + 4, ancientbricks);
        chunkPrimer.setBlock(i + 9, j + 2, k + 5, heatTraps);
        chunkPrimer.setBlock(i + 9, j + 2, k + 6, ancientbricks);
        chunkPrimer.setBlock(i + 9, j + 2, k + 9, ancientbricks);
        chunkPrimer.setBlock(i + 9, j + 2, k + 10, ancientbricks);
        chunkPrimer.setBlock(i + 9, j + 2, k + 11, ancientbricks);
        chunkPrimer.setBlock(i + 9, j + 2, k + 14, ancientbricks);
        chunkPrimer.setBlock(i + 9, j + 2, k + 15, ancientstone);
        chunkPrimer.setBlock(i + 9, j + 3, k + 0, arcaniteMetal);
        chunkPrimer.setBlock(i + 9, j + 3, k + 10, ancientbricks);
        chunkPrimer.setBlock(i + 9, j + 3, k + 11, dungeonBricks);
        chunkPrimer.setBlock(i + 9, j + 3, k + 12, ancientbricks);
        chunkPrimer.setBlock(i + 9, j + 3, k + 13, ancientbricks);
        chunkPrimer.setBlock(i + 9, j + 3, k + 14, dungeonBricks);
        chunkPrimer.setBlock(i + 9, j + 3, k + 15, ancientstone);
        chunkPrimer.setBlock(i + 9, j + 4, k + 0, dungeonBricks);
        chunkPrimer.setBlock(i + 9, j + 4, k + 15, dungeonBricks);
        chunkPrimer.setBlock(i + 9, j + 5, k + 0, ancientbricks);
        chunkPrimer.setBlock(i + 9, j + 5, k + 15, dungeonBricks);
        chunkPrimer.setBlock(i + 9, j + 6, k + 0, ancientbricks);
        chunkPrimer.setBlock(i + 9, j + 6, k + 15, dungeonBricks);
        chunkPrimer.setBlock(i + 9, j + 7, k + 0, ancientbricks);
        chunkPrimer.setBlock(i + 9, j + 7, k + 15, dungeonBricks);
        chunkPrimer.setBlock(i + 10, j + 0, k + 0, ancientbricks);
        chunkPrimer.setBlock(i + 10, j + 0, k + 1, ancientbricks);
        chunkPrimer.setBlock(i + 10, j + 0, k + 2, ancientbricks);
        chunkPrimer.setBlock(i + 10, j + 0, k + 3, ancientbricks);
        chunkPrimer.setBlock(i + 10, j + 0, k + 4, ancientbricks);
        chunkPrimer.setBlock(i + 10, j + 0, k + 5, ancientbricks);
        chunkPrimer.setBlock(i + 10, j + 0, k + 6, ancientbricks);
        chunkPrimer.setBlock(i + 10, j + 0, k + 7, ancientbricks);
        chunkPrimer.setBlock(i + 10, j + 0, k + 8, ancientbricks);
        chunkPrimer.setBlock(i + 10, j + 0, k + 9, ancientbricks);
        chunkPrimer.setBlock(i + 10, j + 0, k + 10, ancientbricks);
        chunkPrimer.setBlock(i + 10, j + 0, k + 11, ancientbricks);
        chunkPrimer.setBlock(i + 10, j + 0, k + 12, ancientbricks);
        chunkPrimer.setBlock(i + 10, j + 0, k + 13, ancientbricks);
        chunkPrimer.setBlock(i + 10, j + 0, k + 14, ancientbricks);
        chunkPrimer.setBlock(i + 10, j + 0, k + 15, dungeonBricks);
        chunkPrimer.setBlock(i + 10, j + 1, k + 0, dungeonBricks);
        chunkPrimer.setBlock(i + 10, j + 1, k + 2, ancientbricks);
        chunkPrimer.setBlock(i + 10, j + 1, k + 3, heatTraps);
        chunkPrimer.setBlock(i + 10, j + 1, k + 4, ancientbricks);
        chunkPrimer.setBlock(i + 10, j + 1, k + 5, ancientbricks);
        chunkPrimer.setBlock(i + 10, j + 1, k + 6, ancientbricks);
        chunkPrimer.setBlock(i + 10, j + 1, k + 7, heatTraps);
        chunkPrimer.setBlock(i + 10, j + 1, k + 8, heatTraps);
        chunkPrimer.setBlock(i + 10, j + 1, k + 9, ancientbricks);
        chunkPrimer.setBlock(i + 10, j + 1, k + 10, ancientbricks);
        chunkPrimer.setBlock(i + 10, j + 1, k + 11, ancientbricks);
        chunkPrimer.setBlock(i + 10, j + 1, k + 14, ancientbricks);
        chunkPrimer.setBlock(i + 10, j + 1, k + 15, dungeonBricks);
        chunkPrimer.setBlock(i + 10, j + 2, k + 0, dungeonBricks);
        chunkPrimer.setBlock(i + 10, j + 2, k + 4, ancientbricks);
        chunkPrimer.setBlock(i + 10, j + 2, k + 5, heatTraps);
        chunkPrimer.setBlock(i + 10, j + 2, k + 6, ancientbricks);
        chunkPrimer.setBlock(i + 10, j + 2, k + 9, ancientbricks);
        chunkPrimer.setBlock(i + 10, j + 2, k + 10, ancientbricks);
        chunkPrimer.setBlock(i + 10, j + 2, k + 11, ancientbricks);
        chunkPrimer.setBlock(i + 10, j + 2, k + 14, ancientbricks);
        chunkPrimer.setBlock(i + 10, j + 2, k + 15, dungeonBricks);
        chunkPrimer.setBlock(i + 10, j + 3, k + 0, dungeonBricks);
        chunkPrimer.setBlock(i + 10, j + 3, k + 10, ancientbricks);
        chunkPrimer.setBlock(i + 10, j + 3, k + 11, dungeonBricks);
        chunkPrimer.setBlock(i + 10, j + 3, k + 14, dungeonBricks);
        chunkPrimer.setBlock(i + 10, j + 3, k + 15, dungeonBricks);
        chunkPrimer.setBlock(i + 10, j + 4, k + 0, dungeonBricks);
        chunkPrimer.setBlock(i + 10, j + 4, k + 15, dungeonBricks);
        chunkPrimer.setBlock(i + 10, j + 5, k + 0, ancientbricks);
        chunkPrimer.setBlock(i + 10, j + 5, k + 15, dungeonBricks);
        chunkPrimer.setBlock(i + 10, j + 6, k + 0, ancientbricks);
        chunkPrimer.setBlock(i + 10, j + 6, k + 15, ArcanaBlocks.arcanaLamp);
        chunkPrimer.setBlock(i + 10, j + 7, k + 0, ancientbricks);
        chunkPrimer.setBlock(i + 10, j + 7, k + 15, dungeonBricks);
        chunkPrimer.setBlock(i + 11, j + 0, k + 0, ancientbricks);
        chunkPrimer.setBlock(i + 11, j + 0, k + 1, ancientbricks);
        chunkPrimer.setBlock(i + 11, j + 0, k + 2, ancientbricks);
        chunkPrimer.setBlock(i + 11, j + 0, k + 3, ancientbricks);
        chunkPrimer.setBlock(i + 11, j + 0, k + 4, ancientbricks);
        chunkPrimer.setBlock(i + 11, j + 0, k + 5, ancientbricks);
        chunkPrimer.setBlock(i + 11, j + 0, k + 6, ancientbricks);
        chunkPrimer.setBlock(i + 11, j + 0, k + 7, ancientbricks);
        chunkPrimer.setBlock(i + 11, j + 0, k + 8, ancientbricks);
        chunkPrimer.setBlock(i + 11, j + 0, k + 9, ancientbricks);
        chunkPrimer.setBlock(i + 11, j + 0, k + 10, ancientbricks);
        chunkPrimer.setBlock(i + 11, j + 0, k + 11, ancientbricks);
        chunkPrimer.setBlock(i + 11, j + 0, k + 12, ancientbricks);
        chunkPrimer.setBlock(i + 11, j + 0, k + 13, ancientbricks);
        chunkPrimer.setBlock(i + 11, j + 0, k + 14, ancientbricks);
        chunkPrimer.setBlock(i + 11, j + 0, k + 15, dungeonBricks);
        chunkPrimer.setBlock(i + 11, j + 1, k + 0, ancientbricks);
        chunkPrimer.setBlock(i + 11, j + 1, k + 1, ancientbricks);
        chunkPrimer.setBlock(i + 11, j + 1, k + 2, ancientbricks);
        chunkPrimer.setBlock(i + 11, j + 1, k + 3, heatTraps);
        chunkPrimer.setBlock(i + 11, j + 1, k + 4, ancientbricks);
        chunkPrimer.setBlock(i + 11, j + 1, k + 5, ancientbricks);
        chunkPrimer.setBlock(i + 11, j + 1, k + 6, ancientbricks);
        chunkPrimer.setBlock(i + 11, j + 1, k + 7, heatTraps);
        chunkPrimer.setBlock(i + 11, j + 1, k + 8, heatTraps);
        chunkPrimer.setBlock(i + 11, j + 1, k + 9, ancientbricks);
        chunkPrimer.setBlock(i + 11, j + 1, k + 10, ancientbricks);
        chunkPrimer.setBlock(i + 11, j + 1, k + 11, ancientbricks);
        chunkPrimer.setBlock(i + 11, j + 1, k + 14, ancientbricks);
        chunkPrimer.setBlock(i + 11, j + 1, k + 15, ancientstone);
        chunkPrimer.setBlock(i + 11, j + 2, k + 0, dungeonBricks);
        chunkPrimer.setBlock(i + 11, j + 2, k + 4, ancientbricks);
        chunkPrimer.setBlock(i + 11, j + 2, k + 5, heatTraps);
        chunkPrimer.setBlock(i + 11, j + 2, k + 6, ancientbricks);
        chunkPrimer.setBlock(i + 11, j + 2, k + 9, ancientbricks);
        chunkPrimer.setBlock(i + 11, j + 2, k + 10, ancientbricks);
        chunkPrimer.setBlock(i + 11, j + 2, k + 11, ancientbricks);
        chunkPrimer.setBlock(i + 11, j + 2, k + 14, ancientbricks);
        chunkPrimer.setBlock(i + 11, j + 2, k + 15, ancientstone);
        chunkPrimer.setBlock(i + 11, j + 3, k + 0, ancientbricks);
        chunkPrimer.setBlock(i + 11, j + 3, k + 10, ancientbricks);
        chunkPrimer.setBlock(i + 11, j + 3, k + 11, dungeonBricks);
        chunkPrimer.setBlock(i + 11, j + 3, k + 14, dungeonBricks);
        chunkPrimer.setBlock(i + 11, j + 3, k + 15, dungeonBricks);
        chunkPrimer.setBlock(i + 11, j + 4, k + 0, ancientbricks);
        chunkPrimer.setBlock(i + 11, j + 4, k + 15, dungeonBricks);
        chunkPrimer.setBlock(i + 11, j + 5, k + 0, ancientbricks);
        chunkPrimer.setBlock(i + 11, j + 5, k + 15, dungeonBricks);
        chunkPrimer.setBlock(i + 11, j + 6, k + 0, ancientbricks);
        chunkPrimer.setBlock(i + 11, j + 6, k + 15, dungeonBricks);
        chunkPrimer.setBlock(i + 11, j + 7, k + 0, ancientbricks);
        chunkPrimer.setBlock(i + 11, j + 7, k + 15, dungeonBricks);
        chunkPrimer.setBlock(i + 12, j + 0, k + 0, ancientbricks);
        chunkPrimer.setBlock(i + 12, j + 0, k + 1, ancientbricks);
        chunkPrimer.setBlock(i + 12, j + 0, k + 2, ancientbricks);
        chunkPrimer.setBlock(i + 12, j + 0, k + 3, ancientbricks);
        chunkPrimer.setBlock(i + 12, j + 0, k + 4, ancientbricks);
        chunkPrimer.setBlock(i + 12, j + 0, k + 5, ancientbricks);
        chunkPrimer.setBlock(i + 12, j + 0, k + 6, ancientbricks);
        chunkPrimer.setBlock(i + 12, j + 0, k + 7, ancientbricks);
        chunkPrimer.setBlock(i + 12, j + 0, k + 8, ancientbricks);
        chunkPrimer.setBlock(i + 12, j + 0, k + 9, ancientbricks);
        chunkPrimer.setBlock(i + 12, j + 0, k + 10, ancientbricks);
        chunkPrimer.setBlock(i + 12, j + 0, k + 11, ancientbricks);
        chunkPrimer.setBlock(i + 12, j + 0, k + 12, ancientbricks);
        chunkPrimer.setBlock(i + 12, j + 0, k + 13, ancientbricks);
        chunkPrimer.setBlock(i + 12, j + 0, k + 14, ancientbricks);
        chunkPrimer.setBlock(i + 12, j + 0, k + 15, dungeonBricks);
        chunkPrimer.setBlock(i + 12, j + 1, k + 0, heatTraps);
        chunkPrimer.setBlock(i + 12, j + 1, k + 1, heatTraps);
        chunkPrimer.setBlock(i + 12, j + 1, k + 2, heatTraps);
        chunkPrimer.setBlock(i + 12, j + 1, k + 3, heatTraps);
        chunkPrimer.setBlock(i + 12, j + 1, k + 4, ancientbricks);
        chunkPrimer.setBlock(i + 12, j + 1, k + 5, dungeonBricks);
        chunkPrimer.setBlock(i + 12, j + 1, k + 6, ancientbricks);
        chunkPrimer.setBlock(i + 12, j + 1, k + 7, heatTraps);
        chunkPrimer.setBlock(i + 12, j + 1, k + 8, heatTraps);
        chunkPrimer.setBlock(i + 12, j + 1, k + 9, ancientbricks);
        chunkPrimer.setBlock(i + 12, j + 1, k + 10, ancientbricks);
        chunkPrimer.setBlock(i + 12, j + 1, k + 11, ancientbricks);
        chunkPrimer.setBlock(i + 12, j + 1, k + 12, ancientbricks);
        chunkPrimer.setBlock(i + 12, j + 1, k + 13, ancientbricks);
        chunkPrimer.setBlock(i + 12, j + 1, k + 14, ancientbricks);
        chunkPrimer.setBlock(i + 12, j + 1, k + 15, ancientstone);
        chunkPrimer.setBlock(i + 12, j + 2, k + 0, dungeonBricks);
        chunkPrimer.setBlock(i + 12, j + 2, k + 4, ancientbricks);
        chunkPrimer.setBlock(i + 12, j + 2, k + 5, heatTraps);
        chunkPrimer.setBlock(i + 12, j + 2, k + 6, ancientbricks);
        chunkPrimer.setBlock(i + 12, j + 2, k + 9, ancientbricks);
        chunkPrimer.setBlock(i + 12, j + 2, k + 10, ancientbricks);
        chunkPrimer.setBlock(i + 12, j + 2, k + 11, ancientbricks);
        chunkPrimer.setBlock(i + 12, j + 2, k + 14, ancientbricks);
        chunkPrimer.setBlock(i + 12, j + 2, k + 15, dungeonBricks);
        chunkPrimer.setBlock(i + 12, j + 3, k + 0, ancientbricks);
        chunkPrimer.setBlock(i + 12, j + 3, k + 10, ancientbricks);
        chunkPrimer.setBlock(i + 12, j + 3, k + 11, dungeonBricks);
        chunkPrimer.setBlock(i + 12, j + 3, k + 14, dungeonBricks);
        chunkPrimer.setBlock(i + 12, j + 3, k + 15, dungeonBricks);
        chunkPrimer.setBlock(i + 12, j + 4, k + 0, ancientbricks);
        chunkPrimer.setBlock(i + 12, j + 4, k + 15, dungeonBricks);
        chunkPrimer.setBlock(i + 12, j + 5, k + 0, ancientbricks);
        chunkPrimer.setBlock(i + 12, j + 5, k + 15, ancientbricks);
        chunkPrimer.setBlock(i + 12, j + 6, k + 0, ancientbricks);
        chunkPrimer.setBlock(i + 12, j + 6, k + 15, ancientbricks);
        chunkPrimer.setBlock(i + 12, j + 7, k + 0, ancientbricks);
        chunkPrimer.setBlock(i + 12, j + 7, k + 15, ancientbricks);
        chunkPrimer.setBlock(i + 13, j + 0, k + 0, ancientbricks);
        chunkPrimer.setBlock(i + 13, j + 0, k + 1, ancientbricks);
        chunkPrimer.setBlock(i + 13, j + 0, k + 2, ancientbricks);
        chunkPrimer.setBlock(i + 13, j + 0, k + 3, ancientbricks);
        chunkPrimer.setBlock(i + 13, j + 0, k + 4, ancientbricks);
        chunkPrimer.setBlock(i + 13, j + 0, k + 5, ancientbricks);
        chunkPrimer.setBlock(i + 13, j + 0, k + 6, ancientbricks);
        chunkPrimer.setBlock(i + 13, j + 0, k + 7, ancientbricks);
        chunkPrimer.setBlock(i + 13, j + 0, k + 8, ancientbricks);
        chunkPrimer.setBlock(i + 13, j + 0, k + 9, ancientbricks);
        chunkPrimer.setBlock(i + 13, j + 0, k + 10, ancientbricks);
        chunkPrimer.setBlock(i + 13, j + 0, k + 11, ancientbricks);
        chunkPrimer.setBlock(i + 13, j + 0, k + 12, ancientbricks);
        chunkPrimer.setBlock(i + 13, j + 0, k + 13, ancientbricks);
        chunkPrimer.setBlock(i + 13, j + 0, k + 14, ancientbricks);
        chunkPrimer.setBlock(i + 13, j + 0, k + 15, dungeonBricks);
        chunkPrimer.setBlock(i + 13, j + 1, k + 0, ancientbricks);
        chunkPrimer.setBlock(i + 13, j + 1, k + 1, ancientbricks);
        chunkPrimer.setBlock(i + 13, j + 1, k + 2, ancientbricks);
        chunkPrimer.setBlock(i + 13, j + 1, k + 3, ancientbricks);
        chunkPrimer.setBlock(i + 13, j + 1, k + 4, ancientbricks);
        chunkPrimer.setBlock(i + 13, j + 1, k + 5, dungeonBricks);
        chunkPrimer.setBlock(i + 13, j + 1, k + 6, ancientbricks);
        chunkPrimer.setBlock(i + 13, j + 1, k + 7, heatTraps);
        chunkPrimer.setBlock(i + 13, j + 1, k + 8, heatTraps);
        chunkPrimer.setBlock(i + 13, j + 1, k + 9, ancientbricks);
        chunkPrimer.setBlock(i + 13, j + 1, k + 10, ancientbricks);
        chunkPrimer.setBlock(i + 13, j + 1, k + 11, ancientbricks);
        chunkPrimer.setBlock(i + 13, j + 1, k + 12, ancientbricks);
        chunkPrimer.setBlock(i + 13, j + 1, k + 13, ancientbricks);
        chunkPrimer.setBlock(i + 13, j + 1, k + 14, ancientbricks);
        chunkPrimer.setBlock(i + 13, j + 1, k + 15, ancientstone);
        chunkPrimer.setBlock(i + 13, j + 2, k + 0, ancientbricks);
        chunkPrimer.setBlock(i + 13, j + 2, k + 1, ancientbricks);
        chunkPrimer.setBlock(i + 13, j + 2, k + 2, ancientbricks);
        chunkPrimer.setBlock(i + 13, j + 2, k + 3, ancientbricks);
        chunkPrimer.setBlock(i + 13, j + 2, k + 4, ancientbricks);
        chunkPrimer.setBlock(i + 13, j + 2, k + 5, heatTraps);
        chunkPrimer.setBlock(i + 13, j + 2, k + 6, ancientbricks);
        chunkPrimer.setBlock(i + 13, j + 2, k + 9, ancientbricks);
        chunkPrimer.setBlock(i + 13, j + 2, k + 10, ancientbricks);
        chunkPrimer.setBlock(i + 13, j + 2, k + 11, ancientbricks);
        chunkPrimer.setBlock(i + 13, j + 2, k + 12, ancientbricks);
        chunkPrimer.setBlock(i + 13, j + 2, k + 13, ancientbricks);
        chunkPrimer.setBlock(i + 13, j + 2, k + 14, ancientbricks);
        chunkPrimer.setBlock(i + 13, j + 2, k + 15, dungeonBricks);
        chunkPrimer.setBlock(i + 13, j + 3, k + 0, ancientbricks);
        chunkPrimer.setBlock(i + 13, j + 3, k + 10, ancientbricks);
        chunkPrimer.setBlock(i + 13, j + 3, k + 11, dungeonBricks);
        chunkPrimer.setBlock(i + 13, j + 3, k + 14, dungeonBricks);
        chunkPrimer.setBlock(i + 13, j + 3, k + 15, ancientstone);
        chunkPrimer.setBlock(i + 13, j + 4, k + 0, ancientbricks);
        chunkPrimer.setBlock(i + 13, j + 4, k + 15, dungeonBricks);
        chunkPrimer.setBlock(i + 13, j + 5, k + 0, ancientbricks);
        chunkPrimer.setBlock(i + 13, j + 5, k + 15, ancientbricks);
        chunkPrimer.setBlock(i + 13, j + 6, k + 0, ancientbricks);
        chunkPrimer.setBlock(i + 13, j + 6, k + 15, ancientTile);
        chunkPrimer.setBlock(i + 13, j + 7, k + 0, ancientbricks);
        chunkPrimer.setBlock(i + 13, j + 7, k + 15, ancientbricks);
        chunkPrimer.setBlock(i + 14, j + 0, k + 0, ancientbricks);
        chunkPrimer.setBlock(i + 14, j + 0, k + 1, ancientbricks);
        chunkPrimer.setBlock(i + 14, j + 0, k + 2, ancientbricks);
        chunkPrimer.setBlock(i + 14, j + 0, k + 3, ancientbricks);
        chunkPrimer.setBlock(i + 14, j + 0, k + 4, ancientbricks);
        chunkPrimer.setBlock(i + 14, j + 0, k + 5, ancientbricks);
        chunkPrimer.setBlock(i + 14, j + 0, k + 6, ancientbricks);
        chunkPrimer.setBlock(i + 14, j + 0, k + 7, ancientbricks);
        chunkPrimer.setBlock(i + 14, j + 0, k + 8, ancientbricks);
        chunkPrimer.setBlock(i + 14, j + 0, k + 9, ancientbricks);
        chunkPrimer.setBlock(i + 14, j + 0, k + 10, ancientbricks);
        chunkPrimer.setBlock(i + 14, j + 0, k + 11, ancientbricks);
        chunkPrimer.setBlock(i + 14, j + 0, k + 12, ancientbricks);
        chunkPrimer.setBlock(i + 14, j + 0, k + 13, ancientbricks);
        chunkPrimer.setBlock(i + 14, j + 0, k + 14, ancientbricks);
        chunkPrimer.setBlock(i + 14, j + 0, k + 15, dungeonBricks);
        chunkPrimer.setBlock(i + 14, j + 1, k + 0, dungeonBricks);
        chunkPrimer.setBlock(i + 14, j + 1, k + 1, dungeonBricks);
        chunkPrimer.setBlock(i + 14, j + 1, k + 2, dungeonBricks);
        chunkPrimer.setBlock(i + 14, j + 1, k + 3, dungeonBricks);
        chunkPrimer.setBlock(i + 14, j + 1, k + 4, dungeonBricks);
        chunkPrimer.setBlock(i + 14, j + 1, k + 5, dungeonBricks);
        chunkPrimer.setBlock(i + 14, j + 1, k + 6, ancientbricks);
        chunkPrimer.setBlock(i + 14, j + 1, k + 7, heatTraps);
        chunkPrimer.setBlock(i + 14, j + 1, k + 8, heatTraps);
        chunkPrimer.setBlock(i + 14, j + 1, k + 9, ancientbricks);
        chunkPrimer.setBlock(i + 14, j + 1, k + 10, ancientbricks);
        chunkPrimer.setBlock(i + 14, j + 1, k + 11, ancientbricks);
        chunkPrimer.setBlock(i + 14, j + 1, k + 12, ancientbricks);
        chunkPrimer.setBlock(i + 14, j + 1, k + 13, ancientbricks);
        chunkPrimer.setBlock(i + 14, j + 1, k + 14, ancientbricks);
        chunkPrimer.setBlock(i + 14, j + 1, k + 15, ancientstone);
        chunkPrimer.setBlock(i + 14, j + 2, k + 0, heatTraps);
        chunkPrimer.setBlock(i + 14, j + 2, k + 1, heatTraps);
        chunkPrimer.setBlock(i + 14, j + 2, k + 2, heatTraps);
        chunkPrimer.setBlock(i + 14, j + 2, k + 3, heatTraps);
        chunkPrimer.setBlock(i + 14, j + 2, k + 4, heatTraps);
        chunkPrimer.setBlock(i + 14, j + 2, k + 5, heatTraps);
        chunkPrimer.setBlock(i + 14, j + 2, k + 6, ancientbricks);
        chunkPrimer.setBlock(i + 14, j + 2, k + 9, ancientbricks);
        chunkPrimer.setBlock(i + 14, j + 2, k + 10, ancientbricks);
        chunkPrimer.setBlock(i + 14, j + 2, k + 11, ancientbricks);
        chunkPrimer.setBlock(i + 14, j + 2, k + 12, ancientbricks);
        chunkPrimer.setBlock(i + 14, j + 2, k + 13, ancientbricks);
        chunkPrimer.setBlock(i + 14, j + 2, k + 14, ancientbricks);
        chunkPrimer.setBlock(i + 14, j + 2, k + 15, dungeonBricks);
        chunkPrimer.setBlock(i + 14, j + 3, k + 0, ancientbricks);
        chunkPrimer.setBlock(i + 14, j + 3, k + 10, ancientbricks);
        chunkPrimer.setBlock(i + 14, j + 3, k + 11, dungeonBricks);
        chunkPrimer.setBlock(i + 14, j + 3, k + 12, dungeonBricks);
        chunkPrimer.setBlock(i + 14, j + 3, k + 13, dungeonBricks);
        chunkPrimer.setBlock(i + 14, j + 3, k + 14, dungeonBricks);
        chunkPrimer.setBlock(i + 14, j + 3, k + 15, dungeonBricks);
        chunkPrimer.setBlock(i + 14, j + 4, k + 0, ancientbricks);
        chunkPrimer.setBlock(i + 14, j + 4, k + 15, dungeonBricks);
        chunkPrimer.setBlock(i + 14, j + 5, k + 0, ancientbricks);
        chunkPrimer.setBlock(i + 14, j + 5, k + 15, ancientbricks);
        chunkPrimer.setBlock(i + 14, j + 6, k + 0, ancientbricks);
        chunkPrimer.setBlock(i + 14, j + 6, k + 15, ancientbricks);
        chunkPrimer.setBlock(i + 14, j + 7, k + 0, ancientbricks);
        chunkPrimer.setBlock(i + 14, j + 7, k + 15, ancientbricks);
        chunkPrimer.setBlock(i + 15, j + 0, k + 0, dungeonBricks);
        chunkPrimer.setBlock(i + 15, j + 0, k + 1, dungeonBricks);
        chunkPrimer.setBlock(i + 15, j + 0, k + 2, dungeonBricks);
        chunkPrimer.setBlock(i + 15, j + 0, k + 3, dungeonBricks);
        chunkPrimer.setBlock(i + 15, j + 0, k + 4, dungeonBricks);
        chunkPrimer.setBlock(i + 15, j + 0, k + 5, dungeonBricks);
        chunkPrimer.setBlock(i + 15, j + 0, k + 6, dungeonBricks);
        chunkPrimer.setBlock(i + 15, j + 0, k + 7, dungeonBricks);
        chunkPrimer.setBlock(i + 15, j + 0, k + 8, dungeonBricks);
        chunkPrimer.setBlock(i + 15, j + 0, k + 9, dungeonBricks);
        chunkPrimer.setBlock(i + 15, j + 0, k + 10, dungeonBricks);
        chunkPrimer.setBlock(i + 15, j + 0, k + 11, dungeonBricks);
        chunkPrimer.setBlock(i + 15, j + 0, k + 12, dungeonBricks);
        chunkPrimer.setBlock(i + 15, j + 0, k + 13, dungeonBricks);
        chunkPrimer.setBlock(i + 15, j + 0, k + 14, dungeonBricks);
        chunkPrimer.setBlock(i + 15, j + 0, k + 15, dungeonBricks);
        chunkPrimer.setBlock(i + 15, j + 1, k + 0, ancientstone);
        chunkPrimer.setBlock(i + 15, j + 1, k + 1, ancientstone);
        chunkPrimer.setBlock(i + 15, j + 1, k + 2, ancientstone);
        chunkPrimer.setBlock(i + 15, j + 1, k + 3, ancientstone);
        chunkPrimer.setBlock(i + 15, j + 1, k + 4, dungeonBricks);
        chunkPrimer.setBlock(i + 15, j + 1, k + 5, dungeonBricks);
        chunkPrimer.setBlock(i + 15, j + 1, k + 6, dungeonBricks);
        chunkPrimer.setBlock(i + 15, j + 1, k + 7, ancientstone);
        chunkPrimer.setBlock(i + 15, j + 1, k + 8, ancientstone);
        chunkPrimer.setBlock(i + 15, j + 1, k + 9, ancientstone);
        chunkPrimer.setBlock(i + 15, j + 1, k + 10, dungeonBricks);
        chunkPrimer.setBlock(i + 15, j + 1, k + 11, dungeonBricks);
        chunkPrimer.setBlock(i + 15, j + 1, k + 12, dungeonBricks);
        chunkPrimer.setBlock(i + 15, j + 1, k + 13, ancientstone);
        chunkPrimer.setBlock(i + 15, j + 1, k + 14, ancientstone);
        chunkPrimer.setBlock(i + 15, j + 1, k + 15, ancientstone);
        chunkPrimer.setBlock(i + 15, j + 2, k + 0, dungeonBricks);
        chunkPrimer.setBlock(i + 15, j + 2, k + 1, dungeonBricks);
        chunkPrimer.setBlock(i + 15, j + 2, k + 2, dungeonBricks);
        chunkPrimer.setBlock(i + 15, j + 2, k + 3, ancientstone);
        chunkPrimer.setBlock(i + 15, j + 2, k + 4, dungeonBricks);
        chunkPrimer.setBlock(i + 15, j + 2, k + 5, ancientstone);
        chunkPrimer.setBlock(i + 15, j + 2, k + 6, dungeonBricks);
        chunkPrimer.setBlock(i + 15, j + 2, k + 7, dungeonBricks);
        chunkPrimer.setBlock(i + 15, j + 2, k + 8, dungeonBricks);
        chunkPrimer.setBlock(i + 15, j + 2, k + 9, ancientstone);
        chunkPrimer.setBlock(i + 15, j + 2, k + 10, dungeonBricks);
        chunkPrimer.setBlock(i + 15, j + 2, k + 11, ancientstone);
        chunkPrimer.setBlock(i + 15, j + 2, k + 12, dungeonBricks);
        chunkPrimer.setBlock(i + 15, j + 2, k + 13, dungeonBricks);
        chunkPrimer.setBlock(i + 15, j + 2, k + 14, dungeonBricks);
        chunkPrimer.setBlock(i + 15, j + 2, k + 15, ancientstone);
        chunkPrimer.setBlock(i + 15, j + 3, k + 0, dungeonBricks);
        chunkPrimer.setBlock(i + 15, j + 3, k + 1, ancientstone);
        chunkPrimer.setBlock(i + 15, j + 3, k + 2, dungeonBricks);
        chunkPrimer.setBlock(i + 15, j + 3, k + 3, dungeonBricks);
        chunkPrimer.setBlock(i + 15, j + 3, k + 4, dungeonBricks);
        chunkPrimer.setBlock(i + 15, j + 3, k + 5, ancientstone);
        chunkPrimer.setBlock(i + 15, j + 3, k + 6, ancientstone);
        chunkPrimer.setBlock(i + 15, j + 3, k + 7, ancientstone);
        chunkPrimer.setBlock(i + 15, j + 3, k + 8, dungeonBricks);
        chunkPrimer.setBlock(i + 15, j + 3, k + 9, dungeonBricks);
        chunkPrimer.setBlock(i + 15, j + 3, k + 10, dungeonBricks);
        chunkPrimer.setBlock(i + 15, j + 3, k + 11, ancientstone);
        chunkPrimer.setBlock(i + 15, j + 3, k + 12, ancientstone);
        chunkPrimer.setBlock(i + 15, j + 3, k + 13, ancientstone);
        chunkPrimer.setBlock(i + 15, j + 3, k + 14, dungeonBricks);
        chunkPrimer.setBlock(i + 15, j + 3, k + 15, dungeonBricks);
        chunkPrimer.setBlock(i + 15, j + 4, k + 0, dungeonBricks);
        chunkPrimer.setBlock(i + 15, j + 4, k + 1, dungeonBricks);
        chunkPrimer.setBlock(i + 15, j + 4, k + 2, dungeonBricks);
        chunkPrimer.setBlock(i + 15, j + 4, k + 3, dungeonBricks);
        chunkPrimer.setBlock(i + 15, j + 4, k + 4, dungeonBricks);
        chunkPrimer.setBlock(i + 15, j + 4, k + 5, dungeonBricks);
        chunkPrimer.setBlock(i + 15, j + 4, k + 6, dungeonBricks);
        chunkPrimer.setBlock(i + 15, j + 4, k + 7, dungeonBricks);
        chunkPrimer.setBlock(i + 15, j + 4, k + 8, dungeonBricks);
        chunkPrimer.setBlock(i + 15, j + 4, k + 9, dungeonBricks);
        chunkPrimer.setBlock(i + 15, j + 4, k + 10, dungeonBricks);
        chunkPrimer.setBlock(i + 15, j + 4, k + 11, dungeonBricks);
        chunkPrimer.setBlock(i + 15, j + 4, k + 12, dungeonBricks);
        chunkPrimer.setBlock(i + 15, j + 4, k + 13, dungeonBricks);
        chunkPrimer.setBlock(i + 15, j + 4, k + 14, dungeonBricks);
        chunkPrimer.setBlock(i + 15, j + 4, k + 15, dungeonBricks);
        chunkPrimer.setBlock(i + 15, j + 5, k + 0, dungeonBricks);
        chunkPrimer.setBlock(i + 15, j + 5, k + 1, dungeonBricks);
        chunkPrimer.setBlock(i + 15, j + 5, k + 2, dungeonBricks);
        chunkPrimer.setBlock(i + 15, j + 5, k + 3, ancientbricks);
        chunkPrimer.setBlock(i + 15, j + 5, k + 4, ancientbricks);
        chunkPrimer.setBlock(i + 15, j + 5, k + 5, ancientbricks);
        chunkPrimer.setBlock(i + 15, j + 5, k + 6, dungeonBricks);
        chunkPrimer.setBlock(i + 15, j + 5, k + 7, dungeonBricks);
        chunkPrimer.setBlock(i + 15, j + 5, k + 8, dungeonBricks);
        chunkPrimer.setBlock(i + 15, j + 5, k + 9, ancientbricks);
        chunkPrimer.setBlock(i + 15, j + 5, k + 10, ancientbricks);
        chunkPrimer.setBlock(i + 15, j + 5, k + 11, ancientbricks);
        chunkPrimer.setBlock(i + 15, j + 5, k + 12, dungeonBricks);
        chunkPrimer.setBlock(i + 15, j + 5, k + 13, dungeonBricks);
        chunkPrimer.setBlock(i + 15, j + 5, k + 14, dungeonBricks);
        chunkPrimer.setBlock(i + 15, j + 5, k + 15, ancientbricks);
        chunkPrimer.setBlock(i + 15, j + 6, k + 0, dungeonBricks);
        chunkPrimer.setBlock(i + 15, j + 6, k + 1, ancientTile);
        chunkPrimer.setBlock(i + 15, j + 6, k + 2, dungeonBricks);
        chunkPrimer.setBlock(i + 15, j + 6, k + 3, ancientbricks);
        chunkPrimer.setBlock(i + 15, j + 6, k + 4, ancientTile);
        chunkPrimer.setBlock(i + 15, j + 6, k + 5, ancientbricks);
        chunkPrimer.setBlock(i + 15, j + 6, k + 6, dungeonBricks);
        chunkPrimer.setBlock(i + 15, j + 6, k + 7, ArcanaBlocks.arcanaLamp);
        chunkPrimer.setBlock(i + 15, j + 6, k + 8, dungeonBricks);
        chunkPrimer.setBlock(i + 15, j + 6, k + 9, ancientbricks);
        chunkPrimer.setBlock(i + 15, j + 6, k + 10, ancientTile);
        chunkPrimer.setBlock(i + 15, j + 6, k + 11, ancientbricks);
        chunkPrimer.setBlock(i + 15, j + 6, k + 12, dungeonBricks);
        chunkPrimer.setBlock(i + 15, j + 6, k + 13, ancientTile);
        chunkPrimer.setBlock(i + 15, j + 6, k + 14, dungeonBricks);
        chunkPrimer.setBlock(i + 15, j + 6, k + 15, ancientbricks);
        chunkPrimer.setBlock(i + 15, j + 7, k + 0, dungeonBricks);
        chunkPrimer.setBlock(i + 15, j + 7, k + 1, dungeonBricks);
        chunkPrimer.setBlock(i + 15, j + 7, k + 2, dungeonBricks);
        chunkPrimer.setBlock(i + 15, j + 7, k + 3, ancientbricks);
        chunkPrimer.setBlock(i + 15, j + 7, k + 4, ancientbricks);
        chunkPrimer.setBlock(i + 15, j + 7, k + 5, ancientbricks);
        chunkPrimer.setBlock(i + 15, j + 7, k + 6, dungeonBricks);
        chunkPrimer.setBlock(i + 15, j + 7, k + 7, dungeonBricks);
        chunkPrimer.setBlock(i + 15, j + 7, k + 8, dungeonBricks);
        chunkPrimer.setBlock(i + 15, j + 7, k + 9, ancientbricks);
        chunkPrimer.setBlock(i + 15, j + 7, k + 10, ancientbricks);
        chunkPrimer.setBlock(i + 15, j + 7, k + 11, ancientbricks);
        chunkPrimer.setBlock(i + 15, j + 7, k + 12, dungeonBricks);
        chunkPrimer.setBlock(i + 15, j + 7, k + 13, dungeonBricks);
        chunkPrimer.setBlock(i + 15, j + 7, k + 14, dungeonBricks);
        chunkPrimer.setBlock(i + 15, j + 7, k + 15, ancientbricks);
        return true;
    }
}

