/*
 * Decompiled with CFR 0.152.
 * 
 * Could not load the following classes:
 *  net.minecraft.block.Block
 */
package net.divinerpg.dimensions.arcana.components;

import java.util.Random;
import net.divinerpg.dimensions.arcana.ChunkPrimer;
import net.divinerpg.dimensions.arcana.components.DungeonComponentBase;
import net.divinerpg.utils.blocks.ArcanaBlocks;
import net.minecraft.block.Block;

public class DungeonComponent14
extends DungeonComponentBase {
    @Override
    public boolean generate(ChunkPrimer chunkPrimer, Random rand, int i, int j, int k) {
        Block dungeonBricks = ArcanaBlocks.degradedBrick;
        Block ancientbricks = ArcanaBlocks.ancientBrick;
        Block soulStone = ArcanaBlocks.soulStone;
        Block arcaniumSoulSludge = ArcanaBlocks.soulSludge;
        Block arcaniteMetal = ArcanaBlocks.arcaniumMetal;
        Block arcanaPower = ArcanaBlocks.arcaniumPower;
        chunkPrimer.setBlock(i + 0, j + 0, k + 0, ancientbricks);
        chunkPrimer.setBlock(i + 0, j + 0, k + 1, ancientbricks);
        chunkPrimer.setBlock(i + 0, j + 0, k + 2, ancientbricks);
        chunkPrimer.setBlock(i + 0, j + 0, k + 3, ancientbricks);
        chunkPrimer.setBlock(i + 0, j + 0, k + 4, ancientbricks);
        chunkPrimer.setBlock(i + 0, j + 0, k + 5, ancientbricks);
        chunkPrimer.setBlock(i + 0, j + 0, k + 6, ancientbricks);
        chunkPrimer.setBlock(i + 0, j + 0, k + 7, ancientbricks);
        chunkPrimer.setBlock(i + 0, j + 0, k + 8, ancientbricks);
        chunkPrimer.setBlock(i + 0, j + 0, k + 9, ancientbricks);
        chunkPrimer.setBlock(i + 0, j + 0, k + 10, ancientbricks);
        chunkPrimer.setBlock(i + 0, j + 0, k + 11, ancientbricks);
        chunkPrimer.setBlock(i + 0, j + 0, k + 12, ancientbricks);
        chunkPrimer.setBlock(i + 0, j + 0, k + 13, ancientbricks);
        chunkPrimer.setBlock(i + 0, j + 0, k + 14, ancientbricks);
        chunkPrimer.setBlock(i + 0, j + 0, k + 15, ancientbricks);
        chunkPrimer.setBlock(i + 0, j + 1, k + 0, dungeonBricks);
        chunkPrimer.setBlock(i + 0, j + 1, k + 1, dungeonBricks);
        chunkPrimer.setBlock(i + 0, j + 1, k + 2, dungeonBricks);
        chunkPrimer.setBlock(i + 0, j + 1, k + 3, dungeonBricks);
        chunkPrimer.setBlock(i + 0, j + 1, k + 4, dungeonBricks);
        chunkPrimer.setBlock(i + 0, j + 1, k + 5, dungeonBricks);
        chunkPrimer.setBlock(i + 0, j + 1, k + 6, arcaniteMetal);
        chunkPrimer.setBlock(i + 0, j + 1, k + 9, arcaniteMetal);
        chunkPrimer.setBlock(i + 0, j + 1, k + 10, dungeonBricks);
        chunkPrimer.setBlock(i + 0, j + 1, k + 11, dungeonBricks);
        chunkPrimer.setBlock(i + 0, j + 1, k + 12, dungeonBricks);
        chunkPrimer.setBlock(i + 0, j + 1, k + 13, dungeonBricks);
        chunkPrimer.setBlock(i + 0, j + 1, k + 14, dungeonBricks);
        chunkPrimer.setBlock(i + 0, j + 1, k + 15, dungeonBricks);
        chunkPrimer.setBlock(i + 0, j + 2, k + 0, ancientbricks);
        chunkPrimer.setBlock(i + 0, j + 2, k + 1, ancientbricks);
        chunkPrimer.setBlock(i + 0, j + 2, k + 2, ancientbricks);
        chunkPrimer.setBlock(i + 0, j + 2, k + 3, ancientbricks);
        chunkPrimer.setBlock(i + 0, j + 2, k + 4, ancientbricks);
        chunkPrimer.setBlock(i + 0, j + 2, k + 5, ancientbricks);
        chunkPrimer.setBlock(i + 0, j + 2, k + 6, arcaniteMetal);
        chunkPrimer.setBlock(i + 0, j + 2, k + 9, arcaniteMetal);
        chunkPrimer.setBlock(i + 0, j + 2, k + 10, ancientbricks);
        chunkPrimer.setBlock(i + 0, j + 2, k + 11, ancientbricks);
        chunkPrimer.setBlock(i + 0, j + 2, k + 12, ancientbricks);
        chunkPrimer.setBlock(i + 0, j + 2, k + 13, ancientbricks);
        chunkPrimer.setBlock(i + 0, j + 2, k + 14, ancientbricks);
        chunkPrimer.setBlock(i + 0, j + 2, k + 15, ancientbricks);
        chunkPrimer.setBlock(i + 0, j + 3, k + 0, dungeonBricks);
        chunkPrimer.setBlock(i + 0, j + 3, k + 1, dungeonBricks);
        chunkPrimer.setBlock(i + 0, j + 3, k + 2, dungeonBricks);
        chunkPrimer.setBlock(i + 0, j + 3, k + 3, dungeonBricks);
        chunkPrimer.setBlock(i + 0, j + 3, k + 4, dungeonBricks);
        chunkPrimer.setBlock(i + 0, j + 3, k + 5, dungeonBricks);
        chunkPrimer.setBlock(i + 0, j + 3, k + 6, arcaniteMetal);
        chunkPrimer.setBlock(i + 0, j + 3, k + 7, arcanaPower);
        chunkPrimer.setBlock(i + 0, j + 3, k + 8, arcanaPower);
        chunkPrimer.setBlock(i + 0, j + 3, k + 9, arcaniteMetal);
        chunkPrimer.setBlock(i + 0, j + 3, k + 10, dungeonBricks);
        chunkPrimer.setBlock(i + 0, j + 3, k + 11, dungeonBricks);
        chunkPrimer.setBlock(i + 0, j + 3, k + 12, dungeonBricks);
        chunkPrimer.setBlock(i + 0, j + 3, k + 13, dungeonBricks);
        chunkPrimer.setBlock(i + 0, j + 3, k + 14, dungeonBricks);
        chunkPrimer.setBlock(i + 0, j + 3, k + 15, dungeonBricks);
        chunkPrimer.setBlock(i + 0, j + 4, k + 0, arcaniumSoulSludge);
        chunkPrimer.setBlock(i + 0, j + 4, k + 1, arcaniumSoulSludge);
        chunkPrimer.setBlock(i + 0, j + 4, k + 2, arcaniumSoulSludge);
        chunkPrimer.setBlock(i + 0, j + 4, k + 3, arcaniumSoulSludge);
        chunkPrimer.setBlock(i + 0, j + 4, k + 4, arcaniumSoulSludge);
        chunkPrimer.setBlock(i + 0, j + 4, k + 5, arcaniumSoulSludge);
        chunkPrimer.setBlock(i + 0, j + 4, k + 6, arcaniumSoulSludge);
        chunkPrimer.setBlock(i + 0, j + 4, k + 7, arcaniumSoulSludge);
        chunkPrimer.setBlock(i + 0, j + 4, k + 8, arcaniumSoulSludge);
        chunkPrimer.setBlock(i + 0, j + 4, k + 9, arcaniumSoulSludge);
        chunkPrimer.setBlock(i + 0, j + 4, k + 10, arcaniumSoulSludge);
        chunkPrimer.setBlock(i + 0, j + 4, k + 11, arcaniumSoulSludge);
        chunkPrimer.setBlock(i + 0, j + 4, k + 12, arcaniumSoulSludge);
        chunkPrimer.setBlock(i + 0, j + 4, k + 13, arcaniumSoulSludge);
        chunkPrimer.setBlock(i + 0, j + 4, k + 14, arcaniumSoulSludge);
        chunkPrimer.setBlock(i + 0, j + 4, k + 15, arcaniumSoulSludge);
        chunkPrimer.setBlock(i + 0, j + 5, k + 0, arcaniumSoulSludge);
        chunkPrimer.setBlock(i + 0, j + 5, k + 1, arcaniumSoulSludge);
        chunkPrimer.setBlock(i + 0, j + 5, k + 2, arcaniumSoulSludge);
        chunkPrimer.setBlock(i + 0, j + 5, k + 3, arcaniumSoulSludge);
        chunkPrimer.setBlock(i + 0, j + 5, k + 4, arcaniumSoulSludge);
        chunkPrimer.setBlock(i + 0, j + 5, k + 5, arcaniumSoulSludge);
        chunkPrimer.setBlock(i + 0, j + 5, k + 6, arcaniumSoulSludge);
        chunkPrimer.setBlock(i + 0, j + 5, k + 7, arcaniumSoulSludge);
        chunkPrimer.setBlock(i + 0, j + 5, k + 8, arcaniumSoulSludge);
        chunkPrimer.setBlock(i + 0, j + 5, k + 9, arcaniumSoulSludge);
        chunkPrimer.setBlock(i + 0, j + 5, k + 10, arcaniumSoulSludge);
        chunkPrimer.setBlock(i + 0, j + 5, k + 11, arcaniumSoulSludge);
        chunkPrimer.setBlock(i + 0, j + 5, k + 12, arcaniumSoulSludge);
        chunkPrimer.setBlock(i + 0, j + 5, k + 13, arcaniumSoulSludge);
        chunkPrimer.setBlock(i + 0, j + 5, k + 14, arcaniumSoulSludge);
        chunkPrimer.setBlock(i + 0, j + 5, k + 15, arcaniumSoulSludge);
        chunkPrimer.setBlock(i + 0, j + 6, k + 0, arcaniumSoulSludge);
        chunkPrimer.setBlock(i + 0, j + 6, k + 1, arcaniumSoulSludge);
        chunkPrimer.setBlock(i + 0, j + 6, k + 2, arcaniumSoulSludge);
        chunkPrimer.setBlock(i + 0, j + 6, k + 3, arcaniumSoulSludge);
        chunkPrimer.setBlock(i + 0, j + 6, k + 4, arcaniumSoulSludge);
        chunkPrimer.setBlock(i + 0, j + 6, k + 5, arcaniumSoulSludge);
        chunkPrimer.setBlock(i + 0, j + 6, k + 6, arcaniumSoulSludge);
        chunkPrimer.setBlock(i + 0, j + 6, k + 7, arcaniumSoulSludge);
        chunkPrimer.setBlock(i + 0, j + 6, k + 8, arcaniumSoulSludge);
        chunkPrimer.setBlock(i + 0, j + 6, k + 9, arcaniumSoulSludge);
        chunkPrimer.setBlock(i + 0, j + 6, k + 10, arcaniumSoulSludge);
        chunkPrimer.setBlock(i + 0, j + 6, k + 11, arcaniumSoulSludge);
        chunkPrimer.setBlock(i + 0, j + 6, k + 12, arcaniumSoulSludge);
        chunkPrimer.setBlock(i + 0, j + 6, k + 13, arcaniumSoulSludge);
        chunkPrimer.setBlock(i + 0, j + 6, k + 14, arcaniumSoulSludge);
        chunkPrimer.setBlock(i + 0, j + 6, k + 15, arcaniumSoulSludge);
        chunkPrimer.setBlock(i + 0, j + 7, k + 0, dungeonBricks);
        chunkPrimer.setBlock(i + 0, j + 7, k + 1, dungeonBricks);
        chunkPrimer.setBlock(i + 0, j + 7, k + 2, dungeonBricks);
        chunkPrimer.setBlock(i + 0, j + 7, k + 3, dungeonBricks);
        chunkPrimer.setBlock(i + 0, j + 7, k + 4, dungeonBricks);
        chunkPrimer.setBlock(i + 0, j + 7, k + 5, dungeonBricks);
        chunkPrimer.setBlock(i + 0, j + 7, k + 6, dungeonBricks);
        chunkPrimer.setBlock(i + 0, j + 7, k + 7, dungeonBricks);
        chunkPrimer.setBlock(i + 0, j + 7, k + 8, dungeonBricks);
        chunkPrimer.setBlock(i + 0, j + 7, k + 9, dungeonBricks);
        chunkPrimer.setBlock(i + 0, j + 7, k + 10, dungeonBricks);
        chunkPrimer.setBlock(i + 0, j + 7, k + 11, dungeonBricks);
        chunkPrimer.setBlock(i + 0, j + 7, k + 12, dungeonBricks);
        chunkPrimer.setBlock(i + 0, j + 7, k + 13, dungeonBricks);
        chunkPrimer.setBlock(i + 0, j + 7, k + 14, dungeonBricks);
        chunkPrimer.setBlock(i + 0, j + 7, k + 15, dungeonBricks);
        chunkPrimer.setBlock(i + 1, j + 0, k + 0, ancientbricks);
        chunkPrimer.setBlock(i + 1, j + 0, k + 1, soulStone);
        chunkPrimer.setBlock(i + 1, j + 0, k + 2, soulStone);
        chunkPrimer.setBlock(i + 1, j + 0, k + 3, soulStone);
        chunkPrimer.setBlock(i + 1, j + 0, k + 4, soulStone);
        chunkPrimer.setBlock(i + 1, j + 0, k + 5, soulStone);
        chunkPrimer.setBlock(i + 1, j + 0, k + 6, soulStone);
        chunkPrimer.setBlock(i + 1, j + 0, k + 7, soulStone);
        chunkPrimer.setBlock(i + 1, j + 0, k + 8, soulStone);
        chunkPrimer.setBlock(i + 1, j + 0, k + 9, soulStone);
        chunkPrimer.setBlock(i + 1, j + 0, k + 10, soulStone);
        chunkPrimer.setBlock(i + 1, j + 0, k + 11, soulStone);
        chunkPrimer.setBlock(i + 1, j + 0, k + 12, soulStone);
        chunkPrimer.setBlock(i + 1, j + 0, k + 13, soulStone);
        chunkPrimer.setBlock(i + 1, j + 0, k + 14, soulStone);
        chunkPrimer.setBlock(i + 1, j + 0, k + 15, ancientbricks);
        chunkPrimer.setBlock(i + 1, j + 1, k + 0, dungeonBricks);
        chunkPrimer.setBlock(i + 1, j + 1, k + 12, ArcanaBlocks.ancientBrickDoor, 1);
        chunkPrimer.setBlock(i + 1, j + 1, k + 15, dungeonBricks);
        chunkPrimer.setBlock(i + 1, j + 2, k + 0, ancientbricks);
        chunkPrimer.setBlock(i + 1, j + 2, k + 12, ArcanaBlocks.ancientBrickDoor, 8);
        chunkPrimer.setBlock(i + 1, j + 2, k + 15, ancientbricks);
        chunkPrimer.setBlock(i + 1, j + 3, k + 0, dungeonBricks);
        chunkPrimer.setBlock(i + 1, j + 3, k + 12, ancientbricks);
        chunkPrimer.setBlock(i + 1, j + 3, k + 13, dungeonBricks);
        chunkPrimer.setBlock(i + 1, j + 3, k + 14, dungeonBricks);
        chunkPrimer.setBlock(i + 1, j + 3, k + 15, dungeonBricks);
        chunkPrimer.setBlock(i + 1, j + 4, k + 0, arcaniumSoulSludge);
        chunkPrimer.setBlock(i + 1, j + 4, k + 12, ArcanaBlocks.arcanaLamp);
        chunkPrimer.setBlock(i + 1, j + 4, k + 15, arcaniumSoulSludge);
        chunkPrimer.setBlock(i + 1, j + 5, k + 0, arcaniumSoulSludge);
        chunkPrimer.setBlock(i + 1, j + 5, k + 15, arcaniumSoulSludge);
        chunkPrimer.setBlock(i + 1, j + 6, k + 0, arcaniumSoulSludge);
        chunkPrimer.setBlock(i + 1, j + 6, k + 15, arcaniumSoulSludge);
        chunkPrimer.setBlock(i + 1, j + 7, k + 0, dungeonBricks);
        chunkPrimer.setBlock(i + 1, j + 7, k + 15, dungeonBricks);
        chunkPrimer.setBlock(i + 2, j + 0, k + 0, ancientbricks);
        chunkPrimer.setBlock(i + 2, j + 0, k + 1, soulStone);
        chunkPrimer.setBlock(i + 2, j + 0, k + 2, soulStone);
        chunkPrimer.setBlock(i + 2, j + 0, k + 3, soulStone);
        chunkPrimer.setBlock(i + 2, j + 0, k + 4, soulStone);
        chunkPrimer.setBlock(i + 2, j + 0, k + 5, soulStone);
        chunkPrimer.setBlock(i + 2, j + 0, k + 6, soulStone);
        chunkPrimer.setBlock(i + 2, j + 0, k + 7, soulStone);
        chunkPrimer.setBlock(i + 2, j + 0, k + 8, soulStone);
        chunkPrimer.setBlock(i + 2, j + 0, k + 9, soulStone);
        chunkPrimer.setBlock(i + 2, j + 0, k + 10, soulStone);
        chunkPrimer.setBlock(i + 2, j + 0, k + 11, soulStone);
        chunkPrimer.setBlock(i + 2, j + 0, k + 12, soulStone);
        chunkPrimer.setBlock(i + 2, j + 0, k + 13, soulStone);
        chunkPrimer.setBlock(i + 2, j + 0, k + 14, soulStone);
        chunkPrimer.setBlock(i + 2, j + 0, k + 15, ancientbricks);
        chunkPrimer.setBlock(i + 2, j + 1, k + 0, dungeonBricks);
        chunkPrimer.setBlock(i + 2, j + 1, k + 2, dungeonBricks);
        chunkPrimer.setBlock(i + 2, j + 1, k + 3, dungeonBricks);
        chunkPrimer.setBlock(i + 2, j + 1, k + 4, dungeonBricks);
        chunkPrimer.setBlock(i + 2, j + 1, k + 5, dungeonBricks);
        chunkPrimer.setBlock(i + 2, j + 1, k + 12, arcaniteMetal);
        chunkPrimer.setBlock(i + 2, j + 1, k + 15, dungeonBricks);
        chunkPrimer.setBlock(i + 2, j + 2, k + 0, ancientbricks);
        chunkPrimer.setBlock(i + 2, j + 2, k + 12, arcaniteMetal);
        chunkPrimer.setBlock(i + 2, j + 2, k + 15, ancientbricks);
        chunkPrimer.setBlock(i + 2, j + 3, k + 0, dungeonBricks);
        chunkPrimer.setBlock(i + 2, j + 3, k + 12, arcaniteMetal);
        chunkPrimer.setBlock(i + 2, j + 3, k + 13, dungeonBricks);
        chunkPrimer.setBlock(i + 2, j + 3, k + 14, dungeonBricks);
        chunkPrimer.setBlock(i + 2, j + 3, k + 15, dungeonBricks);
        chunkPrimer.setBlock(i + 2, j + 4, k + 0, arcaniumSoulSludge);
        chunkPrimer.setBlock(i + 2, j + 4, k + 12, arcaniteMetal);
        chunkPrimer.setBlock(i + 2, j + 4, k + 15, arcaniumSoulSludge);
        chunkPrimer.setBlock(i + 2, j + 5, k + 0, arcaniumSoulSludge);
        chunkPrimer.setBlock(i + 2, j + 5, k + 15, arcaniumSoulSludge);
        chunkPrimer.setBlock(i + 2, j + 6, k + 0, arcaniumSoulSludge);
        chunkPrimer.setBlock(i + 2, j + 6, k + 15, arcaniumSoulSludge);
        chunkPrimer.setBlock(i + 2, j + 7, k + 0, dungeonBricks);
        chunkPrimer.setBlock(i + 2, j + 7, k + 2, dungeonBricks);
        chunkPrimer.setBlock(i + 2, j + 7, k + 3, dungeonBricks);
        chunkPrimer.setBlock(i + 2, j + 7, k + 4, dungeonBricks);
        chunkPrimer.setBlock(i + 2, j + 7, k + 5, dungeonBricks);
        chunkPrimer.setBlock(i + 2, j + 7, k + 15, dungeonBricks);
        chunkPrimer.setBlock(i + 3, j + 0, k + 0, ancientbricks);
        chunkPrimer.setBlock(i + 3, j + 0, k + 1, soulStone);
        chunkPrimer.setBlock(i + 3, j + 0, k + 2, soulStone);
        chunkPrimer.setBlock(i + 3, j + 0, k + 3, soulStone);
        chunkPrimer.setBlock(i + 3, j + 0, k + 4, soulStone);
        chunkPrimer.setBlock(i + 3, j + 0, k + 5, soulStone);
        chunkPrimer.setBlock(i + 3, j + 0, k + 6, soulStone);
        chunkPrimer.setBlock(i + 3, j + 0, k + 7, soulStone);
        chunkPrimer.setBlock(i + 3, j + 0, k + 8, soulStone);
        chunkPrimer.setBlock(i + 3, j + 0, k + 9, soulStone);
        chunkPrimer.setBlock(i + 3, j + 0, k + 10, soulStone);
        chunkPrimer.setBlock(i + 3, j + 0, k + 11, soulStone);
        chunkPrimer.setBlock(i + 3, j + 0, k + 12, soulStone);
        chunkPrimer.setBlock(i + 3, j + 0, k + 13, soulStone);
        chunkPrimer.setBlock(i + 3, j + 0, k + 14, soulStone);
        chunkPrimer.setBlock(i + 3, j + 0, k + 15, ancientbricks);
        chunkPrimer.setBlock(i + 3, j + 1, k + 0, dungeonBricks);
        chunkPrimer.setBlock(i + 3, j + 1, k + 2, dungeonBricks);
        chunkPrimer.setBlock(i + 3, j + 1, k + 3, ancientbricks);
        chunkPrimer.setBlock(i + 3, j + 1, k + 4, ancientbricks);
        chunkPrimer.setBlock(i + 3, j + 1, k + 5, dungeonBricks);
        chunkPrimer.setBlock(i + 3, j + 1, k + 12, ancientbricks);
        chunkPrimer.setBlock(i + 3, j + 1, k + 15, dungeonBricks);
        chunkPrimer.setBlock(i + 3, j + 2, k + 0, ancientbricks);
        chunkPrimer.setBlock(i + 3, j + 2, k + 3, ancientbricks);
        chunkPrimer.setBlock(i + 3, j + 2, k + 4, ancientbricks);
        chunkPrimer.setBlock(i + 3, j + 2, k + 12, ancientbricks);
        chunkPrimer.setBlock(i + 3, j + 2, k + 15, ancientbricks);
        chunkPrimer.setBlock(i + 3, j + 3, k + 0, dungeonBricks);
        chunkPrimer.setBlock(i + 3, j + 3, k + 3, ancientbricks);
        chunkPrimer.setBlock(i + 3, j + 3, k + 4, ancientbricks);
        chunkPrimer.setBlock(i + 3, j + 3, k + 12, ancientbricks);
        chunkPrimer.setBlock(i + 3, j + 3, k + 13, dungeonBricks);
        chunkPrimer.setBlock(i + 3, j + 3, k + 14, dungeonBricks);
        chunkPrimer.setBlock(i + 3, j + 3, k + 15, dungeonBricks);
        chunkPrimer.setBlock(i + 3, j + 4, k + 0, arcaniumSoulSludge);
        chunkPrimer.setBlock(i + 3, j + 4, k + 3, ancientbricks);
        chunkPrimer.setBlock(i + 3, j + 4, k + 4, ancientbricks);
        chunkPrimer.setBlock(i + 3, j + 4, k + 12, arcaniteMetal);
        chunkPrimer.setBlock(i + 3, j + 4, k + 15, arcaniumSoulSludge);
        chunkPrimer.setBlock(i + 3, j + 5, k + 0, arcaniumSoulSludge);
        chunkPrimer.setBlock(i + 3, j + 5, k + 3, ancientbricks);
        chunkPrimer.setBlock(i + 3, j + 5, k + 4, ancientbricks);
        chunkPrimer.setBlock(i + 3, j + 5, k + 15, arcaniumSoulSludge);
        chunkPrimer.setBlock(i + 3, j + 6, k + 0, arcaniumSoulSludge);
        chunkPrimer.setBlock(i + 3, j + 6, k + 3, ancientbricks);
        chunkPrimer.setBlock(i + 3, j + 6, k + 4, ancientbricks);
        chunkPrimer.setBlock(i + 3, j + 6, k + 15, arcaniumSoulSludge);
        chunkPrimer.setBlock(i + 3, j + 7, k + 0, dungeonBricks);
        chunkPrimer.setBlock(i + 3, j + 7, k + 2, dungeonBricks);
        chunkPrimer.setBlock(i + 3, j + 7, k + 3, dungeonBricks);
        chunkPrimer.setBlock(i + 3, j + 7, k + 4, dungeonBricks);
        chunkPrimer.setBlock(i + 3, j + 7, k + 5, dungeonBricks);
        chunkPrimer.setBlock(i + 3, j + 7, k + 15, dungeonBricks);
        chunkPrimer.setBlock(i + 4, j + 0, k + 0, ancientbricks);
        chunkPrimer.setBlock(i + 4, j + 0, k + 1, soulStone);
        chunkPrimer.setBlock(i + 4, j + 0, k + 2, soulStone);
        chunkPrimer.setBlock(i + 4, j + 0, k + 3, soulStone);
        chunkPrimer.setBlock(i + 4, j + 0, k + 4, soulStone);
        chunkPrimer.setBlock(i + 4, j + 0, k + 5, soulStone);
        chunkPrimer.setBlock(i + 4, j + 0, k + 6, soulStone);
        chunkPrimer.setBlock(i + 4, j + 0, k + 7, soulStone);
        chunkPrimer.setBlock(i + 4, j + 0, k + 8, soulStone);
        chunkPrimer.setBlock(i + 4, j + 0, k + 9, soulStone);
        chunkPrimer.setBlock(i + 4, j + 0, k + 10, soulStone);
        chunkPrimer.setBlock(i + 4, j + 0, k + 11, soulStone);
        chunkPrimer.setBlock(i + 4, j + 0, k + 12, soulStone);
        chunkPrimer.setBlock(i + 4, j + 0, k + 13, soulStone);
        chunkPrimer.setBlock(i + 4, j + 0, k + 14, soulStone);
        chunkPrimer.setBlock(i + 4, j + 0, k + 15, ancientbricks);
        chunkPrimer.setBlock(i + 4, j + 1, k + 0, dungeonBricks);
        chunkPrimer.setBlock(i + 4, j + 1, k + 2, dungeonBricks);
        chunkPrimer.setBlock(i + 4, j + 1, k + 3, ancientbricks);
        chunkPrimer.setBlock(i + 4, j + 1, k + 4, ancientbricks);
        chunkPrimer.setBlock(i + 4, j + 1, k + 5, dungeonBricks);
        chunkPrimer.setBlock(i + 4, j + 1, k + 12, ancientbricks);
        chunkPrimer.setBlock(i + 4, j + 1, k + 15, dungeonBricks);
        chunkPrimer.setBlock(i + 4, j + 2, k + 0, ancientbricks);
        chunkPrimer.setBlock(i + 4, j + 2, k + 3, ancientbricks);
        chunkPrimer.setBlock(i + 4, j + 2, k + 4, ancientbricks);
        chunkPrimer.setBlock(i + 4, j + 2, k + 12, ancientbricks);
        chunkPrimer.setBlock(i + 4, j + 2, k + 15, ancientbricks);
        chunkPrimer.setBlock(i + 4, j + 3, k + 0, dungeonBricks);
        chunkPrimer.setBlock(i + 4, j + 3, k + 3, ancientbricks);
        chunkPrimer.setBlock(i + 4, j + 3, k + 4, ancientbricks);
        chunkPrimer.setBlock(i + 4, j + 3, k + 12, ancientbricks);
        chunkPrimer.setBlock(i + 4, j + 3, k + 13, dungeonBricks);
        chunkPrimer.setBlock(i + 4, j + 3, k + 14, dungeonBricks);
        chunkPrimer.setBlock(i + 4, j + 3, k + 15, dungeonBricks);
        chunkPrimer.setBlock(i + 4, j + 4, k + 0, arcaniumSoulSludge);
        chunkPrimer.setBlock(i + 4, j + 4, k + 3, ancientbricks);
        chunkPrimer.setBlock(i + 4, j + 4, k + 4, ancientbricks);
        chunkPrimer.setBlock(i + 4, j + 4, k + 12, arcaniteMetal);
        chunkPrimer.setBlock(i + 4, j + 4, k + 15, arcaniumSoulSludge);
        chunkPrimer.setBlock(i + 4, j + 5, k + 0, arcaniumSoulSludge);
        chunkPrimer.setBlock(i + 4, j + 5, k + 3, ancientbricks);
        chunkPrimer.setBlock(i + 4, j + 5, k + 4, ancientbricks);
        chunkPrimer.setBlock(i + 4, j + 5, k + 15, arcaniumSoulSludge);
        chunkPrimer.setBlock(i + 4, j + 6, k + 0, arcaniumSoulSludge);
        chunkPrimer.setBlock(i + 4, j + 6, k + 3, ancientbricks);
        chunkPrimer.setBlock(i + 4, j + 6, k + 4, ancientbricks);
        chunkPrimer.setBlock(i + 4, j + 6, k + 15, arcaniumSoulSludge);
        chunkPrimer.setBlock(i + 4, j + 7, k + 0, dungeonBricks);
        chunkPrimer.setBlock(i + 4, j + 7, k + 2, dungeonBricks);
        chunkPrimer.setBlock(i + 4, j + 7, k + 3, dungeonBricks);
        chunkPrimer.setBlock(i + 4, j + 7, k + 4, dungeonBricks);
        chunkPrimer.setBlock(i + 4, j + 7, k + 5, dungeonBricks);
        chunkPrimer.setBlock(i + 4, j + 7, k + 15, dungeonBricks);
        chunkPrimer.setBlock(i + 5, j + 0, k + 0, ancientbricks);
        chunkPrimer.setBlock(i + 5, j + 0, k + 1, soulStone);
        chunkPrimer.setBlock(i + 5, j + 0, k + 2, soulStone);
        chunkPrimer.setBlock(i + 5, j + 0, k + 3, soulStone);
        chunkPrimer.setBlock(i + 5, j + 0, k + 4, soulStone);
        chunkPrimer.setBlock(i + 5, j + 0, k + 5, soulStone);
        chunkPrimer.setBlock(i + 5, j + 0, k + 6, soulStone);
        chunkPrimer.setBlock(i + 5, j + 0, k + 7, soulStone);
        chunkPrimer.setBlock(i + 5, j + 0, k + 8, soulStone);
        chunkPrimer.setBlock(i + 5, j + 0, k + 9, soulStone);
        chunkPrimer.setBlock(i + 5, j + 0, k + 10, soulStone);
        chunkPrimer.setBlock(i + 5, j + 0, k + 11, soulStone);
        chunkPrimer.setBlock(i + 5, j + 0, k + 12, soulStone);
        chunkPrimer.setBlock(i + 5, j + 0, k + 13, soulStone);
        chunkPrimer.setBlock(i + 5, j + 0, k + 14, soulStone);
        chunkPrimer.setBlock(i + 5, j + 0, k + 15, ancientbricks);
        chunkPrimer.setBlock(i + 5, j + 1, k + 0, dungeonBricks);
        chunkPrimer.setBlock(i + 5, j + 1, k + 2, dungeonBricks);
        chunkPrimer.setBlock(i + 5, j + 1, k + 3, dungeonBricks);
        chunkPrimer.setBlock(i + 5, j + 1, k + 4, dungeonBricks);
        chunkPrimer.setBlock(i + 5, j + 1, k + 5, dungeonBricks);
        chunkPrimer.setBlock(i + 5, j + 1, k + 12, ancientbricks);
        chunkPrimer.setBlock(i + 5, j + 1, k + 13, ArcanaBlocks.soulSludgeDoor);
        chunkPrimer.setBlock(i + 5, j + 1, k + 14, ArcanaBlocks.soulSludgeDoor);
        chunkPrimer.setBlock(i + 5, j + 1, k + 15, dungeonBricks);
        chunkPrimer.setBlock(i + 5, j + 2, k + 0, ancientbricks);
        chunkPrimer.setBlock(i + 5, j + 2, k + 12, ancientbricks);
        chunkPrimer.setBlock(i + 5, j + 2, k + 13, ArcanaBlocks.soulSludgeDoor, 8);
        chunkPrimer.setBlock(i + 5, j + 2, k + 14, ArcanaBlocks.soulSludgeDoor, 9);
        chunkPrimer.setBlock(i + 5, j + 2, k + 15, ancientbricks);
        chunkPrimer.setBlock(i + 5, j + 3, k + 0, dungeonBricks);
        chunkPrimer.setBlock(i + 5, j + 3, k + 12, ancientbricks);
        chunkPrimer.setBlock(i + 5, j + 3, k + 13, dungeonBricks);
        chunkPrimer.setBlock(i + 5, j + 3, k + 14, dungeonBricks);
        chunkPrimer.setBlock(i + 5, j + 3, k + 15, dungeonBricks);
        chunkPrimer.setBlock(i + 5, j + 4, k + 0, arcaniumSoulSludge);
        chunkPrimer.setBlock(i + 5, j + 4, k + 12, arcaniteMetal);
        chunkPrimer.setBlock(i + 5, j + 4, k + 15, arcaniumSoulSludge);
        chunkPrimer.setBlock(i + 5, j + 5, k + 0, arcaniumSoulSludge);
        chunkPrimer.setBlock(i + 5, j + 5, k + 15, arcaniumSoulSludge);
        chunkPrimer.setBlock(i + 5, j + 6, k + 0, arcaniumSoulSludge);
        chunkPrimer.setBlock(i + 5, j + 6, k + 15, arcaniumSoulSludge);
        chunkPrimer.setBlock(i + 5, j + 7, k + 0, dungeonBricks);
        chunkPrimer.setBlock(i + 5, j + 7, k + 2, dungeonBricks);
        chunkPrimer.setBlock(i + 5, j + 7, k + 3, dungeonBricks);
        chunkPrimer.setBlock(i + 5, j + 7, k + 4, dungeonBricks);
        chunkPrimer.setBlock(i + 5, j + 7, k + 5, dungeonBricks);
        chunkPrimer.setBlock(i + 5, j + 7, k + 15, dungeonBricks);
        chunkPrimer.setBlock(i + 6, j + 0, k + 0, arcaniteMetal);
        chunkPrimer.setBlock(i + 6, j + 0, k + 1, soulStone);
        chunkPrimer.setBlock(i + 6, j + 0, k + 2, soulStone);
        chunkPrimer.setBlock(i + 6, j + 0, k + 3, soulStone);
        chunkPrimer.setBlock(i + 6, j + 0, k + 4, soulStone);
        chunkPrimer.setBlock(i + 6, j + 0, k + 5, soulStone);
        chunkPrimer.setBlock(i + 6, j + 0, k + 6, soulStone);
        chunkPrimer.setBlock(i + 6, j + 0, k + 7, soulStone);
        chunkPrimer.setBlock(i + 6, j + 0, k + 8, soulStone);
        chunkPrimer.setBlock(i + 6, j + 0, k + 9, soulStone);
        chunkPrimer.setBlock(i + 6, j + 0, k + 10, soulStone);
        chunkPrimer.setBlock(i + 6, j + 0, k + 11, soulStone);
        chunkPrimer.setBlock(i + 6, j + 0, k + 12, soulStone);
        chunkPrimer.setBlock(i + 6, j + 0, k + 13, soulStone);
        chunkPrimer.setBlock(i + 6, j + 0, k + 14, soulStone);
        chunkPrimer.setBlock(i + 6, j + 0, k + 15, ancientbricks);
        chunkPrimer.setBlock(i + 6, j + 1, k + 0, arcaniteMetal);
        chunkPrimer.setBlock(i + 6, j + 1, k + 12, ancientbricks);
        chunkPrimer.setBlock(i + 6, j + 1, k + 15, dungeonBricks);
        chunkPrimer.setBlock(i + 6, j + 2, k + 0, arcaniteMetal);
        chunkPrimer.setBlock(i + 6, j + 2, k + 12, ancientbricks);
        chunkPrimer.setBlock(i + 6, j + 2, k + 15, ancientbricks);
        chunkPrimer.setBlock(i + 6, j + 3, k + 0, arcaniteMetal);
        chunkPrimer.setBlock(i + 6, j + 3, k + 12, ancientbricks);
        chunkPrimer.setBlock(i + 6, j + 3, k + 13, dungeonBricks);
        chunkPrimer.setBlock(i + 6, j + 3, k + 14, dungeonBricks);
        chunkPrimer.setBlock(i + 6, j + 3, k + 15, dungeonBricks);
        chunkPrimer.setBlock(i + 6, j + 4, k + 0, arcaniumSoulSludge);
        chunkPrimer.setBlock(i + 6, j + 4, k + 12, arcaniteMetal);
        chunkPrimer.setBlock(i + 6, j + 4, k + 15, arcaniumSoulSludge);
        chunkPrimer.setBlock(i + 6, j + 5, k + 0, arcaniumSoulSludge);
        chunkPrimer.setBlock(i + 6, j + 5, k + 15, arcaniumSoulSludge);
        chunkPrimer.setBlock(i + 6, j + 6, k + 0, arcaniumSoulSludge);
        chunkPrimer.setBlock(i + 6, j + 6, k + 15, arcaniumSoulSludge);
        chunkPrimer.setBlock(i + 6, j + 7, k + 0, dungeonBricks);
        chunkPrimer.setBlock(i + 6, j + 7, k + 15, dungeonBricks);
        chunkPrimer.setBlock(i + 7, j + 0, k + 0, soulStone);
        chunkPrimer.setBlock(i + 7, j + 0, k + 1, soulStone);
        chunkPrimer.setBlock(i + 7, j + 0, k + 2, soulStone);
        chunkPrimer.setBlock(i + 7, j + 0, k + 3, soulStone);
        chunkPrimer.setBlock(i + 7, j + 0, k + 4, soulStone);
        chunkPrimer.setBlock(i + 7, j + 0, k + 5, soulStone);
        chunkPrimer.setBlock(i + 7, j + 0, k + 6, soulStone);
        chunkPrimer.setBlock(i + 7, j + 0, k + 7, soulStone);
        chunkPrimer.setBlock(i + 7, j + 0, k + 8, soulStone);
        chunkPrimer.setBlock(i + 7, j + 0, k + 9, soulStone);
        chunkPrimer.setBlock(i + 7, j + 0, k + 10, soulStone);
        chunkPrimer.setBlock(i + 7, j + 0, k + 11, soulStone);
        chunkPrimer.setBlock(i + 7, j + 0, k + 12, soulStone);
        chunkPrimer.setBlock(i + 7, j + 0, k + 13, ArcanaBlocks.arcanaLamp);
        chunkPrimer.setBlock(i + 7, j + 0, k + 14, soulStone);
        chunkPrimer.setBlock(i + 7, j + 0, k + 15, ancientbricks);
        chunkPrimer.setBlock(i + 7, j + 1, k + 12, ancientbricks);
        chunkPrimer.setBlock(i + 7, j + 1, k + 15, dungeonBricks);
        chunkPrimer.setBlock(i + 7, j + 2, k + 12, ancientbricks);
        chunkPrimer.setBlock(i + 7, j + 2, k + 15, ancientbricks);
        chunkPrimer.setBlock(i + 7, j + 3, k + 0, arcanaPower);
        chunkPrimer.setBlock(i + 7, j + 3, k + 12, ancientbricks);
        chunkPrimer.setBlock(i + 7, j + 3, k + 13, dungeonBricks);
        chunkPrimer.setBlock(i + 7, j + 3, k + 14, dungeonBricks);
        chunkPrimer.setBlock(i + 7, j + 3, k + 15, dungeonBricks);
        chunkPrimer.setBlock(i + 7, j + 4, k + 0, arcaniumSoulSludge);
        chunkPrimer.setBlock(i + 7, j + 4, k + 12, arcaniteMetal);
        chunkPrimer.setBlock(i + 7, j + 4, k + 15, arcaniumSoulSludge);
        chunkPrimer.setBlock(i + 7, j + 5, k + 0, arcaniumSoulSludge);
        chunkPrimer.setBlock(i + 7, j + 5, k + 15, arcaniumSoulSludge);
        chunkPrimer.setBlock(i + 7, j + 6, k + 0, arcaniumSoulSludge);
        chunkPrimer.setBlock(i + 7, j + 6, k + 15, arcaniumSoulSludge);
        chunkPrimer.setBlock(i + 7, j + 7, k + 0, dungeonBricks);
        chunkPrimer.setBlock(i + 7, j + 7, k + 15, dungeonBricks);
        chunkPrimer.setBlock(i + 8, j + 0, k + 0, soulStone);
        chunkPrimer.setBlock(i + 8, j + 0, k + 1, soulStone);
        chunkPrimer.setBlock(i + 8, j + 0, k + 2, soulStone);
        chunkPrimer.setBlock(i + 8, j + 0, k + 3, soulStone);
        chunkPrimer.setBlock(i + 8, j + 0, k + 4, soulStone);
        chunkPrimer.setBlock(i + 8, j + 0, k + 5, soulStone);
        chunkPrimer.setBlock(i + 8, j + 0, k + 6, soulStone);
        chunkPrimer.setBlock(i + 8, j + 0, k + 7, soulStone);
        chunkPrimer.setBlock(i + 8, j + 0, k + 8, ArcanaBlocks.deathHoundSpawner);
        chunkPrimer.setBlock(i + 8, j + 0, k + 9, soulStone);
        chunkPrimer.setBlock(i + 8, j + 0, k + 10, soulStone);
        chunkPrimer.setBlock(i + 8, j + 0, k + 11, soulStone);
        chunkPrimer.setBlock(i + 8, j + 0, k + 12, soulStone);
        chunkPrimer.setBlock(i + 8, j + 0, k + 13, soulStone);
        chunkPrimer.setBlock(i + 8, j + 0, k + 14, soulStone);
        chunkPrimer.setBlock(i + 8, j + 0, k + 15, ancientbricks);
        chunkPrimer.setBlock(i + 8, j + 1, k + 5, dungeonBricks);
        chunkPrimer.setBlock(i + 8, j + 1, k + 6, dungeonBricks);
        chunkPrimer.setBlock(i + 8, j + 1, k + 7, dungeonBricks);
        chunkPrimer.setBlock(i + 8, j + 1, k + 8, dungeonBricks);
        chunkPrimer.setBlock(i + 8, j + 1, k + 12, ancientbricks);
        chunkPrimer.setBlock(i + 8, j + 1, k + 15, dungeonBricks);
        chunkPrimer.setBlock(i + 8, j + 2, k + 12, ancientbricks);
        chunkPrimer.setBlock(i + 8, j + 2, k + 15, ancientbricks);
        chunkPrimer.setBlock(i + 8, j + 3, k + 0, arcanaPower);
        chunkPrimer.setBlock(i + 8, j + 3, k + 12, ancientbricks);
        chunkPrimer.setBlock(i + 8, j + 3, k + 13, dungeonBricks);
        chunkPrimer.setBlock(i + 8, j + 3, k + 14, dungeonBricks);
        chunkPrimer.setBlock(i + 8, j + 3, k + 15, dungeonBricks);
        chunkPrimer.setBlock(i + 8, j + 4, k + 0, arcaniumSoulSludge);
        chunkPrimer.setBlock(i + 8, j + 4, k + 12, arcaniteMetal);
        chunkPrimer.setBlock(i + 8, j + 4, k + 15, arcaniumSoulSludge);
        chunkPrimer.setBlock(i + 8, j + 5, k + 0, arcaniumSoulSludge);
        chunkPrimer.setBlock(i + 8, j + 5, k + 15, arcaniumSoulSludge);
        chunkPrimer.setBlock(i + 8, j + 6, k + 0, arcaniumSoulSludge);
        chunkPrimer.setBlock(i + 8, j + 6, k + 15, arcaniumSoulSludge);
        chunkPrimer.setBlock(i + 8, j + 7, k + 0, dungeonBricks);
        chunkPrimer.setBlock(i + 8, j + 7, k + 5, dungeonBricks);
        chunkPrimer.setBlock(i + 8, j + 7, k + 6, dungeonBricks);
        chunkPrimer.setBlock(i + 8, j + 7, k + 7, dungeonBricks);
        chunkPrimer.setBlock(i + 8, j + 7, k + 8, dungeonBricks);
        chunkPrimer.setBlock(i + 8, j + 7, k + 15, dungeonBricks);
        chunkPrimer.setBlock(i + 9, j + 0, k + 0, arcaniteMetal);
        chunkPrimer.setBlock(i + 9, j + 0, k + 1, soulStone);
        chunkPrimer.setBlock(i + 9, j + 0, k + 2, soulStone);
        chunkPrimer.setBlock(i + 9, j + 0, k + 3, soulStone);
        chunkPrimer.setBlock(i + 9, j + 0, k + 4, soulStone);
        chunkPrimer.setBlock(i + 9, j + 0, k + 5, soulStone);
        chunkPrimer.setBlock(i + 9, j + 0, k + 6, soulStone);
        chunkPrimer.setBlock(i + 9, j + 0, k + 7, soulStone);
        chunkPrimer.setBlock(i + 9, j + 0, k + 8, soulStone);
        chunkPrimer.setBlock(i + 9, j + 0, k + 9, soulStone);
        chunkPrimer.setBlock(i + 9, j + 0, k + 10, soulStone);
        chunkPrimer.setBlock(i + 9, j + 0, k + 11, soulStone);
        chunkPrimer.setBlock(i + 9, j + 0, k + 12, soulStone);
        chunkPrimer.setBlock(i + 9, j + 0, k + 13, soulStone);
        chunkPrimer.setBlock(i + 9, j + 0, k + 14, soulStone);
        chunkPrimer.setBlock(i + 9, j + 0, k + 15, ancientbricks);
        chunkPrimer.setBlock(i + 9, j + 1, k + 0, arcaniteMetal);
        chunkPrimer.setBlock(i + 9, j + 1, k + 5, dungeonBricks);
        chunkPrimer.setBlock(i + 9, j + 1, k + 6, dungeonBricks);
        chunkPrimer.setBlock(i + 9, j + 1, k + 7, dungeonBricks);
        chunkPrimer.setBlock(i + 9, j + 1, k + 8, dungeonBricks);
        chunkPrimer.setBlock(i + 9, j + 1, k + 12, ancientbricks);
        chunkPrimer.setBlock(i + 9, j + 1, k + 14, ArcanaBlocks.arcaniumOre);
        chunkPrimer.setBlock(i + 9, j + 1, k + 15, dungeonBricks);
        chunkPrimer.setBlock(i + 9, j + 2, k + 0, arcaniteMetal);
        chunkPrimer.setBlock(i + 9, j + 2, k + 6, ancientbricks);
        chunkPrimer.setBlock(i + 9, j + 2, k + 7, ancientbricks);
        chunkPrimer.setBlock(i + 9, j + 2, k + 12, ancientbricks);
        chunkPrimer.setBlock(i + 9, j + 2, k + 15, ancientbricks);
        chunkPrimer.setBlock(i + 9, j + 3, k + 0, arcaniteMetal);
        chunkPrimer.setBlock(i + 9, j + 3, k + 6, ancientbricks);
        chunkPrimer.setBlock(i + 9, j + 3, k + 7, ancientbricks);
        chunkPrimer.setBlock(i + 9, j + 3, k + 12, ancientbricks);
        chunkPrimer.setBlock(i + 9, j + 3, k + 13, dungeonBricks);
        chunkPrimer.setBlock(i + 9, j + 3, k + 14, dungeonBricks);
        chunkPrimer.setBlock(i + 9, j + 3, k + 15, dungeonBricks);
        chunkPrimer.setBlock(i + 9, j + 4, k + 0, arcaniumSoulSludge);
        chunkPrimer.setBlock(i + 9, j + 4, k + 6, ancientbricks);
        chunkPrimer.setBlock(i + 9, j + 4, k + 7, ancientbricks);
        chunkPrimer.setBlock(i + 9, j + 4, k + 12, arcaniteMetal);
        chunkPrimer.setBlock(i + 9, j + 4, k + 15, arcaniumSoulSludge);
        chunkPrimer.setBlock(i + 9, j + 5, k + 0, arcaniumSoulSludge);
        chunkPrimer.setBlock(i + 9, j + 5, k + 6, ancientbricks);
        chunkPrimer.setBlock(i + 9, j + 5, k + 7, ancientbricks);
        chunkPrimer.setBlock(i + 9, j + 5, k + 15, arcaniumSoulSludge);
        chunkPrimer.setBlock(i + 9, j + 6, k + 0, arcaniumSoulSludge);
        chunkPrimer.setBlock(i + 9, j + 6, k + 6, ancientbricks);
        chunkPrimer.setBlock(i + 9, j + 6, k + 7, ancientbricks);
        chunkPrimer.setBlock(i + 9, j + 6, k + 15, arcaniumSoulSludge);
        chunkPrimer.setBlock(i + 9, j + 7, k + 0, dungeonBricks);
        chunkPrimer.setBlock(i + 9, j + 7, k + 5, dungeonBricks);
        chunkPrimer.setBlock(i + 9, j + 7, k + 6, dungeonBricks);
        chunkPrimer.setBlock(i + 9, j + 7, k + 7, dungeonBricks);
        chunkPrimer.setBlock(i + 9, j + 7, k + 8, dungeonBricks);
        chunkPrimer.setBlock(i + 9, j + 7, k + 15, dungeonBricks);
        chunkPrimer.setBlock(i + 10, j + 0, k + 0, ancientbricks);
        chunkPrimer.setBlock(i + 10, j + 0, k + 1, soulStone);
        chunkPrimer.setBlock(i + 10, j + 0, k + 2, soulStone);
        chunkPrimer.setBlock(i + 10, j + 0, k + 3, soulStone);
        chunkPrimer.setBlock(i + 10, j + 0, k + 4, soulStone);
        chunkPrimer.setBlock(i + 10, j + 0, k + 5, soulStone);
        chunkPrimer.setBlock(i + 10, j + 0, k + 6, soulStone);
        chunkPrimer.setBlock(i + 10, j + 0, k + 7, soulStone);
        chunkPrimer.setBlock(i + 10, j + 0, k + 8, soulStone);
        chunkPrimer.setBlock(i + 10, j + 0, k + 9, soulStone);
        chunkPrimer.setBlock(i + 10, j + 0, k + 10, soulStone);
        chunkPrimer.setBlock(i + 10, j + 0, k + 11, soulStone);
        chunkPrimer.setBlock(i + 10, j + 0, k + 12, soulStone);
        chunkPrimer.setBlock(i + 10, j + 0, k + 13, soulStone);
        chunkPrimer.setBlock(i + 10, j + 0, k + 14, soulStone);
        chunkPrimer.setBlock(i + 10, j + 0, k + 15, ancientbricks);
        chunkPrimer.setBlock(i + 10, j + 1, k + 0, dungeonBricks);
        chunkPrimer.setBlock(i + 10, j + 1, k + 5, dungeonBricks);
        chunkPrimer.setBlock(i + 10, j + 1, k + 6, dungeonBricks);
        chunkPrimer.setBlock(i + 10, j + 1, k + 7, dungeonBricks);
        chunkPrimer.setBlock(i + 10, j + 1, k + 8, dungeonBricks);
        chunkPrimer.setBlock(i + 10, j + 1, k + 12, ancientbricks);
        chunkPrimer.setBlock(i + 10, j + 1, k + 13, ArcanaBlocks.soulSludgeDoor, 2);
        chunkPrimer.setBlock(i + 10, j + 1, k + 14, ArcanaBlocks.soulSludgeDoor, 2);
        chunkPrimer.setBlock(i + 10, j + 1, k + 15, dungeonBricks);
        chunkPrimer.setBlock(i + 10, j + 2, k + 0, ancientbricks);
        chunkPrimer.setBlock(i + 10, j + 2, k + 6, ancientbricks);
        chunkPrimer.setBlock(i + 10, j + 2, k + 7, ancientbricks);
        chunkPrimer.setBlock(i + 10, j + 2, k + 12, ancientbricks);
        chunkPrimer.setBlock(i + 10, j + 2, k + 13, ArcanaBlocks.soulSludgeDoor, 9);
        chunkPrimer.setBlock(i + 10, j + 2, k + 14, ArcanaBlocks.soulSludgeDoor, 8);
        chunkPrimer.setBlock(i + 10, j + 2, k + 15, ancientbricks);
        chunkPrimer.setBlock(i + 10, j + 3, k + 0, dungeonBricks);
        chunkPrimer.setBlock(i + 10, j + 3, k + 6, ancientbricks);
        chunkPrimer.setBlock(i + 10, j + 3, k + 7, ancientbricks);
        chunkPrimer.setBlock(i + 10, j + 3, k + 12, ancientbricks);
        chunkPrimer.setBlock(i + 10, j + 3, k + 13, dungeonBricks);
        chunkPrimer.setBlock(i + 10, j + 3, k + 14, dungeonBricks);
        chunkPrimer.setBlock(i + 10, j + 3, k + 15, dungeonBricks);
        chunkPrimer.setBlock(i + 10, j + 4, k + 0, arcaniumSoulSludge);
        chunkPrimer.setBlock(i + 10, j + 4, k + 6, ancientbricks);
        chunkPrimer.setBlock(i + 10, j + 4, k + 7, ancientbricks);
        chunkPrimer.setBlock(i + 10, j + 4, k + 12, arcaniteMetal);
        chunkPrimer.setBlock(i + 10, j + 4, k + 15, arcaniumSoulSludge);
        chunkPrimer.setBlock(i + 10, j + 5, k + 0, arcaniumSoulSludge);
        chunkPrimer.setBlock(i + 10, j + 5, k + 6, ancientbricks);
        chunkPrimer.setBlock(i + 10, j + 5, k + 7, ancientbricks);
        chunkPrimer.setBlock(i + 10, j + 5, k + 15, arcaniumSoulSludge);
        chunkPrimer.setBlock(i + 10, j + 6, k + 0, arcaniumSoulSludge);
        chunkPrimer.setBlock(i + 10, j + 6, k + 6, ancientbricks);
        chunkPrimer.setBlock(i + 10, j + 6, k + 7, ancientbricks);
        chunkPrimer.setBlock(i + 10, j + 6, k + 15, arcaniumSoulSludge);
        chunkPrimer.setBlock(i + 10, j + 7, k + 0, dungeonBricks);
        chunkPrimer.setBlock(i + 10, j + 7, k + 5, dungeonBricks);
        chunkPrimer.setBlock(i + 10, j + 7, k + 6, dungeonBricks);
        chunkPrimer.setBlock(i + 10, j + 7, k + 7, dungeonBricks);
        chunkPrimer.setBlock(i + 10, j + 7, k + 8, dungeonBricks);
        chunkPrimer.setBlock(i + 10, j + 7, k + 15, dungeonBricks);
        chunkPrimer.setBlock(i + 11, j + 0, k + 0, ancientbricks);
        chunkPrimer.setBlock(i + 11, j + 0, k + 1, soulStone);
        chunkPrimer.setBlock(i + 11, j + 0, k + 2, soulStone);
        chunkPrimer.setBlock(i + 11, j + 0, k + 3, soulStone);
        chunkPrimer.setBlock(i + 11, j + 0, k + 4, soulStone);
        chunkPrimer.setBlock(i + 11, j + 0, k + 5, soulStone);
        chunkPrimer.setBlock(i + 11, j + 0, k + 6, soulStone);
        chunkPrimer.setBlock(i + 11, j + 0, k + 7, soulStone);
        chunkPrimer.setBlock(i + 11, j + 0, k + 8, soulStone);
        chunkPrimer.setBlock(i + 11, j + 0, k + 9, soulStone);
        chunkPrimer.setBlock(i + 11, j + 0, k + 10, soulStone);
        chunkPrimer.setBlock(i + 11, j + 0, k + 11, soulStone);
        chunkPrimer.setBlock(i + 11, j + 0, k + 12, soulStone);
        chunkPrimer.setBlock(i + 11, j + 0, k + 13, soulStone);
        chunkPrimer.setBlock(i + 11, j + 0, k + 14, soulStone);
        chunkPrimer.setBlock(i + 11, j + 0, k + 15, ancientbricks);
        chunkPrimer.setBlock(i + 11, j + 1, k + 0, dungeonBricks);
        chunkPrimer.setBlock(i + 11, j + 1, k + 5, dungeonBricks);
        chunkPrimer.setBlock(i + 11, j + 1, k + 6, dungeonBricks);
        chunkPrimer.setBlock(i + 11, j + 1, k + 7, dungeonBricks);
        chunkPrimer.setBlock(i + 11, j + 1, k + 8, dungeonBricks);
        chunkPrimer.setBlock(i + 11, j + 1, k + 12, ancientbricks);
        chunkPrimer.setBlock(i + 11, j + 1, k + 15, dungeonBricks);
        chunkPrimer.setBlock(i + 11, j + 2, k + 0, ancientbricks);
        chunkPrimer.setBlock(i + 11, j + 2, k + 12, ancientbricks);
        chunkPrimer.setBlock(i + 11, j + 2, k + 15, ancientbricks);
        chunkPrimer.setBlock(i + 11, j + 3, k + 0, dungeonBricks);
        chunkPrimer.setBlock(i + 11, j + 3, k + 12, ancientbricks);
        chunkPrimer.setBlock(i + 11, j + 3, k + 13, dungeonBricks);
        chunkPrimer.setBlock(i + 11, j + 3, k + 14, dungeonBricks);
        chunkPrimer.setBlock(i + 11, j + 3, k + 15, dungeonBricks);
        chunkPrimer.setBlock(i + 11, j + 4, k + 0, arcaniumSoulSludge);
        chunkPrimer.setBlock(i + 11, j + 4, k + 12, arcaniteMetal);
        chunkPrimer.setBlock(i + 11, j + 4, k + 15, arcaniumSoulSludge);
        chunkPrimer.setBlock(i + 11, j + 5, k + 0, arcaniumSoulSludge);
        chunkPrimer.setBlock(i + 11, j + 5, k + 15, arcaniumSoulSludge);
        chunkPrimer.setBlock(i + 11, j + 6, k + 0, arcaniumSoulSludge);
        chunkPrimer.setBlock(i + 11, j + 6, k + 15, arcaniumSoulSludge);
        chunkPrimer.setBlock(i + 11, j + 7, k + 0, dungeonBricks);
        chunkPrimer.setBlock(i + 11, j + 7, k + 5, dungeonBricks);
        chunkPrimer.setBlock(i + 11, j + 7, k + 6, dungeonBricks);
        chunkPrimer.setBlock(i + 11, j + 7, k + 7, dungeonBricks);
        chunkPrimer.setBlock(i + 11, j + 7, k + 8, dungeonBricks);
        chunkPrimer.setBlock(i + 11, j + 7, k + 15, dungeonBricks);
        chunkPrimer.setBlock(i + 12, j + 0, k + 0, ancientbricks);
        chunkPrimer.setBlock(i + 12, j + 0, k + 1, soulStone);
        chunkPrimer.setBlock(i + 12, j + 0, k + 2, soulStone);
        chunkPrimer.setBlock(i + 12, j + 0, k + 3, soulStone);
        chunkPrimer.setBlock(i + 12, j + 0, k + 4, soulStone);
        chunkPrimer.setBlock(i + 12, j + 0, k + 5, soulStone);
        chunkPrimer.setBlock(i + 12, j + 0, k + 6, soulStone);
        chunkPrimer.setBlock(i + 12, j + 0, k + 7, soulStone);
        chunkPrimer.setBlock(i + 12, j + 0, k + 8, soulStone);
        chunkPrimer.setBlock(i + 12, j + 0, k + 9, soulStone);
        chunkPrimer.setBlock(i + 12, j + 0, k + 10, soulStone);
        chunkPrimer.setBlock(i + 12, j + 0, k + 11, soulStone);
        chunkPrimer.setBlock(i + 12, j + 0, k + 12, soulStone);
        chunkPrimer.setBlock(i + 12, j + 0, k + 13, soulStone);
        chunkPrimer.setBlock(i + 12, j + 0, k + 14, soulStone);
        chunkPrimer.setBlock(i + 12, j + 0, k + 15, ancientbricks);
        chunkPrimer.setBlock(i + 12, j + 1, k + 0, dungeonBricks);
        chunkPrimer.setBlock(i + 12, j + 1, k + 12, ancientbricks);
        chunkPrimer.setBlock(i + 12, j + 1, k + 15, dungeonBricks);
        chunkPrimer.setBlock(i + 12, j + 2, k + 0, ancientbricks);
        chunkPrimer.setBlock(i + 12, j + 2, k + 12, ancientbricks);
        chunkPrimer.setBlock(i + 12, j + 2, k + 15, ancientbricks);
        chunkPrimer.setBlock(i + 12, j + 3, k + 0, dungeonBricks);
        chunkPrimer.setBlock(i + 12, j + 3, k + 12, ancientbricks);
        chunkPrimer.setBlock(i + 12, j + 3, k + 13, dungeonBricks);
        chunkPrimer.setBlock(i + 12, j + 3, k + 14, dungeonBricks);
        chunkPrimer.setBlock(i + 12, j + 3, k + 15, dungeonBricks);
        chunkPrimer.setBlock(i + 12, j + 4, k + 0, arcaniumSoulSludge);
        chunkPrimer.setBlock(i + 12, j + 4, k + 12, ArcanaBlocks.arcanaLamp);
        chunkPrimer.setBlock(i + 12, j + 4, k + 15, arcaniumSoulSludge);
        chunkPrimer.setBlock(i + 12, j + 5, k + 0, arcaniumSoulSludge);
        chunkPrimer.setBlock(i + 12, j + 5, k + 15, arcaniumSoulSludge);
        chunkPrimer.setBlock(i + 12, j + 6, k + 0, arcaniumSoulSludge);
        chunkPrimer.setBlock(i + 12, j + 6, k + 15, arcaniumSoulSludge);
        chunkPrimer.setBlock(i + 12, j + 7, k + 0, dungeonBricks);
        chunkPrimer.setBlock(i + 12, j + 7, k + 15, dungeonBricks);
        chunkPrimer.setBlock(i + 13, j + 0, k + 0, ancientbricks);
        chunkPrimer.setBlock(i + 13, j + 0, k + 1, soulStone);
        chunkPrimer.setBlock(i + 13, j + 0, k + 2, soulStone);
        chunkPrimer.setBlock(i + 13, j + 0, k + 3, soulStone);
        chunkPrimer.setBlock(i + 13, j + 0, k + 4, soulStone);
        chunkPrimer.setBlock(i + 13, j + 0, k + 5, soulStone);
        chunkPrimer.setBlock(i + 13, j + 0, k + 6, soulStone);
        chunkPrimer.setBlock(i + 13, j + 0, k + 7, soulStone);
        chunkPrimer.setBlock(i + 13, j + 0, k + 8, soulStone);
        chunkPrimer.setBlock(i + 13, j + 0, k + 9, soulStone);
        chunkPrimer.setBlock(i + 13, j + 0, k + 10, soulStone);
        chunkPrimer.setBlock(i + 13, j + 0, k + 11, soulStone);
        chunkPrimer.setBlock(i + 13, j + 0, k + 12, soulStone);
        chunkPrimer.setBlock(i + 13, j + 0, k + 13, soulStone);
        chunkPrimer.setBlock(i + 13, j + 0, k + 14, soulStone);
        chunkPrimer.setBlock(i + 13, j + 0, k + 15, ancientbricks);
        chunkPrimer.setBlock(i + 13, j + 1, k + 0, dungeonBricks);
        chunkPrimer.setBlock(i + 13, j + 1, k + 8, ancientbricks);
        chunkPrimer.setBlock(i + 13, j + 1, k + 9, ancientbricks);
        chunkPrimer.setBlock(i + 13, j + 1, k + 10, ancientbricks);
        chunkPrimer.setBlock(i + 13, j + 1, k + 11, ArcanaBlocks.ancientBrickDoor);
        chunkPrimer.setBlock(i + 13, j + 1, k + 12, arcaniteMetal);
        chunkPrimer.setBlock(i + 13, j + 1, k + 15, dungeonBricks);
        chunkPrimer.setBlock(i + 13, j + 2, k + 0, ancientbricks);
        chunkPrimer.setBlock(i + 13, j + 2, k + 9, ancientbricks);
        chunkPrimer.setBlock(i + 13, j + 2, k + 10, ancientbricks);
        chunkPrimer.setBlock(i + 13, j + 2, k + 11, ArcanaBlocks.ancientBrickDoor, 8);
        chunkPrimer.setBlock(i + 13, j + 2, k + 12, arcaniteMetal);
        chunkPrimer.setBlock(i + 13, j + 2, k + 15, ancientbricks);
        chunkPrimer.setBlock(i + 13, j + 3, k + 0, dungeonBricks);
        chunkPrimer.setBlock(i + 13, j + 3, k + 10, ancientbricks);
        chunkPrimer.setBlock(i + 13, j + 3, k + 11, ancientbricks);
        chunkPrimer.setBlock(i + 13, j + 3, k + 12, ancientbricks);
        chunkPrimer.setBlock(i + 13, j + 3, k + 13, dungeonBricks);
        chunkPrimer.setBlock(i + 13, j + 3, k + 14, dungeonBricks);
        chunkPrimer.setBlock(i + 13, j + 3, k + 15, dungeonBricks);
        chunkPrimer.setBlock(i + 13, j + 4, k + 0, arcaniumSoulSludge);
        chunkPrimer.setBlock(i + 13, j + 4, k + 15, arcaniumSoulSludge);
        chunkPrimer.setBlock(i + 13, j + 5, k + 0, arcaniumSoulSludge);
        chunkPrimer.setBlock(i + 13, j + 5, k + 15, arcaniumSoulSludge);
        chunkPrimer.setBlock(i + 13, j + 6, k + 0, arcaniumSoulSludge);
        chunkPrimer.setBlock(i + 13, j + 6, k + 15, arcaniumSoulSludge);
        chunkPrimer.setBlock(i + 13, j + 7, k + 0, dungeonBricks);
        chunkPrimer.setBlock(i + 13, j + 7, k + 15, dungeonBricks);
        chunkPrimer.setBlock(i + 14, j + 0, k + 0, ancientbricks);
        chunkPrimer.setBlock(i + 14, j + 0, k + 1, soulStone);
        chunkPrimer.setBlock(i + 14, j + 0, k + 2, soulStone);
        chunkPrimer.setBlock(i + 14, j + 0, k + 3, soulStone);
        chunkPrimer.setBlock(i + 14, j + 0, k + 4, soulStone);
        chunkPrimer.setBlock(i + 14, j + 0, k + 5, soulStone);
        chunkPrimer.setBlock(i + 14, j + 0, k + 6, soulStone);
        chunkPrimer.setBlock(i + 14, j + 0, k + 7, soulStone);
        chunkPrimer.setBlock(i + 14, j + 0, k + 8, soulStone);
        chunkPrimer.setBlock(i + 14, j + 0, k + 9, soulStone);
        chunkPrimer.setBlock(i + 14, j + 0, k + 10, soulStone);
        chunkPrimer.setBlock(i + 14, j + 0, k + 11, soulStone);
        chunkPrimer.setBlock(i + 14, j + 0, k + 12, soulStone);
        chunkPrimer.setBlock(i + 14, j + 0, k + 13, soulStone);
        chunkPrimer.setBlock(i + 14, j + 0, k + 14, soulStone);
        chunkPrimer.setBlock(i + 14, j + 0, k + 15, ancientbricks);
        chunkPrimer.setBlock(i + 14, j + 1, k + 0, dungeonBricks);
        chunkPrimer.setBlock(i + 14, j + 1, k + 8, ancientbricks);
        chunkPrimer.setBlock(i + 14, j + 1, k + 9, ancientbricks);
        chunkPrimer.setBlock(i + 14, j + 1, k + 10, ancientbricks);
        chunkPrimer.setBlock(i + 14, j + 1, k + 15, dungeonBricks);
        chunkPrimer.setBlock(i + 14, j + 2, k + 0, ancientbricks);
        chunkPrimer.setBlock(i + 14, j + 2, k + 9, ancientbricks);
        chunkPrimer.setBlock(i + 14, j + 2, k + 10, ancientbricks);
        chunkPrimer.setBlock(i + 14, j + 2, k + 15, ancientbricks);
        chunkPrimer.setBlock(i + 14, j + 3, k + 0, dungeonBricks);
        chunkPrimer.setBlock(i + 14, j + 3, k + 10, ancientbricks);
        chunkPrimer.setBlock(i + 14, j + 3, k + 11, ancientbricks);
        chunkPrimer.setBlock(i + 14, j + 3, k + 12, ancientbricks);
        chunkPrimer.setBlock(i + 14, j + 3, k + 13, dungeonBricks);
        chunkPrimer.setBlock(i + 14, j + 3, k + 14, dungeonBricks);
        chunkPrimer.setBlock(i + 14, j + 3, k + 15, dungeonBricks);
        chunkPrimer.setBlock(i + 14, j + 4, k + 0, arcaniumSoulSludge);
        chunkPrimer.setBlock(i + 14, j + 4, k + 15, arcaniumSoulSludge);
        chunkPrimer.setBlock(i + 14, j + 5, k + 0, arcaniumSoulSludge);
        chunkPrimer.setBlock(i + 14, j + 5, k + 15, arcaniumSoulSludge);
        chunkPrimer.setBlock(i + 14, j + 6, k + 0, arcaniumSoulSludge);
        chunkPrimer.setBlock(i + 14, j + 6, k + 15, arcaniumSoulSludge);
        chunkPrimer.setBlock(i + 14, j + 7, k + 0, dungeonBricks);
        chunkPrimer.setBlock(i + 14, j + 7, k + 15, dungeonBricks);
        chunkPrimer.setBlock(i + 15, j + 0, k + 0, ancientbricks);
        chunkPrimer.setBlock(i + 15, j + 0, k + 1, ancientbricks);
        chunkPrimer.setBlock(i + 15, j + 0, k + 2, ancientbricks);
        chunkPrimer.setBlock(i + 15, j + 0, k + 3, ancientbricks);
        chunkPrimer.setBlock(i + 15, j + 0, k + 4, ancientbricks);
        chunkPrimer.setBlock(i + 15, j + 0, k + 5, ancientbricks);
        chunkPrimer.setBlock(i + 15, j + 0, k + 6, ancientbricks);
        chunkPrimer.setBlock(i + 15, j + 0, k + 7, ancientbricks);
        chunkPrimer.setBlock(i + 15, j + 0, k + 8, ancientbricks);
        chunkPrimer.setBlock(i + 15, j + 0, k + 9, ancientbricks);
        chunkPrimer.setBlock(i + 15, j + 0, k + 10, ancientbricks);
        chunkPrimer.setBlock(i + 15, j + 0, k + 11, ancientbricks);
        chunkPrimer.setBlock(i + 15, j + 0, k + 12, ancientbricks);
        chunkPrimer.setBlock(i + 15, j + 0, k + 13, ancientbricks);
        chunkPrimer.setBlock(i + 15, j + 0, k + 14, ancientbricks);
        chunkPrimer.setBlock(i + 15, j + 0, k + 15, ancientbricks);
        chunkPrimer.setBlock(i + 15, j + 1, k + 0, dungeonBricks);
        chunkPrimer.setBlock(i + 15, j + 1, k + 1, dungeonBricks);
        chunkPrimer.setBlock(i + 15, j + 1, k + 2, dungeonBricks);
        chunkPrimer.setBlock(i + 15, j + 1, k + 3, dungeonBricks);
        chunkPrimer.setBlock(i + 15, j + 1, k + 4, dungeonBricks);
        chunkPrimer.setBlock(i + 15, j + 1, k + 5, dungeonBricks);
        chunkPrimer.setBlock(i + 15, j + 1, k + 6, dungeonBricks);
        chunkPrimer.setBlock(i + 15, j + 1, k + 7, dungeonBricks);
        chunkPrimer.setBlock(i + 15, j + 1, k + 8, dungeonBricks);
        chunkPrimer.setBlock(i + 15, j + 1, k + 9, dungeonBricks);
        chunkPrimer.setBlock(i + 15, j + 1, k + 10, dungeonBricks);
        chunkPrimer.setBlock(i + 15, j + 1, k + 11, dungeonBricks);
        chunkPrimer.setBlock(i + 15, j + 1, k + 12, dungeonBricks);
        chunkPrimer.setBlock(i + 15, j + 1, k + 13, dungeonBricks);
        chunkPrimer.setBlock(i + 15, j + 1, k + 14, dungeonBricks);
        chunkPrimer.setBlock(i + 15, j + 1, k + 15, dungeonBricks);
        chunkPrimer.setBlock(i + 15, j + 2, k + 0, ancientbricks);
        chunkPrimer.setBlock(i + 15, j + 2, k + 1, ancientbricks);
        chunkPrimer.setBlock(i + 15, j + 2, k + 2, ancientbricks);
        chunkPrimer.setBlock(i + 15, j + 2, k + 3, ancientbricks);
        chunkPrimer.setBlock(i + 15, j + 2, k + 4, ancientbricks);
        chunkPrimer.setBlock(i + 15, j + 2, k + 5, ancientbricks);
        chunkPrimer.setBlock(i + 15, j + 2, k + 6, ancientbricks);
        chunkPrimer.setBlock(i + 15, j + 2, k + 7, ancientbricks);
        chunkPrimer.setBlock(i + 15, j + 2, k + 8, ancientbricks);
        chunkPrimer.setBlock(i + 15, j + 2, k + 9, ancientbricks);
        chunkPrimer.setBlock(i + 15, j + 2, k + 10, ancientbricks);
        chunkPrimer.setBlock(i + 15, j + 2, k + 11, ancientbricks);
        chunkPrimer.setBlock(i + 15, j + 2, k + 12, ancientbricks);
        chunkPrimer.setBlock(i + 15, j + 2, k + 13, ancientbricks);
        chunkPrimer.setBlock(i + 15, j + 2, k + 14, ancientbricks);
        chunkPrimer.setBlock(i + 15, j + 2, k + 15, ancientbricks);
        chunkPrimer.setBlock(i + 15, j + 3, k + 0, dungeonBricks);
        chunkPrimer.setBlock(i + 15, j + 3, k + 1, dungeonBricks);
        chunkPrimer.setBlock(i + 15, j + 3, k + 2, dungeonBricks);
        chunkPrimer.setBlock(i + 15, j + 3, k + 3, dungeonBricks);
        chunkPrimer.setBlock(i + 15, j + 3, k + 4, dungeonBricks);
        chunkPrimer.setBlock(i + 15, j + 3, k + 5, dungeonBricks);
        chunkPrimer.setBlock(i + 15, j + 3, k + 6, dungeonBricks);
        chunkPrimer.setBlock(i + 15, j + 3, k + 7, dungeonBricks);
        chunkPrimer.setBlock(i + 15, j + 3, k + 8, dungeonBricks);
        chunkPrimer.setBlock(i + 15, j + 3, k + 9, dungeonBricks);
        chunkPrimer.setBlock(i + 15, j + 3, k + 10, dungeonBricks);
        chunkPrimer.setBlock(i + 15, j + 3, k + 11, dungeonBricks);
        chunkPrimer.setBlock(i + 15, j + 3, k + 12, dungeonBricks);
        chunkPrimer.setBlock(i + 15, j + 3, k + 13, dungeonBricks);
        chunkPrimer.setBlock(i + 15, j + 3, k + 14, dungeonBricks);
        chunkPrimer.setBlock(i + 15, j + 3, k + 15, dungeonBricks);
        chunkPrimer.setBlock(i + 15, j + 4, k + 0, arcaniumSoulSludge);
        chunkPrimer.setBlock(i + 15, j + 4, k + 1, arcaniumSoulSludge);
        chunkPrimer.setBlock(i + 15, j + 4, k + 2, arcaniumSoulSludge);
        chunkPrimer.setBlock(i + 15, j + 4, k + 3, arcaniumSoulSludge);
        chunkPrimer.setBlock(i + 15, j + 4, k + 4, arcaniumSoulSludge);
        chunkPrimer.setBlock(i + 15, j + 4, k + 5, arcaniumSoulSludge);
        chunkPrimer.setBlock(i + 15, j + 4, k + 6, arcaniumSoulSludge);
        chunkPrimer.setBlock(i + 15, j + 4, k + 7, arcaniumSoulSludge);
        chunkPrimer.setBlock(i + 15, j + 4, k + 8, arcaniumSoulSludge);
        chunkPrimer.setBlock(i + 15, j + 4, k + 9, arcaniumSoulSludge);
        chunkPrimer.setBlock(i + 15, j + 4, k + 10, arcaniumSoulSludge);
        chunkPrimer.setBlock(i + 15, j + 4, k + 11, arcaniumSoulSludge);
        chunkPrimer.setBlock(i + 15, j + 4, k + 12, arcaniumSoulSludge);
        chunkPrimer.setBlock(i + 15, j + 4, k + 13, arcaniumSoulSludge);
        chunkPrimer.setBlock(i + 15, j + 4, k + 14, arcaniumSoulSludge);
        chunkPrimer.setBlock(i + 15, j + 4, k + 15, arcaniumSoulSludge);
        chunkPrimer.setBlock(i + 15, j + 5, k + 0, arcaniumSoulSludge);
        chunkPrimer.setBlock(i + 15, j + 5, k + 1, arcaniumSoulSludge);
        chunkPrimer.setBlock(i + 15, j + 5, k + 2, arcaniumSoulSludge);
        chunkPrimer.setBlock(i + 15, j + 5, k + 3, arcaniumSoulSludge);
        chunkPrimer.setBlock(i + 15, j + 5, k + 4, arcaniumSoulSludge);
        chunkPrimer.setBlock(i + 15, j + 5, k + 5, arcaniumSoulSludge);
        chunkPrimer.setBlock(i + 15, j + 5, k + 6, arcaniumSoulSludge);
        chunkPrimer.setBlock(i + 15, j + 5, k + 7, arcaniumSoulSludge);
        chunkPrimer.setBlock(i + 15, j + 5, k + 8, arcaniumSoulSludge);
        chunkPrimer.setBlock(i + 15, j + 5, k + 9, arcaniumSoulSludge);
        chunkPrimer.setBlock(i + 15, j + 5, k + 10, arcaniumSoulSludge);
        chunkPrimer.setBlock(i + 15, j + 5, k + 11, arcaniumSoulSludge);
        chunkPrimer.setBlock(i + 15, j + 5, k + 12, arcaniumSoulSludge);
        chunkPrimer.setBlock(i + 15, j + 5, k + 13, arcaniumSoulSludge);
        chunkPrimer.setBlock(i + 15, j + 5, k + 14, arcaniumSoulSludge);
        chunkPrimer.setBlock(i + 15, j + 5, k + 15, arcaniumSoulSludge);
        chunkPrimer.setBlock(i + 15, j + 6, k + 0, arcaniumSoulSludge);
        chunkPrimer.setBlock(i + 15, j + 6, k + 1, arcaniumSoulSludge);
        chunkPrimer.setBlock(i + 15, j + 6, k + 2, arcaniumSoulSludge);
        chunkPrimer.setBlock(i + 15, j + 6, k + 3, arcaniumSoulSludge);
        chunkPrimer.setBlock(i + 15, j + 6, k + 4, arcaniumSoulSludge);
        chunkPrimer.setBlock(i + 15, j + 6, k + 5, arcaniumSoulSludge);
        chunkPrimer.setBlock(i + 15, j + 6, k + 6, arcaniumSoulSludge);
        chunkPrimer.setBlock(i + 15, j + 6, k + 7, arcaniumSoulSludge);
        chunkPrimer.setBlock(i + 15, j + 6, k + 8, arcaniumSoulSludge);
        chunkPrimer.setBlock(i + 15, j + 6, k + 9, arcaniumSoulSludge);
        chunkPrimer.setBlock(i + 15, j + 6, k + 10, arcaniumSoulSludge);
        chunkPrimer.setBlock(i + 15, j + 6, k + 11, arcaniumSoulSludge);
        chunkPrimer.setBlock(i + 15, j + 6, k + 12, arcaniumSoulSludge);
        chunkPrimer.setBlock(i + 15, j + 6, k + 13, arcaniumSoulSludge);
        chunkPrimer.setBlock(i + 15, j + 6, k + 14, arcaniumSoulSludge);
        chunkPrimer.setBlock(i + 15, j + 6, k + 15, arcaniumSoulSludge);
        chunkPrimer.setBlock(i + 15, j + 7, k + 0, dungeonBricks);
        chunkPrimer.setBlock(i + 15, j + 7, k + 1, dungeonBricks);
        chunkPrimer.setBlock(i + 15, j + 7, k + 2, dungeonBricks);
        chunkPrimer.setBlock(i + 15, j + 7, k + 3, dungeonBricks);
        chunkPrimer.setBlock(i + 15, j + 7, k + 4, dungeonBricks);
        chunkPrimer.setBlock(i + 15, j + 7, k + 5, dungeonBricks);
        chunkPrimer.setBlock(i + 15, j + 7, k + 6, dungeonBricks);
        chunkPrimer.setBlock(i + 15, j + 7, k + 7, dungeonBricks);
        chunkPrimer.setBlock(i + 15, j + 7, k + 8, dungeonBricks);
        chunkPrimer.setBlock(i + 15, j + 7, k + 9, dungeonBricks);
        chunkPrimer.setBlock(i + 15, j + 7, k + 10, dungeonBricks);
        chunkPrimer.setBlock(i + 15, j + 7, k + 11, dungeonBricks);
        chunkPrimer.setBlock(i + 15, j + 7, k + 12, dungeonBricks);
        chunkPrimer.setBlock(i + 15, j + 7, k + 13, dungeonBricks);
        chunkPrimer.setBlock(i + 15, j + 7, k + 14, dungeonBricks);
        chunkPrimer.setBlock(i + 15, j + 7, k + 15, dungeonBricks);
        return true;
    }
}

