/*
 * Decompiled with CFR 0.152.
 * 
 * Could not load the following classes:
 *  net.minecraft.block.Block
 *  net.minecraft.init.Blocks
 */
package net.divinerpg.dimensions.arcana.components;

import java.util.Random;
import net.divinerpg.dimensions.arcana.ChunkPrimer;
import net.divinerpg.dimensions.arcana.components.DungeonComponentBase;
import net.divinerpg.utils.blocks.ArcanaBlocks;
import net.minecraft.block.Block;
import net.minecraft.init.Blocks;

public class DungeonComponent8
extends DungeonComponentBase {
    /*
     * Opcode count of 15302 triggered aggressive code reduction.  Override with --aggressivesizethreshold.
     */
    @Override
    public boolean generate(ChunkPrimer chunkPrimer, Random rand, int i, int j, int k) {
        Block dungeonBricks = ArcanaBlocks.degradedBrick;
        Block ancientbricks = ArcanaBlocks.ancientBrick;
        Block soulStone = ArcanaBlocks.soulStone;
        Block ancientstone = ArcanaBlocks.ancientStone;
        Block arcaniumSoulSludge = ArcanaBlocks.soulSludge;
        Block arcaniteMetal = ArcanaBlocks.arcaniumMetal;
        Block arcanaPower = ArcanaBlocks.arcaniumPower;
        for (int n = 0; n < 16; ++n) {
            for (int m = 0; m < 16; ++m) {
                for (int o = 0; o < 16; ++o) {
                    chunkPrimer.setBlock(i + n, j + o, k + m, Blocks.air);
                }
            }
        }
        chunkPrimer.setBlock(i + 0, j + 0, k + 0, ancientbricks);
        chunkPrimer.setBlock(i + 0, j + 0, k + 1, ancientbricks);
        chunkPrimer.setBlock(i + 0, j + 0, k + 2, ancientbricks);
        chunkPrimer.setBlock(i + 0, j + 0, k + 3, ancientbricks);
        chunkPrimer.setBlock(i + 0, j + 0, k + 4, ancientbricks);
        chunkPrimer.setBlock(i + 0, j + 0, k + 5, ancientbricks);
        chunkPrimer.setBlock(i + 0, j + 0, k + 6, ancientbricks);
        chunkPrimer.setBlock(i + 0, j + 0, k + 7, ancientbricks);
        chunkPrimer.setBlock(i + 0, j + 0, k + 8, ancientbricks);
        chunkPrimer.setBlock(i + 0, j + 0, k + 9, ancientbricks);
        chunkPrimer.setBlock(i + 0, j + 0, k + 10, ancientbricks);
        chunkPrimer.setBlock(i + 0, j + 0, k + 11, ancientbricks);
        chunkPrimer.setBlock(i + 0, j + 0, k + 12, ancientbricks);
        chunkPrimer.setBlock(i + 0, j + 0, k + 13, ancientbricks);
        chunkPrimer.setBlock(i + 0, j + 0, k + 14, ancientbricks);
        chunkPrimer.setBlock(i + 0, j + 0, k + 15, ancientbricks);
        chunkPrimer.setBlock(i + 0, j + 1, k + 0, arcaniumSoulSludge);
        chunkPrimer.setBlock(i + 0, j + 1, k + 1, arcaniumSoulSludge);
        chunkPrimer.setBlock(i + 0, j + 1, k + 2, arcaniumSoulSludge);
        chunkPrimer.setBlock(i + 0, j + 1, k + 3, arcaniteMetal);
        chunkPrimer.setBlock(i + 0, j + 1, k + 4, arcaniumSoulSludge);
        chunkPrimer.setBlock(i + 0, j + 1, k + 5, arcaniumSoulSludge);
        chunkPrimer.setBlock(i + 0, j + 1, k + 6, arcaniteMetal);
        chunkPrimer.setBlock(i + 0, j + 1, k + 9, arcaniteMetal);
        chunkPrimer.setBlock(i + 0, j + 1, k + 10, arcaniumSoulSludge);
        chunkPrimer.setBlock(i + 0, j + 1, k + 11, arcaniumSoulSludge);
        chunkPrimer.setBlock(i + 0, j + 1, k + 12, arcaniteMetal);
        chunkPrimer.setBlock(i + 0, j + 1, k + 13, arcaniumSoulSludge);
        chunkPrimer.setBlock(i + 0, j + 1, k + 14, arcaniumSoulSludge);
        chunkPrimer.setBlock(i + 0, j + 1, k + 15, arcaniumSoulSludge);
        chunkPrimer.setBlock(i + 0, j + 2, k + 0, arcaniumSoulSludge);
        chunkPrimer.setBlock(i + 0, j + 2, k + 1, arcaniumSoulSludge);
        chunkPrimer.setBlock(i + 0, j + 2, k + 2, arcaniumSoulSludge);
        chunkPrimer.setBlock(i + 0, j + 2, k + 3, arcaniteMetal);
        chunkPrimer.setBlock(i + 0, j + 2, k + 4, arcaniumSoulSludge);
        chunkPrimer.setBlock(i + 0, j + 2, k + 5, arcaniumSoulSludge);
        chunkPrimer.setBlock(i + 0, j + 2, k + 6, arcaniteMetal);
        chunkPrimer.setBlock(i + 0, j + 2, k + 9, arcaniteMetal);
        chunkPrimer.setBlock(i + 0, j + 2, k + 10, arcaniumSoulSludge);
        chunkPrimer.setBlock(i + 0, j + 2, k + 11, arcaniumSoulSludge);
        chunkPrimer.setBlock(i + 0, j + 2, k + 12, arcaniteMetal);
        chunkPrimer.setBlock(i + 0, j + 2, k + 13, arcaniumSoulSludge);
        chunkPrimer.setBlock(i + 0, j + 2, k + 14, arcaniumSoulSludge);
        chunkPrimer.setBlock(i + 0, j + 2, k + 15, arcaniumSoulSludge);
        chunkPrimer.setBlock(i + 0, j + 3, k + 0, arcaniumSoulSludge);
        chunkPrimer.setBlock(i + 0, j + 3, k + 1, arcaniumSoulSludge);
        chunkPrimer.setBlock(i + 0, j + 3, k + 2, arcaniumSoulSludge);
        chunkPrimer.setBlock(i + 0, j + 3, k + 3, arcaniteMetal);
        chunkPrimer.setBlock(i + 0, j + 3, k + 4, arcaniumSoulSludge);
        chunkPrimer.setBlock(i + 0, j + 3, k + 5, arcaniumSoulSludge);
        chunkPrimer.setBlock(i + 0, j + 3, k + 6, arcaniteMetal);
        chunkPrimer.setBlock(i + 0, j + 3, k + 7, arcanaPower);
        chunkPrimer.setBlock(i + 0, j + 3, k + 8, arcanaPower);
        chunkPrimer.setBlock(i + 0, j + 3, k + 9, arcaniteMetal);
        chunkPrimer.setBlock(i + 0, j + 3, k + 10, arcaniumSoulSludge);
        chunkPrimer.setBlock(i + 0, j + 3, k + 11, arcaniumSoulSludge);
        chunkPrimer.setBlock(i + 0, j + 3, k + 12, arcaniteMetal);
        chunkPrimer.setBlock(i + 0, j + 3, k + 13, arcaniumSoulSludge);
        chunkPrimer.setBlock(i + 0, j + 3, k + 14, arcaniumSoulSludge);
        chunkPrimer.setBlock(i + 0, j + 3, k + 15, arcaniumSoulSludge);
        chunkPrimer.setBlock(i + 0, j + 4, k + 0, arcaniumSoulSludge);
        chunkPrimer.setBlock(i + 0, j + 4, k + 1, arcaniumSoulSludge);
        chunkPrimer.setBlock(i + 0, j + 4, k + 2, arcaniumSoulSludge);
        chunkPrimer.setBlock(i + 0, j + 4, k + 3, arcaniteMetal);
        chunkPrimer.setBlock(i + 0, j + 4, k + 4, arcaniumSoulSludge);
        chunkPrimer.setBlock(i + 0, j + 4, k + 5, arcaniumSoulSludge);
        chunkPrimer.setBlock(i + 0, j + 4, k + 6, arcaniteMetal);
        chunkPrimer.setBlock(i + 0, j + 4, k + 7, arcaniumSoulSludge);
        chunkPrimer.setBlock(i + 0, j + 4, k + 8, arcaniumSoulSludge);
        chunkPrimer.setBlock(i + 0, j + 4, k + 9, arcaniteMetal);
        chunkPrimer.setBlock(i + 0, j + 4, k + 10, arcaniumSoulSludge);
        chunkPrimer.setBlock(i + 0, j + 4, k + 11, arcaniumSoulSludge);
        chunkPrimer.setBlock(i + 0, j + 4, k + 12, arcaniteMetal);
        chunkPrimer.setBlock(i + 0, j + 4, k + 13, arcaniumSoulSludge);
        chunkPrimer.setBlock(i + 0, j + 4, k + 14, arcaniumSoulSludge);
        chunkPrimer.setBlock(i + 0, j + 4, k + 15, arcaniumSoulSludge);
        chunkPrimer.setBlock(i + 0, j + 5, k + 0, arcaniumSoulSludge);
        chunkPrimer.setBlock(i + 0, j + 5, k + 1, arcaniumSoulSludge);
        chunkPrimer.setBlock(i + 0, j + 5, k + 2, arcaniumSoulSludge);
        chunkPrimer.setBlock(i + 0, j + 5, k + 3, arcaniteMetal);
        chunkPrimer.setBlock(i + 0, j + 5, k + 4, arcaniumSoulSludge);
        chunkPrimer.setBlock(i + 0, j + 5, k + 5, arcaniumSoulSludge);
        chunkPrimer.setBlock(i + 0, j + 5, k + 6, arcaniteMetal);
        chunkPrimer.setBlock(i + 0, j + 5, k + 7, arcaniumSoulSludge);
        chunkPrimer.setBlock(i + 0, j + 5, k + 8, arcaniumSoulSludge);
        chunkPrimer.setBlock(i + 0, j + 5, k + 9, arcaniteMetal);
        chunkPrimer.setBlock(i + 0, j + 5, k + 10, arcaniumSoulSludge);
        chunkPrimer.setBlock(i + 0, j + 5, k + 11, arcaniumSoulSludge);
        chunkPrimer.setBlock(i + 0, j + 5, k + 12, arcaniteMetal);
        chunkPrimer.setBlock(i + 0, j + 5, k + 13, arcaniumSoulSludge);
        chunkPrimer.setBlock(i + 0, j + 5, k + 14, arcaniumSoulSludge);
        chunkPrimer.setBlock(i + 0, j + 5, k + 15, arcaniumSoulSludge);
        chunkPrimer.setBlock(i + 0, j + 6, k + 0, arcaniumSoulSludge);
        chunkPrimer.setBlock(i + 0, j + 6, k + 1, arcaniumSoulSludge);
        chunkPrimer.setBlock(i + 0, j + 6, k + 2, arcaniumSoulSludge);
        chunkPrimer.setBlock(i + 0, j + 6, k + 3, arcaniteMetal);
        chunkPrimer.setBlock(i + 0, j + 6, k + 4, arcaniumSoulSludge);
        chunkPrimer.setBlock(i + 0, j + 6, k + 5, arcaniumSoulSludge);
        chunkPrimer.setBlock(i + 0, j + 6, k + 6, arcaniteMetal);
        chunkPrimer.setBlock(i + 0, j + 6, k + 7, arcaniumSoulSludge);
        chunkPrimer.setBlock(i + 0, j + 6, k + 8, arcaniumSoulSludge);
        chunkPrimer.setBlock(i + 0, j + 6, k + 9, arcaniteMetal);
        chunkPrimer.setBlock(i + 0, j + 6, k + 10, arcaniumSoulSludge);
        chunkPrimer.setBlock(i + 0, j + 6, k + 11, arcaniumSoulSludge);
        chunkPrimer.setBlock(i + 0, j + 6, k + 12, arcaniteMetal);
        chunkPrimer.setBlock(i + 0, j + 6, k + 13, arcaniumSoulSludge);
        chunkPrimer.setBlock(i + 0, j + 6, k + 14, arcaniumSoulSludge);
        chunkPrimer.setBlock(i + 0, j + 6, k + 15, arcaniumSoulSludge);
        chunkPrimer.setBlock(i + 0, j + 7, k + 0, arcaniumSoulSludge);
        chunkPrimer.setBlock(i + 0, j + 7, k + 1, arcaniumSoulSludge);
        chunkPrimer.setBlock(i + 0, j + 7, k + 2, arcaniumSoulSludge);
        chunkPrimer.setBlock(i + 0, j + 7, k + 3, arcaniteMetal);
        chunkPrimer.setBlock(i + 0, j + 7, k + 4, arcaniumSoulSludge);
        chunkPrimer.setBlock(i + 0, j + 7, k + 5, arcaniumSoulSludge);
        chunkPrimer.setBlock(i + 0, j + 7, k + 6, arcaniteMetal);
        chunkPrimer.setBlock(i + 0, j + 7, k + 7, arcaniumSoulSludge);
        chunkPrimer.setBlock(i + 0, j + 7, k + 8, arcaniumSoulSludge);
        chunkPrimer.setBlock(i + 0, j + 7, k + 9, arcaniteMetal);
        chunkPrimer.setBlock(i + 0, j + 7, k + 10, arcaniumSoulSludge);
        chunkPrimer.setBlock(i + 0, j + 7, k + 11, arcaniumSoulSludge);
        chunkPrimer.setBlock(i + 0, j + 7, k + 12, arcaniteMetal);
        chunkPrimer.setBlock(i + 0, j + 7, k + 13, arcaniumSoulSludge);
        chunkPrimer.setBlock(i + 0, j + 7, k + 14, arcaniumSoulSludge);
        chunkPrimer.setBlock(i + 0, j + 7, k + 15, arcaniumSoulSludge);
        chunkPrimer.setBlock(i + 0, j + 8, k + 0, ancientstone);
        chunkPrimer.setBlock(i + 0, j + 8, k + 1, ancientstone);
        chunkPrimer.setBlock(i + 0, j + 8, k + 2, ancientstone);
        chunkPrimer.setBlock(i + 0, j + 8, k + 3, ancientstone);
        chunkPrimer.setBlock(i + 0, j + 8, k + 4, ancientstone);
        chunkPrimer.setBlock(i + 0, j + 8, k + 5, ancientstone);
        chunkPrimer.setBlock(i + 0, j + 8, k + 6, ancientstone);
        chunkPrimer.setBlock(i + 0, j + 8, k + 7, ancientstone);
        chunkPrimer.setBlock(i + 0, j + 8, k + 8, ancientstone);
        chunkPrimer.setBlock(i + 0, j + 8, k + 9, ancientstone);
        chunkPrimer.setBlock(i + 0, j + 8, k + 10, ancientstone);
        chunkPrimer.setBlock(i + 0, j + 8, k + 11, ancientstone);
        chunkPrimer.setBlock(i + 0, j + 8, k + 12, ancientstone);
        chunkPrimer.setBlock(i + 0, j + 8, k + 13, ancientstone);
        chunkPrimer.setBlock(i + 0, j + 8, k + 14, ancientstone);
        chunkPrimer.setBlock(i + 0, j + 8, k + 15, ancientstone);
        chunkPrimer.setBlock(i + 0, j + 9, k + 0, soulStone);
        chunkPrimer.setBlock(i + 0, j + 9, k + 1, soulStone);
        chunkPrimer.setBlock(i + 0, j + 9, k + 2, soulStone);
        chunkPrimer.setBlock(i + 0, j + 9, k + 3, soulStone);
        chunkPrimer.setBlock(i + 0, j + 9, k + 4, soulStone);
        chunkPrimer.setBlock(i + 0, j + 9, k + 5, soulStone);
        chunkPrimer.setBlock(i + 0, j + 9, k + 6, arcaniteMetal);
        chunkPrimer.setBlock(i + 0, j + 9, k + 9, arcaniteMetal);
        chunkPrimer.setBlock(i + 0, j + 9, k + 10, soulStone);
        chunkPrimer.setBlock(i + 0, j + 9, k + 11, soulStone);
        chunkPrimer.setBlock(i + 0, j + 9, k + 12, soulStone);
        chunkPrimer.setBlock(i + 0, j + 9, k + 13, soulStone);
        chunkPrimer.setBlock(i + 0, j + 9, k + 14, soulStone);
        chunkPrimer.setBlock(i + 0, j + 9, k + 15, soulStone);
        chunkPrimer.setBlock(i + 0, j + 10, k + 0, soulStone);
        chunkPrimer.setBlock(i + 0, j + 10, k + 1, soulStone);
        chunkPrimer.setBlock(i + 0, j + 10, k + 2, soulStone);
        chunkPrimer.setBlock(i + 0, j + 10, k + 3, soulStone);
        chunkPrimer.setBlock(i + 0, j + 10, k + 4, soulStone);
        chunkPrimer.setBlock(i + 0, j + 10, k + 5, soulStone);
        chunkPrimer.setBlock(i + 0, j + 10, k + 6, arcaniteMetal);
        chunkPrimer.setBlock(i + 0, j + 10, k + 9, arcaniteMetal);
        chunkPrimer.setBlock(i + 0, j + 10, k + 10, soulStone);
        chunkPrimer.setBlock(i + 0, j + 10, k + 11, soulStone);
        chunkPrimer.setBlock(i + 0, j + 10, k + 12, soulStone);
        chunkPrimer.setBlock(i + 0, j + 10, k + 13, soulStone);
        chunkPrimer.setBlock(i + 0, j + 10, k + 14, soulStone);
        chunkPrimer.setBlock(i + 0, j + 10, k + 15, soulStone);
        chunkPrimer.setBlock(i + 0, j + 11, k + 0, soulStone);
        chunkPrimer.setBlock(i + 0, j + 11, k + 1, soulStone);
        chunkPrimer.setBlock(i + 0, j + 11, k + 2, soulStone);
        chunkPrimer.setBlock(i + 0, j + 11, k + 3, soulStone);
        chunkPrimer.setBlock(i + 0, j + 11, k + 4, soulStone);
        chunkPrimer.setBlock(i + 0, j + 11, k + 5, soulStone);
        chunkPrimer.setBlock(i + 0, j + 11, k + 6, arcaniteMetal);
        chunkPrimer.setBlock(i + 0, j + 11, k + 7, arcanaPower);
        chunkPrimer.setBlock(i + 0, j + 11, k + 8, arcanaPower);
        chunkPrimer.setBlock(i + 0, j + 11, k + 9, arcaniteMetal);
        chunkPrimer.setBlock(i + 0, j + 11, k + 10, soulStone);
        chunkPrimer.setBlock(i + 0, j + 11, k + 11, soulStone);
        chunkPrimer.setBlock(i + 0, j + 11, k + 12, soulStone);
        chunkPrimer.setBlock(i + 0, j + 11, k + 13, soulStone);
        chunkPrimer.setBlock(i + 0, j + 11, k + 14, soulStone);
        chunkPrimer.setBlock(i + 0, j + 11, k + 15, soulStone);
        chunkPrimer.setBlock(i + 0, j + 12, k + 0, ancientbricks);
        chunkPrimer.setBlock(i + 0, j + 12, k + 1, ancientbricks);
        chunkPrimer.setBlock(i + 0, j + 12, k + 2, ancientbricks);
        chunkPrimer.setBlock(i + 0, j + 12, k + 3, ancientbricks);
        chunkPrimer.setBlock(i + 0, j + 12, k + 4, ancientbricks);
        chunkPrimer.setBlock(i + 0, j + 12, k + 5, ancientbricks);
        chunkPrimer.setBlock(i + 0, j + 12, k + 6, ancientbricks);
        chunkPrimer.setBlock(i + 0, j + 12, k + 7, ancientbricks);
        chunkPrimer.setBlock(i + 0, j + 12, k + 8, ancientbricks);
        chunkPrimer.setBlock(i + 0, j + 12, k + 9, ancientbricks);
        chunkPrimer.setBlock(i + 0, j + 12, k + 10, ancientbricks);
        chunkPrimer.setBlock(i + 0, j + 12, k + 11, ancientbricks);
        chunkPrimer.setBlock(i + 0, j + 12, k + 12, ancientbricks);
        chunkPrimer.setBlock(i + 0, j + 12, k + 13, ancientbricks);
        chunkPrimer.setBlock(i + 0, j + 12, k + 14, ancientbricks);
        chunkPrimer.setBlock(i + 0, j + 12, k + 15, ancientbricks);
        chunkPrimer.setBlock(i + 0, j + 13, k + 0, ancientstone);
        chunkPrimer.setBlock(i + 0, j + 13, k + 1, ancientstone);
        chunkPrimer.setBlock(i + 0, j + 13, k + 2, ancientstone);
        chunkPrimer.setBlock(i + 0, j + 13, k + 3, ancientstone);
        chunkPrimer.setBlock(i + 0, j + 13, k + 4, ancientstone);
        chunkPrimer.setBlock(i + 0, j + 13, k + 5, ancientstone);
        chunkPrimer.setBlock(i + 0, j + 13, k + 6, ancientstone);
        chunkPrimer.setBlock(i + 0, j + 13, k + 7, ancientstone);
        chunkPrimer.setBlock(i + 0, j + 13, k + 8, ancientstone);
        chunkPrimer.setBlock(i + 0, j + 13, k + 9, ancientstone);
        chunkPrimer.setBlock(i + 0, j + 13, k + 10, ancientstone);
        chunkPrimer.setBlock(i + 0, j + 13, k + 11, ancientstone);
        chunkPrimer.setBlock(i + 0, j + 13, k + 12, ancientstone);
        chunkPrimer.setBlock(i + 0, j + 13, k + 13, ancientstone);
        chunkPrimer.setBlock(i + 0, j + 13, k + 14, ancientstone);
        chunkPrimer.setBlock(i + 0, j + 13, k + 15, ancientstone);
        chunkPrimer.setBlock(i + 0, j + 14, k + 0, ancientstone);
        chunkPrimer.setBlock(i + 0, j + 14, k + 1, ancientstone);
        chunkPrimer.setBlock(i + 0, j + 14, k + 2, ancientstone);
        chunkPrimer.setBlock(i + 0, j + 14, k + 3, ancientstone);
        chunkPrimer.setBlock(i + 0, j + 14, k + 4, ancientstone);
        chunkPrimer.setBlock(i + 0, j + 14, k + 5, ancientstone);
        chunkPrimer.setBlock(i + 0, j + 14, k + 6, ancientstone);
        chunkPrimer.setBlock(i + 0, j + 14, k + 7, ancientstone);
        chunkPrimer.setBlock(i + 0, j + 14, k + 8, ancientstone);
        chunkPrimer.setBlock(i + 0, j + 14, k + 9, ancientstone);
        chunkPrimer.setBlock(i + 0, j + 14, k + 10, ancientstone);
        chunkPrimer.setBlock(i + 0, j + 14, k + 11, ancientstone);
        chunkPrimer.setBlock(i + 0, j + 14, k + 12, ancientstone);
        chunkPrimer.setBlock(i + 0, j + 14, k + 13, ancientstone);
        chunkPrimer.setBlock(i + 0, j + 14, k + 14, ancientstone);
        chunkPrimer.setBlock(i + 0, j + 14, k + 15, ancientstone);
        chunkPrimer.setBlock(i + 0, j + 15, k + 0, ancientstone);
        chunkPrimer.setBlock(i + 0, j + 15, k + 1, ancientstone);
        chunkPrimer.setBlock(i + 0, j + 15, k + 2, ancientstone);
        chunkPrimer.setBlock(i + 0, j + 15, k + 3, ancientstone);
        chunkPrimer.setBlock(i + 0, j + 15, k + 4, ancientstone);
        chunkPrimer.setBlock(i + 0, j + 15, k + 5, ancientstone);
        chunkPrimer.setBlock(i + 0, j + 15, k + 6, ancientstone);
        chunkPrimer.setBlock(i + 0, j + 15, k + 7, ancientstone);
        chunkPrimer.setBlock(i + 0, j + 15, k + 8, ancientstone);
        chunkPrimer.setBlock(i + 0, j + 15, k + 9, ancientstone);
        chunkPrimer.setBlock(i + 0, j + 15, k + 10, ancientstone);
        chunkPrimer.setBlock(i + 0, j + 15, k + 11, ancientstone);
        chunkPrimer.setBlock(i + 0, j + 15, k + 12, ancientstone);
        chunkPrimer.setBlock(i + 0, j + 15, k + 13, ancientstone);
        chunkPrimer.setBlock(i + 0, j + 15, k + 14, ancientstone);
        chunkPrimer.setBlock(i + 0, j + 15, k + 15, ancientstone);
        chunkPrimer.setBlock(i + 1, j + 0, k + 0, ancientbricks);
        chunkPrimer.setBlock(i + 1, j + 0, k + 1, dungeonBricks);
        chunkPrimer.setBlock(i + 1, j + 0, k + 2, dungeonBricks);
        chunkPrimer.setBlock(i + 1, j + 0, k + 3, dungeonBricks);
        chunkPrimer.setBlock(i + 1, j + 0, k + 4, dungeonBricks);
        chunkPrimer.setBlock(i + 1, j + 0, k + 5, dungeonBricks);
        chunkPrimer.setBlock(i + 1, j + 0, k + 6, dungeonBricks);
        chunkPrimer.setBlock(i + 1, j + 0, k + 7, dungeonBricks);
        chunkPrimer.setBlock(i + 1, j + 0, k + 8, dungeonBricks);
        chunkPrimer.setBlock(i + 1, j + 0, k + 9, dungeonBricks);
        chunkPrimer.setBlock(i + 1, j + 0, k + 10, dungeonBricks);
        chunkPrimer.setBlock(i + 1, j + 0, k + 11, dungeonBricks);
        chunkPrimer.setBlock(i + 1, j + 0, k + 12, dungeonBricks);
        chunkPrimer.setBlock(i + 1, j + 0, k + 13, dungeonBricks);
        chunkPrimer.setBlock(i + 1, j + 0, k + 14, dungeonBricks);
        chunkPrimer.setBlock(i + 1, j + 0, k + 15, ancientbricks);
        chunkPrimer.setBlock(i + 1, j + 1, k + 0, arcaniumSoulSludge);
        chunkPrimer.setBlock(i + 1, j + 1, k + 15, arcaniumSoulSludge);
        chunkPrimer.setBlock(i + 1, j + 2, k + 0, arcaniumSoulSludge);
        chunkPrimer.setBlock(i + 1, j + 2, k + 15, arcaniumSoulSludge);
        chunkPrimer.setBlock(i + 1, j + 3, k + 0, arcaniumSoulSludge);
        chunkPrimer.setBlock(i + 1, j + 3, k + 15, arcaniumSoulSludge);
        chunkPrimer.setBlock(i + 1, j + 4, k + 0, arcaniumSoulSludge);
        chunkPrimer.setBlock(i + 1, j + 4, k + 15, arcaniumSoulSludge);
        chunkPrimer.setBlock(i + 1, j + 5, k + 0, arcaniumSoulSludge);
        chunkPrimer.setBlock(i + 1, j + 5, k + 15, arcaniumSoulSludge);
        chunkPrimer.setBlock(i + 1, j + 6, k + 0, arcaniumSoulSludge);
        chunkPrimer.setBlock(i + 1, j + 6, k + 15, arcaniumSoulSludge);
        chunkPrimer.setBlock(i + 1, j + 7, k + 0, arcaniumSoulSludge);
        chunkPrimer.setBlock(i + 1, j + 7, k + 15, arcaniumSoulSludge);
        chunkPrimer.setBlock(i + 1, j + 8, k + 0, ancientstone);
        chunkPrimer.setBlock(i + 1, j + 8, k + 1, dungeonBricks);
        chunkPrimer.setBlock(i + 1, j + 8, k + 2, dungeonBricks);
        chunkPrimer.setBlock(i + 1, j + 8, k + 3, dungeonBricks);
        chunkPrimer.setBlock(i + 1, j + 8, k + 4, dungeonBricks);
        chunkPrimer.setBlock(i + 1, j + 8, k + 5, dungeonBricks);
        chunkPrimer.setBlock(i + 1, j + 8, k + 6, dungeonBricks);
        chunkPrimer.setBlock(i + 1, j + 8, k + 7, dungeonBricks);
        chunkPrimer.setBlock(i + 1, j + 8, k + 8, dungeonBricks);
        chunkPrimer.setBlock(i + 1, j + 8, k + 9, dungeonBricks);
        chunkPrimer.setBlock(i + 1, j + 8, k + 10, dungeonBricks);
        chunkPrimer.setBlock(i + 1, j + 8, k + 15, ancientstone);
        chunkPrimer.setBlock(i + 1, j + 9, k + 0, soulStone);
        chunkPrimer.setBlock(i + 1, j + 9, k + 15, soulStone);
        chunkPrimer.setBlock(i + 1, j + 10, k + 0, soulStone);
        chunkPrimer.setBlock(i + 1, j + 10, k + 15, soulStone);
        chunkPrimer.setBlock(i + 1, j + 11, k + 0, soulStone);
        chunkPrimer.setBlock(i + 1, j + 11, k + 15, soulStone);
        chunkPrimer.setBlock(i + 1, j + 12, k + 0, ancientbricks);
        chunkPrimer.setBlock(i + 1, j + 12, k + 15, ancientbricks);
        chunkPrimer.setBlock(i + 1, j + 13, k + 0, ancientstone);
        chunkPrimer.setBlock(i + 1, j + 13, k + 15, ancientstone);
        chunkPrimer.setBlock(i + 1, j + 14, k + 0, ancientstone);
        chunkPrimer.setBlock(i + 1, j + 14, k + 15, ancientstone);
        chunkPrimer.setBlock(i + 1, j + 15, k + 0, ancientstone);
        chunkPrimer.setBlock(i + 1, j + 15, k + 15, ancientstone);
        chunkPrimer.setBlock(i + 2, j + 0, k + 0, ancientbricks);
        chunkPrimer.setBlock(i + 2, j + 0, k + 1, dungeonBricks);
        chunkPrimer.setBlock(i + 2, j + 0, k + 2, dungeonBricks);
        chunkPrimer.setBlock(i + 2, j + 0, k + 3, dungeonBricks);
        chunkPrimer.setBlock(i + 2, j + 0, k + 4, dungeonBricks);
        chunkPrimer.setBlock(i + 2, j + 0, k + 5, dungeonBricks);
        chunkPrimer.setBlock(i + 2, j + 0, k + 6, dungeonBricks);
        chunkPrimer.setBlock(i + 2, j + 0, k + 7, dungeonBricks);
        chunkPrimer.setBlock(i + 2, j + 0, k + 8, dungeonBricks);
        chunkPrimer.setBlock(i + 2, j + 0, k + 9, dungeonBricks);
        chunkPrimer.setBlock(i + 2, j + 0, k + 10, dungeonBricks);
        chunkPrimer.setBlock(i + 2, j + 0, k + 11, dungeonBricks);
        chunkPrimer.setBlock(i + 2, j + 0, k + 12, dungeonBricks);
        chunkPrimer.setBlock(i + 2, j + 0, k + 13, dungeonBricks);
        chunkPrimer.setBlock(i + 2, j + 0, k + 14, dungeonBricks);
        chunkPrimer.setBlock(i + 2, j + 0, k + 15, ancientbricks);
        chunkPrimer.setBlock(i + 2, j + 1, k + 0, arcaniumSoulSludge);
        chunkPrimer.setBlock(i + 2, j + 1, k + 15, arcaniumSoulSludge);
        chunkPrimer.setBlock(i + 2, j + 2, k + 0, arcaniumSoulSludge);
        chunkPrimer.setBlock(i + 2, j + 2, k + 15, arcaniumSoulSludge);
        chunkPrimer.setBlock(i + 2, j + 3, k + 0, arcaniumSoulSludge);
        chunkPrimer.setBlock(i + 2, j + 3, k + 15, arcaniumSoulSludge);
        chunkPrimer.setBlock(i + 2, j + 4, k + 0, arcaniumSoulSludge);
        chunkPrimer.setBlock(i + 2, j + 4, k + 15, arcaniumSoulSludge);
        chunkPrimer.setBlock(i + 2, j + 5, k + 0, arcaniumSoulSludge);
        chunkPrimer.setBlock(i + 2, j + 5, k + 15, arcaniumSoulSludge);
        chunkPrimer.setBlock(i + 2, j + 6, k + 0, arcaniumSoulSludge);
        chunkPrimer.setBlock(i + 2, j + 6, k + 15, arcaniumSoulSludge);
        chunkPrimer.setBlock(i + 2, j + 7, k + 0, arcaniumSoulSludge);
        chunkPrimer.setBlock(i + 2, j + 7, k + 15, arcaniumSoulSludge);
        chunkPrimer.setBlock(i + 2, j + 8, k + 0, ancientstone);
        chunkPrimer.setBlock(i + 2, j + 8, k + 1, dungeonBricks);
        chunkPrimer.setBlock(i + 2, j + 8, k + 2, dungeonBricks);
        chunkPrimer.setBlock(i + 2, j + 8, k + 3, dungeonBricks);
        chunkPrimer.setBlock(i + 2, j + 8, k + 4, dungeonBricks);
        chunkPrimer.setBlock(i + 2, j + 8, k + 5, dungeonBricks);
        chunkPrimer.setBlock(i + 2, j + 8, k + 6, dungeonBricks);
        chunkPrimer.setBlock(i + 2, j + 8, k + 7, dungeonBricks);
        chunkPrimer.setBlock(i + 2, j + 8, k + 8, dungeonBricks);
        chunkPrimer.setBlock(i + 2, j + 8, k + 9, dungeonBricks);
        chunkPrimer.setBlock(i + 2, j + 8, k + 10, dungeonBricks);
        chunkPrimer.setBlock(i + 2, j + 8, k + 15, ancientstone);
        chunkPrimer.setBlock(i + 2, j + 9, k + 0, soulStone);
        chunkPrimer.setBlock(i + 2, j + 9, k + 15, soulStone);
        chunkPrimer.setBlock(i + 2, j + 10, k + 0, soulStone);
        chunkPrimer.setBlock(i + 2, j + 10, k + 15, soulStone);
        chunkPrimer.setBlock(i + 2, j + 11, k + 0, soulStone);
        chunkPrimer.setBlock(i + 2, j + 11, k + 15, soulStone);
        chunkPrimer.setBlock(i + 2, j + 12, k + 0, ancientbricks);
        chunkPrimer.setBlock(i + 2, j + 12, k + 15, ancientbricks);
        chunkPrimer.setBlock(i + 2, j + 13, k + 0, ancientstone);
        chunkPrimer.setBlock(i + 2, j + 13, k + 15, ancientstone);
        chunkPrimer.setBlock(i + 2, j + 14, k + 0, ancientstone);
        chunkPrimer.setBlock(i + 2, j + 14, k + 15, ancientstone);
        chunkPrimer.setBlock(i + 2, j + 15, k + 0, ancientstone);
        chunkPrimer.setBlock(i + 2, j + 15, k + 15, ancientstone);
        chunkPrimer.setBlock(i + 3, j + 0, k + 0, ancientbricks);
        chunkPrimer.setBlock(i + 3, j + 0, k + 1, dungeonBricks);
        chunkPrimer.setBlock(i + 3, j + 0, k + 2, dungeonBricks);
        chunkPrimer.setBlock(i + 3, j + 0, k + 3, dungeonBricks);
        chunkPrimer.setBlock(i + 3, j + 0, k + 4, dungeonBricks);
        chunkPrimer.setBlock(i + 3, j + 0, k + 5, dungeonBricks);
        chunkPrimer.setBlock(i + 3, j + 0, k + 6, dungeonBricks);
        chunkPrimer.setBlock(i + 3, j + 0, k + 7, dungeonBricks);
        chunkPrimer.setBlock(i + 3, j + 0, k + 8, dungeonBricks);
        chunkPrimer.setBlock(i + 3, j + 0, k + 9, dungeonBricks);
        chunkPrimer.setBlock(i + 3, j + 0, k + 10, dungeonBricks);
        chunkPrimer.setBlock(i + 3, j + 0, k + 11, dungeonBricks);
        chunkPrimer.setBlock(i + 3, j + 0, k + 12, dungeonBricks);
        chunkPrimer.setBlock(i + 3, j + 0, k + 13, dungeonBricks);
        chunkPrimer.setBlock(i + 3, j + 0, k + 14, dungeonBricks);
        chunkPrimer.setBlock(i + 3, j + 0, k + 15, ancientbricks);
        chunkPrimer.setBlock(i + 3, j + 1, k + 0, arcaniteMetal);
        chunkPrimer.setBlock(i + 3, j + 1, k + 7, dungeonBricks);
        chunkPrimer.setBlock(i + 3, j + 1, k + 8, dungeonBricks);
        chunkPrimer.setBlock(i + 3, j + 1, k + 15, arcaniteMetal);
        chunkPrimer.setBlock(i + 3, j + 2, k + 0, arcaniteMetal);
        chunkPrimer.setBlock(i + 3, j + 2, k + 15, arcaniteMetal);
        chunkPrimer.setBlock(i + 3, j + 3, k + 0, arcaniteMetal);
        chunkPrimer.setBlock(i + 3, j + 3, k + 15, arcaniteMetal);
        chunkPrimer.setBlock(i + 3, j + 4, k + 0, arcaniteMetal);
        chunkPrimer.setBlock(i + 3, j + 4, k + 15, arcaniteMetal);
        chunkPrimer.setBlock(i + 3, j + 5, k + 0, arcaniteMetal);
        chunkPrimer.setBlock(i + 3, j + 5, k + 15, arcaniteMetal);
        chunkPrimer.setBlock(i + 3, j + 6, k + 0, arcaniteMetal);
        chunkPrimer.setBlock(i + 3, j + 6, k + 15, arcaniteMetal);
        chunkPrimer.setBlock(i + 3, j + 7, k + 0, arcaniteMetal);
        chunkPrimer.setBlock(i + 3, j + 7, k + 5, dungeonBricks);
        chunkPrimer.setBlock(i + 3, j + 7, k + 6, dungeonBricks);
        chunkPrimer.setBlock(i + 3, j + 7, k + 9, dungeonBricks);
        chunkPrimer.setBlock(i + 3, j + 7, k + 10, dungeonBricks);
        chunkPrimer.setBlock(i + 3, j + 7, k + 15, arcaniteMetal);
        chunkPrimer.setBlock(i + 3, j + 8, k + 0, ancientstone);
        chunkPrimer.setBlock(i + 3, j + 8, k + 1, dungeonBricks);
        chunkPrimer.setBlock(i + 3, j + 8, k + 2, dungeonBricks);
        chunkPrimer.setBlock(i + 3, j + 8, k + 5, dungeonBricks);
        chunkPrimer.setBlock(i + 3, j + 8, k + 6, dungeonBricks);
        chunkPrimer.setBlock(i + 3, j + 8, k + 9, dungeonBricks);
        chunkPrimer.setBlock(i + 3, j + 8, k + 10, dungeonBricks);
        chunkPrimer.setBlock(i + 3, j + 8, k + 15, ancientstone);
        chunkPrimer.setBlock(i + 3, j + 9, k + 0, soulStone);
        chunkPrimer.setBlock(i + 3, j + 9, k + 15, soulStone);
        chunkPrimer.setBlock(i + 3, j + 10, k + 0, soulStone);
        chunkPrimer.setBlock(i + 3, j + 10, k + 15, soulStone);
        chunkPrimer.setBlock(i + 3, j + 11, k + 0, soulStone);
        chunkPrimer.setBlock(i + 3, j + 11, k + 15, soulStone);
        chunkPrimer.setBlock(i + 3, j + 12, k + 0, ancientbricks);
        chunkPrimer.setBlock(i + 3, j + 12, k + 15, ancientbricks);
        chunkPrimer.setBlock(i + 3, j + 13, k + 0, ancientstone);
        chunkPrimer.setBlock(i + 3, j + 13, k + 15, ancientstone);
        chunkPrimer.setBlock(i + 3, j + 14, k + 0, ancientstone);
        chunkPrimer.setBlock(i + 3, j + 14, k + 15, ancientstone);
        chunkPrimer.setBlock(i + 3, j + 15, k + 0, ancientstone);
        chunkPrimer.setBlock(i + 3, j + 15, k + 15, ancientstone);
        chunkPrimer.setBlock(i + 4, j + 0, k + 0, ancientbricks);
        chunkPrimer.setBlock(i + 4, j + 0, k + 1, dungeonBricks);
        chunkPrimer.setBlock(i + 4, j + 0, k + 2, dungeonBricks);
        chunkPrimer.setBlock(i + 4, j + 0, k + 3, dungeonBricks);
        chunkPrimer.setBlock(i + 4, j + 0, k + 4, dungeonBricks);
        chunkPrimer.setBlock(i + 4, j + 0, k + 5, dungeonBricks);
        chunkPrimer.setBlock(i + 4, j + 0, k + 6, dungeonBricks);
        chunkPrimer.setBlock(i + 4, j + 0, k + 7, dungeonBricks);
        chunkPrimer.setBlock(i + 4, j + 0, k + 8, dungeonBricks);
        chunkPrimer.setBlock(i + 4, j + 0, k + 9, dungeonBricks);
        chunkPrimer.setBlock(i + 4, j + 0, k + 10, dungeonBricks);
        chunkPrimer.setBlock(i + 4, j + 0, k + 11, dungeonBricks);
        chunkPrimer.setBlock(i + 4, j + 0, k + 12, dungeonBricks);
        chunkPrimer.setBlock(i + 4, j + 0, k + 13, dungeonBricks);
        chunkPrimer.setBlock(i + 4, j + 0, k + 14, dungeonBricks);
        chunkPrimer.setBlock(i + 4, j + 0, k + 15, ancientbricks);
        chunkPrimer.setBlock(i + 4, j + 1, k + 0, arcaniumSoulSludge);
        chunkPrimer.setBlock(i + 4, j + 1, k + 7, dungeonBricks);
        chunkPrimer.setBlock(i + 4, j + 1, k + 8, dungeonBricks);
        chunkPrimer.setBlock(i + 4, j + 1, k + 15, arcaniumSoulSludge);
        chunkPrimer.setBlock(i + 4, j + 2, k + 0, arcaniumSoulSludge);
        chunkPrimer.setBlock(i + 4, j + 2, k + 7, dungeonBricks);
        chunkPrimer.setBlock(i + 4, j + 2, k + 8, dungeonBricks);
        chunkPrimer.setBlock(i + 4, j + 2, k + 15, arcaniumSoulSludge);
        chunkPrimer.setBlock(i + 4, j + 3, k + 0, arcaniumSoulSludge);
        chunkPrimer.setBlock(i + 4, j + 3, k + 15, arcaniumSoulSludge);
        chunkPrimer.setBlock(i + 4, j + 4, k + 0, arcaniumSoulSludge);
        chunkPrimer.setBlock(i + 4, j + 4, k + 15, arcaniumSoulSludge);
        chunkPrimer.setBlock(i + 4, j + 5, k + 0, arcaniumSoulSludge);
        chunkPrimer.setBlock(i + 4, j + 5, k + 15, arcaniumSoulSludge);
        chunkPrimer.setBlock(i + 4, j + 6, k + 0, arcaniumSoulSludge);
        chunkPrimer.setBlock(i + 4, j + 6, k + 5, dungeonBricks);
        chunkPrimer.setBlock(i + 4, j + 6, k + 6, dungeonBricks);
        chunkPrimer.setBlock(i + 4, j + 6, k + 9, dungeonBricks);
        chunkPrimer.setBlock(i + 4, j + 6, k + 10, dungeonBricks);
        chunkPrimer.setBlock(i + 4, j + 6, k + 15, arcaniumSoulSludge);
        chunkPrimer.setBlock(i + 4, j + 7, k + 0, arcaniumSoulSludge);
        chunkPrimer.setBlock(i + 4, j + 7, k + 5, dungeonBricks);
        chunkPrimer.setBlock(i + 4, j + 7, k + 6, dungeonBricks);
        chunkPrimer.setBlock(i + 4, j + 7, k + 9, dungeonBricks);
        chunkPrimer.setBlock(i + 4, j + 7, k + 10, dungeonBricks);
        chunkPrimer.setBlock(i + 4, j + 7, k + 15, arcaniumSoulSludge);
        chunkPrimer.setBlock(i + 4, j + 8, k + 0, ancientstone);
        chunkPrimer.setBlock(i + 4, j + 8, k + 1, dungeonBricks);
        chunkPrimer.setBlock(i + 4, j + 8, k + 2, dungeonBricks);
        chunkPrimer.setBlock(i + 4, j + 8, k + 15, ancientstone);
        chunkPrimer.setBlock(i + 4, j + 9, k + 0, soulStone);
        chunkPrimer.setBlock(i + 4, j + 9, k + 15, soulStone);
        chunkPrimer.setBlock(i + 4, j + 10, k + 0, soulStone);
        chunkPrimer.setBlock(i + 4, j + 10, k + 15, soulStone);
        chunkPrimer.setBlock(i + 4, j + 11, k + 0, soulStone);
        chunkPrimer.setBlock(i + 4, j + 11, k + 15, soulStone);
        chunkPrimer.setBlock(i + 4, j + 12, k + 0, ancientbricks);
        chunkPrimer.setBlock(i + 4, j + 12, k + 15, ancientbricks);
        chunkPrimer.setBlock(i + 4, j + 13, k + 0, ancientstone);
        chunkPrimer.setBlock(i + 4, j + 13, k + 15, ancientstone);
        chunkPrimer.setBlock(i + 4, j + 14, k + 0, ancientstone);
        chunkPrimer.setBlock(i + 4, j + 14, k + 15, ancientstone);
        chunkPrimer.setBlock(i + 4, j + 15, k + 0, ancientstone);
        chunkPrimer.setBlock(i + 4, j + 15, k + 15, ancientstone);
        chunkPrimer.setBlock(i + 5, j + 0, k + 0, ancientbricks);
        chunkPrimer.setBlock(i + 5, j + 0, k + 1, dungeonBricks);
        chunkPrimer.setBlock(i + 5, j + 0, k + 2, dungeonBricks);
        chunkPrimer.setBlock(i + 5, j + 0, k + 3, dungeonBricks);
        chunkPrimer.setBlock(i + 5, j + 0, k + 4, dungeonBricks);
        chunkPrimer.setBlock(i + 5, j + 0, k + 5, dungeonBricks);
        chunkPrimer.setBlock(i + 5, j + 0, k + 6, dungeonBricks);
        chunkPrimer.setBlock(i + 5, j + 0, k + 7, dungeonBricks);
        chunkPrimer.setBlock(i + 5, j + 0, k + 8, dungeonBricks);
        chunkPrimer.setBlock(i + 5, j + 0, k + 9, dungeonBricks);
        chunkPrimer.setBlock(i + 5, j + 0, k + 10, dungeonBricks);
        chunkPrimer.setBlock(i + 5, j + 0, k + 11, dungeonBricks);
        chunkPrimer.setBlock(i + 5, j + 0, k + 12, dungeonBricks);
        chunkPrimer.setBlock(i + 5, j + 0, k + 13, dungeonBricks);
        chunkPrimer.setBlock(i + 5, j + 0, k + 14, dungeonBricks);
        chunkPrimer.setBlock(i + 5, j + 0, k + 15, ancientbricks);
        chunkPrimer.setBlock(i + 5, j + 1, k + 0, arcaniumSoulSludge);
        chunkPrimer.setBlock(i + 5, j + 1, k + 7, dungeonBricks);
        chunkPrimer.setBlock(i + 5, j + 1, k + 8, dungeonBricks);
        chunkPrimer.setBlock(i + 5, j + 1, k + 15, arcaniumSoulSludge);
        chunkPrimer.setBlock(i + 5, j + 2, k + 0, arcaniumSoulSludge);
        chunkPrimer.setBlock(i + 5, j + 2, k + 7, dungeonBricks);
        chunkPrimer.setBlock(i + 5, j + 2, k + 8, dungeonBricks);
        chunkPrimer.setBlock(i + 5, j + 2, k + 15, arcaniumSoulSludge);
        chunkPrimer.setBlock(i + 5, j + 3, k + 0, arcaniumSoulSludge);
        chunkPrimer.setBlock(i + 5, j + 3, k + 7, dungeonBricks);
        chunkPrimer.setBlock(i + 5, j + 3, k + 8, dungeonBricks);
        chunkPrimer.setBlock(i + 5, j + 3, k + 15, arcaniumSoulSludge);
        chunkPrimer.setBlock(i + 5, j + 4, k + 0, arcaniumSoulSludge);
        chunkPrimer.setBlock(i + 5, j + 4, k + 15, arcaniumSoulSludge);
        chunkPrimer.setBlock(i + 5, j + 5, k + 0, arcaniumSoulSludge);
        chunkPrimer.setBlock(i + 5, j + 5, k + 5, dungeonBricks);
        chunkPrimer.setBlock(i + 5, j + 5, k + 6, dungeonBricks);
        chunkPrimer.setBlock(i + 5, j + 5, k + 9, dungeonBricks);
        chunkPrimer.setBlock(i + 5, j + 5, k + 10, dungeonBricks);
        chunkPrimer.setBlock(i + 5, j + 5, k + 15, arcaniumSoulSludge);
        chunkPrimer.setBlock(i + 5, j + 6, k + 0, arcaniumSoulSludge);
        chunkPrimer.setBlock(i + 5, j + 6, k + 5, dungeonBricks);
        chunkPrimer.setBlock(i + 5, j + 6, k + 6, dungeonBricks);
        chunkPrimer.setBlock(i + 5, j + 6, k + 9, dungeonBricks);
        chunkPrimer.setBlock(i + 5, j + 6, k + 10, dungeonBricks);
        chunkPrimer.setBlock(i + 5, j + 6, k + 15, arcaniumSoulSludge);
        chunkPrimer.setBlock(i + 5, j + 7, k + 0, arcaniumSoulSludge);
        chunkPrimer.setBlock(i + 5, j + 7, k + 15, arcaniumSoulSludge);
        chunkPrimer.setBlock(i + 5, j + 8, k + 0, ancientstone);
        chunkPrimer.setBlock(i + 5, j + 8, k + 1, dungeonBricks);
        chunkPrimer.setBlock(i + 5, j + 8, k + 2, dungeonBricks);
        chunkPrimer.setBlock(i + 5, j + 8, k + 15, ancientstone);
        chunkPrimer.setBlock(i + 5, j + 9, k + 0, soulStone);
        chunkPrimer.setBlock(i + 5, j + 9, k + 15, soulStone);
        chunkPrimer.setBlock(i + 5, j + 10, k + 0, soulStone);
        chunkPrimer.setBlock(i + 5, j + 10, k + 15, soulStone);
        chunkPrimer.setBlock(i + 5, j + 11, k + 0, soulStone);
        chunkPrimer.setBlock(i + 5, j + 11, k + 15, soulStone);
        chunkPrimer.setBlock(i + 5, j + 12, k + 0, ancientbricks);
        chunkPrimer.setBlock(i + 5, j + 12, k + 15, ancientbricks);
        chunkPrimer.setBlock(i + 5, j + 13, k + 0, ancientstone);
        chunkPrimer.setBlock(i + 5, j + 13, k + 15, ancientstone);
        chunkPrimer.setBlock(i + 5, j + 14, k + 0, ancientstone);
        chunkPrimer.setBlock(i + 5, j + 14, k + 15, ancientstone);
        chunkPrimer.setBlock(i + 5, j + 15, k + 0, ancientstone);
        chunkPrimer.setBlock(i + 5, j + 15, k + 15, ancientstone);
        chunkPrimer.setBlock(i + 6, j + 0, k + 0, ancientbricks);
        chunkPrimer.setBlock(i + 6, j + 0, k + 1, dungeonBricks);
        chunkPrimer.setBlock(i + 6, j + 0, k + 2, dungeonBricks);
        chunkPrimer.setBlock(i + 6, j + 0, k + 3, dungeonBricks);
        chunkPrimer.setBlock(i + 6, j + 0, k + 4, dungeonBricks);
        chunkPrimer.setBlock(i + 6, j + 0, k + 5, dungeonBricks);
        chunkPrimer.setBlock(i + 6, j + 0, k + 6, dungeonBricks);
        chunkPrimer.setBlock(i + 6, j + 0, k + 7, dungeonBricks);
        chunkPrimer.setBlock(i + 6, j + 0, k + 8, dungeonBricks);
        chunkPrimer.setBlock(i + 6, j + 0, k + 9, dungeonBricks);
        chunkPrimer.setBlock(i + 6, j + 0, k + 10, dungeonBricks);
        chunkPrimer.setBlock(i + 6, j + 0, k + 11, dungeonBricks);
        chunkPrimer.setBlock(i + 6, j + 0, k + 12, dungeonBricks);
        chunkPrimer.setBlock(i + 6, j + 0, k + 13, dungeonBricks);
        chunkPrimer.setBlock(i + 6, j + 0, k + 14, dungeonBricks);
        chunkPrimer.setBlock(i + 6, j + 0, k + 15, ancientbricks);
        chunkPrimer.setBlock(i + 6, j + 1, k + 0, arcaniteMetal);
        chunkPrimer.setBlock(i + 6, j + 1, k + 7, ArcanaBlocks.arcanaLamp);
        chunkPrimer.setBlock(i + 6, j + 1, k + 8, ArcanaBlocks.arcanaLamp);
        chunkPrimer.setBlock(i + 6, j + 1, k + 15, arcaniteMetal);
        chunkPrimer.setBlock(i + 6, j + 2, k + 0, arcaniteMetal);
        chunkPrimer.setBlock(i + 6, j + 2, k + 7, dungeonBricks);
        chunkPrimer.setBlock(i + 6, j + 2, k + 8, dungeonBricks);
        chunkPrimer.setBlock(i + 6, j + 2, k + 15, arcaniteMetal);
        chunkPrimer.setBlock(i + 6, j + 3, k + 0, arcaniteMetal);
        chunkPrimer.setBlock(i + 6, j + 3, k + 7, dungeonBricks);
        chunkPrimer.setBlock(i + 6, j + 3, k + 8, dungeonBricks);
        chunkPrimer.setBlock(i + 6, j + 3, k + 15, arcaniteMetal);
        chunkPrimer.setBlock(i + 6, j + 4, k + 0, arcaniteMetal);
        chunkPrimer.setBlock(i + 6, j + 4, k + 7, dungeonBricks);
        chunkPrimer.setBlock(i + 6, j + 4, k + 8, dungeonBricks);
        chunkPrimer.setBlock(i + 6, j + 4, k + 15, arcaniteMetal);
        chunkPrimer.setBlock(i + 6, j + 5, k + 0, arcaniteMetal);
        chunkPrimer.setBlock(i + 6, j + 5, k + 5, dungeonBricks);
        chunkPrimer.setBlock(i + 6, j + 5, k + 6, dungeonBricks);
        chunkPrimer.setBlock(i + 6, j + 5, k + 9, dungeonBricks);
        chunkPrimer.setBlock(i + 6, j + 5, k + 10, dungeonBricks);
        chunkPrimer.setBlock(i + 6, j + 5, k + 15, arcaniteMetal);
        chunkPrimer.setBlock(i + 6, j + 6, k + 0, arcaniteMetal);
        chunkPrimer.setBlock(i + 6, j + 6, k + 15, arcaniteMetal);
        chunkPrimer.setBlock(i + 6, j + 7, k + 0, arcaniteMetal);
        chunkPrimer.setBlock(i + 6, j + 7, k + 15, arcaniteMetal);
        chunkPrimer.setBlock(i + 6, j + 8, k + 0, ancientstone);
        chunkPrimer.setBlock(i + 6, j + 8, k + 1, dungeonBricks);
        chunkPrimer.setBlock(i + 6, j + 8, k + 2, dungeonBricks);
        chunkPrimer.setBlock(i + 6, j + 8, k + 15, ancientstone);
        chunkPrimer.setBlock(i + 6, j + 9, k + 0, arcaniteMetal);
        chunkPrimer.setBlock(i + 6, j + 9, k + 15, soulStone);
        chunkPrimer.setBlock(i + 6, j + 10, k + 0, arcaniteMetal);
        chunkPrimer.setBlock(i + 6, j + 10, k + 15, soulStone);
        chunkPrimer.setBlock(i + 6, j + 11, k + 0, arcaniteMetal);
        chunkPrimer.setBlock(i + 6, j + 11, k + 15, soulStone);
        chunkPrimer.setBlock(i + 6, j + 12, k + 0, ancientbricks);
        chunkPrimer.setBlock(i + 6, j + 12, k + 15, ancientbricks);
        chunkPrimer.setBlock(i + 6, j + 13, k + 0, ancientstone);
        chunkPrimer.setBlock(i + 6, j + 13, k + 15, ancientstone);
        chunkPrimer.setBlock(i + 6, j + 14, k + 0, ancientstone);
        chunkPrimer.setBlock(i + 6, j + 14, k + 15, ancientstone);
        chunkPrimer.setBlock(i + 6, j + 15, k + 0, ancientstone);
        chunkPrimer.setBlock(i + 6, j + 15, k + 15, ancientstone);
        chunkPrimer.setBlock(i + 7, j + 0, k + 0, ancientbricks);
        chunkPrimer.setBlock(i + 7, j + 0, k + 1, dungeonBricks);
        chunkPrimer.setBlock(i + 7, j + 0, k + 2, dungeonBricks);
        chunkPrimer.setBlock(i + 7, j + 0, k + 3, dungeonBricks);
        chunkPrimer.setBlock(i + 7, j + 0, k + 4, dungeonBricks);
        chunkPrimer.setBlock(i + 7, j + 0, k + 5, dungeonBricks);
        chunkPrimer.setBlock(i + 7, j + 0, k + 6, dungeonBricks);
        chunkPrimer.setBlock(i + 7, j + 0, k + 7, dungeonBricks);
        chunkPrimer.setBlock(i + 7, j + 0, k + 8, dungeonBricks);
        chunkPrimer.setBlock(i + 7, j + 0, k + 9, dungeonBricks);
        chunkPrimer.setBlock(i + 7, j + 0, k + 10, dungeonBricks);
        chunkPrimer.setBlock(i + 7, j + 0, k + 11, dungeonBricks);
        chunkPrimer.setBlock(i + 7, j + 0, k + 12, dungeonBricks);
        chunkPrimer.setBlock(i + 7, j + 0, k + 13, dungeonBricks);
        chunkPrimer.setBlock(i + 7, j + 0, k + 14, dungeonBricks);
        chunkPrimer.setBlock(i + 7, j + 0, k + 15, ancientbricks);
        chunkPrimer.setBlock(i + 7, j + 1, k + 0, arcaniumSoulSludge);
        chunkPrimer.setBlock(i + 7, j + 1, k + 15, arcaniumSoulSludge);
        chunkPrimer.setBlock(i + 7, j + 2, k + 0, arcaniumSoulSludge);
        chunkPrimer.setBlock(i + 7, j + 2, k + 15, arcaniumSoulSludge);
        chunkPrimer.setBlock(i + 7, j + 3, k + 0, arcaniumSoulSludge);
        chunkPrimer.setBlock(i + 7, j + 3, k + 15, arcaniumSoulSludge);
        chunkPrimer.setBlock(i + 7, j + 4, k + 0, arcaniumSoulSludge);
        chunkPrimer.setBlock(i + 7, j + 4, k + 5, dungeonBricks);
        chunkPrimer.setBlock(i + 7, j + 4, k + 6, dungeonBricks);
        chunkPrimer.setBlock(i + 7, j + 4, k + 7, dungeonBricks);
        chunkPrimer.setBlock(i + 7, j + 4, k + 8, dungeonBricks);
        chunkPrimer.setBlock(i + 7, j + 4, k + 9, dungeonBricks);
        chunkPrimer.setBlock(i + 7, j + 4, k + 10, dungeonBricks);
        chunkPrimer.setBlock(i + 7, j + 4, k + 15, arcaniumSoulSludge);
        chunkPrimer.setBlock(i + 7, j + 5, k + 0, arcaniumSoulSludge);
        chunkPrimer.setBlock(i + 7, j + 5, k + 15, arcaniumSoulSludge);
        chunkPrimer.setBlock(i + 7, j + 6, k + 0, arcaniumSoulSludge);
        chunkPrimer.setBlock(i + 7, j + 6, k + 15, arcaniumSoulSludge);
        chunkPrimer.setBlock(i + 7, j + 7, k + 0, arcaniumSoulSludge);
        chunkPrimer.setBlock(i + 7, j + 7, k + 15, arcaniumSoulSludge);
        chunkPrimer.setBlock(i + 7, j + 8, k + 0, ancientstone);
        chunkPrimer.setBlock(i + 7, j + 8, k + 1, dungeonBricks);
        chunkPrimer.setBlock(i + 7, j + 8, k + 2, dungeonBricks);
        chunkPrimer.setBlock(i + 7, j + 8, k + 15, ancientstone);
        chunkPrimer.setBlock(i + 7, j + 9, k + 15, soulStone);
        chunkPrimer.setBlock(i + 7, j + 10, k + 15, soulStone);
        chunkPrimer.setBlock(i + 7, j + 11, k + 0, arcanaPower);
        chunkPrimer.setBlock(i + 7, j + 11, k + 15, soulStone);
        chunkPrimer.setBlock(i + 7, j + 12, k + 0, ancientbricks);
        chunkPrimer.setBlock(i + 7, j + 12, k + 15, ancientbricks);
        chunkPrimer.setBlock(i + 7, j + 13, k + 0, ancientstone);
        chunkPrimer.setBlock(i + 7, j + 13, k + 15, ancientstone);
        chunkPrimer.setBlock(i + 7, j + 14, k + 0, ancientstone);
        chunkPrimer.setBlock(i + 7, j + 14, k + 15, ancientstone);
        chunkPrimer.setBlock(i + 7, j + 15, k + 0, ancientstone);
        chunkPrimer.setBlock(i + 7, j + 15, k + 15, ancientstone);
        chunkPrimer.setBlock(i + 8, j + 0, k + 0, ancientbricks);
        chunkPrimer.setBlock(i + 8, j + 0, k + 1, dungeonBricks);
        chunkPrimer.setBlock(i + 8, j + 0, k + 2, dungeonBricks);
        chunkPrimer.setBlock(i + 8, j + 0, k + 3, dungeonBricks);
        chunkPrimer.setBlock(i + 8, j + 0, k + 4, dungeonBricks);
        chunkPrimer.setBlock(i + 8, j + 0, k + 5, dungeonBricks);
        chunkPrimer.setBlock(i + 8, j + 0, k + 6, dungeonBricks);
        chunkPrimer.setBlock(i + 8, j + 0, k + 7, dungeonBricks);
        chunkPrimer.setBlock(i + 8, j + 0, k + 8, dungeonBricks);
        chunkPrimer.setBlock(i + 8, j + 0, k + 9, dungeonBricks);
        chunkPrimer.setBlock(i + 8, j + 0, k + 10, dungeonBricks);
        chunkPrimer.setBlock(i + 8, j + 0, k + 11, dungeonBricks);
        chunkPrimer.setBlock(i + 8, j + 0, k + 12, dungeonBricks);
        chunkPrimer.setBlock(i + 8, j + 0, k + 13, dungeonBricks);
        chunkPrimer.setBlock(i + 8, j + 0, k + 14, dungeonBricks);
        chunkPrimer.setBlock(i + 8, j + 0, k + 15, ancientbricks);
        chunkPrimer.setBlock(i + 8, j + 1, k + 0, arcaniumSoulSludge);
        chunkPrimer.setBlock(i + 8, j + 1, k + 15, arcaniumSoulSludge);
        chunkPrimer.setBlock(i + 8, j + 2, k + 0, arcaniumSoulSludge);
        chunkPrimer.setBlock(i + 8, j + 2, k + 15, arcaniumSoulSludge);
        chunkPrimer.setBlock(i + 8, j + 3, k + 0, arcaniumSoulSludge);
        chunkPrimer.setBlock(i + 8, j + 3, k + 7, dungeonBricks);
        chunkPrimer.setBlock(i + 8, j + 3, k + 8, dungeonBricks);
        chunkPrimer.setBlock(i + 8, j + 3, k + 15, arcaniumSoulSludge);
        chunkPrimer.setBlock(i + 8, j + 4, k + 0, arcaniumSoulSludge);
        chunkPrimer.setBlock(i + 8, j + 4, k + 5, dungeonBricks);
        chunkPrimer.setBlock(i + 8, j + 4, k + 6, dungeonBricks);
        chunkPrimer.setBlock(i + 8, j + 4, k + 7, dungeonBricks);
        chunkPrimer.setBlock(i + 8, j + 4, k + 8, dungeonBricks);
        chunkPrimer.setBlock(i + 8, j + 4, k + 9, dungeonBricks);
        chunkPrimer.setBlock(i + 8, j + 4, k + 10, dungeonBricks);
        chunkPrimer.setBlock(i + 8, j + 4, k + 15, arcaniumSoulSludge);
        chunkPrimer.setBlock(i + 8, j + 5, k + 0, arcaniumSoulSludge);
        chunkPrimer.setBlock(i + 8, j + 5, k + 15, arcaniumSoulSludge);
        chunkPrimer.setBlock(i + 8, j + 6, k + 0, arcaniumSoulSludge);
        chunkPrimer.setBlock(i + 8, j + 6, k + 15, arcaniumSoulSludge);
        chunkPrimer.setBlock(i + 8, j + 7, k + 0, arcaniumSoulSludge);
        chunkPrimer.setBlock(i + 8, j + 7, k + 15, arcaniumSoulSludge);
        chunkPrimer.setBlock(i + 8, j + 8, k + 0, ancientstone);
        chunkPrimer.setBlock(i + 8, j + 8, k + 1, dungeonBricks);
        chunkPrimer.setBlock(i + 8, j + 8, k + 2, dungeonBricks);
        chunkPrimer.setBlock(i + 8, j + 8, k + 15, ancientstone);
        chunkPrimer.setBlock(i + 8, j + 9, k + 15, soulStone);
        chunkPrimer.setBlock(i + 8, j + 10, k + 15, soulStone);
        chunkPrimer.setBlock(i + 8, j + 11, k + 0, arcanaPower);
        chunkPrimer.setBlock(i + 8, j + 11, k + 15, soulStone);
        chunkPrimer.setBlock(i + 8, j + 12, k + 0, ancientbricks);
        chunkPrimer.setBlock(i + 8, j + 12, k + 15, ancientbricks);
        chunkPrimer.setBlock(i + 8, j + 13, k + 0, ancientstone);
        chunkPrimer.setBlock(i + 8, j + 13, k + 15, ancientstone);
        chunkPrimer.setBlock(i + 8, j + 14, k + 0, ancientstone);
        chunkPrimer.setBlock(i + 8, j + 14, k + 15, ancientstone);
        chunkPrimer.setBlock(i + 8, j + 15, k + 0, ancientstone);
        chunkPrimer.setBlock(i + 8, j + 15, k + 15, ancientstone);
        chunkPrimer.setBlock(i + 9, j + 0, k + 0, ancientbricks);
        chunkPrimer.setBlock(i + 9, j + 0, k + 1, dungeonBricks);
        chunkPrimer.setBlock(i + 9, j + 0, k + 2, dungeonBricks);
        chunkPrimer.setBlock(i + 9, j + 0, k + 3, dungeonBricks);
        chunkPrimer.setBlock(i + 9, j + 0, k + 4, dungeonBricks);
        chunkPrimer.setBlock(i + 9, j + 0, k + 5, dungeonBricks);
        chunkPrimer.setBlock(i + 9, j + 0, k + 6, dungeonBricks);
        chunkPrimer.setBlock(i + 9, j + 0, k + 7, dungeonBricks);
        chunkPrimer.setBlock(i + 9, j + 0, k + 8, dungeonBricks);
        chunkPrimer.setBlock(i + 9, j + 0, k + 9, dungeonBricks);
        chunkPrimer.setBlock(i + 9, j + 0, k + 10, dungeonBricks);
        chunkPrimer.setBlock(i + 9, j + 0, k + 11, dungeonBricks);
        chunkPrimer.setBlock(i + 9, j + 0, k + 12, dungeonBricks);
        chunkPrimer.setBlock(i + 9, j + 0, k + 13, dungeonBricks);
        chunkPrimer.setBlock(i + 9, j + 0, k + 14, dungeonBricks);
        chunkPrimer.setBlock(i + 9, j + 0, k + 15, ancientbricks);
        chunkPrimer.setBlock(i + 9, j + 1, k + 0, arcaniteMetal);
        chunkPrimer.setBlock(i + 9, j + 1, k + 7, ArcanaBlocks.arcanaLamp);
        chunkPrimer.setBlock(i + 9, j + 1, k + 8, ArcanaBlocks.arcanaLamp);
        chunkPrimer.setBlock(i + 9, j + 1, k + 15, arcaniteMetal);
        chunkPrimer.setBlock(i + 9, j + 2, k + 0, arcaniteMetal);
        chunkPrimer.setBlock(i + 9, j + 2, k + 7, dungeonBricks);
        chunkPrimer.setBlock(i + 9, j + 2, k + 8, dungeonBricks);
        chunkPrimer.setBlock(i + 9, j + 2, k + 15, arcaniteMetal);
        chunkPrimer.setBlock(i + 9, j + 3, k + 0, arcaniteMetal);
        chunkPrimer.setBlock(i + 9, j + 3, k + 7, dungeonBricks);
        chunkPrimer.setBlock(i + 9, j + 3, k + 8, dungeonBricks);
        chunkPrimer.setBlock(i + 9, j + 3, k + 15, arcaniteMetal);
        chunkPrimer.setBlock(i + 9, j + 4, k + 0, arcaniteMetal);
        chunkPrimer.setBlock(i + 9, j + 4, k + 15, arcaniteMetal);
        chunkPrimer.setBlock(i + 9, j + 5, k + 0, arcaniteMetal);
        chunkPrimer.setBlock(i + 9, j + 5, k + 15, arcaniteMetal);
        chunkPrimer.setBlock(i + 9, j + 6, k + 0, arcaniteMetal);
        chunkPrimer.setBlock(i + 9, j + 6, k + 15, arcaniteMetal);
        chunkPrimer.setBlock(i + 9, j + 7, k + 0, arcaniteMetal);
        chunkPrimer.setBlock(i + 9, j + 7, k + 15, arcaniteMetal);
        chunkPrimer.setBlock(i + 9, j + 8, k + 0, ancientstone);
        chunkPrimer.setBlock(i + 9, j + 8, k + 15, ancientstone);
        chunkPrimer.setBlock(i + 9, j + 9, k + 0, arcaniteMetal);
        chunkPrimer.setBlock(i + 9, j + 9, k + 15, soulStone);
        chunkPrimer.setBlock(i + 9, j + 10, k + 0, arcaniteMetal);
        chunkPrimer.setBlock(i + 9, j + 10, k + 15, soulStone);
        chunkPrimer.setBlock(i + 9, j + 11, k + 0, arcaniteMetal);
        chunkPrimer.setBlock(i + 9, j + 11, k + 15, soulStone);
        chunkPrimer.setBlock(i + 9, j + 12, k + 0, ancientbricks);
        chunkPrimer.setBlock(i + 9, j + 12, k + 4, dungeonBricks);
        chunkPrimer.setBlock(i + 9, j + 12, k + 11, dungeonBricks);
        chunkPrimer.setBlock(i + 9, j + 12, k + 15, ancientbricks);
        chunkPrimer.setBlock(i + 9, j + 13, k + 0, ancientstone);
        chunkPrimer.setBlock(i + 9, j + 13, k + 4, ArcanaBlocks.arcanaLamp);
        chunkPrimer.setBlock(i + 9, j + 13, k + 11, ArcanaBlocks.arcanaLamp);
        chunkPrimer.setBlock(i + 9, j + 13, k + 15, ancientstone);
        chunkPrimer.setBlock(i + 9, j + 14, k + 0, ancientstone);
        chunkPrimer.setBlock(i + 9, j + 14, k + 15, ancientstone);
        chunkPrimer.setBlock(i + 9, j + 15, k + 0, ancientstone);
        chunkPrimer.setBlock(i + 9, j + 15, k + 15, ancientstone);
        chunkPrimer.setBlock(i + 10, j + 0, k + 0, ancientbricks);
        chunkPrimer.setBlock(i + 10, j + 0, k + 1, dungeonBricks);
        chunkPrimer.setBlock(i + 10, j + 0, k + 2, dungeonBricks);
        chunkPrimer.setBlock(i + 10, j + 0, k + 3, dungeonBricks);
        chunkPrimer.setBlock(i + 10, j + 0, k + 4, dungeonBricks);
        chunkPrimer.setBlock(i + 10, j + 0, k + 5, dungeonBricks);
        chunkPrimer.setBlock(i + 10, j + 0, k + 6, dungeonBricks);
        chunkPrimer.setBlock(i + 10, j + 0, k + 7, dungeonBricks);
        chunkPrimer.setBlock(i + 10, j + 0, k + 8, dungeonBricks);
        chunkPrimer.setBlock(i + 10, j + 0, k + 9, dungeonBricks);
        chunkPrimer.setBlock(i + 10, j + 0, k + 10, dungeonBricks);
        chunkPrimer.setBlock(i + 10, j + 0, k + 11, dungeonBricks);
        chunkPrimer.setBlock(i + 10, j + 0, k + 12, dungeonBricks);
        chunkPrimer.setBlock(i + 10, j + 0, k + 13, dungeonBricks);
        chunkPrimer.setBlock(i + 10, j + 0, k + 14, dungeonBricks);
        chunkPrimer.setBlock(i + 10, j + 0, k + 15, ancientbricks);
        chunkPrimer.setBlock(i + 10, j + 1, k + 0, arcaniumSoulSludge);
        chunkPrimer.setBlock(i + 10, j + 1, k + 7, dungeonBricks);
        chunkPrimer.setBlock(i + 10, j + 1, k + 8, dungeonBricks);
        chunkPrimer.setBlock(i + 10, j + 1, k + 15, arcaniumSoulSludge);
        chunkPrimer.setBlock(i + 10, j + 2, k + 0, arcaniumSoulSludge);
        chunkPrimer.setBlock(i + 10, j + 2, k + 7, dungeonBricks);
        chunkPrimer.setBlock(i + 10, j + 2, k + 8, dungeonBricks);
        chunkPrimer.setBlock(i + 10, j + 2, k + 15, arcaniumSoulSludge);
        chunkPrimer.setBlock(i + 10, j + 3, k + 0, arcaniumSoulSludge);
        chunkPrimer.setBlock(i + 10, j + 3, k + 15, arcaniumSoulSludge);
        chunkPrimer.setBlock(i + 10, j + 4, k + 0, arcaniumSoulSludge);
        chunkPrimer.setBlock(i + 10, j + 4, k + 15, arcaniumSoulSludge);
        chunkPrimer.setBlock(i + 10, j + 5, k + 0, arcaniumSoulSludge);
        chunkPrimer.setBlock(i + 10, j + 5, k + 15, arcaniumSoulSludge);
        chunkPrimer.setBlock(i + 10, j + 6, k + 0, arcaniumSoulSludge);
        chunkPrimer.setBlock(i + 10, j + 6, k + 15, arcaniumSoulSludge);
        chunkPrimer.setBlock(i + 10, j + 7, k + 0, arcaniumSoulSludge);
        chunkPrimer.setBlock(i + 10, j + 7, k + 15, arcaniumSoulSludge);
        chunkPrimer.setBlock(i + 10, j + 8, k + 0, ancientstone);
        chunkPrimer.setBlock(i + 10, j + 8, k + 15, ancientstone);
        chunkPrimer.setBlock(i + 10, j + 9, k + 0, soulStone);
        chunkPrimer.setBlock(i + 10, j + 9, k + 15, soulStone);
        chunkPrimer.setBlock(i + 10, j + 10, k + 0, soulStone);
        chunkPrimer.setBlock(i + 10, j + 10, k + 15, soulStone);
        chunkPrimer.setBlock(i + 10, j + 11, k + 0, soulStone);
        chunkPrimer.setBlock(i + 10, j + 11, k + 15, soulStone);
        chunkPrimer.setBlock(i + 10, j + 12, k + 0, ancientbricks);
        chunkPrimer.setBlock(i + 10, j + 12, k + 4, dungeonBricks);
        chunkPrimer.setBlock(i + 10, j + 12, k + 11, dungeonBricks);
        chunkPrimer.setBlock(i + 10, j + 12, k + 15, ancientbricks);
        chunkPrimer.setBlock(i + 10, j + 13, k + 0, ancientstone);
        chunkPrimer.setBlock(i + 10, j + 13, k + 15, ancientstone);
        chunkPrimer.setBlock(i + 10, j + 14, k + 0, ancientstone);
        chunkPrimer.setBlock(i + 10, j + 14, k + 15, ancientstone);
        chunkPrimer.setBlock(i + 10, j + 15, k + 0, ancientstone);
        chunkPrimer.setBlock(i + 10, j + 15, k + 15, ancientstone);
        chunkPrimer.setBlock(i + 11, j + 0, k + 0, ancientbricks);
        chunkPrimer.setBlock(i + 11, j + 0, k + 1, dungeonBricks);
        chunkPrimer.setBlock(i + 11, j + 0, k + 2, dungeonBricks);
        chunkPrimer.setBlock(i + 11, j + 0, k + 3, dungeonBricks);
        chunkPrimer.setBlock(i + 11, j + 0, k + 4, dungeonBricks);
        chunkPrimer.setBlock(i + 11, j + 0, k + 5, dungeonBricks);
        chunkPrimer.setBlock(i + 11, j + 0, k + 6, dungeonBricks);
        chunkPrimer.setBlock(i + 11, j + 0, k + 7, dungeonBricks);
        chunkPrimer.setBlock(i + 11, j + 0, k + 8, dungeonBricks);
        chunkPrimer.setBlock(i + 11, j + 0, k + 9, dungeonBricks);
        chunkPrimer.setBlock(i + 11, j + 0, k + 10, dungeonBricks);
        chunkPrimer.setBlock(i + 11, j + 0, k + 11, dungeonBricks);
        chunkPrimer.setBlock(i + 11, j + 0, k + 12, dungeonBricks);
        chunkPrimer.setBlock(i + 11, j + 0, k + 13, dungeonBricks);
        chunkPrimer.setBlock(i + 11, j + 0, k + 14, dungeonBricks);
        chunkPrimer.setBlock(i + 11, j + 0, k + 15, ancientbricks);
        chunkPrimer.setBlock(i + 11, j + 1, k + 0, arcaniumSoulSludge);
        chunkPrimer.setBlock(i + 11, j + 1, k + 7, dungeonBricks);
        chunkPrimer.setBlock(i + 11, j + 1, k + 8, dungeonBricks);
        chunkPrimer.setBlock(i + 11, j + 1, k + 15, arcaniumSoulSludge);
        chunkPrimer.setBlock(i + 11, j + 2, k + 0, arcaniumSoulSludge);
        chunkPrimer.setBlock(i + 11, j + 2, k + 15, arcaniumSoulSludge);
        chunkPrimer.setBlock(i + 11, j + 3, k + 0, arcaniumSoulSludge);
        chunkPrimer.setBlock(i + 11, j + 3, k + 15, arcaniumSoulSludge);
        chunkPrimer.setBlock(i + 11, j + 4, k + 0, arcaniumSoulSludge);
        chunkPrimer.setBlock(i + 11, j + 4, k + 15, arcaniumSoulSludge);
        chunkPrimer.setBlock(i + 11, j + 5, k + 0, arcaniumSoulSludge);
        chunkPrimer.setBlock(i + 11, j + 5, k + 15, arcaniumSoulSludge);
        chunkPrimer.setBlock(i + 11, j + 6, k + 0, arcaniumSoulSludge);
        chunkPrimer.setBlock(i + 11, j + 6, k + 15, arcaniumSoulSludge);
        chunkPrimer.setBlock(i + 11, j + 7, k + 0, arcaniumSoulSludge);
        chunkPrimer.setBlock(i + 11, j + 7, k + 15, arcaniumSoulSludge);
        chunkPrimer.setBlock(i + 11, j + 8, k + 0, ancientstone);
        chunkPrimer.setBlock(i + 11, j + 8, k + 15, ancientstone);
        chunkPrimer.setBlock(i + 11, j + 9, k + 0, soulStone);
        chunkPrimer.setBlock(i + 11, j + 9, k + 15, soulStone);
        chunkPrimer.setBlock(i + 11, j + 10, k + 0, soulStone);
        chunkPrimer.setBlock(i + 11, j + 10, k + 15, soulStone);
        chunkPrimer.setBlock(i + 11, j + 11, k + 0, soulStone);
        chunkPrimer.setBlock(i + 11, j + 11, k + 15, soulStone);
        chunkPrimer.setBlock(i + 11, j + 12, k + 0, ancientbricks);
        chunkPrimer.setBlock(i + 11, j + 12, k + 2, dungeonBricks);
        chunkPrimer.setBlock(i + 11, j + 12, k + 3, dungeonBricks);
        chunkPrimer.setBlock(i + 11, j + 12, k + 4, dungeonBricks);
        chunkPrimer.setBlock(i + 11, j + 12, k + 5, dungeonBricks);
        chunkPrimer.setBlock(i + 11, j + 12, k + 6, dungeonBricks);
        chunkPrimer.setBlock(i + 11, j + 12, k + 9, dungeonBricks);
        chunkPrimer.setBlock(i + 11, j + 12, k + 10, dungeonBricks);
        chunkPrimer.setBlock(i + 11, j + 12, k + 11, dungeonBricks);
        chunkPrimer.setBlock(i + 11, j + 12, k + 12, dungeonBricks);
        chunkPrimer.setBlock(i + 11, j + 12, k + 13, dungeonBricks);
        chunkPrimer.setBlock(i + 11, j + 12, k + 15, ancientbricks);
        chunkPrimer.setBlock(i + 11, j + 13, k + 0, ancientstone);
        chunkPrimer.setBlock(i + 11, j + 13, k + 2, ArcanaBlocks.arcanaLamp);
        chunkPrimer.setBlock(i + 11, j + 13, k + 4, dungeonBricks);
        chunkPrimer.setBlock(i + 11, j + 13, k + 6, ArcanaBlocks.arcanaLamp);
        chunkPrimer.setBlock(i + 11, j + 13, k + 9, ArcanaBlocks.arcanaLamp);
        chunkPrimer.setBlock(i + 11, j + 13, k + 11, dungeonBricks);
        chunkPrimer.setBlock(i + 11, j + 13, k + 13, ArcanaBlocks.arcanaLamp);
        chunkPrimer.setBlock(i + 11, j + 13, k + 15, ancientstone);
        chunkPrimer.setBlock(i + 11, j + 14, k + 0, ancientstone);
        chunkPrimer.setBlock(i + 11, j + 14, k + 4, dungeonBricks);
        chunkPrimer.setBlock(i + 11, j + 14, k + 11, dungeonBricks);
        chunkPrimer.setBlock(i + 11, j + 14, k + 15, ancientstone);
        chunkPrimer.setBlock(i + 11, j + 15, k + 0, ancientstone);
        chunkPrimer.setBlock(i + 11, j + 15, k + 11, dungeonBricks);
        chunkPrimer.setBlock(i + 11, j + 15, k + 15, ancientstone);
        chunkPrimer.setBlock(i + 12, j + 0, k + 0, ancientbricks);
        chunkPrimer.setBlock(i + 12, j + 0, k + 1, dungeonBricks);
        chunkPrimer.setBlock(i + 12, j + 0, k + 2, dungeonBricks);
        chunkPrimer.setBlock(i + 12, j + 0, k + 3, dungeonBricks);
        chunkPrimer.setBlock(i + 12, j + 0, k + 4, dungeonBricks);
        chunkPrimer.setBlock(i + 12, j + 0, k + 5, dungeonBricks);
        chunkPrimer.setBlock(i + 12, j + 0, k + 6, dungeonBricks);
        chunkPrimer.setBlock(i + 12, j + 0, k + 7, dungeonBricks);
        chunkPrimer.setBlock(i + 12, j + 0, k + 8, dungeonBricks);
        chunkPrimer.setBlock(i + 12, j + 0, k + 9, dungeonBricks);
        chunkPrimer.setBlock(i + 12, j + 0, k + 10, dungeonBricks);
        chunkPrimer.setBlock(i + 12, j + 0, k + 11, dungeonBricks);
        chunkPrimer.setBlock(i + 12, j + 0, k + 12, dungeonBricks);
        chunkPrimer.setBlock(i + 12, j + 0, k + 13, dungeonBricks);
        chunkPrimer.setBlock(i + 12, j + 0, k + 14, dungeonBricks);
        chunkPrimer.setBlock(i + 12, j + 0, k + 15, ancientbricks);
        chunkPrimer.setBlock(i + 12, j + 1, k + 0, arcaniteMetal);
        chunkPrimer.setBlock(i + 12, j + 1, k + 15, arcaniteMetal);
        chunkPrimer.setBlock(i + 12, j + 2, k + 0, arcaniteMetal);
        chunkPrimer.setBlock(i + 12, j + 2, k + 15, arcaniteMetal);
        chunkPrimer.setBlock(i + 12, j + 3, k + 0, arcaniteMetal);
        chunkPrimer.setBlock(i + 12, j + 3, k + 15, arcaniteMetal);
        chunkPrimer.setBlock(i + 12, j + 4, k + 0, arcaniteMetal);
        chunkPrimer.setBlock(i + 12, j + 4, k + 15, arcaniteMetal);
        chunkPrimer.setBlock(i + 12, j + 5, k + 0, arcaniteMetal);
        chunkPrimer.setBlock(i + 12, j + 5, k + 15, arcaniteMetal);
        chunkPrimer.setBlock(i + 12, j + 6, k + 0, arcaniteMetal);
        chunkPrimer.setBlock(i + 12, j + 6, k + 15, arcaniteMetal);
        chunkPrimer.setBlock(i + 12, j + 7, k + 0, arcaniteMetal);
        chunkPrimer.setBlock(i + 12, j + 7, k + 15, arcaniteMetal);
        chunkPrimer.setBlock(i + 12, j + 8, k + 0, ancientstone);
        chunkPrimer.setBlock(i + 12, j + 8, k + 15, ancientstone);
        chunkPrimer.setBlock(i + 12, j + 9, k + 0, soulStone);
        chunkPrimer.setBlock(i + 12, j + 9, k + 15, soulStone);
        chunkPrimer.setBlock(i + 12, j + 10, k + 0, soulStone);
        chunkPrimer.setBlock(i + 12, j + 10, k + 15, soulStone);
        chunkPrimer.setBlock(i + 12, j + 11, k + 0, soulStone);
        chunkPrimer.setBlock(i + 12, j + 11, k + 15, soulStone);
        chunkPrimer.setBlock(i + 12, j + 12, k + 0, ancientbricks);
        chunkPrimer.setBlock(i + 12, j + 12, k + 15, ancientbricks);
        chunkPrimer.setBlock(i + 12, j + 13, k + 0, ancientstone);
        chunkPrimer.setBlock(i + 12, j + 13, k + 15, ancientstone);
        chunkPrimer.setBlock(i + 12, j + 14, k + 0, ancientstone);
        chunkPrimer.setBlock(i + 12, j + 14, k + 15, ancientstone);
        chunkPrimer.setBlock(i + 12, j + 15, k + 0, ancientstone);
        chunkPrimer.setBlock(i + 12, j + 15, k + 15, ancientstone);
        chunkPrimer.setBlock(i + 13, j + 0, k + 0, ancientbricks);
        chunkPrimer.setBlock(i + 13, j + 0, k + 1, dungeonBricks);
        chunkPrimer.setBlock(i + 13, j + 0, k + 2, dungeonBricks);
        chunkPrimer.setBlock(i + 13, j + 0, k + 3, dungeonBricks);
        chunkPrimer.setBlock(i + 13, j + 0, k + 4, dungeonBricks);
        chunkPrimer.setBlock(i + 13, j + 0, k + 5, dungeonBricks);
        chunkPrimer.setBlock(i + 13, j + 0, k + 6, dungeonBricks);
        chunkPrimer.setBlock(i + 13, j + 0, k + 7, dungeonBricks);
        chunkPrimer.setBlock(i + 13, j + 0, k + 8, dungeonBricks);
        chunkPrimer.setBlock(i + 13, j + 0, k + 9, dungeonBricks);
        chunkPrimer.setBlock(i + 13, j + 0, k + 10, dungeonBricks);
        chunkPrimer.setBlock(i + 13, j + 0, k + 11, dungeonBricks);
        chunkPrimer.setBlock(i + 13, j + 0, k + 12, dungeonBricks);
        chunkPrimer.setBlock(i + 13, j + 0, k + 13, dungeonBricks);
        chunkPrimer.setBlock(i + 13, j + 0, k + 14, dungeonBricks);
        chunkPrimer.setBlock(i + 13, j + 0, k + 15, ancientbricks);
        chunkPrimer.setBlock(i + 13, j + 1, k + 0, arcaniumSoulSludge);
        chunkPrimer.setBlock(i + 13, j + 1, k + 15, arcaniumSoulSludge);
        chunkPrimer.setBlock(i + 13, j + 2, k + 0, arcaniumSoulSludge);
        chunkPrimer.setBlock(i + 13, j + 2, k + 15, arcaniumSoulSludge);
        chunkPrimer.setBlock(i + 13, j + 3, k + 0, arcaniumSoulSludge);
        chunkPrimer.setBlock(i + 13, j + 3, k + 15, arcaniumSoulSludge);
        chunkPrimer.setBlock(i + 13, j + 4, k + 0, arcaniumSoulSludge);
        chunkPrimer.setBlock(i + 13, j + 4, k + 15, arcaniumSoulSludge);
        chunkPrimer.setBlock(i + 13, j + 5, k + 0, arcaniumSoulSludge);
        chunkPrimer.setBlock(i + 13, j + 5, k + 15, arcaniumSoulSludge);
        chunkPrimer.setBlock(i + 13, j + 6, k + 0, arcaniumSoulSludge);
        chunkPrimer.setBlock(i + 13, j + 6, k + 15, arcaniumSoulSludge);
        chunkPrimer.setBlock(i + 13, j + 7, k + 0, arcaniumSoulSludge);
        chunkPrimer.setBlock(i + 13, j + 7, k + 15, arcaniumSoulSludge);
        chunkPrimer.setBlock(i + 13, j + 8, k + 0, ancientstone);
        chunkPrimer.setBlock(i + 13, j + 8, k + 15, ancientstone);
        chunkPrimer.setBlock(i + 13, j + 9, k + 0, soulStone);
        chunkPrimer.setBlock(i + 13, j + 9, k + 15, soulStone);
        chunkPrimer.setBlock(i + 13, j + 10, k + 0, soulStone);
        chunkPrimer.setBlock(i + 13, j + 10, k + 15, soulStone);
        chunkPrimer.setBlock(i + 13, j + 11, k + 0, soulStone);
        chunkPrimer.setBlock(i + 13, j + 11, k + 15, soulStone);
        chunkPrimer.setBlock(i + 13, j + 12, k + 0, ancientbricks);
        chunkPrimer.setBlock(i + 13, j + 12, k + 15, ancientbricks);
        chunkPrimer.setBlock(i + 13, j + 13, k + 0, ancientstone);
        chunkPrimer.setBlock(i + 13, j + 13, k + 15, ancientstone);
        chunkPrimer.setBlock(i + 13, j + 14, k + 0, ancientstone);
        chunkPrimer.setBlock(i + 13, j + 14, k + 15, ancientstone);
        chunkPrimer.setBlock(i + 13, j + 15, k + 0, ancientstone);
        chunkPrimer.setBlock(i + 13, j + 15, k + 15, ancientstone);
        chunkPrimer.setBlock(i + 14, j + 0, k + 0, ancientbricks);
        chunkPrimer.setBlock(i + 14, j + 0, k + 1, dungeonBricks);
        chunkPrimer.setBlock(i + 14, j + 0, k + 2, dungeonBricks);
        chunkPrimer.setBlock(i + 14, j + 0, k + 3, dungeonBricks);
        chunkPrimer.setBlock(i + 14, j + 0, k + 4, dungeonBricks);
        chunkPrimer.setBlock(i + 14, j + 0, k + 5, dungeonBricks);
        chunkPrimer.setBlock(i + 14, j + 0, k + 6, dungeonBricks);
        chunkPrimer.setBlock(i + 14, j + 0, k + 7, dungeonBricks);
        chunkPrimer.setBlock(i + 14, j + 0, k + 8, dungeonBricks);
        chunkPrimer.setBlock(i + 14, j + 0, k + 9, dungeonBricks);
        chunkPrimer.setBlock(i + 14, j + 0, k + 10, dungeonBricks);
        chunkPrimer.setBlock(i + 14, j + 0, k + 11, dungeonBricks);
        chunkPrimer.setBlock(i + 14, j + 0, k + 12, dungeonBricks);
        chunkPrimer.setBlock(i + 14, j + 0, k + 13, dungeonBricks);
        chunkPrimer.setBlock(i + 14, j + 0, k + 14, dungeonBricks);
        chunkPrimer.setBlock(i + 14, j + 0, k + 15, ancientbricks);
        chunkPrimer.setBlock(i + 14, j + 1, k + 0, arcaniumSoulSludge);
        chunkPrimer.setBlock(i + 14, j + 1, k + 15, arcaniumSoulSludge);
        chunkPrimer.setBlock(i + 14, j + 2, k + 0, arcaniumSoulSludge);
        chunkPrimer.setBlock(i + 14, j + 2, k + 15, arcaniumSoulSludge);
        chunkPrimer.setBlock(i + 14, j + 3, k + 0, arcaniumSoulSludge);
        chunkPrimer.setBlock(i + 14, j + 3, k + 15, arcaniumSoulSludge);
        chunkPrimer.setBlock(i + 14, j + 4, k + 0, arcaniumSoulSludge);
        chunkPrimer.setBlock(i + 14, j + 4, k + 15, arcaniumSoulSludge);
        chunkPrimer.setBlock(i + 14, j + 5, k + 0, arcaniumSoulSludge);
        chunkPrimer.setBlock(i + 14, j + 5, k + 15, arcaniumSoulSludge);
        chunkPrimer.setBlock(i + 14, j + 6, k + 0, arcaniumSoulSludge);
        chunkPrimer.setBlock(i + 14, j + 6, k + 15, arcaniumSoulSludge);
        chunkPrimer.setBlock(i + 14, j + 7, k + 0, arcaniumSoulSludge);
        chunkPrimer.setBlock(i + 14, j + 7, k + 15, arcaniumSoulSludge);
        chunkPrimer.setBlock(i + 14, j + 8, k + 0, ancientstone);
        chunkPrimer.setBlock(i + 14, j + 8, k + 15, ancientstone);
        chunkPrimer.setBlock(i + 14, j + 9, k + 0, soulStone);
        chunkPrimer.setBlock(i + 14, j + 9, k + 15, soulStone);
        chunkPrimer.setBlock(i + 14, j + 10, k + 0, soulStone);
        chunkPrimer.setBlock(i + 14, j + 10, k + 15, soulStone);
        chunkPrimer.setBlock(i + 14, j + 11, k + 0, soulStone);
        chunkPrimer.setBlock(i + 14, j + 11, k + 15, soulStone);
        chunkPrimer.setBlock(i + 14, j + 12, k + 0, ancientbricks);
        chunkPrimer.setBlock(i + 14, j + 12, k + 15, ancientbricks);
        chunkPrimer.setBlock(i + 14, j + 13, k + 0, ancientstone);
        chunkPrimer.setBlock(i + 14, j + 13, k + 15, ancientstone);
        chunkPrimer.setBlock(i + 14, j + 14, k + 0, ancientstone);
        chunkPrimer.setBlock(i + 14, j + 14, k + 15, ancientstone);
        chunkPrimer.setBlock(i + 14, j + 15, k + 0, ancientstone);
        chunkPrimer.setBlock(i + 14, j + 15, k + 15, ancientstone);
        chunkPrimer.setBlock(i + 15, j + 0, k + 0, ancientbricks);
        chunkPrimer.setBlock(i + 15, j + 0, k + 1, ancientbricks);
        chunkPrimer.setBlock(i + 15, j + 0, k + 2, ancientbricks);
        chunkPrimer.setBlock(i + 15, j + 0, k + 3, ancientbricks);
        chunkPrimer.setBlock(i + 15, j + 0, k + 4, ancientbricks);
        chunkPrimer.setBlock(i + 15, j + 0, k + 5, ancientbricks);
        chunkPrimer.setBlock(i + 15, j + 0, k + 6, ancientbricks);
        chunkPrimer.setBlock(i + 15, j + 0, k + 7, ancientbricks);
        chunkPrimer.setBlock(i + 15, j + 0, k + 8, ancientbricks);
        chunkPrimer.setBlock(i + 15, j + 0, k + 9, ancientbricks);
        chunkPrimer.setBlock(i + 15, j + 0, k + 10, ancientbricks);
        chunkPrimer.setBlock(i + 15, j + 0, k + 11, ancientbricks);
        chunkPrimer.setBlock(i + 15, j + 0, k + 12, ancientbricks);
        chunkPrimer.setBlock(i + 15, j + 0, k + 13, ancientbricks);
        chunkPrimer.setBlock(i + 15, j + 0, k + 14, ancientbricks);
        chunkPrimer.setBlock(i + 15, j + 0, k + 15, ancientbricks);
        chunkPrimer.setBlock(i + 15, j + 1, k + 0, arcaniteMetal);
        chunkPrimer.setBlock(i + 15, j + 1, k + 1, arcaniumSoulSludge);
        chunkPrimer.setBlock(i + 15, j + 1, k + 2, arcaniumSoulSludge);
        chunkPrimer.setBlock(i + 15, j + 1, k + 3, arcaniteMetal);
        chunkPrimer.setBlock(i + 15, j + 1, k + 4, arcaniumSoulSludge);
        chunkPrimer.setBlock(i + 15, j + 1, k + 5, arcaniumSoulSludge);
        chunkPrimer.setBlock(i + 15, j + 1, k + 6, arcaniteMetal);
        chunkPrimer.setBlock(i + 15, j + 1, k + 9, arcaniteMetal);
        chunkPrimer.setBlock(i + 15, j + 1, k + 10, arcaniumSoulSludge);
        chunkPrimer.setBlock(i + 15, j + 1, k + 11, arcaniumSoulSludge);
        chunkPrimer.setBlock(i + 15, j + 1, k + 12, arcaniteMetal);
        chunkPrimer.setBlock(i + 15, j + 1, k + 13, arcaniumSoulSludge);
        chunkPrimer.setBlock(i + 15, j + 1, k + 14, arcaniumSoulSludge);
        chunkPrimer.setBlock(i + 15, j + 1, k + 15, arcaniteMetal);
        chunkPrimer.setBlock(i + 15, j + 2, k + 0, arcaniteMetal);
        chunkPrimer.setBlock(i + 15, j + 2, k + 1, arcaniumSoulSludge);
        chunkPrimer.setBlock(i + 15, j + 2, k + 2, arcaniumSoulSludge);
        chunkPrimer.setBlock(i + 15, j + 2, k + 3, arcaniteMetal);
        chunkPrimer.setBlock(i + 15, j + 2, k + 4, arcaniumSoulSludge);
        chunkPrimer.setBlock(i + 15, j + 2, k + 5, arcaniumSoulSludge);
        chunkPrimer.setBlock(i + 15, j + 2, k + 6, arcaniteMetal);
        chunkPrimer.setBlock(i + 15, j + 2, k + 9, arcaniteMetal);
        chunkPrimer.setBlock(i + 15, j + 2, k + 10, arcaniumSoulSludge);
        chunkPrimer.setBlock(i + 15, j + 2, k + 11, arcaniumSoulSludge);
        chunkPrimer.setBlock(i + 15, j + 2, k + 12, arcaniteMetal);
        chunkPrimer.setBlock(i + 15, j + 2, k + 13, arcaniumSoulSludge);
        chunkPrimer.setBlock(i + 15, j + 2, k + 14, arcaniumSoulSludge);
        chunkPrimer.setBlock(i + 15, j + 2, k + 15, arcaniteMetal);
        chunkPrimer.setBlock(i + 15, j + 3, k + 0, arcaniteMetal);
        chunkPrimer.setBlock(i + 15, j + 3, k + 1, arcaniumSoulSludge);
        chunkPrimer.setBlock(i + 15, j + 3, k + 2, arcaniumSoulSludge);
        chunkPrimer.setBlock(i + 15, j + 3, k + 3, arcaniteMetal);
        chunkPrimer.setBlock(i + 15, j + 3, k + 4, arcaniumSoulSludge);
        chunkPrimer.setBlock(i + 15, j + 3, k + 5, arcaniumSoulSludge);
        chunkPrimer.setBlock(i + 15, j + 3, k + 6, arcaniteMetal);
        chunkPrimer.setBlock(i + 15, j + 3, k + 7, arcanaPower);
        chunkPrimer.setBlock(i + 15, j + 3, k + 8, arcanaPower);
        chunkPrimer.setBlock(i + 15, j + 3, k + 9, arcaniteMetal);
        chunkPrimer.setBlock(i + 15, j + 3, k + 10, arcaniumSoulSludge);
        chunkPrimer.setBlock(i + 15, j + 3, k + 11, arcaniumSoulSludge);
        chunkPrimer.setBlock(i + 15, j + 3, k + 12, arcaniteMetal);
        chunkPrimer.setBlock(i + 15, j + 3, k + 13, arcaniumSoulSludge);
        chunkPrimer.setBlock(i + 15, j + 3, k + 14, arcaniumSoulSludge);
        chunkPrimer.setBlock(i + 15, j + 3, k + 15, arcaniteMetal);
        chunkPrimer.setBlock(i + 15, j + 4, k + 0, arcaniteMetal);
        chunkPrimer.setBlock(i + 15, j + 4, k + 1, arcaniumSoulSludge);
        chunkPrimer.setBlock(i + 15, j + 4, k + 2, arcaniumSoulSludge);
        chunkPrimer.setBlock(i + 15, j + 4, k + 3, arcaniteMetal);
        chunkPrimer.setBlock(i + 15, j + 4, k + 4, arcaniumSoulSludge);
        chunkPrimer.setBlock(i + 15, j + 4, k + 5, arcaniumSoulSludge);
        chunkPrimer.setBlock(i + 15, j + 4, k + 6, arcaniteMetal);
        chunkPrimer.setBlock(i + 15, j + 4, k + 7, arcaniumSoulSludge);
        chunkPrimer.setBlock(i + 15, j + 4, k + 8, arcaniumSoulSludge);
        chunkPrimer.setBlock(i + 15, j + 4, k + 9, arcaniteMetal);
        chunkPrimer.setBlock(i + 15, j + 4, k + 10, arcaniumSoulSludge);
        chunkPrimer.setBlock(i + 15, j + 4, k + 11, arcaniumSoulSludge);
        chunkPrimer.setBlock(i + 15, j + 4, k + 12, arcaniteMetal);
        chunkPrimer.setBlock(i + 15, j + 4, k + 13, arcaniumSoulSludge);
        chunkPrimer.setBlock(i + 15, j + 4, k + 14, arcaniumSoulSludge);
        chunkPrimer.setBlock(i + 15, j + 4, k + 15, arcaniteMetal);
        chunkPrimer.setBlock(i + 15, j + 5, k + 0, arcaniteMetal);
        chunkPrimer.setBlock(i + 15, j + 5, k + 1, arcaniumSoulSludge);
        chunkPrimer.setBlock(i + 15, j + 5, k + 2, arcaniumSoulSludge);
        chunkPrimer.setBlock(i + 15, j + 5, k + 3, arcaniteMetal);
        chunkPrimer.setBlock(i + 15, j + 5, k + 4, arcaniumSoulSludge);
        chunkPrimer.setBlock(i + 15, j + 5, k + 5, arcaniumSoulSludge);
        chunkPrimer.setBlock(i + 15, j + 5, k + 6, arcaniteMetal);
        chunkPrimer.setBlock(i + 15, j + 5, k + 7, arcaniumSoulSludge);
        chunkPrimer.setBlock(i + 15, j + 5, k + 8, arcaniumSoulSludge);
        chunkPrimer.setBlock(i + 15, j + 5, k + 9, arcaniteMetal);
        chunkPrimer.setBlock(i + 15, j + 5, k + 10, arcaniumSoulSludge);
        chunkPrimer.setBlock(i + 15, j + 5, k + 11, arcaniumSoulSludge);
        chunkPrimer.setBlock(i + 15, j + 5, k + 12, arcaniteMetal);
        chunkPrimer.setBlock(i + 15, j + 5, k + 13, arcaniumSoulSludge);
        chunkPrimer.setBlock(i + 15, j + 5, k + 14, arcaniumSoulSludge);
        chunkPrimer.setBlock(i + 15, j + 5, k + 15, arcaniteMetal);
        chunkPrimer.setBlock(i + 15, j + 6, k + 0, arcaniteMetal);
        chunkPrimer.setBlock(i + 15, j + 6, k + 1, arcaniumSoulSludge);
        chunkPrimer.setBlock(i + 15, j + 6, k + 2, arcaniumSoulSludge);
        chunkPrimer.setBlock(i + 15, j + 6, k + 3, arcaniteMetal);
        chunkPrimer.setBlock(i + 15, j + 6, k + 4, arcaniumSoulSludge);
        chunkPrimer.setBlock(i + 15, j + 6, k + 5, arcaniumSoulSludge);
        chunkPrimer.setBlock(i + 15, j + 6, k + 6, arcaniteMetal);
        chunkPrimer.setBlock(i + 15, j + 6, k + 7, arcaniumSoulSludge);
        chunkPrimer.setBlock(i + 15, j + 6, k + 8, arcaniumSoulSludge);
        chunkPrimer.setBlock(i + 15, j + 6, k + 9, arcaniteMetal);
        chunkPrimer.setBlock(i + 15, j + 6, k + 10, arcaniumSoulSludge);
        chunkPrimer.setBlock(i + 15, j + 6, k + 11, arcaniumSoulSludge);
        chunkPrimer.setBlock(i + 15, j + 6, k + 12, arcaniteMetal);
        chunkPrimer.setBlock(i + 15, j + 6, k + 13, arcaniumSoulSludge);
        chunkPrimer.setBlock(i + 15, j + 6, k + 14, arcaniumSoulSludge);
        chunkPrimer.setBlock(i + 15, j + 6, k + 15, arcaniteMetal);
        chunkPrimer.setBlock(i + 15, j + 7, k + 0, arcaniteMetal);
        chunkPrimer.setBlock(i + 15, j + 7, k + 1, arcaniumSoulSludge);
        chunkPrimer.setBlock(i + 15, j + 7, k + 2, arcaniumSoulSludge);
        chunkPrimer.setBlock(i + 15, j + 7, k + 3, arcaniteMetal);
        chunkPrimer.setBlock(i + 15, j + 7, k + 4, arcaniumSoulSludge);
        chunkPrimer.setBlock(i + 15, j + 7, k + 5, arcaniumSoulSludge);
        chunkPrimer.setBlock(i + 15, j + 7, k + 6, arcaniteMetal);
        chunkPrimer.setBlock(i + 15, j + 7, k + 7, arcaniumSoulSludge);
        chunkPrimer.setBlock(i + 15, j + 7, k + 8, arcaniumSoulSludge);
        chunkPrimer.setBlock(i + 15, j + 7, k + 9, arcaniteMetal);
        chunkPrimer.setBlock(i + 15, j + 7, k + 10, arcaniumSoulSludge);
        chunkPrimer.setBlock(i + 15, j + 7, k + 11, arcaniumSoulSludge);
        chunkPrimer.setBlock(i + 15, j + 7, k + 12, arcaniteMetal);
        chunkPrimer.setBlock(i + 15, j + 7, k + 13, arcaniumSoulSludge);
        chunkPrimer.setBlock(i + 15, j + 7, k + 14, arcaniumSoulSludge);
        chunkPrimer.setBlock(i + 15, j + 7, k + 15, arcaniteMetal);
        chunkPrimer.setBlock(i + 15, j + 8, k + 0, ancientstone);
        chunkPrimer.setBlock(i + 15, j + 8, k + 1, ancientstone);
        chunkPrimer.setBlock(i + 15, j + 8, k + 2, ancientstone);
        chunkPrimer.setBlock(i + 15, j + 8, k + 3, ancientstone);
        chunkPrimer.setBlock(i + 15, j + 8, k + 4, ancientstone);
        chunkPrimer.setBlock(i + 15, j + 8, k + 5, ancientstone);
        chunkPrimer.setBlock(i + 15, j + 8, k + 6, ancientstone);
        chunkPrimer.setBlock(i + 15, j + 8, k + 7, ancientstone);
        chunkPrimer.setBlock(i + 15, j + 8, k + 8, ancientstone);
        chunkPrimer.setBlock(i + 15, j + 8, k + 9, ancientstone);
        chunkPrimer.setBlock(i + 15, j + 8, k + 10, ancientstone);
        chunkPrimer.setBlock(i + 15, j + 8, k + 11, ancientstone);
        chunkPrimer.setBlock(i + 15, j + 8, k + 12, ancientstone);
        chunkPrimer.setBlock(i + 15, j + 8, k + 13, ancientstone);
        chunkPrimer.setBlock(i + 15, j + 8, k + 14, ancientstone);
        chunkPrimer.setBlock(i + 15, j + 8, k + 15, ancientstone);
        chunkPrimer.setBlock(i + 15, j + 9, k + 0, soulStone);
        chunkPrimer.setBlock(i + 15, j + 9, k + 1, soulStone);
        chunkPrimer.setBlock(i + 15, j + 9, k + 2, soulStone);
        chunkPrimer.setBlock(i + 15, j + 9, k + 3, soulStone);
        chunkPrimer.setBlock(i + 15, j + 9, k + 4, soulStone);
        chunkPrimer.setBlock(i + 15, j + 9, k + 5, soulStone);
        chunkPrimer.setBlock(i + 15, j + 9, k + 6, soulStone);
        chunkPrimer.setBlock(i + 15, j + 9, k + 7, soulStone);
        chunkPrimer.setBlock(i + 15, j + 9, k + 8, soulStone);
        chunkPrimer.setBlock(i + 15, j + 9, k + 9, soulStone);
        chunkPrimer.setBlock(i + 15, j + 9, k + 10, soulStone);
        chunkPrimer.setBlock(i + 15, j + 9, k + 11, soulStone);
        chunkPrimer.setBlock(i + 15, j + 9, k + 12, soulStone);
        chunkPrimer.setBlock(i + 15, j + 9, k + 13, soulStone);
        chunkPrimer.setBlock(i + 15, j + 9, k + 14, soulStone);
        chunkPrimer.setBlock(i + 15, j + 9, k + 15, soulStone);
        chunkPrimer.setBlock(i + 15, j + 10, k + 0, soulStone);
        chunkPrimer.setBlock(i + 15, j + 10, k + 1, soulStone);
        chunkPrimer.setBlock(i + 15, j + 10, k + 2, soulStone);
        chunkPrimer.setBlock(i + 15, j + 10, k + 3, soulStone);
        chunkPrimer.setBlock(i + 15, j + 10, k + 4, soulStone);
        chunkPrimer.setBlock(i + 15, j + 10, k + 5, soulStone);
        chunkPrimer.setBlock(i + 15, j + 10, k + 6, soulStone);
        chunkPrimer.setBlock(i + 15, j + 10, k + 7, soulStone);
        chunkPrimer.setBlock(i + 15, j + 10, k + 8, soulStone);
        chunkPrimer.setBlock(i + 15, j + 10, k + 9, soulStone);
        chunkPrimer.setBlock(i + 15, j + 10, k + 10, soulStone);
        chunkPrimer.setBlock(i + 15, j + 10, k + 11, soulStone);
        chunkPrimer.setBlock(i + 15, j + 10, k + 12, soulStone);
        chunkPrimer.setBlock(i + 15, j + 10, k + 13, soulStone);
        chunkPrimer.setBlock(i + 15, j + 10, k + 14, soulStone);
        chunkPrimer.setBlock(i + 15, j + 10, k + 15, soulStone);
        chunkPrimer.setBlock(i + 15, j + 11, k + 0, soulStone);
        chunkPrimer.setBlock(i + 15, j + 11, k + 1, soulStone);
        chunkPrimer.setBlock(i + 15, j + 11, k + 2, soulStone);
        chunkPrimer.setBlock(i + 15, j + 11, k + 3, soulStone);
        chunkPrimer.setBlock(i + 15, j + 11, k + 4, soulStone);
        chunkPrimer.setBlock(i + 15, j + 11, k + 5, soulStone);
        chunkPrimer.setBlock(i + 15, j + 11, k + 6, soulStone);
        chunkPrimer.setBlock(i + 15, j + 11, k + 7, soulStone);
        chunkPrimer.setBlock(i + 15, j + 11, k + 8, soulStone);
        chunkPrimer.setBlock(i + 15, j + 11, k + 9, soulStone);
        chunkPrimer.setBlock(i + 15, j + 11, k + 10, soulStone);
        chunkPrimer.setBlock(i + 15, j + 11, k + 11, soulStone);
        chunkPrimer.setBlock(i + 15, j + 11, k + 12, soulStone);
        chunkPrimer.setBlock(i + 15, j + 11, k + 13, soulStone);
        chunkPrimer.setBlock(i + 15, j + 11, k + 14, soulStone);
        chunkPrimer.setBlock(i + 15, j + 11, k + 15, soulStone);
        chunkPrimer.setBlock(i + 15, j + 12, k + 0, ancientbricks);
        chunkPrimer.setBlock(i + 15, j + 12, k + 1, ancientbricks);
        chunkPrimer.setBlock(i + 15, j + 12, k + 2, ancientbricks);
        chunkPrimer.setBlock(i + 15, j + 12, k + 3, ancientbricks);
        chunkPrimer.setBlock(i + 15, j + 12, k + 4, ancientbricks);
        chunkPrimer.setBlock(i + 15, j + 12, k + 5, ancientbricks);
        chunkPrimer.setBlock(i + 15, j + 12, k + 6, ancientbricks);
        chunkPrimer.setBlock(i + 15, j + 12, k + 7, ancientbricks);
        chunkPrimer.setBlock(i + 15, j + 12, k + 8, ancientbricks);
        chunkPrimer.setBlock(i + 15, j + 12, k + 9, ancientbricks);
        chunkPrimer.setBlock(i + 15, j + 12, k + 10, ancientbricks);
        chunkPrimer.setBlock(i + 15, j + 12, k + 11, ancientbricks);
        chunkPrimer.setBlock(i + 15, j + 12, k + 12, ancientbricks);
        chunkPrimer.setBlock(i + 15, j + 12, k + 13, ancientbricks);
        chunkPrimer.setBlock(i + 15, j + 12, k + 14, ancientbricks);
        chunkPrimer.setBlock(i + 15, j + 12, k + 15, ancientbricks);
        chunkPrimer.setBlock(i + 15, j + 13, k + 0, ancientstone);
        chunkPrimer.setBlock(i + 15, j + 13, k + 1, ancientstone);
        chunkPrimer.setBlock(i + 15, j + 13, k + 2, ancientstone);
        chunkPrimer.setBlock(i + 15, j + 13, k + 3, ancientstone);
        chunkPrimer.setBlock(i + 15, j + 13, k + 4, ancientstone);
        chunkPrimer.setBlock(i + 15, j + 13, k + 5, ancientstone);
        chunkPrimer.setBlock(i + 15, j + 13, k + 6, ancientstone);
        chunkPrimer.setBlock(i + 15, j + 13, k + 7, ancientstone);
        chunkPrimer.setBlock(i + 15, j + 13, k + 8, ancientstone);
        chunkPrimer.setBlock(i + 15, j + 13, k + 9, ancientstone);
        chunkPrimer.setBlock(i + 15, j + 13, k + 10, ancientstone);
        chunkPrimer.setBlock(i + 15, j + 13, k + 11, ancientstone);
        chunkPrimer.setBlock(i + 15, j + 13, k + 12, ancientstone);
        chunkPrimer.setBlock(i + 15, j + 13, k + 13, ancientstone);
        chunkPrimer.setBlock(i + 15, j + 13, k + 14, ancientstone);
        chunkPrimer.setBlock(i + 15, j + 13, k + 15, ancientstone);
        chunkPrimer.setBlock(i + 15, j + 14, k + 0, ancientstone);
        chunkPrimer.setBlock(i + 15, j + 14, k + 1, ancientstone);
        chunkPrimer.setBlock(i + 15, j + 14, k + 2, ancientstone);
        chunkPrimer.setBlock(i + 15, j + 14, k + 3, ancientstone);
        chunkPrimer.setBlock(i + 15, j + 14, k + 4, ancientstone);
        chunkPrimer.setBlock(i + 15, j + 14, k + 5, ancientstone);
        chunkPrimer.setBlock(i + 15, j + 14, k + 6, ancientstone);
        chunkPrimer.setBlock(i + 15, j + 14, k + 7, ancientstone);
        chunkPrimer.setBlock(i + 15, j + 14, k + 8, ancientstone);
        chunkPrimer.setBlock(i + 15, j + 14, k + 9, ancientstone);
        chunkPrimer.setBlock(i + 15, j + 14, k + 10, ancientstone);
        chunkPrimer.setBlock(i + 15, j + 14, k + 11, ancientstone);
        chunkPrimer.setBlock(i + 15, j + 14, k + 12, ancientstone);
        chunkPrimer.setBlock(i + 15, j + 14, k + 13, ancientstone);
        chunkPrimer.setBlock(i + 15, j + 14, k + 14, ancientstone);
        chunkPrimer.setBlock(i + 15, j + 14, k + 15, ancientstone);
        chunkPrimer.setBlock(i + 15, j + 15, k + 0, ancientstone);
        chunkPrimer.setBlock(i + 15, j + 15, k + 1, ancientstone);
        chunkPrimer.setBlock(i + 15, j + 15, k + 2, ancientstone);
        chunkPrimer.setBlock(i + 15, j + 15, k + 3, ancientstone);
        chunkPrimer.setBlock(i + 15, j + 15, k + 4, ancientstone);
        chunkPrimer.setBlock(i + 15, j + 15, k + 5, ancientstone);
        chunkPrimer.setBlock(i + 15, j + 15, k + 6, ancientstone);
        chunkPrimer.setBlock(i + 15, j + 15, k + 7, ancientstone);
        chunkPrimer.setBlock(i + 15, j + 15, k + 8, ancientstone);
        chunkPrimer.setBlock(i + 15, j + 15, k + 9, ancientstone);
        chunkPrimer.setBlock(i + 15, j + 15, k + 10, ancientstone);
        chunkPrimer.setBlock(i + 15, j + 15, k + 11, ancientstone);
        chunkPrimer.setBlock(i + 15, j + 15, k + 12, ancientstone);
        chunkPrimer.setBlock(i + 15, j + 15, k + 13, ancientstone);
        chunkPrimer.setBlock(i + 15, j + 15, k + 14, ancientstone);
        chunkPrimer.setBlock(i + 15, j + 15, k + 15, ancientstone);
        return true;
    }
}

